[2023-08-29T19:06:14.486+0000] {processor.py:157} INFO - Started process (PID=168) to work on /opt/airflow/dags/test_data_migration.py
[2023-08-29T19:06:14.487+0000] {processor.py:829} INFO - Processing file /opt/airflow/dags/test_data_migration.py for tasks to queue
[2023-08-29T19:06:14.489+0000] {logging_mixin.py:151} INFO - [2023-08-29T19:06:14.489+0000] {dagbag.py:539} INFO - Filling up the DagBag from /opt/airflow/dags/test_data_migration.py
[2023-08-29T19:06:14.542+0000] {logging_mixin.py:151} INFO - [2023-08-29T19:06:14.534+0000] {dagbag.py:347} ERROR - Failed to import: /opt/airflow/dags/test_data_migration.py
Traceback (most recent call last):
  File "/home/airflow/.local/lib/python3.8/site-packages/airflow/models/dagbag.py", line 343, in parse
    loader.exec_module(new_module)
  File "<frozen importlib._bootstrap_external>", line 843, in exec_module
  File "<frozen importlib._bootstrap>", line 219, in _call_with_frames_removed
  File "/opt/airflow/dags/test_data_migration.py", line 6, in <module>
    from model import Connection
  File "/opt/airflow/dags/model.py", line 5, in <module>
    from geoalchemy2 import Geometry
ModuleNotFoundError: No module named 'geoalchemy2'
[2023-08-29T19:06:14.543+0000] {processor.py:841} WARNING - No viable dags retrieved from /opt/airflow/dags/test_data_migration.py
[2023-08-29T19:06:14.565+0000] {processor.py:179} INFO - Processing /opt/airflow/dags/test_data_migration.py took 0.082 seconds
[2023-08-29T19:06:44.983+0000] {processor.py:157} INFO - Started process (PID=184) to work on /opt/airflow/dags/test_data_migration.py
[2023-08-29T19:06:44.985+0000] {processor.py:829} INFO - Processing file /opt/airflow/dags/test_data_migration.py for tasks to queue
[2023-08-29T19:06:44.987+0000] {logging_mixin.py:151} INFO - [2023-08-29T19:06:44.987+0000] {dagbag.py:539} INFO - Filling up the DagBag from /opt/airflow/dags/test_data_migration.py
[2023-08-29T19:06:45.032+0000] {logging_mixin.py:151} INFO - [2023-08-29T19:06:45.028+0000] {dagbag.py:347} ERROR - Failed to import: /opt/airflow/dags/test_data_migration.py
Traceback (most recent call last):
  File "/home/airflow/.local/lib/python3.8/site-packages/airflow/models/dagbag.py", line 343, in parse
    loader.exec_module(new_module)
  File "<frozen importlib._bootstrap_external>", line 843, in exec_module
  File "<frozen importlib._bootstrap>", line 219, in _call_with_frames_removed
  File "/opt/airflow/dags/test_data_migration.py", line 6, in <module>
    from model import Connection
  File "/opt/airflow/dags/model.py", line 5, in <module>
    from geoalchemy2 import Geometry
ModuleNotFoundError: No module named 'geoalchemy2'
[2023-08-29T19:06:45.034+0000] {processor.py:841} WARNING - No viable dags retrieved from /opt/airflow/dags/test_data_migration.py
[2023-08-29T19:06:45.051+0000] {processor.py:179} INFO - Processing /opt/airflow/dags/test_data_migration.py took 0.071 seconds
[2023-08-29T19:07:15.525+0000] {processor.py:157} INFO - Started process (PID=200) to work on /opt/airflow/dags/test_data_migration.py
[2023-08-29T19:07:15.527+0000] {processor.py:829} INFO - Processing file /opt/airflow/dags/test_data_migration.py for tasks to queue
[2023-08-29T19:07:15.529+0000] {logging_mixin.py:151} INFO - [2023-08-29T19:07:15.529+0000] {dagbag.py:539} INFO - Filling up the DagBag from /opt/airflow/dags/test_data_migration.py
[2023-08-29T19:07:15.571+0000] {logging_mixin.py:151} INFO - [2023-08-29T19:07:15.566+0000] {dagbag.py:347} ERROR - Failed to import: /opt/airflow/dags/test_data_migration.py
Traceback (most recent call last):
  File "/home/airflow/.local/lib/python3.8/site-packages/airflow/models/dagbag.py", line 343, in parse
    loader.exec_module(new_module)
  File "<frozen importlib._bootstrap_external>", line 843, in exec_module
  File "<frozen importlib._bootstrap>", line 219, in _call_with_frames_removed
  File "/opt/airflow/dags/test_data_migration.py", line 6, in <module>
    from model import Connection
  File "/opt/airflow/dags/model.py", line 5, in <module>
    from geoalchemy2 import Geometry
ModuleNotFoundError: No module named 'geoalchemy2'
[2023-08-29T19:07:15.574+0000] {processor.py:841} WARNING - No viable dags retrieved from /opt/airflow/dags/test_data_migration.py
[2023-08-29T19:07:15.591+0000] {processor.py:179} INFO - Processing /opt/airflow/dags/test_data_migration.py took 0.069 seconds
[2023-08-29T19:07:46.139+0000] {processor.py:157} INFO - Started process (PID=216) to work on /opt/airflow/dags/test_data_migration.py
[2023-08-29T19:07:46.142+0000] {processor.py:829} INFO - Processing file /opt/airflow/dags/test_data_migration.py for tasks to queue
[2023-08-29T19:07:46.145+0000] {logging_mixin.py:151} INFO - [2023-08-29T19:07:46.144+0000] {dagbag.py:539} INFO - Filling up the DagBag from /opt/airflow/dags/test_data_migration.py
[2023-08-29T19:07:46.205+0000] {logging_mixin.py:151} INFO - [2023-08-29T19:07:46.202+0000] {dagbag.py:347} ERROR - Failed to import: /opt/airflow/dags/test_data_migration.py
Traceback (most recent call last):
  File "/home/airflow/.local/lib/python3.8/site-packages/airflow/models/dagbag.py", line 343, in parse
    loader.exec_module(new_module)
  File "<frozen importlib._bootstrap_external>", line 843, in exec_module
  File "<frozen importlib._bootstrap>", line 219, in _call_with_frames_removed
  File "/opt/airflow/dags/test_data_migration.py", line 6, in <module>
    from model import Connection
  File "/opt/airflow/dags/model.py", line 5, in <module>
    from geoalchemy2 import Geometry
ModuleNotFoundError: No module named 'geoalchemy2'
[2023-08-29T19:07:46.207+0000] {processor.py:841} WARNING - No viable dags retrieved from /opt/airflow/dags/test_data_migration.py
[2023-08-29T19:07:46.225+0000] {processor.py:179} INFO - Processing /opt/airflow/dags/test_data_migration.py took 0.091 seconds
[2023-08-29T19:08:16.684+0000] {processor.py:157} INFO - Started process (PID=232) to work on /opt/airflow/dags/test_data_migration.py
[2023-08-29T19:08:16.687+0000] {processor.py:829} INFO - Processing file /opt/airflow/dags/test_data_migration.py for tasks to queue
[2023-08-29T19:08:16.690+0000] {logging_mixin.py:151} INFO - [2023-08-29T19:08:16.689+0000] {dagbag.py:539} INFO - Filling up the DagBag from /opt/airflow/dags/test_data_migration.py
[2023-08-29T19:08:16.734+0000] {logging_mixin.py:151} INFO - [2023-08-29T19:08:16.731+0000] {dagbag.py:347} ERROR - Failed to import: /opt/airflow/dags/test_data_migration.py
Traceback (most recent call last):
  File "/home/airflow/.local/lib/python3.8/site-packages/airflow/models/dagbag.py", line 343, in parse
    loader.exec_module(new_module)
  File "<frozen importlib._bootstrap_external>", line 843, in exec_module
  File "<frozen importlib._bootstrap>", line 219, in _call_with_frames_removed
  File "/opt/airflow/dags/test_data_migration.py", line 6, in <module>
    from model import Connection
  File "/opt/airflow/dags/model.py", line 5, in <module>
    from geoalchemy2 import Geometry
ModuleNotFoundError: No module named 'geoalchemy2'
[2023-08-29T19:08:16.735+0000] {processor.py:841} WARNING - No viable dags retrieved from /opt/airflow/dags/test_data_migration.py
[2023-08-29T19:08:16.751+0000] {processor.py:179} INFO - Processing /opt/airflow/dags/test_data_migration.py took 0.070 seconds
[2023-08-29T19:08:47.189+0000] {processor.py:157} INFO - Started process (PID=248) to work on /opt/airflow/dags/test_data_migration.py
[2023-08-29T19:08:47.191+0000] {processor.py:829} INFO - Processing file /opt/airflow/dags/test_data_migration.py for tasks to queue
[2023-08-29T19:08:47.193+0000] {logging_mixin.py:151} INFO - [2023-08-29T19:08:47.193+0000] {dagbag.py:539} INFO - Filling up the DagBag from /opt/airflow/dags/test_data_migration.py
[2023-08-29T19:08:47.234+0000] {logging_mixin.py:151} INFO - [2023-08-29T19:08:47.231+0000] {dagbag.py:347} ERROR - Failed to import: /opt/airflow/dags/test_data_migration.py
Traceback (most recent call last):
  File "/home/airflow/.local/lib/python3.8/site-packages/airflow/models/dagbag.py", line 343, in parse
    loader.exec_module(new_module)
  File "<frozen importlib._bootstrap_external>", line 843, in exec_module
  File "<frozen importlib._bootstrap>", line 219, in _call_with_frames_removed
  File "/opt/airflow/dags/test_data_migration.py", line 6, in <module>
    from model import Connection
  File "/opt/airflow/dags/model.py", line 5, in <module>
    from geoalchemy2 import Geometry
ModuleNotFoundError: No module named 'geoalchemy2'
[2023-08-29T19:08:47.237+0000] {processor.py:841} WARNING - No viable dags retrieved from /opt/airflow/dags/test_data_migration.py
[2023-08-29T19:08:47.252+0000] {processor.py:179} INFO - Processing /opt/airflow/dags/test_data_migration.py took 0.065 seconds
[2023-08-29T19:09:17.861+0000] {processor.py:157} INFO - Started process (PID=264) to work on /opt/airflow/dags/test_data_migration.py
[2023-08-29T19:09:17.863+0000] {processor.py:829} INFO - Processing file /opt/airflow/dags/test_data_migration.py for tasks to queue
[2023-08-29T19:09:17.865+0000] {logging_mixin.py:151} INFO - [2023-08-29T19:09:17.864+0000] {dagbag.py:539} INFO - Filling up the DagBag from /opt/airflow/dags/test_data_migration.py
[2023-08-29T19:09:17.906+0000] {logging_mixin.py:151} INFO - [2023-08-29T19:09:17.902+0000] {dagbag.py:347} ERROR - Failed to import: /opt/airflow/dags/test_data_migration.py
Traceback (most recent call last):
  File "/home/airflow/.local/lib/python3.8/site-packages/airflow/models/dagbag.py", line 343, in parse
    loader.exec_module(new_module)
  File "<frozen importlib._bootstrap_external>", line 843, in exec_module
  File "<frozen importlib._bootstrap>", line 219, in _call_with_frames_removed
  File "/opt/airflow/dags/test_data_migration.py", line 6, in <module>
    from model import Connection
  File "/opt/airflow/dags/model.py", line 5, in <module>
    from geoalchemy2 import Geometry
ModuleNotFoundError: No module named 'geoalchemy2'
[2023-08-29T19:09:17.907+0000] {processor.py:841} WARNING - No viable dags retrieved from /opt/airflow/dags/test_data_migration.py
[2023-08-29T19:09:17.922+0000] {processor.py:179} INFO - Processing /opt/airflow/dags/test_data_migration.py took 0.067 seconds
[2023-08-29T19:09:48.449+0000] {processor.py:157} INFO - Started process (PID=280) to work on /opt/airflow/dags/test_data_migration.py
[2023-08-29T19:09:48.451+0000] {processor.py:829} INFO - Processing file /opt/airflow/dags/test_data_migration.py for tasks to queue
[2023-08-29T19:09:48.454+0000] {logging_mixin.py:151} INFO - [2023-08-29T19:09:48.452+0000] {dagbag.py:539} INFO - Filling up the DagBag from /opt/airflow/dags/test_data_migration.py
[2023-08-29T19:09:48.499+0000] {logging_mixin.py:151} INFO - [2023-08-29T19:09:48.496+0000] {dagbag.py:347} ERROR - Failed to import: /opt/airflow/dags/test_data_migration.py
Traceback (most recent call last):
  File "/home/airflow/.local/lib/python3.8/site-packages/airflow/models/dagbag.py", line 343, in parse
    loader.exec_module(new_module)
  File "<frozen importlib._bootstrap_external>", line 843, in exec_module
  File "<frozen importlib._bootstrap>", line 219, in _call_with_frames_removed
  File "/opt/airflow/dags/test_data_migration.py", line 6, in <module>
    from model import Connection
  File "/opt/airflow/dags/model.py", line 5, in <module>
    from geoalchemy2 import Geometry
ModuleNotFoundError: No module named 'geoalchemy2'
[2023-08-29T19:09:48.500+0000] {processor.py:841} WARNING - No viable dags retrieved from /opt/airflow/dags/test_data_migration.py
[2023-08-29T19:09:48.515+0000] {processor.py:179} INFO - Processing /opt/airflow/dags/test_data_migration.py took 0.069 seconds
[2023-08-29T19:10:19.013+0000] {processor.py:157} INFO - Started process (PID=296) to work on /opt/airflow/dags/test_data_migration.py
[2023-08-29T19:10:19.015+0000] {processor.py:829} INFO - Processing file /opt/airflow/dags/test_data_migration.py for tasks to queue
[2023-08-29T19:10:19.016+0000] {logging_mixin.py:151} INFO - [2023-08-29T19:10:19.016+0000] {dagbag.py:539} INFO - Filling up the DagBag from /opt/airflow/dags/test_data_migration.py
[2023-08-29T19:10:19.057+0000] {logging_mixin.py:151} INFO - [2023-08-29T19:10:19.053+0000] {dagbag.py:347} ERROR - Failed to import: /opt/airflow/dags/test_data_migration.py
Traceback (most recent call last):
  File "/home/airflow/.local/lib/python3.8/site-packages/airflow/models/dagbag.py", line 343, in parse
    loader.exec_module(new_module)
  File "<frozen importlib._bootstrap_external>", line 843, in exec_module
  File "<frozen importlib._bootstrap>", line 219, in _call_with_frames_removed
  File "/opt/airflow/dags/test_data_migration.py", line 6, in <module>
    from model import Connection
  File "/opt/airflow/dags/model.py", line 5, in <module>
    from geoalchemy2 import Geometry
ModuleNotFoundError: No module named 'geoalchemy2'
[2023-08-29T19:10:19.060+0000] {processor.py:841} WARNING - No viable dags retrieved from /opt/airflow/dags/test_data_migration.py
[2023-08-29T19:10:19.073+0000] {processor.py:179} INFO - Processing /opt/airflow/dags/test_data_migration.py took 0.063 seconds
[2023-08-29T19:10:49.524+0000] {processor.py:157} INFO - Started process (PID=312) to work on /opt/airflow/dags/test_data_migration.py
[2023-08-29T19:10:49.526+0000] {processor.py:829} INFO - Processing file /opt/airflow/dags/test_data_migration.py for tasks to queue
[2023-08-29T19:10:49.528+0000] {logging_mixin.py:151} INFO - [2023-08-29T19:10:49.527+0000] {dagbag.py:539} INFO - Filling up the DagBag from /opt/airflow/dags/test_data_migration.py
[2023-08-29T19:10:49.567+0000] {logging_mixin.py:151} INFO - [2023-08-29T19:10:49.563+0000] {dagbag.py:347} ERROR - Failed to import: /opt/airflow/dags/test_data_migration.py
Traceback (most recent call last):
  File "/home/airflow/.local/lib/python3.8/site-packages/airflow/models/dagbag.py", line 343, in parse
    loader.exec_module(new_module)
  File "<frozen importlib._bootstrap_external>", line 843, in exec_module
  File "<frozen importlib._bootstrap>", line 219, in _call_with_frames_removed
  File "/opt/airflow/dags/test_data_migration.py", line 6, in <module>
    from model import Connection
  File "/opt/airflow/dags/model.py", line 5, in <module>
    from geoalchemy2 import Geometry
ModuleNotFoundError: No module named 'geoalchemy2'
[2023-08-29T19:10:49.568+0000] {processor.py:841} WARNING - No viable dags retrieved from /opt/airflow/dags/test_data_migration.py
[2023-08-29T19:10:49.585+0000] {processor.py:179} INFO - Processing /opt/airflow/dags/test_data_migration.py took 0.066 seconds
[2023-08-29T19:11:20.219+0000] {processor.py:157} INFO - Started process (PID=328) to work on /opt/airflow/dags/test_data_migration.py
[2023-08-29T19:11:20.221+0000] {processor.py:829} INFO - Processing file /opt/airflow/dags/test_data_migration.py for tasks to queue
[2023-08-29T19:11:20.223+0000] {logging_mixin.py:151} INFO - [2023-08-29T19:11:20.223+0000] {dagbag.py:539} INFO - Filling up the DagBag from /opt/airflow/dags/test_data_migration.py
[2023-08-29T19:11:20.265+0000] {logging_mixin.py:151} INFO - [2023-08-29T19:11:20.262+0000] {dagbag.py:347} ERROR - Failed to import: /opt/airflow/dags/test_data_migration.py
Traceback (most recent call last):
  File "/home/airflow/.local/lib/python3.8/site-packages/airflow/models/dagbag.py", line 343, in parse
    loader.exec_module(new_module)
  File "<frozen importlib._bootstrap_external>", line 843, in exec_module
  File "<frozen importlib._bootstrap>", line 219, in _call_with_frames_removed
  File "/opt/airflow/dags/test_data_migration.py", line 6, in <module>
    from model import Connection
  File "/opt/airflow/dags/model.py", line 5, in <module>
    from geoalchemy2 import Geometry
ModuleNotFoundError: No module named 'geoalchemy2'
[2023-08-29T19:11:20.267+0000] {processor.py:841} WARNING - No viable dags retrieved from /opt/airflow/dags/test_data_migration.py
[2023-08-29T19:11:20.282+0000] {processor.py:179} INFO - Processing /opt/airflow/dags/test_data_migration.py took 0.065 seconds
[2023-08-29T19:11:50.829+0000] {processor.py:157} INFO - Started process (PID=344) to work on /opt/airflow/dags/test_data_migration.py
[2023-08-29T19:11:50.830+0000] {processor.py:829} INFO - Processing file /opt/airflow/dags/test_data_migration.py for tasks to queue
[2023-08-29T19:11:50.832+0000] {logging_mixin.py:151} INFO - [2023-08-29T19:11:50.832+0000] {dagbag.py:539} INFO - Filling up the DagBag from /opt/airflow/dags/test_data_migration.py
[2023-08-29T19:11:50.874+0000] {logging_mixin.py:151} INFO - [2023-08-29T19:11:50.870+0000] {dagbag.py:347} ERROR - Failed to import: /opt/airflow/dags/test_data_migration.py
Traceback (most recent call last):
  File "/home/airflow/.local/lib/python3.8/site-packages/airflow/models/dagbag.py", line 343, in parse
    loader.exec_module(new_module)
  File "<frozen importlib._bootstrap_external>", line 843, in exec_module
  File "<frozen importlib._bootstrap>", line 219, in _call_with_frames_removed
  File "/opt/airflow/dags/test_data_migration.py", line 6, in <module>
    from model import Connection
  File "/opt/airflow/dags/model.py", line 5, in <module>
    from geoalchemy2 import Geometry
ModuleNotFoundError: No module named 'geoalchemy2'
[2023-08-29T19:11:50.875+0000] {processor.py:841} WARNING - No viable dags retrieved from /opt/airflow/dags/test_data_migration.py
[2023-08-29T19:11:50.889+0000] {processor.py:179} INFO - Processing /opt/airflow/dags/test_data_migration.py took 0.067 seconds
[2023-08-29T19:12:21.379+0000] {processor.py:157} INFO - Started process (PID=360) to work on /opt/airflow/dags/test_data_migration.py
[2023-08-29T19:12:21.381+0000] {processor.py:829} INFO - Processing file /opt/airflow/dags/test_data_migration.py for tasks to queue
[2023-08-29T19:12:21.382+0000] {logging_mixin.py:151} INFO - [2023-08-29T19:12:21.382+0000] {dagbag.py:539} INFO - Filling up the DagBag from /opt/airflow/dags/test_data_migration.py
[2023-08-29T19:12:21.423+0000] {logging_mixin.py:151} INFO - [2023-08-29T19:12:21.419+0000] {dagbag.py:347} ERROR - Failed to import: /opt/airflow/dags/test_data_migration.py
Traceback (most recent call last):
  File "/home/airflow/.local/lib/python3.8/site-packages/airflow/models/dagbag.py", line 343, in parse
    loader.exec_module(new_module)
  File "<frozen importlib._bootstrap_external>", line 843, in exec_module
  File "<frozen importlib._bootstrap>", line 219, in _call_with_frames_removed
  File "/opt/airflow/dags/test_data_migration.py", line 6, in <module>
    from model import Connection
  File "/opt/airflow/dags/model.py", line 5, in <module>
    from geoalchemy2 import Geometry
ModuleNotFoundError: No module named 'geoalchemy2'
[2023-08-29T19:12:21.424+0000] {processor.py:841} WARNING - No viable dags retrieved from /opt/airflow/dags/test_data_migration.py
[2023-08-29T19:12:21.439+0000] {processor.py:179} INFO - Processing /opt/airflow/dags/test_data_migration.py took 0.063 seconds
[2023-08-29T19:12:51.895+0000] {processor.py:157} INFO - Started process (PID=376) to work on /opt/airflow/dags/test_data_migration.py
[2023-08-29T19:12:51.896+0000] {processor.py:829} INFO - Processing file /opt/airflow/dags/test_data_migration.py for tasks to queue
[2023-08-29T19:12:51.898+0000] {logging_mixin.py:151} INFO - [2023-08-29T19:12:51.897+0000] {dagbag.py:539} INFO - Filling up the DagBag from /opt/airflow/dags/test_data_migration.py
[2023-08-29T19:12:51.939+0000] {logging_mixin.py:151} INFO - [2023-08-29T19:12:51.935+0000] {dagbag.py:347} ERROR - Failed to import: /opt/airflow/dags/test_data_migration.py
Traceback (most recent call last):
  File "/home/airflow/.local/lib/python3.8/site-packages/airflow/models/dagbag.py", line 343, in parse
    loader.exec_module(new_module)
  File "<frozen importlib._bootstrap_external>", line 843, in exec_module
  File "<frozen importlib._bootstrap>", line 219, in _call_with_frames_removed
  File "/opt/airflow/dags/test_data_migration.py", line 6, in <module>
    from model import Connection
  File "/opt/airflow/dags/model.py", line 5, in <module>
    from geoalchemy2 import Geometry
ModuleNotFoundError: No module named 'geoalchemy2'
[2023-08-29T19:12:51.941+0000] {processor.py:841} WARNING - No viable dags retrieved from /opt/airflow/dags/test_data_migration.py
[2023-08-29T19:12:52.034+0000] {processor.py:179} INFO - Processing /opt/airflow/dags/test_data_migration.py took 0.142 seconds
[2023-08-29T19:13:22.543+0000] {processor.py:157} INFO - Started process (PID=392) to work on /opt/airflow/dags/test_data_migration.py
[2023-08-29T19:13:22.545+0000] {processor.py:829} INFO - Processing file /opt/airflow/dags/test_data_migration.py for tasks to queue
[2023-08-29T19:13:22.546+0000] {logging_mixin.py:151} INFO - [2023-08-29T19:13:22.546+0000] {dagbag.py:539} INFO - Filling up the DagBag from /opt/airflow/dags/test_data_migration.py
[2023-08-29T19:13:22.666+0000] {logging_mixin.py:151} INFO - [2023-08-29T19:13:22.662+0000] {dagbag.py:347} ERROR - Failed to import: /opt/airflow/dags/test_data_migration.py
Traceback (most recent call last):
  File "/home/airflow/.local/lib/python3.8/site-packages/airflow/models/dagbag.py", line 343, in parse
    loader.exec_module(new_module)
  File "<frozen importlib._bootstrap_external>", line 843, in exec_module
  File "<frozen importlib._bootstrap>", line 219, in _call_with_frames_removed
  File "/opt/airflow/dags/test_data_migration.py", line 6, in <module>
    from model import Connection
  File "/opt/airflow/dags/model.py", line 5, in <module>
    from geoalchemy2 import Geometry
ModuleNotFoundError: No module named 'geoalchemy2'
[2023-08-29T19:13:22.667+0000] {processor.py:841} WARNING - No viable dags retrieved from /opt/airflow/dags/test_data_migration.py
[2023-08-29T19:13:22.680+0000] {processor.py:179} INFO - Processing /opt/airflow/dags/test_data_migration.py took 0.144 seconds
[2023-08-29T19:13:53.327+0000] {processor.py:157} INFO - Started process (PID=408) to work on /opt/airflow/dags/test_data_migration.py
[2023-08-29T19:13:53.330+0000] {processor.py:829} INFO - Processing file /opt/airflow/dags/test_data_migration.py for tasks to queue
[2023-08-29T19:13:53.332+0000] {logging_mixin.py:151} INFO - [2023-08-29T19:13:53.331+0000] {dagbag.py:539} INFO - Filling up the DagBag from /opt/airflow/dags/test_data_migration.py
[2023-08-29T19:13:53.387+0000] {logging_mixin.py:151} INFO - [2023-08-29T19:13:53.382+0000] {dagbag.py:347} ERROR - Failed to import: /opt/airflow/dags/test_data_migration.py
Traceback (most recent call last):
  File "/home/airflow/.local/lib/python3.8/site-packages/airflow/models/dagbag.py", line 343, in parse
    loader.exec_module(new_module)
  File "<frozen importlib._bootstrap_external>", line 843, in exec_module
  File "<frozen importlib._bootstrap>", line 219, in _call_with_frames_removed
  File "/opt/airflow/dags/test_data_migration.py", line 6, in <module>
    from model import Connection
  File "/opt/airflow/dags/model.py", line 5, in <module>
    from geoalchemy2 import Geometry
ModuleNotFoundError: No module named 'geoalchemy2'
[2023-08-29T19:13:53.389+0000] {processor.py:841} WARNING - No viable dags retrieved from /opt/airflow/dags/test_data_migration.py
[2023-08-29T19:13:53.407+0000] {processor.py:179} INFO - Processing /opt/airflow/dags/test_data_migration.py took 0.090 seconds
[2023-08-29T19:14:23.847+0000] {processor.py:157} INFO - Started process (PID=424) to work on /opt/airflow/dags/test_data_migration.py
[2023-08-29T19:14:23.849+0000] {processor.py:829} INFO - Processing file /opt/airflow/dags/test_data_migration.py for tasks to queue
[2023-08-29T19:14:23.851+0000] {logging_mixin.py:151} INFO - [2023-08-29T19:14:23.851+0000] {dagbag.py:539} INFO - Filling up the DagBag from /opt/airflow/dags/test_data_migration.py
[2023-08-29T19:14:23.891+0000] {logging_mixin.py:151} INFO - [2023-08-29T19:14:23.888+0000] {dagbag.py:347} ERROR - Failed to import: /opt/airflow/dags/test_data_migration.py
Traceback (most recent call last):
  File "/home/airflow/.local/lib/python3.8/site-packages/airflow/models/dagbag.py", line 343, in parse
    loader.exec_module(new_module)
  File "<frozen importlib._bootstrap_external>", line 843, in exec_module
  File "<frozen importlib._bootstrap>", line 219, in _call_with_frames_removed
  File "/opt/airflow/dags/test_data_migration.py", line 6, in <module>
    from model import Connection
  File "/opt/airflow/dags/model.py", line 5, in <module>
    from geoalchemy2 import Geometry
ModuleNotFoundError: No module named 'geoalchemy2'
[2023-08-29T19:14:23.892+0000] {processor.py:841} WARNING - No viable dags retrieved from /opt/airflow/dags/test_data_migration.py
[2023-08-29T19:14:23.909+0000] {processor.py:179} INFO - Processing /opt/airflow/dags/test_data_migration.py took 0.067 seconds
[2023-08-29T19:14:54.390+0000] {processor.py:157} INFO - Started process (PID=440) to work on /opt/airflow/dags/test_data_migration.py
[2023-08-29T19:14:54.392+0000] {processor.py:829} INFO - Processing file /opt/airflow/dags/test_data_migration.py for tasks to queue
[2023-08-29T19:14:54.393+0000] {logging_mixin.py:151} INFO - [2023-08-29T19:14:54.393+0000] {dagbag.py:539} INFO - Filling up the DagBag from /opt/airflow/dags/test_data_migration.py
[2023-08-29T19:14:54.437+0000] {logging_mixin.py:151} INFO - [2023-08-29T19:14:54.433+0000] {dagbag.py:347} ERROR - Failed to import: /opt/airflow/dags/test_data_migration.py
Traceback (most recent call last):
  File "/home/airflow/.local/lib/python3.8/site-packages/airflow/models/dagbag.py", line 343, in parse
    loader.exec_module(new_module)
  File "<frozen importlib._bootstrap_external>", line 843, in exec_module
  File "<frozen importlib._bootstrap>", line 219, in _call_with_frames_removed
  File "/opt/airflow/dags/test_data_migration.py", line 6, in <module>
    from model import Connection
  File "/opt/airflow/dags/model.py", line 5, in <module>
    from geoalchemy2 import Geometry
ModuleNotFoundError: No module named 'geoalchemy2'
[2023-08-29T19:14:54.439+0000] {processor.py:841} WARNING - No viable dags retrieved from /opt/airflow/dags/test_data_migration.py
[2023-08-29T19:14:54.456+0000] {processor.py:179} INFO - Processing /opt/airflow/dags/test_data_migration.py took 0.069 seconds
[2023-08-29T19:15:25.037+0000] {processor.py:157} INFO - Started process (PID=456) to work on /opt/airflow/dags/test_data_migration.py
[2023-08-29T19:15:25.039+0000] {processor.py:829} INFO - Processing file /opt/airflow/dags/test_data_migration.py for tasks to queue
[2023-08-29T19:15:25.041+0000] {logging_mixin.py:151} INFO - [2023-08-29T19:15:25.041+0000] {dagbag.py:539} INFO - Filling up the DagBag from /opt/airflow/dags/test_data_migration.py
[2023-08-29T19:15:25.084+0000] {logging_mixin.py:151} INFO - [2023-08-29T19:15:25.080+0000] {dagbag.py:347} ERROR - Failed to import: /opt/airflow/dags/test_data_migration.py
Traceback (most recent call last):
  File "/home/airflow/.local/lib/python3.8/site-packages/airflow/models/dagbag.py", line 343, in parse
    loader.exec_module(new_module)
  File "<frozen importlib._bootstrap_external>", line 843, in exec_module
  File "<frozen importlib._bootstrap>", line 219, in _call_with_frames_removed
  File "/opt/airflow/dags/test_data_migration.py", line 6, in <module>
    from model import Connection
  File "/opt/airflow/dags/model.py", line 5, in <module>
    from geoalchemy2 import Geometry
ModuleNotFoundError: No module named 'geoalchemy2'
[2023-08-29T19:15:25.086+0000] {processor.py:841} WARNING - No viable dags retrieved from /opt/airflow/dags/test_data_migration.py
[2023-08-29T19:15:25.102+0000] {processor.py:179} INFO - Processing /opt/airflow/dags/test_data_migration.py took 0.067 seconds
[2023-08-29T19:16:06.793+0000] {processor.py:157} INFO - Started process (PID=168) to work on /opt/airflow/dags/test_data_migration.py
[2023-08-29T19:16:06.795+0000] {processor.py:829} INFO - Processing file /opt/airflow/dags/test_data_migration.py for tasks to queue
[2023-08-29T19:16:06.796+0000] {logging_mixin.py:151} INFO - [2023-08-29T19:16:06.796+0000] {dagbag.py:539} INFO - Filling up the DagBag from /opt/airflow/dags/test_data_migration.py
[2023-08-29T19:16:06.838+0000] {logging_mixin.py:151} INFO - [2023-08-29T19:16:06.833+0000] {dagbag.py:347} ERROR - Failed to import: /opt/airflow/dags/test_data_migration.py
Traceback (most recent call last):
  File "/home/airflow/.local/lib/python3.8/site-packages/airflow/models/dagbag.py", line 343, in parse
    loader.exec_module(new_module)
  File "<frozen importlib._bootstrap_external>", line 843, in exec_module
  File "<frozen importlib._bootstrap>", line 219, in _call_with_frames_removed
  File "/opt/airflow/dags/test_data_migration.py", line 6, in <module>
    from model import Connection
  File "/opt/airflow/dags/model.py", line 5, in <module>
    from geoalchemy2 import Geometry
ModuleNotFoundError: No module named 'geoalchemy2'
[2023-08-29T19:16:06.840+0000] {processor.py:841} WARNING - No viable dags retrieved from /opt/airflow/dags/test_data_migration.py
[2023-08-29T19:16:06.856+0000] {processor.py:179} INFO - Processing /opt/airflow/dags/test_data_migration.py took 0.066 seconds
[2023-08-29T19:16:37.422+0000] {processor.py:157} INFO - Started process (PID=184) to work on /opt/airflow/dags/test_data_migration.py
[2023-08-29T19:16:37.424+0000] {processor.py:829} INFO - Processing file /opt/airflow/dags/test_data_migration.py for tasks to queue
[2023-08-29T19:16:37.426+0000] {logging_mixin.py:151} INFO - [2023-08-29T19:16:37.426+0000] {dagbag.py:539} INFO - Filling up the DagBag from /opt/airflow/dags/test_data_migration.py
[2023-08-29T19:16:37.476+0000] {logging_mixin.py:151} INFO - [2023-08-29T19:16:37.473+0000] {dagbag.py:347} ERROR - Failed to import: /opt/airflow/dags/test_data_migration.py
Traceback (most recent call last):
  File "/home/airflow/.local/lib/python3.8/site-packages/airflow/models/dagbag.py", line 343, in parse
    loader.exec_module(new_module)
  File "<frozen importlib._bootstrap_external>", line 843, in exec_module
  File "<frozen importlib._bootstrap>", line 219, in _call_with_frames_removed
  File "/opt/airflow/dags/test_data_migration.py", line 6, in <module>
    from model import Connection
  File "/opt/airflow/dags/model.py", line 5, in <module>
    from geoalchemy2 import Geometry
ModuleNotFoundError: No module named 'geoalchemy2'
[2023-08-29T19:16:37.477+0000] {processor.py:841} WARNING - No viable dags retrieved from /opt/airflow/dags/test_data_migration.py
[2023-08-29T19:16:37.498+0000] {processor.py:179} INFO - Processing /opt/airflow/dags/test_data_migration.py took 0.082 seconds
[2023-08-29T19:17:08.025+0000] {processor.py:157} INFO - Started process (PID=200) to work on /opt/airflow/dags/test_data_migration.py
[2023-08-29T19:17:08.027+0000] {processor.py:829} INFO - Processing file /opt/airflow/dags/test_data_migration.py for tasks to queue
[2023-08-29T19:17:08.029+0000] {logging_mixin.py:151} INFO - [2023-08-29T19:17:08.029+0000] {dagbag.py:539} INFO - Filling up the DagBag from /opt/airflow/dags/test_data_migration.py
[2023-08-29T19:17:08.072+0000] {logging_mixin.py:151} INFO - [2023-08-29T19:17:08.068+0000] {dagbag.py:347} ERROR - Failed to import: /opt/airflow/dags/test_data_migration.py
Traceback (most recent call last):
  File "/home/airflow/.local/lib/python3.8/site-packages/airflow/models/dagbag.py", line 343, in parse
    loader.exec_module(new_module)
  File "<frozen importlib._bootstrap_external>", line 843, in exec_module
  File "<frozen importlib._bootstrap>", line 219, in _call_with_frames_removed
  File "/opt/airflow/dags/test_data_migration.py", line 6, in <module>
    from model import Connection
  File "/opt/airflow/dags/model.py", line 5, in <module>
    from geoalchemy2 import Geometry
ModuleNotFoundError: No module named 'geoalchemy2'
[2023-08-29T19:17:08.073+0000] {processor.py:841} WARNING - No viable dags retrieved from /opt/airflow/dags/test_data_migration.py
[2023-08-29T19:17:08.098+0000] {processor.py:179} INFO - Processing /opt/airflow/dags/test_data_migration.py took 0.076 seconds
[2023-08-29T19:17:38.630+0000] {processor.py:157} INFO - Started process (PID=216) to work on /opt/airflow/dags/test_data_migration.py
[2023-08-29T19:17:38.632+0000] {processor.py:829} INFO - Processing file /opt/airflow/dags/test_data_migration.py for tasks to queue
[2023-08-29T19:17:38.636+0000] {logging_mixin.py:151} INFO - [2023-08-29T19:17:38.636+0000] {dagbag.py:539} INFO - Filling up the DagBag from /opt/airflow/dags/test_data_migration.py
[2023-08-29T19:17:38.677+0000] {logging_mixin.py:151} INFO - [2023-08-29T19:17:38.674+0000] {dagbag.py:347} ERROR - Failed to import: /opt/airflow/dags/test_data_migration.py
Traceback (most recent call last):
  File "/home/airflow/.local/lib/python3.8/site-packages/airflow/models/dagbag.py", line 343, in parse
    loader.exec_module(new_module)
  File "<frozen importlib._bootstrap_external>", line 843, in exec_module
  File "<frozen importlib._bootstrap>", line 219, in _call_with_frames_removed
  File "/opt/airflow/dags/test_data_migration.py", line 6, in <module>
    from model import Connection
  File "/opt/airflow/dags/model.py", line 5, in <module>
    from geoalchemy2 import Geometry
ModuleNotFoundError: No module named 'geoalchemy2'
[2023-08-29T19:17:38.679+0000] {processor.py:841} WARNING - No viable dags retrieved from /opt/airflow/dags/test_data_migration.py
[2023-08-29T19:17:38.696+0000] {processor.py:179} INFO - Processing /opt/airflow/dags/test_data_migration.py took 0.069 seconds
[2023-08-29T19:18:09.243+0000] {processor.py:157} INFO - Started process (PID=238) to work on /opt/airflow/dags/test_data_migration.py
[2023-08-29T19:18:09.245+0000] {processor.py:829} INFO - Processing file /opt/airflow/dags/test_data_migration.py for tasks to queue
[2023-08-29T19:18:09.247+0000] {logging_mixin.py:151} INFO - [2023-08-29T19:18:09.246+0000] {dagbag.py:539} INFO - Filling up the DagBag from /opt/airflow/dags/test_data_migration.py
[2023-08-29T19:18:09.292+0000] {logging_mixin.py:151} INFO - [2023-08-29T19:18:09.288+0000] {dagbag.py:347} ERROR - Failed to import: /opt/airflow/dags/test_data_migration.py
Traceback (most recent call last):
  File "/home/airflow/.local/lib/python3.8/site-packages/airflow/models/dagbag.py", line 343, in parse
    loader.exec_module(new_module)
  File "<frozen importlib._bootstrap_external>", line 843, in exec_module
  File "<frozen importlib._bootstrap>", line 219, in _call_with_frames_removed
  File "/opt/airflow/dags/test_data_migration.py", line 6, in <module>
    from model import Connection
  File "/opt/airflow/dags/model.py", line 5, in <module>
    from geoalchemy2 import Geometry
ModuleNotFoundError: No module named 'geoalchemy2'
[2023-08-29T19:18:09.293+0000] {processor.py:841} WARNING - No viable dags retrieved from /opt/airflow/dags/test_data_migration.py
[2023-08-29T19:18:09.310+0000] {processor.py:179} INFO - Processing /opt/airflow/dags/test_data_migration.py took 0.069 seconds
[2023-08-29T19:40:36.652+0000] {processor.py:157} INFO - Started process (PID=178) to work on /opt/airflow/dags/test_data_migration.py
[2023-08-29T19:40:36.654+0000] {processor.py:829} INFO - Processing file /opt/airflow/dags/test_data_migration.py for tasks to queue
[2023-08-29T19:40:36.656+0000] {logging_mixin.py:151} INFO - [2023-08-29T19:40:36.656+0000] {dagbag.py:539} INFO - Filling up the DagBag from /opt/airflow/dags/test_data_migration.py
[2023-08-29T19:40:36.708+0000] {logging_mixin.py:151} INFO - [2023-08-29T19:40:36.701+0000] {dagbag.py:347} ERROR - Failed to import: /opt/airflow/dags/test_data_migration.py
Traceback (most recent call last):
  File "/home/airflow/.local/lib/python3.8/site-packages/airflow/models/dagbag.py", line 343, in parse
    loader.exec_module(new_module)
  File "<frozen importlib._bootstrap_external>", line 843, in exec_module
  File "<frozen importlib._bootstrap>", line 219, in _call_with_frames_removed
  File "/opt/airflow/dags/test_data_migration.py", line 6, in <module>
    from model import Connection
  File "/opt/airflow/dags/model.py", line 5, in <module>
    from geoalchemy2 import Geometry
ModuleNotFoundError: No module named 'geoalchemy2'
[2023-08-29T19:40:36.709+0000] {processor.py:841} WARNING - No viable dags retrieved from /opt/airflow/dags/test_data_migration.py
[2023-08-29T19:40:36.729+0000] {processor.py:179} INFO - Processing /opt/airflow/dags/test_data_migration.py took 0.080 seconds
[2023-08-29T19:41:07.344+0000] {processor.py:157} INFO - Started process (PID=206) to work on /opt/airflow/dags/test_data_migration.py
[2023-08-29T19:41:07.346+0000] {processor.py:829} INFO - Processing file /opt/airflow/dags/test_data_migration.py for tasks to queue
[2023-08-29T19:41:07.347+0000] {logging_mixin.py:151} INFO - [2023-08-29T19:41:07.347+0000] {dagbag.py:539} INFO - Filling up the DagBag from /opt/airflow/dags/test_data_migration.py
[2023-08-29T19:41:07.390+0000] {logging_mixin.py:151} INFO - [2023-08-29T19:41:07.386+0000] {dagbag.py:347} ERROR - Failed to import: /opt/airflow/dags/test_data_migration.py
Traceback (most recent call last):
  File "/home/airflow/.local/lib/python3.8/site-packages/airflow/models/dagbag.py", line 343, in parse
    loader.exec_module(new_module)
  File "<frozen importlib._bootstrap_external>", line 843, in exec_module
  File "<frozen importlib._bootstrap>", line 219, in _call_with_frames_removed
  File "/opt/airflow/dags/test_data_migration.py", line 6, in <module>
    from model import Connection
  File "/opt/airflow/dags/model.py", line 5, in <module>
    from geoalchemy2 import Geometry
ModuleNotFoundError: No module named 'geoalchemy2'
[2023-08-29T19:41:07.391+0000] {processor.py:841} WARNING - No viable dags retrieved from /opt/airflow/dags/test_data_migration.py
[2023-08-29T19:41:07.410+0000] {processor.py:179} INFO - Processing /opt/airflow/dags/test_data_migration.py took 0.069 seconds
[2023-08-29T19:41:38.062+0000] {processor.py:157} INFO - Started process (PID=230) to work on /opt/airflow/dags/test_data_migration.py
[2023-08-29T19:41:38.064+0000] {processor.py:829} INFO - Processing file /opt/airflow/dags/test_data_migration.py for tasks to queue
[2023-08-29T19:41:38.066+0000] {logging_mixin.py:151} INFO - [2023-08-29T19:41:38.066+0000] {dagbag.py:539} INFO - Filling up the DagBag from /opt/airflow/dags/test_data_migration.py
[2023-08-29T19:41:38.114+0000] {logging_mixin.py:151} INFO - [2023-08-29T19:41:38.109+0000] {dagbag.py:347} ERROR - Failed to import: /opt/airflow/dags/test_data_migration.py
Traceback (most recent call last):
  File "/home/airflow/.local/lib/python3.8/site-packages/airflow/models/dagbag.py", line 343, in parse
    loader.exec_module(new_module)
  File "<frozen importlib._bootstrap_external>", line 843, in exec_module
  File "<frozen importlib._bootstrap>", line 219, in _call_with_frames_removed
  File "/opt/airflow/dags/test_data_migration.py", line 6, in <module>
    from model import Connection
  File "/opt/airflow/dags/model.py", line 5, in <module>
    from geoalchemy2 import Geometry
ModuleNotFoundError: No module named 'geoalchemy2'
[2023-08-29T19:41:38.117+0000] {processor.py:841} WARNING - No viable dags retrieved from /opt/airflow/dags/test_data_migration.py
[2023-08-29T19:41:38.139+0000] {processor.py:179} INFO - Processing /opt/airflow/dags/test_data_migration.py took 0.080 seconds
[2023-08-29T19:42:08.638+0000] {processor.py:157} INFO - Started process (PID=258) to work on /opt/airflow/dags/test_data_migration.py
[2023-08-29T19:42:08.640+0000] {processor.py:829} INFO - Processing file /opt/airflow/dags/test_data_migration.py for tasks to queue
[2023-08-29T19:42:08.641+0000] {logging_mixin.py:151} INFO - [2023-08-29T19:42:08.641+0000] {dagbag.py:539} INFO - Filling up the DagBag from /opt/airflow/dags/test_data_migration.py
[2023-08-29T19:42:08.679+0000] {logging_mixin.py:151} INFO - [2023-08-29T19:42:08.675+0000] {dagbag.py:347} ERROR - Failed to import: /opt/airflow/dags/test_data_migration.py
Traceback (most recent call last):
  File "/home/airflow/.local/lib/python3.8/site-packages/airflow/models/dagbag.py", line 343, in parse
    loader.exec_module(new_module)
  File "<frozen importlib._bootstrap_external>", line 843, in exec_module
  File "<frozen importlib._bootstrap>", line 219, in _call_with_frames_removed
  File "/opt/airflow/dags/test_data_migration.py", line 6, in <module>
    from model import Connection
  File "/opt/airflow/dags/model.py", line 5, in <module>
    from geoalchemy2 import Geometry
ModuleNotFoundError: No module named 'geoalchemy2'
[2023-08-29T19:42:08.681+0000] {processor.py:841} WARNING - No viable dags retrieved from /opt/airflow/dags/test_data_migration.py
[2023-08-29T19:42:08.699+0000] {processor.py:179} INFO - Processing /opt/airflow/dags/test_data_migration.py took 0.063 seconds
[2023-08-29T19:42:39.388+0000] {processor.py:157} INFO - Started process (PID=284) to work on /opt/airflow/dags/test_data_migration.py
[2023-08-29T19:42:39.391+0000] {processor.py:829} INFO - Processing file /opt/airflow/dags/test_data_migration.py for tasks to queue
[2023-08-29T19:42:39.393+0000] {logging_mixin.py:151} INFO - [2023-08-29T19:42:39.393+0000] {dagbag.py:539} INFO - Filling up the DagBag from /opt/airflow/dags/test_data_migration.py
[2023-08-29T19:42:39.434+0000] {logging_mixin.py:151} INFO - [2023-08-29T19:42:39.431+0000] {dagbag.py:347} ERROR - Failed to import: /opt/airflow/dags/test_data_migration.py
Traceback (most recent call last):
  File "/home/airflow/.local/lib/python3.8/site-packages/airflow/models/dagbag.py", line 343, in parse
    loader.exec_module(new_module)
  File "<frozen importlib._bootstrap_external>", line 843, in exec_module
  File "<frozen importlib._bootstrap>", line 219, in _call_with_frames_removed
  File "/opt/airflow/dags/test_data_migration.py", line 6, in <module>
    from model import Connection
  File "/opt/airflow/dags/model.py", line 5, in <module>
    from geoalchemy2 import Geometry
ModuleNotFoundError: No module named 'geoalchemy2'
[2023-08-29T19:42:39.436+0000] {processor.py:841} WARNING - No viable dags retrieved from /opt/airflow/dags/test_data_migration.py
[2023-08-29T19:42:39.452+0000] {processor.py:179} INFO - Processing /opt/airflow/dags/test_data_migration.py took 0.067 seconds
[2023-08-29T19:43:10.503+0000] {processor.py:157} INFO - Started process (PID=310) to work on /opt/airflow/dags/test_data_migration.py
[2023-08-29T19:43:10.504+0000] {processor.py:829} INFO - Processing file /opt/airflow/dags/test_data_migration.py for tasks to queue
[2023-08-29T19:43:10.506+0000] {logging_mixin.py:151} INFO - [2023-08-29T19:43:10.506+0000] {dagbag.py:539} INFO - Filling up the DagBag from /opt/airflow/dags/test_data_migration.py
[2023-08-29T19:43:10.551+0000] {logging_mixin.py:151} INFO - [2023-08-29T19:43:10.547+0000] {dagbag.py:347} ERROR - Failed to import: /opt/airflow/dags/test_data_migration.py
Traceback (most recent call last):
  File "/home/airflow/.local/lib/python3.8/site-packages/airflow/models/dagbag.py", line 343, in parse
    loader.exec_module(new_module)
  File "<frozen importlib._bootstrap_external>", line 843, in exec_module
  File "<frozen importlib._bootstrap>", line 219, in _call_with_frames_removed
  File "/opt/airflow/dags/test_data_migration.py", line 6, in <module>
    from model import Connection
  File "/opt/airflow/dags/model.py", line 5, in <module>
    from geoalchemy2 import Geometry
ModuleNotFoundError: No module named 'geoalchemy2'
[2023-08-29T19:43:10.553+0000] {processor.py:841} WARNING - No viable dags retrieved from /opt/airflow/dags/test_data_migration.py
[2023-08-29T19:43:10.569+0000] {processor.py:179} INFO - Processing /opt/airflow/dags/test_data_migration.py took 0.069 seconds
[2023-08-29T19:43:41.280+0000] {processor.py:157} INFO - Started process (PID=336) to work on /opt/airflow/dags/test_data_migration.py
[2023-08-29T19:43:41.282+0000] {processor.py:829} INFO - Processing file /opt/airflow/dags/test_data_migration.py for tasks to queue
[2023-08-29T19:43:41.284+0000] {logging_mixin.py:151} INFO - [2023-08-29T19:43:41.284+0000] {dagbag.py:539} INFO - Filling up the DagBag from /opt/airflow/dags/test_data_migration.py
[2023-08-29T19:43:41.328+0000] {logging_mixin.py:151} INFO - [2023-08-29T19:43:41.324+0000] {dagbag.py:347} ERROR - Failed to import: /opt/airflow/dags/test_data_migration.py
Traceback (most recent call last):
  File "/home/airflow/.local/lib/python3.8/site-packages/airflow/models/dagbag.py", line 343, in parse
    loader.exec_module(new_module)
  File "<frozen importlib._bootstrap_external>", line 843, in exec_module
  File "<frozen importlib._bootstrap>", line 219, in _call_with_frames_removed
  File "/opt/airflow/dags/test_data_migration.py", line 6, in <module>
    from model import Connection
  File "/opt/airflow/dags/model.py", line 5, in <module>
    from geoalchemy2 import Geometry
ModuleNotFoundError: No module named 'geoalchemy2'
[2023-08-29T19:43:41.329+0000] {processor.py:841} WARNING - No viable dags retrieved from /opt/airflow/dags/test_data_migration.py
[2023-08-29T19:43:41.346+0000] {processor.py:179} INFO - Processing /opt/airflow/dags/test_data_migration.py took 0.068 seconds
[2023-08-29T19:44:12.379+0000] {processor.py:157} INFO - Started process (PID=380) to work on /opt/airflow/dags/test_data_migration.py
[2023-08-29T19:44:12.382+0000] {processor.py:829} INFO - Processing file /opt/airflow/dags/test_data_migration.py for tasks to queue
[2023-08-29T19:44:12.383+0000] {logging_mixin.py:151} INFO - [2023-08-29T19:44:12.383+0000] {dagbag.py:539} INFO - Filling up the DagBag from /opt/airflow/dags/test_data_migration.py
[2023-08-29T19:44:12.459+0000] {logging_mixin.py:151} INFO - [2023-08-29T19:44:12.449+0000] {dagbag.py:347} ERROR - Failed to import: /opt/airflow/dags/test_data_migration.py
Traceback (most recent call last):
  File "/home/airflow/.local/lib/python3.8/site-packages/airflow/models/dagbag.py", line 343, in parse
    loader.exec_module(new_module)
  File "<frozen importlib._bootstrap_external>", line 843, in exec_module
  File "<frozen importlib._bootstrap>", line 219, in _call_with_frames_removed
  File "/opt/airflow/dags/test_data_migration.py", line 6, in <module>
    from model import Connection
  File "/opt/airflow/dags/model.py", line 5, in <module>
    from geoalchemy2 import Geometry
ModuleNotFoundError: No module named 'geoalchemy2'
[2023-08-29T19:44:12.463+0000] {processor.py:841} WARNING - No viable dags retrieved from /opt/airflow/dags/test_data_migration.py
[2023-08-29T19:44:12.483+0000] {processor.py:179} INFO - Processing /opt/airflow/dags/test_data_migration.py took 0.108 seconds
[2023-08-29T19:44:42.612+0000] {processor.py:157} INFO - Started process (PID=404) to work on /opt/airflow/dags/test_data_migration.py
[2023-08-29T19:44:42.614+0000] {processor.py:829} INFO - Processing file /opt/airflow/dags/test_data_migration.py for tasks to queue
[2023-08-29T19:44:42.616+0000] {logging_mixin.py:151} INFO - [2023-08-29T19:44:42.615+0000] {dagbag.py:539} INFO - Filling up the DagBag from /opt/airflow/dags/test_data_migration.py
[2023-08-29T19:44:42.658+0000] {logging_mixin.py:151} INFO - [2023-08-29T19:44:42.654+0000] {dagbag.py:347} ERROR - Failed to import: /opt/airflow/dags/test_data_migration.py
Traceback (most recent call last):
  File "/home/airflow/.local/lib/python3.8/site-packages/airflow/models/dagbag.py", line 343, in parse
    loader.exec_module(new_module)
  File "<frozen importlib._bootstrap_external>", line 843, in exec_module
  File "<frozen importlib._bootstrap>", line 219, in _call_with_frames_removed
  File "/opt/airflow/dags/test_data_migration.py", line 6, in <module>
    from model import Connection
  File "/opt/airflow/dags/model.py", line 5, in <module>
    from geoalchemy2 import Geometry
ModuleNotFoundError: No module named 'geoalchemy2'
[2023-08-29T19:44:42.659+0000] {processor.py:841} WARNING - No viable dags retrieved from /opt/airflow/dags/test_data_migration.py
[2023-08-29T19:44:42.676+0000] {processor.py:179} INFO - Processing /opt/airflow/dags/test_data_migration.py took 0.066 seconds
[2023-08-29T19:45:13.334+0000] {processor.py:157} INFO - Started process (PID=430) to work on /opt/airflow/dags/test_data_migration.py
[2023-08-29T19:45:13.336+0000] {processor.py:829} INFO - Processing file /opt/airflow/dags/test_data_migration.py for tasks to queue
[2023-08-29T19:45:13.338+0000] {logging_mixin.py:151} INFO - [2023-08-29T19:45:13.338+0000] {dagbag.py:539} INFO - Filling up the DagBag from /opt/airflow/dags/test_data_migration.py
[2023-08-29T19:45:13.381+0000] {logging_mixin.py:151} INFO - [2023-08-29T19:45:13.378+0000] {dagbag.py:347} ERROR - Failed to import: /opt/airflow/dags/test_data_migration.py
Traceback (most recent call last):
  File "/home/airflow/.local/lib/python3.8/site-packages/airflow/models/dagbag.py", line 343, in parse
    loader.exec_module(new_module)
  File "<frozen importlib._bootstrap_external>", line 843, in exec_module
  File "<frozen importlib._bootstrap>", line 219, in _call_with_frames_removed
  File "/opt/airflow/dags/test_data_migration.py", line 6, in <module>
    from model import Connection
  File "/opt/airflow/dags/model.py", line 5, in <module>
    from geoalchemy2 import Geometry
ModuleNotFoundError: No module named 'geoalchemy2'
[2023-08-29T19:45:13.384+0000] {processor.py:841} WARNING - No viable dags retrieved from /opt/airflow/dags/test_data_migration.py
[2023-08-29T19:45:13.401+0000] {processor.py:179} INFO - Processing /opt/airflow/dags/test_data_migration.py took 0.072 seconds
[2023-08-29T19:45:44.331+0000] {processor.py:157} INFO - Started process (PID=458) to work on /opt/airflow/dags/test_data_migration.py
[2023-08-29T19:45:44.332+0000] {processor.py:829} INFO - Processing file /opt/airflow/dags/test_data_migration.py for tasks to queue
[2023-08-29T19:45:44.333+0000] {logging_mixin.py:151} INFO - [2023-08-29T19:45:44.333+0000] {dagbag.py:539} INFO - Filling up the DagBag from /opt/airflow/dags/test_data_migration.py
[2023-08-29T19:45:44.371+0000] {logging_mixin.py:151} INFO - [2023-08-29T19:45:44.367+0000] {dagbag.py:347} ERROR - Failed to import: /opt/airflow/dags/test_data_migration.py
Traceback (most recent call last):
  File "/home/airflow/.local/lib/python3.8/site-packages/airflow/models/dagbag.py", line 343, in parse
    loader.exec_module(new_module)
  File "<frozen importlib._bootstrap_external>", line 843, in exec_module
  File "<frozen importlib._bootstrap>", line 219, in _call_with_frames_removed
  File "/opt/airflow/dags/test_data_migration.py", line 6, in <module>
    from model import Connection
  File "/opt/airflow/dags/model.py", line 5, in <module>
    from geoalchemy2 import Geometry
ModuleNotFoundError: No module named 'geoalchemy2'
[2023-08-29T19:45:44.372+0000] {processor.py:841} WARNING - No viable dags retrieved from /opt/airflow/dags/test_data_migration.py
[2023-08-29T19:45:44.388+0000] {processor.py:179} INFO - Processing /opt/airflow/dags/test_data_migration.py took 0.060 seconds
[2023-08-29T19:46:15.039+0000] {processor.py:157} INFO - Started process (PID=482) to work on /opt/airflow/dags/test_data_migration.py
[2023-08-29T19:46:15.041+0000] {processor.py:829} INFO - Processing file /opt/airflow/dags/test_data_migration.py for tasks to queue
[2023-08-29T19:46:15.043+0000] {logging_mixin.py:151} INFO - [2023-08-29T19:46:15.043+0000] {dagbag.py:539} INFO - Filling up the DagBag from /opt/airflow/dags/test_data_migration.py
[2023-08-29T19:46:15.083+0000] {logging_mixin.py:151} INFO - [2023-08-29T19:46:15.081+0000] {dagbag.py:347} ERROR - Failed to import: /opt/airflow/dags/test_data_migration.py
Traceback (most recent call last):
  File "/home/airflow/.local/lib/python3.8/site-packages/airflow/models/dagbag.py", line 343, in parse
    loader.exec_module(new_module)
  File "<frozen importlib._bootstrap_external>", line 843, in exec_module
  File "<frozen importlib._bootstrap>", line 219, in _call_with_frames_removed
  File "/opt/airflow/dags/test_data_migration.py", line 6, in <module>
    from model import Connection
  File "/opt/airflow/dags/model.py", line 5, in <module>
    from geoalchemy2 import Geometry
ModuleNotFoundError: No module named 'geoalchemy2'
[2023-08-29T19:46:15.084+0000] {processor.py:841} WARNING - No viable dags retrieved from /opt/airflow/dags/test_data_migration.py
[2023-08-29T19:46:15.100+0000] {processor.py:179} INFO - Processing /opt/airflow/dags/test_data_migration.py took 0.063 seconds
[2023-08-29T19:46:45.866+0000] {processor.py:157} INFO - Started process (PID=510) to work on /opt/airflow/dags/test_data_migration.py
[2023-08-29T19:46:45.868+0000] {processor.py:829} INFO - Processing file /opt/airflow/dags/test_data_migration.py for tasks to queue
[2023-08-29T19:46:45.870+0000] {logging_mixin.py:151} INFO - [2023-08-29T19:46:45.869+0000] {dagbag.py:539} INFO - Filling up the DagBag from /opt/airflow/dags/test_data_migration.py
[2023-08-29T19:46:45.994+0000] {logging_mixin.py:151} INFO - [2023-08-29T19:46:45.991+0000] {dagbag.py:347} ERROR - Failed to import: /opt/airflow/dags/test_data_migration.py
Traceback (most recent call last):
  File "/home/airflow/.local/lib/python3.8/site-packages/airflow/models/dagbag.py", line 343, in parse
    loader.exec_module(new_module)
  File "<frozen importlib._bootstrap_external>", line 843, in exec_module
  File "<frozen importlib._bootstrap>", line 219, in _call_with_frames_removed
  File "/opt/airflow/dags/test_data_migration.py", line 6, in <module>
    from model import Connection
  File "/opt/airflow/dags/model.py", line 5, in <module>
    from geoalchemy2 import Geometry
ModuleNotFoundError: No module named 'geoalchemy2'
[2023-08-29T19:46:45.997+0000] {processor.py:841} WARNING - No viable dags retrieved from /opt/airflow/dags/test_data_migration.py
[2023-08-29T19:46:46.013+0000] {processor.py:179} INFO - Processing /opt/airflow/dags/test_data_migration.py took 0.149 seconds
[2023-08-29T19:47:16.700+0000] {processor.py:157} INFO - Started process (PID=534) to work on /opt/airflow/dags/test_data_migration.py
[2023-08-29T19:47:16.702+0000] {processor.py:829} INFO - Processing file /opt/airflow/dags/test_data_migration.py for tasks to queue
[2023-08-29T19:47:16.704+0000] {logging_mixin.py:151} INFO - [2023-08-29T19:47:16.704+0000] {dagbag.py:539} INFO - Filling up the DagBag from /opt/airflow/dags/test_data_migration.py
[2023-08-29T19:47:16.747+0000] {logging_mixin.py:151} INFO - [2023-08-29T19:47:16.744+0000] {dagbag.py:347} ERROR - Failed to import: /opt/airflow/dags/test_data_migration.py
Traceback (most recent call last):
  File "/home/airflow/.local/lib/python3.8/site-packages/airflow/models/dagbag.py", line 343, in parse
    loader.exec_module(new_module)
  File "<frozen importlib._bootstrap_external>", line 843, in exec_module
  File "<frozen importlib._bootstrap>", line 219, in _call_with_frames_removed
  File "/opt/airflow/dags/test_data_migration.py", line 6, in <module>
    from model import Connection
  File "/opt/airflow/dags/model.py", line 5, in <module>
    from geoalchemy2 import Geometry
ModuleNotFoundError: No module named 'geoalchemy2'
[2023-08-29T19:47:16.749+0000] {processor.py:841} WARNING - No viable dags retrieved from /opt/airflow/dags/test_data_migration.py
[2023-08-29T19:47:16.767+0000] {processor.py:179} INFO - Processing /opt/airflow/dags/test_data_migration.py took 0.070 seconds
[2023-08-29T19:47:47.308+0000] {processor.py:157} INFO - Started process (PID=562) to work on /opt/airflow/dags/test_data_migration.py
[2023-08-29T19:47:47.310+0000] {processor.py:829} INFO - Processing file /opt/airflow/dags/test_data_migration.py for tasks to queue
[2023-08-29T19:47:47.312+0000] {logging_mixin.py:151} INFO - [2023-08-29T19:47:47.311+0000] {dagbag.py:539} INFO - Filling up the DagBag from /opt/airflow/dags/test_data_migration.py
[2023-08-29T19:47:47.350+0000] {logging_mixin.py:151} INFO - [2023-08-29T19:47:47.347+0000] {dagbag.py:347} ERROR - Failed to import: /opt/airflow/dags/test_data_migration.py
Traceback (most recent call last):
  File "/home/airflow/.local/lib/python3.8/site-packages/airflow/models/dagbag.py", line 343, in parse
    loader.exec_module(new_module)
  File "<frozen importlib._bootstrap_external>", line 843, in exec_module
  File "<frozen importlib._bootstrap>", line 219, in _call_with_frames_removed
  File "/opt/airflow/dags/test_data_migration.py", line 6, in <module>
    from model import Connection
  File "/opt/airflow/dags/model.py", line 5, in <module>
    from geoalchemy2 import Geometry
ModuleNotFoundError: No module named 'geoalchemy2'
[2023-08-29T19:47:47.351+0000] {processor.py:841} WARNING - No viable dags retrieved from /opt/airflow/dags/test_data_migration.py
[2023-08-29T19:47:47.368+0000] {processor.py:179} INFO - Processing /opt/airflow/dags/test_data_migration.py took 0.063 seconds
