[2023-08-30T19:31:43.085+0000] {logging_mixin.py:151} WARNING - /home/***/.local/lib/python3.8/site-packages/***/utils/sqlalchemy.py:124 DeprecationWarning: The sql_alchemy_conn option in [core] has been moved to the sql_alchemy_conn option in [database] - the old setting has been used, but please update your config.
[2023-08-30T19:31:43.108+0000] {taskinstance.py:1159} INFO - Dependencies all met for dep_context=non-requeueable deps ti=<TaskInstance: traffic_report.export_data_to_db scheduled__2023-08-29T00:00:00+00:00 [queued]>
[2023-08-30T19:31:43.120+0000] {taskinstance.py:1159} INFO - Dependencies all met for dep_context=requeueable deps ti=<TaskInstance: traffic_report.export_data_to_db scheduled__2023-08-29T00:00:00+00:00 [queued]>
[2023-08-30T19:31:43.123+0000] {taskinstance.py:1361} INFO - Starting attempt 1 of 2
[2023-08-30T19:31:43.136+0000] {taskinstance.py:1382} INFO - Executing <Task(BashOperator): export_data_to_db> on 2023-08-29 00:00:00+00:00
[2023-08-30T19:31:43.140+0000] {standard_task_runner.py:57} INFO - Started process 316 to run task
[2023-08-30T19:31:43.161+0000] {standard_task_runner.py:84} INFO - Running: ['***', 'tasks', 'run', 'traffic_report', 'export_data_to_db', 'scheduled__2023-08-29T00:00:00+00:00', '--job-id', '16', '--raw', '--subdir', 'DAGS_FOLDER/traffic_dag.py', '--cfg-path', '/tmp/tmpdtkempd1']
[2023-08-30T19:31:43.170+0000] {standard_task_runner.py:85} INFO - Job 16: Subtask export_data_to_db
[2023-08-30T19:31:43.197+0000] {logging_mixin.py:151} WARNING - /home/***/.local/lib/python3.8/site-packages/***/settings.py:195 DeprecationWarning: The sql_alchemy_conn option in [core] has been moved to the sql_alchemy_conn option in [database] - the old setting has been used, but please update your config.
[2023-08-30T19:31:43.245+0000] {task_command.py:415} INFO - Running <TaskInstance: traffic_report.export_data_to_db scheduled__2023-08-29T00:00:00+00:00 [running]> on host f6bcf103ff79
[2023-08-30T19:31:43.263+0000] {logging_mixin.py:151} WARNING - /home/***/.local/lib/python3.8/site-packages/***/utils/sqlalchemy.py:124 DeprecationWarning: The sql_alchemy_conn option in [core] has been moved to the sql_alchemy_conn option in [database] - the old setting has been used, but please update your config.
[2023-08-30T19:31:43.320+0000] {taskinstance.py:1660} INFO - Exporting env vars: AIRFLOW_CTX_DAG_OWNER='***' AIRFLOW_CTX_DAG_ID='traffic_report' AIRFLOW_CTX_TASK_ID='export_data_to_db' AIRFLOW_CTX_EXECUTION_DATE='2023-08-29T00:00:00+00:00' AIRFLOW_CTX_TRY_NUMBER='1' AIRFLOW_CTX_DAG_RUN_ID='scheduled__2023-08-29T00:00:00+00:00'
[2023-08-30T19:31:43.323+0000] {subprocess.py:63} INFO - Tmp dir root location: /tmp
[2023-08-30T19:31:43.324+0000] {subprocess.py:75} INFO - Running command: ['/bin/bash', '-c', 'python /opt/***/dags/data_to_db.py --date 2023-08-29 --connection postgresql+psycopg2://***:***@postgres/***']
[2023-08-30T19:31:43.336+0000] {subprocess.py:86} INFO - Output:
[2023-08-30T19:31:43.757+0000] {subprocess.py:93} INFO - Traceback (most recent call last):
[2023-08-30T19:31:43.758+0000] {subprocess.py:93} INFO -   File "/opt/***/dags/data_to_db.py", line 6, in <module>
[2023-08-30T19:31:43.760+0000] {subprocess.py:93} INFO -     from model import Connection, Traffic
[2023-08-30T19:31:43.762+0000] {subprocess.py:93} INFO -   File "/opt/***/dags/model.py", line 5, in <module>
[2023-08-30T19:31:43.763+0000] {subprocess.py:93} INFO -     from geoalchemy2 import Geometry
[2023-08-30T19:31:43.765+0000] {subprocess.py:93} INFO - ModuleNotFoundError: No module named 'geoalchemy2'
[2023-08-30T19:31:43.801+0000] {subprocess.py:97} INFO - Command exited with return code 1
[2023-08-30T19:31:43.830+0000] {taskinstance.py:1943} ERROR - Task failed with exception
Traceback (most recent call last):
  File "/home/airflow/.local/lib/python3.8/site-packages/airflow/operators/bash.py", line 210, in execute
    raise AirflowException(
airflow.exceptions.AirflowException: Bash command failed. The command returned a non-zero exit code 1.
[2023-08-30T19:31:43.836+0000] {taskinstance.py:1400} INFO - Marking task as UP_FOR_RETRY. dag_id=traffic_report, task_id=export_data_to_db, execution_date=20230829T000000, start_date=20230830T193143, end_date=20230830T193143
[2023-08-30T19:31:43.860+0000] {standard_task_runner.py:104} ERROR - Failed to execute job 16 for task export_data_to_db (Bash command failed. The command returned a non-zero exit code 1.; 316)
[2023-08-30T19:31:43.883+0000] {local_task_job_runner.py:228} INFO - Task exited with return code 1
[2023-08-30T19:31:43.902+0000] {taskinstance.py:2784} INFO - 0 downstream tasks scheduled from follow-on schedule check
[2023-08-30T19:42:02.047+0000] {logging_mixin.py:151} WARNING - /home/***/.local/lib/python3.8/site-packages/***/utils/sqlalchemy.py:124 DeprecationWarning: The sql_alchemy_conn option in [core] has been moved to the sql_alchemy_conn option in [database] - the old setting has been used, but please update your config.
[2023-08-30T19:42:02.065+0000] {taskinstance.py:1159} INFO - Dependencies all met for dep_context=non-requeueable deps ti=<TaskInstance: traffic_report.export_data_to_db scheduled__2023-08-29T00:00:00+00:00 [queued]>
[2023-08-30T19:42:02.081+0000] {taskinstance.py:1159} INFO - Dependencies all met for dep_context=requeueable deps ti=<TaskInstance: traffic_report.export_data_to_db scheduled__2023-08-29T00:00:00+00:00 [queued]>
[2023-08-30T19:42:02.082+0000] {taskinstance.py:1361} INFO - Starting attempt 1 of 2
[2023-08-30T19:42:02.106+0000] {taskinstance.py:1382} INFO - Executing <Task(BashOperator): export_data_to_db> on 2023-08-29 00:00:00+00:00
[2023-08-30T19:42:02.112+0000] {standard_task_runner.py:57} INFO - Started process 385 to run task
[2023-08-30T19:42:02.123+0000] {standard_task_runner.py:84} INFO - Running: ['***', 'tasks', 'run', 'traffic_report', 'export_data_to_db', 'scheduled__2023-08-29T00:00:00+00:00', '--job-id', '15', '--raw', '--subdir', 'DAGS_FOLDER/traffic_dag.py', '--cfg-path', '/tmp/tmpt7k8wq9f']
[2023-08-30T19:42:02.129+0000] {standard_task_runner.py:85} INFO - Job 15: Subtask export_data_to_db
[2023-08-30T19:42:02.158+0000] {logging_mixin.py:151} WARNING - /home/***/.local/lib/python3.8/site-packages/***/settings.py:195 DeprecationWarning: The sql_alchemy_conn option in [core] has been moved to the sql_alchemy_conn option in [database] - the old setting has been used, but please update your config.
[2023-08-30T19:42:02.217+0000] {task_command.py:415} INFO - Running <TaskInstance: traffic_report.export_data_to_db scheduled__2023-08-29T00:00:00+00:00 [running]> on host 81eeb4b7c8a9
[2023-08-30T19:42:02.236+0000] {logging_mixin.py:151} WARNING - /home/***/.local/lib/python3.8/site-packages/***/utils/sqlalchemy.py:124 DeprecationWarning: The sql_alchemy_conn option in [core] has been moved to the sql_alchemy_conn option in [database] - the old setting has been used, but please update your config.
[2023-08-30T19:42:02.321+0000] {taskinstance.py:1660} INFO - Exporting env vars: AIRFLOW_CTX_DAG_OWNER='***' AIRFLOW_CTX_DAG_ID='traffic_report' AIRFLOW_CTX_TASK_ID='export_data_to_db' AIRFLOW_CTX_EXECUTION_DATE='2023-08-29T00:00:00+00:00' AIRFLOW_CTX_TRY_NUMBER='1' AIRFLOW_CTX_DAG_RUN_ID='scheduled__2023-08-29T00:00:00+00:00'
[2023-08-30T19:42:02.324+0000] {subprocess.py:63} INFO - Tmp dir root location: /tmp
[2023-08-30T19:42:02.329+0000] {subprocess.py:75} INFO - Running command: ['/bin/bash', '-c', 'python /opt/***/dags/data_to_db.py --date 2023-08-29 --connection postgresql+psycopg2://***:***@postgres/***']
[2023-08-30T19:42:02.341+0000] {subprocess.py:86} INFO - Output:
[2023-08-30T19:42:02.875+0000] {subprocess.py:93} INFO - Traceback (most recent call last):
[2023-08-30T19:42:02.879+0000] {subprocess.py:93} INFO -   File "/opt/***/dags/data_to_db.py", line 6, in <module>
[2023-08-30T19:42:02.880+0000] {subprocess.py:93} INFO -     from model import Connection, Traffic
[2023-08-30T19:42:02.881+0000] {subprocess.py:93} INFO -   File "/opt/***/dags/model.py", line 5, in <module>
[2023-08-30T19:42:02.882+0000] {subprocess.py:93} INFO -     from geoalchemy2 import Geometry
[2023-08-30T19:42:02.883+0000] {subprocess.py:93} INFO - ModuleNotFoundError: No module named 'geoalchemy2'
[2023-08-30T19:42:02.933+0000] {subprocess.py:97} INFO - Command exited with return code 1
[2023-08-30T19:42:02.951+0000] {taskinstance.py:1943} ERROR - Task failed with exception
Traceback (most recent call last):
  File "/home/airflow/.local/lib/python3.8/site-packages/airflow/operators/bash.py", line 210, in execute
    raise AirflowException(
airflow.exceptions.AirflowException: Bash command failed. The command returned a non-zero exit code 1.
[2023-08-30T19:42:02.959+0000] {taskinstance.py:1400} INFO - Marking task as UP_FOR_RETRY. dag_id=traffic_report, task_id=export_data_to_db, execution_date=20230829T000000, start_date=20230830T194202, end_date=20230830T194202
[2023-08-30T19:42:02.977+0000] {standard_task_runner.py:104} ERROR - Failed to execute job 15 for task export_data_to_db (Bash command failed. The command returned a non-zero exit code 1.; 385)
[2023-08-30T19:42:03.017+0000] {local_task_job_runner.py:228} INFO - Task exited with return code 1
[2023-08-30T19:42:03.034+0000] {taskinstance.py:2784} INFO - 0 downstream tasks scheduled from follow-on schedule check
[2023-08-30T19:51:05.589+0000] {logging_mixin.py:151} WARNING - /home/***/.local/lib/python3.8/site-packages/***/utils/sqlalchemy.py:124 DeprecationWarning: The sql_alchemy_conn option in [core] has been moved to the sql_alchemy_conn option in [database] - the old setting has been used, but please update your config.
[2023-08-30T19:51:05.608+0000] {taskinstance.py:1159} INFO - Dependencies all met for dep_context=non-requeueable deps ti=<TaskInstance: traffic_report.export_data_to_db scheduled__2023-08-29T00:00:00+00:00 [queued]>
[2023-08-30T19:51:05.625+0000] {taskinstance.py:1159} INFO - Dependencies all met for dep_context=requeueable deps ti=<TaskInstance: traffic_report.export_data_to_db scheduled__2023-08-29T00:00:00+00:00 [queued]>
[2023-08-30T19:51:05.626+0000] {taskinstance.py:1361} INFO - Starting attempt 1 of 2
[2023-08-30T19:51:05.657+0000] {taskinstance.py:1382} INFO - Executing <Task(BashOperator): export_data_to_db> on 2023-08-29 00:00:00+00:00
[2023-08-30T19:51:05.675+0000] {standard_task_runner.py:57} INFO - Started process 361 to run task
[2023-08-30T19:51:05.708+0000] {standard_task_runner.py:84} INFO - Running: ['***', 'tasks', 'run', 'traffic_report', 'export_data_to_db', 'scheduled__2023-08-29T00:00:00+00:00', '--job-id', '18', '--raw', '--subdir', 'DAGS_FOLDER/traffic_dag.py', '--cfg-path', '/tmp/tmputuyyt9y']
[2023-08-30T19:51:05.717+0000] {standard_task_runner.py:85} INFO - Job 18: Subtask export_data_to_db
[2023-08-30T19:51:06.787+0000] {logging_mixin.py:151} WARNING - /home/***/.local/lib/python3.8/site-packages/***/settings.py:195 DeprecationWarning: The sql_alchemy_conn option in [core] has been moved to the sql_alchemy_conn option in [database] - the old setting has been used, but please update your config.
[2023-08-30T19:51:07.983+0000] {task_command.py:415} INFO - Running <TaskInstance: traffic_report.export_data_to_db scheduled__2023-08-29T00:00:00+00:00 [running]> on host 206ecb1dc8df
[2023-08-30T19:51:08.322+0000] {logging_mixin.py:151} WARNING - /home/***/.local/lib/python3.8/site-packages/***/utils/sqlalchemy.py:124 DeprecationWarning: The sql_alchemy_conn option in [core] has been moved to the sql_alchemy_conn option in [database] - the old setting has been used, but please update your config.
[2023-08-30T19:51:15.259+0000] {taskinstance.py:1660} INFO - Exporting env vars: AIRFLOW_CTX_DAG_OWNER='***' AIRFLOW_CTX_DAG_ID='traffic_report' AIRFLOW_CTX_TASK_ID='export_data_to_db' AIRFLOW_CTX_EXECUTION_DATE='2023-08-29T00:00:00+00:00' AIRFLOW_CTX_TRY_NUMBER='1' AIRFLOW_CTX_DAG_RUN_ID='scheduled__2023-08-29T00:00:00+00:00'
[2023-08-30T19:51:15.297+0000] {subprocess.py:63} INFO - Tmp dir root location: /tmp
[2023-08-30T19:51:15.322+0000] {subprocess.py:75} INFO - Running command: ['/bin/bash', '-c', 'python /opt/***/dags/data_to_db.py --date 2023-08-29 --connection postgresql+psycopg2://***:***@postgres/***']
[2023-08-30T19:51:15.375+0000] {subprocess.py:86} INFO - Output:
[2023-08-30T19:51:33.980+0000] {subprocess.py:93} INFO - Traceback (most recent call last):
[2023-08-30T19:51:33.987+0000] {subprocess.py:93} INFO -   File "/opt/***/dags/data_to_db.py", line 50, in <module>
[2023-08-30T19:51:33.989+0000] {subprocess.py:93} INFO -     main(args.date, args.connection)
[2023-08-30T19:51:33.991+0000] {subprocess.py:93} INFO -   File "/opt/***/dags/data_to_db.py", line 22, in main
[2023-08-30T19:51:33.992+0000] {subprocess.py:93} INFO -     with open(filename, encoding='utf-8') as csvf:
[2023-08-30T19:51:33.994+0000] {subprocess.py:93} INFO - FileNotFoundError: [Errno 2] No such file or directory: '/opt/***/dags/data/traffic_2023-08-28.csv'
[2023-08-30T19:51:34.140+0000] {subprocess.py:97} INFO - Command exited with return code 1
[2023-08-30T19:51:34.173+0000] {taskinstance.py:1943} ERROR - Task failed with exception
Traceback (most recent call last):
  File "/home/airflow/.local/lib/python3.8/site-packages/airflow/operators/bash.py", line 210, in execute
    raise AirflowException(
airflow.exceptions.AirflowException: Bash command failed. The command returned a non-zero exit code 1.
[2023-08-30T19:51:34.185+0000] {taskinstance.py:1400} INFO - Marking task as UP_FOR_RETRY. dag_id=traffic_report, task_id=export_data_to_db, execution_date=20230829T000000, start_date=20230830T195105, end_date=20230830T195134
[2023-08-30T19:51:34.206+0000] {standard_task_runner.py:104} ERROR - Failed to execute job 18 for task export_data_to_db (Bash command failed. The command returned a non-zero exit code 1.; 361)
[2023-08-30T19:51:34.270+0000] {local_task_job_runner.py:228} INFO - Task exited with return code 1
[2023-08-30T19:51:34.301+0000] {taskinstance.py:2784} INFO - 0 downstream tasks scheduled from follow-on schedule check
[2023-08-30T19:54:33.312+0000] {logging_mixin.py:151} WARNING - /home/***/.local/lib/python3.8/site-packages/***/utils/sqlalchemy.py:124 DeprecationWarning: The sql_alchemy_conn option in [core] has been moved to the sql_alchemy_conn option in [database] - the old setting has been used, but please update your config.
[2023-08-30T19:54:33.341+0000] {taskinstance.py:1159} INFO - Dependencies all met for dep_context=non-requeueable deps ti=<TaskInstance: traffic_report.export_data_to_db scheduled__2023-08-29T00:00:00+00:00 [queued]>
[2023-08-30T19:54:33.359+0000] {taskinstance.py:1159} INFO - Dependencies all met for dep_context=requeueable deps ti=<TaskInstance: traffic_report.export_data_to_db scheduled__2023-08-29T00:00:00+00:00 [queued]>
[2023-08-30T19:54:33.361+0000] {taskinstance.py:1361} INFO - Starting attempt 1 of 2
[2023-08-30T19:54:33.375+0000] {taskinstance.py:1382} INFO - Executing <Task(BashOperator): export_data_to_db> on 2023-08-29 00:00:00+00:00
[2023-08-30T19:54:33.380+0000] {standard_task_runner.py:57} INFO - Started process 316 to run task
[2023-08-30T19:54:33.389+0000] {standard_task_runner.py:84} INFO - Running: ['***', 'tasks', 'run', 'traffic_report', 'export_data_to_db', 'scheduled__2023-08-29T00:00:00+00:00', '--job-id', '19', '--raw', '--subdir', 'DAGS_FOLDER/traffic_dag.py', '--cfg-path', '/tmp/tmpbgr8ntfv']
[2023-08-30T19:54:33.393+0000] {standard_task_runner.py:85} INFO - Job 19: Subtask export_data_to_db
[2023-08-30T19:54:33.419+0000] {logging_mixin.py:151} WARNING - /home/***/.local/lib/python3.8/site-packages/***/settings.py:195 DeprecationWarning: The sql_alchemy_conn option in [core] has been moved to the sql_alchemy_conn option in [database] - the old setting has been used, but please update your config.
[2023-08-30T19:54:33.475+0000] {task_command.py:415} INFO - Running <TaskInstance: traffic_report.export_data_to_db scheduled__2023-08-29T00:00:00+00:00 [running]> on host 86f9e97d6c70
[2023-08-30T19:54:33.491+0000] {logging_mixin.py:151} WARNING - /home/***/.local/lib/python3.8/site-packages/***/utils/sqlalchemy.py:124 DeprecationWarning: The sql_alchemy_conn option in [core] has been moved to the sql_alchemy_conn option in [database] - the old setting has been used, but please update your config.
[2023-08-30T19:54:33.571+0000] {taskinstance.py:1660} INFO - Exporting env vars: AIRFLOW_CTX_DAG_OWNER='***' AIRFLOW_CTX_DAG_ID='traffic_report' AIRFLOW_CTX_TASK_ID='export_data_to_db' AIRFLOW_CTX_EXECUTION_DATE='2023-08-29T00:00:00+00:00' AIRFLOW_CTX_TRY_NUMBER='1' AIRFLOW_CTX_DAG_RUN_ID='scheduled__2023-08-29T00:00:00+00:00'
[2023-08-30T19:54:33.578+0000] {subprocess.py:63} INFO - Tmp dir root location: /tmp
[2023-08-30T19:54:33.579+0000] {subprocess.py:75} INFO - Running command: ['/bin/bash', '-c', 'python /opt/***/dags/data_to_db.py --date 2023-08-29 --connection postgresql+psycopg2://***:***@postgres/***']
[2023-08-30T19:54:33.597+0000] {subprocess.py:86} INFO - Output:
[2023-08-30T19:54:34.560+0000] {subprocess.py:93} INFO - Traceback (most recent call last):
[2023-08-30T19:54:34.562+0000] {subprocess.py:93} INFO -   File "/home/***/.local/lib/python3.8/site-packages/sqlalchemy/engine/base.py", line 1910, in _execute_context
[2023-08-30T19:54:34.563+0000] {subprocess.py:93} INFO -     self.dialect.do_execute(
[2023-08-30T19:54:34.564+0000] {subprocess.py:93} INFO -   File "/home/***/.local/lib/python3.8/site-packages/sqlalchemy/engine/default.py", line 736, in do_execute
[2023-08-30T19:54:34.565+0000] {subprocess.py:93} INFO -     cursor.execute(statement, parameters)
[2023-08-30T19:54:34.567+0000] {subprocess.py:93} INFO - psycopg2.errors.UndefinedTable: relation "traffic_report" does not exist
[2023-08-30T19:54:34.568+0000] {subprocess.py:93} INFO - LINE 1: DELETE FROM traffic_report where date_time >= timestamp '202...
[2023-08-30T19:54:34.570+0000] {subprocess.py:93} INFO -                     ^
[2023-08-30T19:54:34.572+0000] {subprocess.py:93} INFO - 
[2023-08-30T19:54:34.573+0000] {subprocess.py:93} INFO - 
[2023-08-30T19:54:34.574+0000] {subprocess.py:93} INFO - The above exception was the direct cause of the following exception:
[2023-08-30T19:54:34.578+0000] {subprocess.py:93} INFO - 
[2023-08-30T19:54:34.579+0000] {subprocess.py:93} INFO - Traceback (most recent call last):
[2023-08-30T19:54:34.580+0000] {subprocess.py:93} INFO -   File "/opt/***/dags/data_to_db.py", line 50, in <module>
[2023-08-30T19:54:34.581+0000] {subprocess.py:93} INFO -     main(args.date, args.connection)
[2023-08-30T19:54:34.583+0000] {subprocess.py:93} INFO -   File "/opt/***/dags/data_to_db.py", line 40, in main
[2023-08-30T19:54:34.584+0000] {subprocess.py:93} INFO -     session.execute("DELETE FROM traffic_report where date_time >= timestamp '{} 00:00:00' and date_time < timestamp'{} 00:00:00'".format(yesterday, fetch_date))
[2023-08-30T19:54:34.585+0000] {subprocess.py:93} INFO -   File "/home/***/.local/lib/python3.8/site-packages/sqlalchemy/orm/session.py", line 1717, in execute
[2023-08-30T19:54:34.586+0000] {subprocess.py:93} INFO -     result = conn._execute_20(statement, params or {}, execution_options)
[2023-08-30T19:54:34.588+0000] {subprocess.py:93} INFO -   File "/home/***/.local/lib/python3.8/site-packages/sqlalchemy/engine/base.py", line 1710, in _execute_20
[2023-08-30T19:54:34.589+0000] {subprocess.py:93} INFO -     return meth(self, args_10style, kwargs_10style, execution_options)
[2023-08-30T19:54:34.591+0000] {subprocess.py:93} INFO -   File "/home/***/.local/lib/python3.8/site-packages/sqlalchemy/sql/elements.py", line 334, in _execute_on_connection
[2023-08-30T19:54:34.592+0000] {subprocess.py:93} INFO -     return connection._execute_clauseelement(
[2023-08-30T19:54:34.593+0000] {subprocess.py:93} INFO -   File "/home/***/.local/lib/python3.8/site-packages/sqlalchemy/engine/base.py", line 1577, in _execute_clauseelement
[2023-08-30T19:54:34.595+0000] {subprocess.py:93} INFO -     ret = self._execute_context(
[2023-08-30T19:54:34.596+0000] {subprocess.py:93} INFO -   File "/home/***/.local/lib/python3.8/site-packages/sqlalchemy/engine/base.py", line 1953, in _execute_context
[2023-08-30T19:54:34.597+0000] {subprocess.py:93} INFO -     self._handle_dbapi_exception(
[2023-08-30T19:54:34.599+0000] {subprocess.py:93} INFO -   File "/home/***/.local/lib/python3.8/site-packages/sqlalchemy/engine/base.py", line 2134, in _handle_dbapi_exception
[2023-08-30T19:54:34.600+0000] {subprocess.py:93} INFO -     util.raise_(
[2023-08-30T19:54:34.611+0000] {subprocess.py:93} INFO -   File "/home/***/.local/lib/python3.8/site-packages/sqlalchemy/util/compat.py", line 211, in raise_
[2023-08-30T19:54:34.615+0000] {subprocess.py:93} INFO -     raise exception
[2023-08-30T19:54:34.623+0000] {subprocess.py:93} INFO -   File "/home/***/.local/lib/python3.8/site-packages/sqlalchemy/engine/base.py", line 1910, in _execute_context
[2023-08-30T19:54:34.631+0000] {subprocess.py:93} INFO -     self.dialect.do_execute(
[2023-08-30T19:54:34.635+0000] {subprocess.py:93} INFO -   File "/home/***/.local/lib/python3.8/site-packages/sqlalchemy/engine/default.py", line 736, in do_execute
[2023-08-30T19:54:34.638+0000] {subprocess.py:93} INFO -     cursor.execute(statement, parameters)
[2023-08-30T19:54:34.642+0000] {subprocess.py:93} INFO - sqlalchemy.exc.ProgrammingError: (psycopg2.errors.UndefinedTable) relation "traffic_report" does not exist
[2023-08-30T19:54:34.649+0000] {subprocess.py:93} INFO - LINE 1: DELETE FROM traffic_report where date_time >= timestamp '202...
[2023-08-30T19:54:34.658+0000] {subprocess.py:93} INFO -                     ^
[2023-08-30T19:54:34.661+0000] {subprocess.py:93} INFO - 
[2023-08-30T19:54:34.661+0000] {subprocess.py:93} INFO - [SQL: DELETE FROM traffic_report where date_time >= timestamp '2023-08-28 00:00:00' and date_time < timestamp'2023-08-29 00:00:00']
[2023-08-30T19:54:34.662+0000] {subprocess.py:93} INFO - (Background on this error at: https://sqlalche.me/e/14/f405)
[2023-08-30T19:54:34.771+0000] {subprocess.py:97} INFO - Command exited with return code 1
[2023-08-30T19:54:34.788+0000] {taskinstance.py:1943} ERROR - Task failed with exception
Traceback (most recent call last):
  File "/home/airflow/.local/lib/python3.8/site-packages/airflow/operators/bash.py", line 210, in execute
    raise AirflowException(
airflow.exceptions.AirflowException: Bash command failed. The command returned a non-zero exit code 1.
[2023-08-30T19:54:34.795+0000] {taskinstance.py:1400} INFO - Marking task as UP_FOR_RETRY. dag_id=traffic_report, task_id=export_data_to_db, execution_date=20230829T000000, start_date=20230830T195433, end_date=20230830T195434
[2023-08-30T19:54:34.807+0000] {standard_task_runner.py:104} ERROR - Failed to execute job 19 for task export_data_to_db (Bash command failed. The command returned a non-zero exit code 1.; 316)
[2023-08-30T19:54:34.842+0000] {local_task_job_runner.py:228} INFO - Task exited with return code 1
[2023-08-30T19:54:34.863+0000] {taskinstance.py:2784} INFO - 0 downstream tasks scheduled from follow-on schedule check
[2023-08-30T20:05:57.161+0000] {logging_mixin.py:151} WARNING - /home/***/.local/lib/python3.8/site-packages/***/utils/sqlalchemy.py:124 DeprecationWarning: The sql_alchemy_conn option in [core] has been moved to the sql_alchemy_conn option in [database] - the old setting has been used, but please update your config.
[2023-08-30T20:05:57.173+0000] {taskinstance.py:1159} INFO - Dependencies all met for dep_context=non-requeueable deps ti=<TaskInstance: traffic_report.export_data_to_db scheduled__2023-08-29T00:00:00+00:00 [queued]>
[2023-08-30T20:05:57.181+0000] {taskinstance.py:1159} INFO - Dependencies all met for dep_context=requeueable deps ti=<TaskInstance: traffic_report.export_data_to_db scheduled__2023-08-29T00:00:00+00:00 [queued]>
[2023-08-30T20:05:57.183+0000] {taskinstance.py:1361} INFO - Starting attempt 1 of 2
[2023-08-30T20:05:57.194+0000] {taskinstance.py:1382} INFO - Executing <Task(BashOperator): export_data_to_db> on 2023-08-29 00:00:00+00:00
[2023-08-30T20:05:57.199+0000] {standard_task_runner.py:57} INFO - Started process 517 to run task
[2023-08-30T20:05:57.202+0000] {standard_task_runner.py:84} INFO - Running: ['***', 'tasks', 'run', 'traffic_report', 'export_data_to_db', 'scheduled__2023-08-29T00:00:00+00:00', '--job-id', '22', '--raw', '--subdir', 'DAGS_FOLDER/traffic_dag.py', '--cfg-path', '/tmp/tmp8vsdl67j']
[2023-08-30T20:05:57.206+0000] {standard_task_runner.py:85} INFO - Job 22: Subtask export_data_to_db
[2023-08-30T20:05:57.222+0000] {logging_mixin.py:151} WARNING - /home/***/.local/lib/python3.8/site-packages/***/settings.py:195 DeprecationWarning: The sql_alchemy_conn option in [core] has been moved to the sql_alchemy_conn option in [database] - the old setting has been used, but please update your config.
[2023-08-30T20:05:57.262+0000] {task_command.py:415} INFO - Running <TaskInstance: traffic_report.export_data_to_db scheduled__2023-08-29T00:00:00+00:00 [running]> on host 3938d7abd9ff
[2023-08-30T20:05:57.278+0000] {logging_mixin.py:151} WARNING - /home/***/.local/lib/python3.8/site-packages/***/utils/sqlalchemy.py:124 DeprecationWarning: The sql_alchemy_conn option in [core] has been moved to the sql_alchemy_conn option in [database] - the old setting has been used, but please update your config.
[2023-08-30T20:05:57.333+0000] {taskinstance.py:1660} INFO - Exporting env vars: AIRFLOW_CTX_DAG_OWNER='***' AIRFLOW_CTX_DAG_ID='traffic_report' AIRFLOW_CTX_TASK_ID='export_data_to_db' AIRFLOW_CTX_EXECUTION_DATE='2023-08-29T00:00:00+00:00' AIRFLOW_CTX_TRY_NUMBER='1' AIRFLOW_CTX_DAG_RUN_ID='scheduled__2023-08-29T00:00:00+00:00'
[2023-08-30T20:05:57.335+0000] {subprocess.py:63} INFO - Tmp dir root location: /tmp
[2023-08-30T20:05:57.337+0000] {subprocess.py:75} INFO - Running command: ['/bin/bash', '-c', 'python /opt/***/dags/data_to_db.py --date 2023-08-29 --connection postgresql+psycopg2://***:***@postgres/***']
[2023-08-30T20:05:57.348+0000] {subprocess.py:86} INFO - Output:
[2023-08-30T20:05:58.188+0000] {subprocess.py:93} INFO - Traceback (most recent call last):
[2023-08-30T20:05:58.190+0000] {subprocess.py:93} INFO -   File "/home/***/.local/lib/python3.8/site-packages/sqlalchemy/engine/base.py", line 1890, in _execute_context
[2023-08-30T20:05:58.194+0000] {subprocess.py:93} INFO -     self.dialect.do_executemany(
[2023-08-30T20:05:58.195+0000] {subprocess.py:93} INFO -   File "/home/***/.local/lib/python3.8/site-packages/sqlalchemy/dialects/postgresql/psycopg2.py", line 982, in do_executemany
[2023-08-30T20:05:58.196+0000] {subprocess.py:93} INFO -     context._psycopg2_fetched_rows = xtras.execute_values(
[2023-08-30T20:05:58.197+0000] {subprocess.py:93} INFO -   File "/home/***/.local/lib/python3.8/site-packages/psycopg2/extras.py", line 1299, in execute_values
[2023-08-30T20:05:58.199+0000] {subprocess.py:93} INFO -     cur.execute(b''.join(parts))
[2023-08-30T20:05:58.201+0000] {subprocess.py:93} INFO - psycopg2.errors.UndefinedFunction: function st_geomfromewkt(unknown) does not exist
[2023-08-30T20:05:58.203+0000] {subprocess.py:93} INFO - LINE 1: ...', '2023-08-28 00:03:52+00:00', 'traffic hazard', ST_GeomFro...
[2023-08-30T20:05:58.205+0000] {subprocess.py:93} INFO -                                                              ^
[2023-08-30T20:05:58.206+0000] {subprocess.py:93} INFO - HINT:  No function matches the given name and argument types. You might need to add explicit type casts.
[2023-08-30T20:05:58.207+0000] {subprocess.py:93} INFO - 
[2023-08-30T20:05:58.208+0000] {subprocess.py:93} INFO - 
[2023-08-30T20:05:58.212+0000] {subprocess.py:93} INFO - The above exception was the direct cause of the following exception:
[2023-08-30T20:05:58.214+0000] {subprocess.py:93} INFO - 
[2023-08-30T20:05:58.215+0000] {subprocess.py:93} INFO - Traceback (most recent call last):
[2023-08-30T20:05:58.216+0000] {subprocess.py:93} INFO -   File "/opt/***/dags/data_to_db.py", line 50, in <module>
[2023-08-30T20:05:58.217+0000] {subprocess.py:93} INFO -     main(args.date, args.connection)
[2023-08-30T20:05:58.218+0000] {subprocess.py:93} INFO -   File "/opt/***/dags/data_to_db.py", line 41, in main
[2023-08-30T20:05:58.219+0000] {subprocess.py:93} INFO -     session.bulk_save_objects(data_insert)
[2023-08-30T20:05:58.221+0000] {subprocess.py:93} INFO -   File "/home/***/.local/lib/python3.8/site-packages/sqlalchemy/orm/session.py", line 3705, in bulk_save_objects
[2023-08-30T20:05:58.222+0000] {subprocess.py:93} INFO -     self._bulk_save_mappings(
[2023-08-30T20:05:58.224+0000] {subprocess.py:93} INFO -   File "/home/***/.local/lib/python3.8/site-packages/sqlalchemy/orm/session.py", line 3913, in _bulk_save_mappings
[2023-08-30T20:05:58.226+0000] {subprocess.py:93} INFO -     transaction.rollback(_capture_exception=True)
[2023-08-30T20:05:58.227+0000] {subprocess.py:93} INFO -   File "/home/***/.local/lib/python3.8/site-packages/sqlalchemy/util/langhelpers.py", line 70, in __exit__
[2023-08-30T20:05:58.229+0000] {subprocess.py:93} INFO -     compat.raise_(
[2023-08-30T20:05:58.230+0000] {subprocess.py:93} INFO -   File "/home/***/.local/lib/python3.8/site-packages/sqlalchemy/util/compat.py", line 211, in raise_
[2023-08-30T20:05:58.231+0000] {subprocess.py:93} INFO -     raise exception
[2023-08-30T20:05:58.232+0000] {subprocess.py:93} INFO -   File "/home/***/.local/lib/python3.8/site-packages/sqlalchemy/orm/session.py", line 3901, in _bulk_save_mappings
[2023-08-30T20:05:58.234+0000] {subprocess.py:93} INFO -     persistence._bulk_insert(
[2023-08-30T20:05:58.235+0000] {subprocess.py:93} INFO -   File "/home/***/.local/lib/python3.8/site-packages/sqlalchemy/orm/persistence.py", line 107, in _bulk_insert
[2023-08-30T20:05:58.240+0000] {subprocess.py:93} INFO -     _emit_insert_statements(
[2023-08-30T20:05:58.241+0000] {subprocess.py:93} INFO -   File "/home/***/.local/lib/python3.8/site-packages/sqlalchemy/orm/persistence.py", line 1097, in _emit_insert_statements
[2023-08-30T20:05:58.243+0000] {subprocess.py:93} INFO -     c = connection._execute_20(
[2023-08-30T20:05:58.245+0000] {subprocess.py:93} INFO -   File "/home/***/.local/lib/python3.8/site-packages/sqlalchemy/engine/base.py", line 1710, in _execute_20
[2023-08-30T20:05:58.246+0000] {subprocess.py:93} INFO -     return meth(self, args_10style, kwargs_10style, execution_options)
[2023-08-30T20:05:58.247+0000] {subprocess.py:93} INFO -   File "/home/***/.local/lib/python3.8/site-packages/sqlalchemy/sql/elements.py", line 334, in _execute_on_connection
[2023-08-30T20:05:58.248+0000] {subprocess.py:93} INFO -     return connection._execute_clauseelement(
[2023-08-30T20:05:58.249+0000] {subprocess.py:93} INFO -   File "/home/***/.local/lib/python3.8/site-packages/sqlalchemy/engine/base.py", line 1577, in _execute_clauseelement
[2023-08-30T20:05:58.251+0000] {subprocess.py:93} INFO -     ret = self._execute_context(
[2023-08-30T20:05:58.252+0000] {subprocess.py:93} INFO -   File "/home/***/.local/lib/python3.8/site-packages/sqlalchemy/engine/base.py", line 1953, in _execute_context
[2023-08-30T20:05:58.254+0000] {subprocess.py:93} INFO -     self._handle_dbapi_exception(
[2023-08-30T20:05:58.258+0000] {subprocess.py:93} INFO -   File "/home/***/.local/lib/python3.8/site-packages/sqlalchemy/engine/base.py", line 2134, in _handle_dbapi_exception
[2023-08-30T20:05:58.259+0000] {subprocess.py:93} INFO -     util.raise_(
[2023-08-30T20:05:58.260+0000] {subprocess.py:93} INFO -   File "/home/***/.local/lib/python3.8/site-packages/sqlalchemy/util/compat.py", line 211, in raise_
[2023-08-30T20:05:58.261+0000] {subprocess.py:93} INFO -     raise exception
[2023-08-30T20:05:58.262+0000] {subprocess.py:93} INFO -   File "/home/***/.local/lib/python3.8/site-packages/sqlalchemy/engine/base.py", line 1890, in _execute_context
[2023-08-30T20:05:58.263+0000] {subprocess.py:93} INFO -     self.dialect.do_executemany(
[2023-08-30T20:05:58.264+0000] {subprocess.py:93} INFO -   File "/home/***/.local/lib/python3.8/site-packages/sqlalchemy/dialects/postgresql/psycopg2.py", line 982, in do_executemany
[2023-08-30T20:05:58.266+0000] {subprocess.py:93} INFO -     context._psycopg2_fetched_rows = xtras.execute_values(
[2023-08-30T20:05:58.268+0000] {subprocess.py:93} INFO -   File "/home/***/.local/lib/python3.8/site-packages/psycopg2/extras.py", line 1299, in execute_values
[2023-08-30T20:05:58.269+0000] {subprocess.py:93} INFO -     cur.execute(b''.join(parts))
[2023-08-30T20:05:58.271+0000] {subprocess.py:93} INFO - sqlalchemy.exc.ProgrammingError: (psycopg2.errors.UndefinedFunction) function st_geomfromewkt(unknown) does not exist
[2023-08-30T20:05:58.272+0000] {subprocess.py:93} INFO - LINE 1: ...', '2023-08-28 00:03:52+00:00', 'traffic hazard', ST_GeomFro...
[2023-08-30T20:05:58.275+0000] {subprocess.py:93} INFO -                                                              ^
[2023-08-30T20:05:58.276+0000] {subprocess.py:93} INFO - HINT:  No function matches the given name and argument types. You might need to add explicit type casts.
[2023-08-30T20:05:58.277+0000] {subprocess.py:93} INFO - 
[2023-08-30T20:05:58.278+0000] {subprocess.py:93} INFO - [SQL: INSERT INTO traffic_report (timestamp, traffic_report_id, date_time, issue_reported, location, latitude, longitude, address, weekday, date, time) VALUES (%(timestamp)s, %(traffic_report_id)s, %(date_time)s, %(issue_reported)s, ST_GeomFromEWKT(%(location)s), %(latitude)s, %(longitude)s, %(address)s, %(weekday)s, %(date)s, %(time)s)]
[2023-08-30T20:05:58.279+0000] {subprocess.py:93} INFO - [parameters: ({'timestamp': '1693181032000000000', 'traffic_report_id': '5378C3D8A9417D31D1ABDB3DA9FFB909420656EB_1693181032', 'date_time': '2023-08-28 00:03:52+00:00', 'issue_reported': 'traffic hazard', 'location': 'POINT(-97.745893 30.399081)', 'latitude': '30.399081', 'longitude': '-97.745893', 'address': '10211-11149 research blvd nb', 'weekday': 'Monday', 'date': '2023-08-28', 'time': '00:03:52'}, {'timestamp': '1693181060000000000', 'traffic_report_id': 'BC4D45844D467B9FBD27DCD0B41FE52D229884C3_1693181060', 'date_time': '2023-08-28 00:04:20+00:00', 'issue_reported': 'traffic hazard', 'location': 'POINT(-97.72848 30.374077)', 'latitude': '30.374077', 'longitude': '-97.72848', 'address': '9000-9098 research blvd sb', 'weekday': 'Monday', 'date': '2023-08-28', 'time': '00:04:20'}, {'timestamp': '1693181080000000000', 'traffic_report_id': 'BE69557045E8D95F6C5BC62BEA729B2E4BC50A7C_1693181080', 'date_time': '2023-08-28 00:04:40+00:00', 'issue_reported': 'stalled vehicle', 'location': 'POINT(-97.657377 30.402212)', 'latitude': '30.402212', 'longitude': '-97.657377', 'address': 'tech ridge blvd / e parmer ln', 'weekday': 'Monday', 'date': '2023-08-28', 'time': '00:04:40'}, {'timestamp': '1693181387000000000', 'traffic_report_id': 'B25B748A59D8B6B5B5AE3E9D985289E795C874ED_1693181387', 'date_time': '2023-08-28 00:09:47+00:00', 'issue_reported': 'crash service', 'location': 'POINT(-97.752877 30.21522)', 'latitude': '30.21522', 'longitude': '-97.752877', 'address': '4108 s ih 35 svrd sb', 'weekday': 'Monday', 'date': '2023-08-28', 'time': '00:09:47'}, {'timestamp': '1693182276000000000', 'traffic_report_id': '91A0461DA8536C97056D3B86390D0BDD472CA52B_1693182276', 'date_time': '2023-08-28 00:24:36+00:00', 'issue_reported': 'traffic hazard', 'location': 'POINT(-97.614943 30.237362)', 'latitude': '30.237362', 'longitude': '-97.614943', 'address': '600-1625 s sh 130 nb', 'weekday': 'Monday', 'date': '2023-08-28', 'time': '00:24:36'}, {'timestamp': '1693182347000000000', 'traffic_report_id': '4A4AB45448022F0C738FE9E310148EA1EB7F856B_1693182347', 'date_time': '2023-08-28 00:25:47+00:00', 'issue_reported': 'stalled vehicle', 'location': 'POINT(-97.67912 30.433455)', 'latitude': '30.433455', 'longitude': '-97.67912', 'address': '1831 w wells branch pkwy', 'weekday': 'Monday', 'date': '2023-08-28', 'time': '00:25:47'}, {'timestamp': '1693182673000000000', 'traffic_report_id': '566EE6D19FEF04459D959B08349D6C07B3A309A2_1693182673', 'date_time': '2023-08-28 00:31:13+00:00', 'issue_reported': 'traffic hazard', 'location': 'POINT(-97.665765 30.30781)', 'latitude': '30.30781', 'longitude': '-97.665765', 'address': '6508 ashland cir', 'weekday': 'Monday', 'date': '2023-08-28', 'time': '00:31:13'}, {'timestamp': '1693183109000000000', 'traffic_report_id': '5527E76C85E5B71C6DEFA5F0099519B1D67B4627_1693183109', 'date_time': '2023-08-28 00:38:29+00:00', 'issue_reported': 'traffic hazard', 'location': 'POINT(-97.601927 30.257985)', 'latitude': '30.257985', 'longitude': '-97.601927', 'address': '5000 n sh 130 sb', 'weekday': 'Monday', 'date': '2023-08-28', 'time': '00:38:29'}  ... displaying 10 of 143 total bound parameter sets ...  {'timestamp': '1693267017000000000', 'traffic_report_id': '8334918DA76533B5C14F235F374E327C95035AA3_1693267017', 'date_time': '2023-08-28 23:56:57+00:00', 'issue_reported': 'crash service', 'location': 'POINT(-97.789714 30.159788)', 'latitude': '30.159788', 'longitude': '-97.789714', 'address': '9700 s ih 35 sb', 'weekday': 'Monday', 'date': '2023-08-28', 'time': '23:56:57'}, {'timestamp': '1693267163000000000', 'traffic_report_id': '73CA0CCD6FF3D0CA58884DEAAAD9E042EC048A8F_1693267163', 'date_time': '2023-08-28 23:59:23+00:00', 'issue_reported': 'loose livestock', 'location': 'POINT(-97.565464 30.301566)', 'latitude': '30.301566', 'longitude': '-97.565464', 'address': 'n fm 973 rd / e braker ln', 'weekday': 'Monday', 'date': '2023-08-28', 'time': '23:59:23'})]
[2023-08-30T20:05:58.281+0000] {subprocess.py:93} INFO - (Background on this error at: https://sqlalche.me/e/14/f405)
[2023-08-30T20:05:58.316+0000] {subprocess.py:97} INFO - Command exited with return code 1
[2023-08-30T20:05:58.334+0000] {taskinstance.py:1943} ERROR - Task failed with exception
Traceback (most recent call last):
  File "/home/airflow/.local/lib/python3.8/site-packages/airflow/operators/bash.py", line 210, in execute
    raise AirflowException(
airflow.exceptions.AirflowException: Bash command failed. The command returned a non-zero exit code 1.
[2023-08-30T20:05:58.348+0000] {taskinstance.py:1400} INFO - Marking task as UP_FOR_RETRY. dag_id=traffic_report, task_id=export_data_to_db, execution_date=20230829T000000, start_date=20230830T200557, end_date=20230830T200558
[2023-08-30T20:05:58.387+0000] {standard_task_runner.py:104} ERROR - Failed to execute job 22 for task export_data_to_db (Bash command failed. The command returned a non-zero exit code 1.; 517)
[2023-08-30T20:05:58.419+0000] {local_task_job_runner.py:228} INFO - Task exited with return code 1
[2023-08-30T20:05:58.439+0000] {taskinstance.py:2784} INFO - 0 downstream tasks scheduled from follow-on schedule check
[2023-08-30T20:33:59.737+0000] {logging_mixin.py:151} WARNING - /home/***/.local/lib/python3.8/site-packages/***/utils/sqlalchemy.py:124 DeprecationWarning: The sql_alchemy_conn option in [core] has been moved to the sql_alchemy_conn option in [database] - the old setting has been used, but please update your config.
[2023-08-30T20:33:59.747+0000] {taskinstance.py:1159} INFO - Dependencies all met for dep_context=non-requeueable deps ti=<TaskInstance: traffic_report.export_data_to_db scheduled__2023-08-29T00:00:00+00:00 [queued]>
[2023-08-30T20:33:59.765+0000] {taskinstance.py:1159} INFO - Dependencies all met for dep_context=requeueable deps ti=<TaskInstance: traffic_report.export_data_to_db scheduled__2023-08-29T00:00:00+00:00 [queued]>
[2023-08-30T20:33:59.766+0000] {taskinstance.py:1361} INFO - Starting attempt 1 of 2
[2023-08-30T20:33:59.783+0000] {taskinstance.py:1382} INFO - Executing <Task(BashOperator): export_data_to_db> on 2023-08-29 00:00:00+00:00
[2023-08-30T20:33:59.797+0000] {standard_task_runner.py:57} INFO - Started process 337 to run task
[2023-08-30T20:33:59.801+0000] {standard_task_runner.py:84} INFO - Running: ['***', 'tasks', 'run', 'traffic_report', 'export_data_to_db', 'scheduled__2023-08-29T00:00:00+00:00', '--job-id', '18', '--raw', '--subdir', 'DAGS_FOLDER/traffic_dag.py', '--cfg-path', '/tmp/tmp1_gg89ry']
[2023-08-30T20:33:59.805+0000] {standard_task_runner.py:85} INFO - Job 18: Subtask export_data_to_db
[2023-08-30T20:33:59.840+0000] {logging_mixin.py:151} WARNING - /home/***/.local/lib/python3.8/site-packages/***/settings.py:195 DeprecationWarning: The sql_alchemy_conn option in [core] has been moved to the sql_alchemy_conn option in [database] - the old setting has been used, but please update your config.
[2023-08-30T20:33:59.899+0000] {task_command.py:415} INFO - Running <TaskInstance: traffic_report.export_data_to_db scheduled__2023-08-29T00:00:00+00:00 [running]> on host 961f38e8363e
[2023-08-30T20:33:59.927+0000] {logging_mixin.py:151} WARNING - /home/***/.local/lib/python3.8/site-packages/***/utils/sqlalchemy.py:124 DeprecationWarning: The sql_alchemy_conn option in [core] has been moved to the sql_alchemy_conn option in [database] - the old setting has been used, but please update your config.
[2023-08-30T20:34:00.021+0000] {taskinstance.py:1660} INFO - Exporting env vars: AIRFLOW_CTX_DAG_OWNER='***' AIRFLOW_CTX_DAG_ID='traffic_report' AIRFLOW_CTX_TASK_ID='export_data_to_db' AIRFLOW_CTX_EXECUTION_DATE='2023-08-29T00:00:00+00:00' AIRFLOW_CTX_TRY_NUMBER='1' AIRFLOW_CTX_DAG_RUN_ID='scheduled__2023-08-29T00:00:00+00:00'
[2023-08-30T20:34:00.028+0000] {subprocess.py:63} INFO - Tmp dir root location: /tmp
[2023-08-30T20:34:00.037+0000] {subprocess.py:75} INFO - Running command: ['/bin/bash', '-c', 'python /opt/***/dags/data_to_db.py --date 2023-08-29 --connection postgresql+psycopg2://***:***@postgres/***']
[2023-08-30T20:34:00.062+0000] {subprocess.py:86} INFO - Output:
[2023-08-30T20:34:01.056+0000] {subprocess.py:93} INFO - Traceback (most recent call last):
[2023-08-30T20:34:01.058+0000] {subprocess.py:93} INFO -   File "/home/***/.local/lib/python3.8/site-packages/sqlalchemy/engine/base.py", line 1890, in _execute_context
[2023-08-30T20:34:01.060+0000] {subprocess.py:93} INFO -     self.dialect.do_executemany(
[2023-08-30T20:34:01.061+0000] {subprocess.py:93} INFO -   File "/home/***/.local/lib/python3.8/site-packages/sqlalchemy/dialects/postgresql/psycopg2.py", line 982, in do_executemany
[2023-08-30T20:34:01.068+0000] {subprocess.py:93} INFO -     context._psycopg2_fetched_rows = xtras.execute_values(
[2023-08-30T20:34:01.070+0000] {subprocess.py:93} INFO -   File "/home/***/.local/lib/python3.8/site-packages/psycopg2/extras.py", line 1299, in execute_values
[2023-08-30T20:34:01.072+0000] {subprocess.py:93} INFO -     cur.execute(b''.join(parts))
[2023-08-30T20:34:01.074+0000] {subprocess.py:93} INFO - psycopg2.errors.UndefinedFunction: function st_geomfromewkt(unknown) does not exist
[2023-08-30T20:34:01.076+0000] {subprocess.py:93} INFO - LINE 1: ...', '2023-08-28 00:03:52+00:00', 'traffic hazard', ST_GeomFro...
[2023-08-30T20:34:01.078+0000] {subprocess.py:93} INFO -                                                              ^
[2023-08-30T20:34:01.080+0000] {subprocess.py:93} INFO - HINT:  No function matches the given name and argument types. You might need to add explicit type casts.
[2023-08-30T20:34:01.081+0000] {subprocess.py:93} INFO - 
[2023-08-30T20:34:01.086+0000] {subprocess.py:93} INFO - 
[2023-08-30T20:34:01.088+0000] {subprocess.py:93} INFO - The above exception was the direct cause of the following exception:
[2023-08-30T20:34:01.089+0000] {subprocess.py:93} INFO - 
[2023-08-30T20:34:01.094+0000] {subprocess.py:93} INFO - Traceback (most recent call last):
[2023-08-30T20:34:01.096+0000] {subprocess.py:93} INFO -   File "/opt/***/dags/data_to_db.py", line 50, in <module>
[2023-08-30T20:34:01.097+0000] {subprocess.py:93} INFO -     main(args.date, args.connection)
[2023-08-30T20:34:01.101+0000] {subprocess.py:93} INFO -   File "/opt/***/dags/data_to_db.py", line 41, in main
[2023-08-30T20:34:01.104+0000] {subprocess.py:93} INFO -     session.bulk_save_objects(data_insert)
[2023-08-30T20:34:01.108+0000] {subprocess.py:93} INFO -   File "/home/***/.local/lib/python3.8/site-packages/sqlalchemy/orm/session.py", line 3705, in bulk_save_objects
[2023-08-30T20:34:01.111+0000] {subprocess.py:93} INFO -     self._bulk_save_mappings(
[2023-08-30T20:34:01.112+0000] {subprocess.py:93} INFO -   File "/home/***/.local/lib/python3.8/site-packages/sqlalchemy/orm/session.py", line 3913, in _bulk_save_mappings
[2023-08-30T20:34:01.114+0000] {subprocess.py:93} INFO -     transaction.rollback(_capture_exception=True)
[2023-08-30T20:34:01.116+0000] {subprocess.py:93} INFO -   File "/home/***/.local/lib/python3.8/site-packages/sqlalchemy/util/langhelpers.py", line 70, in __exit__
[2023-08-30T20:34:01.118+0000] {subprocess.py:93} INFO -     compat.raise_(
[2023-08-30T20:34:01.120+0000] {subprocess.py:93} INFO -   File "/home/***/.local/lib/python3.8/site-packages/sqlalchemy/util/compat.py", line 211, in raise_
[2023-08-30T20:34:01.122+0000] {subprocess.py:93} INFO -     raise exception
[2023-08-30T20:34:01.130+0000] {subprocess.py:93} INFO -   File "/home/***/.local/lib/python3.8/site-packages/sqlalchemy/orm/session.py", line 3901, in _bulk_save_mappings
[2023-08-30T20:34:01.141+0000] {subprocess.py:93} INFO -     persistence._bulk_insert(
[2023-08-30T20:34:01.144+0000] {subprocess.py:93} INFO -   File "/home/***/.local/lib/python3.8/site-packages/sqlalchemy/orm/persistence.py", line 107, in _bulk_insert
[2023-08-30T20:34:01.146+0000] {subprocess.py:93} INFO -     _emit_insert_statements(
[2023-08-30T20:34:01.148+0000] {subprocess.py:93} INFO -   File "/home/***/.local/lib/python3.8/site-packages/sqlalchemy/orm/persistence.py", line 1097, in _emit_insert_statements
[2023-08-30T20:34:01.151+0000] {subprocess.py:93} INFO -     c = connection._execute_20(
[2023-08-30T20:34:01.157+0000] {subprocess.py:93} INFO -   File "/home/***/.local/lib/python3.8/site-packages/sqlalchemy/engine/base.py", line 1710, in _execute_20
[2023-08-30T20:34:01.163+0000] {subprocess.py:93} INFO -     return meth(self, args_10style, kwargs_10style, execution_options)
[2023-08-30T20:34:01.165+0000] {subprocess.py:93} INFO -   File "/home/***/.local/lib/python3.8/site-packages/sqlalchemy/sql/elements.py", line 334, in _execute_on_connection
[2023-08-30T20:34:01.171+0000] {subprocess.py:93} INFO -     return connection._execute_clauseelement(
[2023-08-30T20:34:01.172+0000] {subprocess.py:93} INFO -   File "/home/***/.local/lib/python3.8/site-packages/sqlalchemy/engine/base.py", line 1577, in _execute_clauseelement
[2023-08-30T20:34:01.174+0000] {subprocess.py:93} INFO -     ret = self._execute_context(
[2023-08-30T20:34:01.176+0000] {subprocess.py:93} INFO -   File "/home/***/.local/lib/python3.8/site-packages/sqlalchemy/engine/base.py", line 1953, in _execute_context
[2023-08-30T20:34:01.178+0000] {subprocess.py:93} INFO -     self._handle_dbapi_exception(
[2023-08-30T20:34:01.179+0000] {subprocess.py:93} INFO -   File "/home/***/.local/lib/python3.8/site-packages/sqlalchemy/engine/base.py", line 2134, in _handle_dbapi_exception
[2023-08-30T20:34:01.183+0000] {subprocess.py:93} INFO -     util.raise_(
[2023-08-30T20:34:01.186+0000] {subprocess.py:93} INFO -   File "/home/***/.local/lib/python3.8/site-packages/sqlalchemy/util/compat.py", line 211, in raise_
[2023-08-30T20:34:01.188+0000] {subprocess.py:93} INFO -     raise exception
[2023-08-30T20:34:01.196+0000] {subprocess.py:93} INFO -   File "/home/***/.local/lib/python3.8/site-packages/sqlalchemy/engine/base.py", line 1890, in _execute_context
[2023-08-30T20:34:01.199+0000] {subprocess.py:93} INFO -     self.dialect.do_executemany(
[2023-08-30T20:34:01.202+0000] {subprocess.py:93} INFO -   File "/home/***/.local/lib/python3.8/site-packages/sqlalchemy/dialects/postgresql/psycopg2.py", line 982, in do_executemany
[2023-08-30T20:34:01.204+0000] {subprocess.py:93} INFO -     context._psycopg2_fetched_rows = xtras.execute_values(
[2023-08-30T20:34:01.206+0000] {subprocess.py:93} INFO -   File "/home/***/.local/lib/python3.8/site-packages/psycopg2/extras.py", line 1299, in execute_values
[2023-08-30T20:34:01.208+0000] {subprocess.py:93} INFO -     cur.execute(b''.join(parts))
[2023-08-30T20:34:01.211+0000] {subprocess.py:93} INFO - sqlalchemy.exc.ProgrammingError: (psycopg2.errors.UndefinedFunction) function st_geomfromewkt(unknown) does not exist
[2023-08-30T20:34:01.213+0000] {subprocess.py:93} INFO - LINE 1: ...', '2023-08-28 00:03:52+00:00', 'traffic hazard', ST_GeomFro...
[2023-08-30T20:34:01.215+0000] {subprocess.py:93} INFO -                                                              ^
[2023-08-30T20:34:01.217+0000] {subprocess.py:93} INFO - HINT:  No function matches the given name and argument types. You might need to add explicit type casts.
[2023-08-30T20:34:01.219+0000] {subprocess.py:93} INFO - 
[2023-08-30T20:34:01.220+0000] {subprocess.py:93} INFO - [SQL: INSERT INTO traffic_report (timestamp, traffic_report_id, date_time, issue_reported, location, latitude, longitude, address, weekday, date, time) VALUES (%(timestamp)s, %(traffic_report_id)s, %(date_time)s, %(issue_reported)s, ST_GeomFromEWKT(%(location)s), %(latitude)s, %(longitude)s, %(address)s, %(weekday)s, %(date)s, %(time)s)]
[2023-08-30T20:34:01.223+0000] {subprocess.py:93} INFO - [parameters: ({'timestamp': '1693181032000000000', 'traffic_report_id': '5378C3D8A9417D31D1ABDB3DA9FFB909420656EB_1693181032', 'date_time': '2023-08-28 00:03:52+00:00', 'issue_reported': 'traffic hazard', 'location': 'POINT(-97.745893 30.399081)', 'latitude': '30.399081', 'longitude': '-97.745893', 'address': '10211-11149 research blvd nb', 'weekday': 'Monday', 'date': '2023-08-28', 'time': '00:03:52'}, {'timestamp': '1693181060000000000', 'traffic_report_id': 'BC4D45844D467B9FBD27DCD0B41FE52D229884C3_1693181060', 'date_time': '2023-08-28 00:04:20+00:00', 'issue_reported': 'traffic hazard', 'location': 'POINT(-97.72848 30.374077)', 'latitude': '30.374077', 'longitude': '-97.72848', 'address': '9000-9098 research blvd sb', 'weekday': 'Monday', 'date': '2023-08-28', 'time': '00:04:20'}, {'timestamp': '1693181080000000000', 'traffic_report_id': 'BE69557045E8D95F6C5BC62BEA729B2E4BC50A7C_1693181080', 'date_time': '2023-08-28 00:04:40+00:00', 'issue_reported': 'stalled vehicle', 'location': 'POINT(-97.657377 30.402212)', 'latitude': '30.402212', 'longitude': '-97.657377', 'address': 'tech ridge blvd / e parmer ln', 'weekday': 'Monday', 'date': '2023-08-28', 'time': '00:04:40'}, {'timestamp': '1693181387000000000', 'traffic_report_id': 'B25B748A59D8B6B5B5AE3E9D985289E795C874ED_1693181387', 'date_time': '2023-08-28 00:09:47+00:00', 'issue_reported': 'crash service', 'location': 'POINT(-97.752877 30.21522)', 'latitude': '30.21522', 'longitude': '-97.752877', 'address': '4108 s ih 35 svrd sb', 'weekday': 'Monday', 'date': '2023-08-28', 'time': '00:09:47'}, {'timestamp': '1693182276000000000', 'traffic_report_id': '91A0461DA8536C97056D3B86390D0BDD472CA52B_1693182276', 'date_time': '2023-08-28 00:24:36+00:00', 'issue_reported': 'traffic hazard', 'location': 'POINT(-97.614943 30.237362)', 'latitude': '30.237362', 'longitude': '-97.614943', 'address': '600-1625 s sh 130 nb', 'weekday': 'Monday', 'date': '2023-08-28', 'time': '00:24:36'}, {'timestamp': '1693182347000000000', 'traffic_report_id': '4A4AB45448022F0C738FE9E310148EA1EB7F856B_1693182347', 'date_time': '2023-08-28 00:25:47+00:00', 'issue_reported': 'stalled vehicle', 'location': 'POINT(-97.67912 30.433455)', 'latitude': '30.433455', 'longitude': '-97.67912', 'address': '1831 w wells branch pkwy', 'weekday': 'Monday', 'date': '2023-08-28', 'time': '00:25:47'}, {'timestamp': '1693182673000000000', 'traffic_report_id': '566EE6D19FEF04459D959B08349D6C07B3A309A2_1693182673', 'date_time': '2023-08-28 00:31:13+00:00', 'issue_reported': 'traffic hazard', 'location': 'POINT(-97.665765 30.30781)', 'latitude': '30.30781', 'longitude': '-97.665765', 'address': '6508 ashland cir', 'weekday': 'Monday', 'date': '2023-08-28', 'time': '00:31:13'}, {'timestamp': '1693183109000000000', 'traffic_report_id': '5527E76C85E5B71C6DEFA5F0099519B1D67B4627_1693183109', 'date_time': '2023-08-28 00:38:29+00:00', 'issue_reported': 'traffic hazard', 'location': 'POINT(-97.601927 30.257985)', 'latitude': '30.257985', 'longitude': '-97.601927', 'address': '5000 n sh 130 sb', 'weekday': 'Monday', 'date': '2023-08-28', 'time': '00:38:29'}  ... displaying 10 of 143 total bound parameter sets ...  {'timestamp': '1693267017000000000', 'traffic_report_id': '8334918DA76533B5C14F235F374E327C95035AA3_1693267017', 'date_time': '2023-08-28 23:56:57+00:00', 'issue_reported': 'crash service', 'location': 'POINT(-97.789714 30.159788)', 'latitude': '30.159788', 'longitude': '-97.789714', 'address': '9700 s ih 35 sb', 'weekday': 'Monday', 'date': '2023-08-28', 'time': '23:56:57'}, {'timestamp': '1693267163000000000', 'traffic_report_id': '73CA0CCD6FF3D0CA58884DEAAAD9E042EC048A8F_1693267163', 'date_time': '2023-08-28 23:59:23+00:00', 'issue_reported': 'loose livestock', 'location': 'POINT(-97.565464 30.301566)', 'latitude': '30.301566', 'longitude': '-97.565464', 'address': 'n fm 973 rd / e braker ln', 'weekday': 'Monday', 'date': '2023-08-28', 'time': '23:59:23'})]
[2023-08-30T20:34:01.225+0000] {subprocess.py:93} INFO - (Background on this error at: https://sqlalche.me/e/14/f405)
[2023-08-30T20:34:01.303+0000] {subprocess.py:97} INFO - Command exited with return code 1
[2023-08-30T20:34:01.327+0000] {taskinstance.py:1943} ERROR - Task failed with exception
Traceback (most recent call last):
  File "/home/airflow/.local/lib/python3.8/site-packages/airflow/operators/bash.py", line 210, in execute
    raise AirflowException(
airflow.exceptions.AirflowException: Bash command failed. The command returned a non-zero exit code 1.
[2023-08-30T20:34:01.332+0000] {taskinstance.py:1400} INFO - Marking task as UP_FOR_RETRY. dag_id=traffic_report, task_id=export_data_to_db, execution_date=20230829T000000, start_date=20230830T203359, end_date=20230830T203401
[2023-08-30T20:34:01.355+0000] {standard_task_runner.py:104} ERROR - Failed to execute job 18 for task export_data_to_db (Bash command failed. The command returned a non-zero exit code 1.; 337)
[2023-08-30T20:34:01.385+0000] {local_task_job_runner.py:228} INFO - Task exited with return code 1
[2023-08-30T20:34:01.428+0000] {taskinstance.py:2784} INFO - 0 downstream tasks scheduled from follow-on schedule check
[2023-08-30T20:48:32.608+0000] {logging_mixin.py:151} WARNING - /home/***/.local/lib/python3.8/site-packages/***/utils/sqlalchemy.py:124 DeprecationWarning: The sql_alchemy_conn option in [core] has been moved to the sql_alchemy_conn option in [database] - the old setting has been used, but please update your config.
[2023-08-30T20:48:32.618+0000] {taskinstance.py:1159} INFO - Dependencies all met for dep_context=non-requeueable deps ti=<TaskInstance: traffic_report.export_data_to_db scheduled__2023-08-29T00:00:00+00:00 [queued]>
[2023-08-30T20:48:32.628+0000] {taskinstance.py:1159} INFO - Dependencies all met for dep_context=requeueable deps ti=<TaskInstance: traffic_report.export_data_to_db scheduled__2023-08-29T00:00:00+00:00 [queued]>
[2023-08-30T20:48:32.629+0000] {taskinstance.py:1361} INFO - Starting attempt 1 of 2
[2023-08-30T20:48:32.645+0000] {taskinstance.py:1382} INFO - Executing <Task(BashOperator): export_data_to_db> on 2023-08-29 00:00:00+00:00
[2023-08-30T20:48:32.653+0000] {standard_task_runner.py:57} INFO - Started process 394 to run task
[2023-08-30T20:48:32.665+0000] {standard_task_runner.py:84} INFO - Running: ['***', 'tasks', 'run', 'traffic_report', 'export_data_to_db', 'scheduled__2023-08-29T00:00:00+00:00', '--job-id', '17', '--raw', '--subdir', 'DAGS_FOLDER/traffic_dag.py', '--cfg-path', '/tmp/tmp4vg4w9eh']
[2023-08-30T20:48:32.669+0000] {standard_task_runner.py:85} INFO - Job 17: Subtask export_data_to_db
[2023-08-30T20:48:32.693+0000] {logging_mixin.py:151} WARNING - /home/***/.local/lib/python3.8/site-packages/***/settings.py:195 DeprecationWarning: The sql_alchemy_conn option in [core] has been moved to the sql_alchemy_conn option in [database] - the old setting has been used, but please update your config.
[2023-08-30T20:48:32.749+0000] {task_command.py:415} INFO - Running <TaskInstance: traffic_report.export_data_to_db scheduled__2023-08-29T00:00:00+00:00 [running]> on host 8f66711a2898
[2023-08-30T20:48:32.765+0000] {logging_mixin.py:151} WARNING - /home/***/.local/lib/python3.8/site-packages/***/utils/sqlalchemy.py:124 DeprecationWarning: The sql_alchemy_conn option in [core] has been moved to the sql_alchemy_conn option in [database] - the old setting has been used, but please update your config.
[2023-08-30T20:48:32.834+0000] {taskinstance.py:1660} INFO - Exporting env vars: AIRFLOW_CTX_DAG_OWNER='***' AIRFLOW_CTX_DAG_ID='traffic_report' AIRFLOW_CTX_TASK_ID='export_data_to_db' AIRFLOW_CTX_EXECUTION_DATE='2023-08-29T00:00:00+00:00' AIRFLOW_CTX_TRY_NUMBER='1' AIRFLOW_CTX_DAG_RUN_ID='scheduled__2023-08-29T00:00:00+00:00'
[2023-08-30T20:48:32.844+0000] {subprocess.py:63} INFO - Tmp dir root location: /tmp
[2023-08-30T20:48:32.847+0000] {subprocess.py:75} INFO - Running command: ['/bin/bash', '-c', 'python /opt/***/dags/data_to_db.py --date 2023-08-29 --connection postgresql+psycopg2://***:***@postgres/***']
[2023-08-30T20:48:32.861+0000] {subprocess.py:86} INFO - Output:
[2023-08-30T20:48:33.550+0000] {subprocess.py:93} INFO - Traceback (most recent call last):
[2023-08-30T20:48:33.554+0000] {subprocess.py:93} INFO -   File "/home/***/.local/lib/python3.8/site-packages/sqlalchemy/engine/base.py", line 1890, in _execute_context
[2023-08-30T20:48:33.559+0000] {subprocess.py:93} INFO -     self.dialect.do_executemany(
[2023-08-30T20:48:33.561+0000] {subprocess.py:93} INFO -   File "/home/***/.local/lib/python3.8/site-packages/sqlalchemy/dialects/postgresql/psycopg2.py", line 982, in do_executemany
[2023-08-30T20:48:33.566+0000] {subprocess.py:93} INFO -     context._psycopg2_fetched_rows = xtras.execute_values(
[2023-08-30T20:48:33.569+0000] {subprocess.py:93} INFO -   File "/home/***/.local/lib/python3.8/site-packages/psycopg2/extras.py", line 1299, in execute_values
[2023-08-30T20:48:33.570+0000] {subprocess.py:93} INFO -     cur.execute(b''.join(parts))
[2023-08-30T20:48:33.571+0000] {subprocess.py:93} INFO - psycopg2.errors.NumericValueOutOfRange: value "1693181032000000000" is out of range for type integer
[2023-08-30T20:48:33.573+0000] {subprocess.py:93} INFO - LINE 1: ... longitude, address, weekday, date, time) VALUES ('169318103...
[2023-08-30T20:48:33.573+0000] {subprocess.py:93} INFO -                                                              ^
[2023-08-30T20:48:33.576+0000] {subprocess.py:93} INFO - 
[2023-08-30T20:48:33.577+0000] {subprocess.py:93} INFO - 
[2023-08-30T20:48:33.578+0000] {subprocess.py:93} INFO - The above exception was the direct cause of the following exception:
[2023-08-30T20:48:33.582+0000] {subprocess.py:93} INFO - 
[2023-08-30T20:48:33.586+0000] {subprocess.py:93} INFO - Traceback (most recent call last):
[2023-08-30T20:48:33.587+0000] {subprocess.py:93} INFO -   File "/opt/***/dags/data_to_db.py", line 49, in <module>
[2023-08-30T20:48:33.589+0000] {subprocess.py:93} INFO -     main(args.date, args.connection)
[2023-08-30T20:48:33.591+0000] {subprocess.py:93} INFO -   File "/opt/***/dags/data_to_db.py", line 40, in main
[2023-08-30T20:48:33.592+0000] {subprocess.py:93} INFO -     session.bulk_save_objects(data_insert)
[2023-08-30T20:48:33.595+0000] {subprocess.py:93} INFO -   File "/home/***/.local/lib/python3.8/site-packages/sqlalchemy/orm/session.py", line 3705, in bulk_save_objects
[2023-08-30T20:48:33.599+0000] {subprocess.py:93} INFO -     self._bulk_save_mappings(
[2023-08-30T20:48:33.600+0000] {subprocess.py:93} INFO -   File "/home/***/.local/lib/python3.8/site-packages/sqlalchemy/orm/session.py", line 3913, in _bulk_save_mappings
[2023-08-30T20:48:33.602+0000] {subprocess.py:93} INFO -     transaction.rollback(_capture_exception=True)
[2023-08-30T20:48:33.604+0000] {subprocess.py:93} INFO -   File "/home/***/.local/lib/python3.8/site-packages/sqlalchemy/util/langhelpers.py", line 70, in __exit__
[2023-08-30T20:48:33.606+0000] {subprocess.py:93} INFO -     compat.raise_(
[2023-08-30T20:48:33.607+0000] {subprocess.py:93} INFO -   File "/home/***/.local/lib/python3.8/site-packages/sqlalchemy/util/compat.py", line 211, in raise_
[2023-08-30T20:48:33.609+0000] {subprocess.py:93} INFO -     raise exception
[2023-08-30T20:48:33.613+0000] {subprocess.py:93} INFO -   File "/home/***/.local/lib/python3.8/site-packages/sqlalchemy/orm/session.py", line 3901, in _bulk_save_mappings
[2023-08-30T20:48:33.616+0000] {subprocess.py:93} INFO -     persistence._bulk_insert(
[2023-08-30T20:48:33.617+0000] {subprocess.py:93} INFO -   File "/home/***/.local/lib/python3.8/site-packages/sqlalchemy/orm/persistence.py", line 107, in _bulk_insert
[2023-08-30T20:48:33.618+0000] {subprocess.py:93} INFO -     _emit_insert_statements(
[2023-08-30T20:48:33.620+0000] {subprocess.py:93} INFO -   File "/home/***/.local/lib/python3.8/site-packages/sqlalchemy/orm/persistence.py", line 1097, in _emit_insert_statements
[2023-08-30T20:48:33.621+0000] {subprocess.py:93} INFO -     c = connection._execute_20(
[2023-08-30T20:48:33.622+0000] {subprocess.py:93} INFO -   File "/home/***/.local/lib/python3.8/site-packages/sqlalchemy/engine/base.py", line 1710, in _execute_20
[2023-08-30T20:48:33.625+0000] {subprocess.py:93} INFO -     return meth(self, args_10style, kwargs_10style, execution_options)
[2023-08-30T20:48:33.627+0000] {subprocess.py:93} INFO -   File "/home/***/.local/lib/python3.8/site-packages/sqlalchemy/sql/elements.py", line 334, in _execute_on_connection
[2023-08-30T20:48:33.628+0000] {subprocess.py:93} INFO -     return connection._execute_clauseelement(
[2023-08-30T20:48:33.629+0000] {subprocess.py:93} INFO -   File "/home/***/.local/lib/python3.8/site-packages/sqlalchemy/engine/base.py", line 1577, in _execute_clauseelement
[2023-08-30T20:48:33.630+0000] {subprocess.py:93} INFO -     ret = self._execute_context(
[2023-08-30T20:48:33.630+0000] {subprocess.py:93} INFO -   File "/home/***/.local/lib/python3.8/site-packages/sqlalchemy/engine/base.py", line 1953, in _execute_context
[2023-08-30T20:48:33.632+0000] {subprocess.py:93} INFO -     self._handle_dbapi_exception(
[2023-08-30T20:48:33.633+0000] {subprocess.py:93} INFO -   File "/home/***/.local/lib/python3.8/site-packages/sqlalchemy/engine/base.py", line 2134, in _handle_dbapi_exception
[2023-08-30T20:48:33.634+0000] {subprocess.py:93} INFO -     util.raise_(
[2023-08-30T20:48:33.635+0000] {subprocess.py:93} INFO -   File "/home/***/.local/lib/python3.8/site-packages/sqlalchemy/util/compat.py", line 211, in raise_
[2023-08-30T20:48:33.636+0000] {subprocess.py:93} INFO -     raise exception
[2023-08-30T20:48:33.637+0000] {subprocess.py:93} INFO -   File "/home/***/.local/lib/python3.8/site-packages/sqlalchemy/engine/base.py", line 1890, in _execute_context
[2023-08-30T20:48:33.638+0000] {subprocess.py:93} INFO -     self.dialect.do_executemany(
[2023-08-30T20:48:33.639+0000] {subprocess.py:93} INFO -   File "/home/***/.local/lib/python3.8/site-packages/sqlalchemy/dialects/postgresql/psycopg2.py", line 982, in do_executemany
[2023-08-30T20:48:33.640+0000] {subprocess.py:93} INFO -     context._psycopg2_fetched_rows = xtras.execute_values(
[2023-08-30T20:48:33.641+0000] {subprocess.py:93} INFO -   File "/home/***/.local/lib/python3.8/site-packages/psycopg2/extras.py", line 1299, in execute_values
[2023-08-30T20:48:33.642+0000] {subprocess.py:93} INFO -     cur.execute(b''.join(parts))
[2023-08-30T20:48:33.643+0000] {subprocess.py:93} INFO - sqlalchemy.exc.DataError: (psycopg2.errors.NumericValueOutOfRange) value "1693181032000000000" is out of range for type integer
[2023-08-30T20:48:33.644+0000] {subprocess.py:93} INFO - LINE 1: ... longitude, address, weekday, date, time) VALUES ('169318103...
[2023-08-30T20:48:33.645+0000] {subprocess.py:93} INFO -                                                              ^
[2023-08-30T20:48:33.646+0000] {subprocess.py:93} INFO - 
[2023-08-30T20:48:33.647+0000] {subprocess.py:93} INFO - [SQL: INSERT INTO traffic_report (timestamp, traffic_report_id, date_time, issue_reported, latitude, longitude, address, weekday, date, time) VALUES (%(timestamp)s, %(traffic_report_id)s, %(date_time)s, %(issue_reported)s, %(latitude)s, %(longitude)s, %(address)s, %(weekday)s, %(date)s, %(time)s)]
[2023-08-30T20:48:33.648+0000] {subprocess.py:93} INFO - [parameters: ({'timestamp': '1693181032000000000', 'traffic_report_id': '5378C3D8A9417D31D1ABDB3DA9FFB909420656EB_1693181032', 'date_time': '2023-08-28 00:03:52+00:00', 'issue_reported': 'traffic hazard', 'latitude': '30.399081', 'longitude': '-97.745893', 'address': '10211-11149 research blvd nb', 'weekday': 'Monday', 'date': '2023-08-28', 'time': '00:03:52'}, {'timestamp': '1693181060000000000', 'traffic_report_id': 'BC4D45844D467B9FBD27DCD0B41FE52D229884C3_1693181060', 'date_time': '2023-08-28 00:04:20+00:00', 'issue_reported': 'traffic hazard', 'latitude': '30.374077', 'longitude': '-97.72848', 'address': '9000-9098 research blvd sb', 'weekday': 'Monday', 'date': '2023-08-28', 'time': '00:04:20'}, {'timestamp': '1693181080000000000', 'traffic_report_id': 'BE69557045E8D95F6C5BC62BEA729B2E4BC50A7C_1693181080', 'date_time': '2023-08-28 00:04:40+00:00', 'issue_reported': 'stalled vehicle', 'latitude': '30.402212', 'longitude': '-97.657377', 'address': 'tech ridge blvd / e parmer ln', 'weekday': 'Monday', 'date': '2023-08-28', 'time': '00:04:40'}, {'timestamp': '1693181387000000000', 'traffic_report_id': 'B25B748A59D8B6B5B5AE3E9D985289E795C874ED_1693181387', 'date_time': '2023-08-28 00:09:47+00:00', 'issue_reported': 'crash service', 'latitude': '30.21522', 'longitude': '-97.752877', 'address': '4108 s ih 35 svrd sb', 'weekday': 'Monday', 'date': '2023-08-28', 'time': '00:09:47'}, {'timestamp': '1693182276000000000', 'traffic_report_id': '91A0461DA8536C97056D3B86390D0BDD472CA52B_1693182276', 'date_time': '2023-08-28 00:24:36+00:00', 'issue_reported': 'traffic hazard', 'latitude': '30.237362', 'longitude': '-97.614943', 'address': '600-1625 s sh 130 nb', 'weekday': 'Monday', 'date': '2023-08-28', 'time': '00:24:36'}, {'timestamp': '1693182347000000000', 'traffic_report_id': '4A4AB45448022F0C738FE9E310148EA1EB7F856B_1693182347', 'date_time': '2023-08-28 00:25:47+00:00', 'issue_reported': 'stalled vehicle', 'latitude': '30.433455', 'longitude': '-97.67912', 'address': '1831 w wells branch pkwy', 'weekday': 'Monday', 'date': '2023-08-28', 'time': '00:25:47'}, {'timestamp': '1693182673000000000', 'traffic_report_id': '566EE6D19FEF04459D959B08349D6C07B3A309A2_1693182673', 'date_time': '2023-08-28 00:31:13+00:00', 'issue_reported': 'traffic hazard', 'latitude': '30.30781', 'longitude': '-97.665765', 'address': '6508 ashland cir', 'weekday': 'Monday', 'date': '2023-08-28', 'time': '00:31:13'}, {'timestamp': '1693183109000000000', 'traffic_report_id': '5527E76C85E5B71C6DEFA5F0099519B1D67B4627_1693183109', 'date_time': '2023-08-28 00:38:29+00:00', 'issue_reported': 'traffic hazard', 'latitude': '30.257985', 'longitude': '-97.601927', 'address': '5000 n sh 130 sb', 'weekday': 'Monday', 'date': '2023-08-28', 'time': '00:38:29'}  ... displaying 10 of 143 total bound parameter sets ...  {'timestamp': '1693267017000000000', 'traffic_report_id': '8334918DA76533B5C14F235F374E327C95035AA3_1693267017', 'date_time': '2023-08-28 23:56:57+00:00', 'issue_reported': 'crash service', 'latitude': '30.159788', 'longitude': '-97.789714', 'address': '9700 s ih 35 sb', 'weekday': 'Monday', 'date': '2023-08-28', 'time': '23:56:57'}, {'timestamp': '1693267163000000000', 'traffic_report_id': '73CA0CCD6FF3D0CA58884DEAAAD9E042EC048A8F_1693267163', 'date_time': '2023-08-28 23:59:23+00:00', 'issue_reported': 'loose livestock', 'latitude': '30.301566', 'longitude': '-97.565464', 'address': 'n fm 973 rd / e braker ln', 'weekday': 'Monday', 'date': '2023-08-28', 'time': '23:59:23'})]
[2023-08-30T20:48:33.651+0000] {subprocess.py:93} INFO - (Background on this error at: https://sqlalche.me/e/14/9h9h)
[2023-08-30T20:48:33.653+0000] {subprocess.py:97} INFO - Command exited with return code 1
[2023-08-30T20:48:33.671+0000] {taskinstance.py:1943} ERROR - Task failed with exception
Traceback (most recent call last):
  File "/home/airflow/.local/lib/python3.8/site-packages/airflow/operators/bash.py", line 210, in execute
    raise AirflowException(
airflow.exceptions.AirflowException: Bash command failed. The command returned a non-zero exit code 1.
[2023-08-30T20:48:33.680+0000] {taskinstance.py:1400} INFO - Marking task as UP_FOR_RETRY. dag_id=traffic_report, task_id=export_data_to_db, execution_date=20230829T000000, start_date=20230830T204832, end_date=20230830T204833
[2023-08-30T20:48:33.703+0000] {standard_task_runner.py:104} ERROR - Failed to execute job 17 for task export_data_to_db (Bash command failed. The command returned a non-zero exit code 1.; 394)
[2023-08-30T20:48:33.717+0000] {local_task_job_runner.py:228} INFO - Task exited with return code 1
[2023-08-30T20:48:33.736+0000] {taskinstance.py:2784} INFO - 0 downstream tasks scheduled from follow-on schedule check
[2023-08-30T21:07:56.276+0000] {logging_mixin.py:151} WARNING - /home/***/.local/lib/python3.8/site-packages/***/utils/sqlalchemy.py:124 DeprecationWarning: The sql_alchemy_conn option in [core] has been moved to the sql_alchemy_conn option in [database] - the old setting has been used, but please update your config.
[2023-08-30T21:07:56.286+0000] {taskinstance.py:1159} INFO - Dependencies all met for dep_context=non-requeueable deps ti=<TaskInstance: traffic_report.export_data_to_db scheduled__2023-08-29T00:00:00+00:00 [queued]>
[2023-08-30T21:07:56.298+0000] {taskinstance.py:1159} INFO - Dependencies all met for dep_context=requeueable deps ti=<TaskInstance: traffic_report.export_data_to_db scheduled__2023-08-29T00:00:00+00:00 [queued]>
[2023-08-30T21:07:56.300+0000] {taskinstance.py:1361} INFO - Starting attempt 1 of 2
[2023-08-30T21:07:56.314+0000] {taskinstance.py:1382} INFO - Executing <Task(BashOperator): export_data_to_db> on 2023-08-29 00:00:00+00:00
[2023-08-30T21:07:56.319+0000] {standard_task_runner.py:57} INFO - Started process 365 to run task
[2023-08-30T21:07:56.330+0000] {standard_task_runner.py:84} INFO - Running: ['***', 'tasks', 'run', 'traffic_report', 'export_data_to_db', 'scheduled__2023-08-29T00:00:00+00:00', '--job-id', '19', '--raw', '--subdir', 'DAGS_FOLDER/traffic_dag.py', '--cfg-path', '/tmp/tmpqr_hx8tg']
[2023-08-30T21:07:56.333+0000] {standard_task_runner.py:85} INFO - Job 19: Subtask export_data_to_db
[2023-08-30T21:07:56.361+0000] {logging_mixin.py:151} WARNING - /home/***/.local/lib/python3.8/site-packages/***/settings.py:195 DeprecationWarning: The sql_alchemy_conn option in [core] has been moved to the sql_alchemy_conn option in [database] - the old setting has been used, but please update your config.
[2023-08-30T21:07:56.418+0000] {task_command.py:415} INFO - Running <TaskInstance: traffic_report.export_data_to_db scheduled__2023-08-29T00:00:00+00:00 [running]> on host cbc745b7550b
[2023-08-30T21:07:56.441+0000] {logging_mixin.py:151} WARNING - /home/***/.local/lib/python3.8/site-packages/***/utils/sqlalchemy.py:124 DeprecationWarning: The sql_alchemy_conn option in [core] has been moved to the sql_alchemy_conn option in [database] - the old setting has been used, but please update your config.
[2023-08-30T21:07:56.513+0000] {taskinstance.py:1660} INFO - Exporting env vars: AIRFLOW_CTX_DAG_OWNER='***' AIRFLOW_CTX_DAG_ID='traffic_report' AIRFLOW_CTX_TASK_ID='export_data_to_db' AIRFLOW_CTX_EXECUTION_DATE='2023-08-29T00:00:00+00:00' AIRFLOW_CTX_TRY_NUMBER='1' AIRFLOW_CTX_DAG_RUN_ID='scheduled__2023-08-29T00:00:00+00:00'
[2023-08-30T21:07:56.521+0000] {subprocess.py:63} INFO - Tmp dir root location: /tmp
[2023-08-30T21:07:56.523+0000] {subprocess.py:75} INFO - Running command: ['/bin/bash', '-c', 'python /opt/***/dags/data_to_db.py --date 2023-08-29 --connection postgresql+psycopg2://***:***@postgres/***']
[2023-08-30T21:07:56.541+0000] {subprocess.py:86} INFO - Output:
[2023-08-30T21:07:57.217+0000] {subprocess.py:93} INFO - Traceback (most recent call last):
[2023-08-30T21:07:57.218+0000] {subprocess.py:93} INFO -   File "/home/***/.local/lib/python3.8/site-packages/sqlalchemy/engine/base.py", line 1890, in _execute_context
[2023-08-30T21:07:57.220+0000] {subprocess.py:93} INFO -     self.dialect.do_executemany(
[2023-08-30T21:07:57.221+0000] {subprocess.py:93} INFO -   File "/home/***/.local/lib/python3.8/site-packages/sqlalchemy/dialects/postgresql/psycopg2.py", line 982, in do_executemany
[2023-08-30T21:07:57.221+0000] {subprocess.py:93} INFO -     context._psycopg2_fetched_rows = xtras.execute_values(
[2023-08-30T21:07:57.223+0000] {subprocess.py:93} INFO -   File "/home/***/.local/lib/python3.8/site-packages/psycopg2/extras.py", line 1299, in execute_values
[2023-08-30T21:07:57.224+0000] {subprocess.py:93} INFO -     cur.execute(b''.join(parts))
[2023-08-30T21:07:57.226+0000] {subprocess.py:93} INFO - psycopg2.errors.StringDataRightTruncation: value too long for type character varying(20)
[2023-08-30T21:07:57.228+0000] {subprocess.py:93} INFO - 
[2023-08-30T21:07:57.229+0000] {subprocess.py:93} INFO - 
[2023-08-30T21:07:57.230+0000] {subprocess.py:93} INFO - The above exception was the direct cause of the following exception:
[2023-08-30T21:07:57.233+0000] {subprocess.py:93} INFO - 
[2023-08-30T21:07:57.234+0000] {subprocess.py:93} INFO - Traceback (most recent call last):
[2023-08-30T21:07:57.238+0000] {subprocess.py:93} INFO -   File "/opt/***/dags/data_to_db.py", line 49, in <module>
[2023-08-30T21:07:57.243+0000] {subprocess.py:93} INFO -     main(args.date, args.connection)
[2023-08-30T21:07:57.244+0000] {subprocess.py:93} INFO -   File "/opt/***/dags/data_to_db.py", line 40, in main
[2023-08-30T21:07:57.245+0000] {subprocess.py:93} INFO -     session.bulk_save_objects(data_insert)
[2023-08-30T21:07:57.247+0000] {subprocess.py:93} INFO -   File "/home/***/.local/lib/python3.8/site-packages/sqlalchemy/orm/session.py", line 3705, in bulk_save_objects
[2023-08-30T21:07:57.248+0000] {subprocess.py:93} INFO -     self._bulk_save_mappings(
[2023-08-30T21:07:57.249+0000] {subprocess.py:93} INFO -   File "/home/***/.local/lib/python3.8/site-packages/sqlalchemy/orm/session.py", line 3913, in _bulk_save_mappings
[2023-08-30T21:07:57.251+0000] {subprocess.py:93} INFO -     transaction.rollback(_capture_exception=True)
[2023-08-30T21:07:57.252+0000] {subprocess.py:93} INFO -   File "/home/***/.local/lib/python3.8/site-packages/sqlalchemy/util/langhelpers.py", line 70, in __exit__
[2023-08-30T21:07:57.265+0000] {subprocess.py:93} INFO -     compat.raise_(
[2023-08-30T21:07:57.275+0000] {subprocess.py:93} INFO -   File "/home/***/.local/lib/python3.8/site-packages/sqlalchemy/util/compat.py", line 211, in raise_
[2023-08-30T21:07:57.278+0000] {subprocess.py:93} INFO -     raise exception
[2023-08-30T21:07:57.284+0000] {subprocess.py:93} INFO -   File "/home/***/.local/lib/python3.8/site-packages/sqlalchemy/orm/session.py", line 3901, in _bulk_save_mappings
[2023-08-30T21:07:57.286+0000] {subprocess.py:93} INFO -     persistence._bulk_insert(
[2023-08-30T21:07:57.286+0000] {subprocess.py:93} INFO -   File "/home/***/.local/lib/python3.8/site-packages/sqlalchemy/orm/persistence.py", line 107, in _bulk_insert
[2023-08-30T21:07:57.288+0000] {subprocess.py:93} INFO -     _emit_insert_statements(
[2023-08-30T21:07:57.290+0000] {subprocess.py:93} INFO -   File "/home/***/.local/lib/python3.8/site-packages/sqlalchemy/orm/persistence.py", line 1097, in _emit_insert_statements
[2023-08-30T21:07:57.291+0000] {subprocess.py:93} INFO -     c = connection._execute_20(
[2023-08-30T21:07:57.294+0000] {subprocess.py:93} INFO -   File "/home/***/.local/lib/python3.8/site-packages/sqlalchemy/engine/base.py", line 1710, in _execute_20
[2023-08-30T21:07:57.296+0000] {subprocess.py:93} INFO -     return meth(self, args_10style, kwargs_10style, execution_options)
[2023-08-30T21:07:57.298+0000] {subprocess.py:93} INFO -   File "/home/***/.local/lib/python3.8/site-packages/sqlalchemy/sql/elements.py", line 334, in _execute_on_connection
[2023-08-30T21:07:57.300+0000] {subprocess.py:93} INFO -     return connection._execute_clauseelement(
[2023-08-30T21:07:57.302+0000] {subprocess.py:93} INFO -   File "/home/***/.local/lib/python3.8/site-packages/sqlalchemy/engine/base.py", line 1577, in _execute_clauseelement
[2023-08-30T21:07:57.304+0000] {subprocess.py:93} INFO -     ret = self._execute_context(
[2023-08-30T21:07:57.307+0000] {subprocess.py:93} INFO -   File "/home/***/.local/lib/python3.8/site-packages/sqlalchemy/engine/base.py", line 1953, in _execute_context
[2023-08-30T21:07:57.309+0000] {subprocess.py:93} INFO -     self._handle_dbapi_exception(
[2023-08-30T21:07:57.310+0000] {subprocess.py:93} INFO -   File "/home/***/.local/lib/python3.8/site-packages/sqlalchemy/engine/base.py", line 2134, in _handle_dbapi_exception
[2023-08-30T21:07:57.311+0000] {subprocess.py:93} INFO -     util.raise_(
[2023-08-30T21:07:57.314+0000] {subprocess.py:93} INFO -   File "/home/***/.local/lib/python3.8/site-packages/sqlalchemy/util/compat.py", line 211, in raise_
[2023-08-30T21:07:57.316+0000] {subprocess.py:93} INFO -     raise exception
[2023-08-30T21:07:57.317+0000] {subprocess.py:93} INFO -   File "/home/***/.local/lib/python3.8/site-packages/sqlalchemy/engine/base.py", line 1890, in _execute_context
[2023-08-30T21:07:57.319+0000] {subprocess.py:93} INFO -     self.dialect.do_executemany(
[2023-08-30T21:07:57.321+0000] {subprocess.py:93} INFO -   File "/home/***/.local/lib/python3.8/site-packages/sqlalchemy/dialects/postgresql/psycopg2.py", line 982, in do_executemany
[2023-08-30T21:07:57.326+0000] {subprocess.py:93} INFO -     context._psycopg2_fetched_rows = xtras.execute_values(
[2023-08-30T21:07:57.334+0000] {subprocess.py:93} INFO -   File "/home/***/.local/lib/python3.8/site-packages/psycopg2/extras.py", line 1299, in execute_values
[2023-08-30T21:07:57.343+0000] {subprocess.py:93} INFO -     cur.execute(b''.join(parts))
[2023-08-30T21:07:57.347+0000] {subprocess.py:93} INFO - sqlalchemy.exc.DataError: (psycopg2.errors.StringDataRightTruncation) value too long for type character varying(20)
[2023-08-30T21:07:57.352+0000] {subprocess.py:93} INFO - 
[2023-08-30T21:07:57.353+0000] {subprocess.py:93} INFO - [SQL: INSERT INTO traffic_report (timestamp, traffic_report_id, date_time, issue_reported, latitude, longitude, address, weekday, date, time) VALUES (%(timestamp)s, %(traffic_report_id)s, %(date_time)s, %(issue_reported)s, %(latitude)s, %(longitude)s, %(address)s, %(weekday)s, %(date)s, %(time)s)]
[2023-08-30T21:07:57.354+0000] {subprocess.py:93} INFO - [parameters: ({'timestamp': '1693181032000000000', 'traffic_report_id': '5378C3D8A9417D31D1ABDB3DA9FFB909420656EB_1693181032', 'date_time': '2023-08-28 00:03:52+00:00', 'issue_reported': 'traffic hazard', 'latitude': '30.399081', 'longitude': '-97.745893', 'address': '10211-11149 research blvd nb', 'weekday': 'Monday', 'date': '2023-08-28', 'time': '00:03:52'}, {'timestamp': '1693181060000000000', 'traffic_report_id': 'BC4D45844D467B9FBD27DCD0B41FE52D229884C3_1693181060', 'date_time': '2023-08-28 00:04:20+00:00', 'issue_reported': 'traffic hazard', 'latitude': '30.374077', 'longitude': '-97.72848', 'address': '9000-9098 research blvd sb', 'weekday': 'Monday', 'date': '2023-08-28', 'time': '00:04:20'}, {'timestamp': '1693181080000000000', 'traffic_report_id': 'BE69557045E8D95F6C5BC62BEA729B2E4BC50A7C_1693181080', 'date_time': '2023-08-28 00:04:40+00:00', 'issue_reported': 'stalled vehicle', 'latitude': '30.402212', 'longitude': '-97.657377', 'address': 'tech ridge blvd / e parmer ln', 'weekday': 'Monday', 'date': '2023-08-28', 'time': '00:04:40'}, {'timestamp': '1693181387000000000', 'traffic_report_id': 'B25B748A59D8B6B5B5AE3E9D985289E795C874ED_1693181387', 'date_time': '2023-08-28 00:09:47+00:00', 'issue_reported': 'crash service', 'latitude': '30.21522', 'longitude': '-97.752877', 'address': '4108 s ih 35 svrd sb', 'weekday': 'Monday', 'date': '2023-08-28', 'time': '00:09:47'}, {'timestamp': '1693182276000000000', 'traffic_report_id': '91A0461DA8536C97056D3B86390D0BDD472CA52B_1693182276', 'date_time': '2023-08-28 00:24:36+00:00', 'issue_reported': 'traffic hazard', 'latitude': '30.237362', 'longitude': '-97.614943', 'address': '600-1625 s sh 130 nb', 'weekday': 'Monday', 'date': '2023-08-28', 'time': '00:24:36'}, {'timestamp': '1693182347000000000', 'traffic_report_id': '4A4AB45448022F0C738FE9E310148EA1EB7F856B_1693182347', 'date_time': '2023-08-28 00:25:47+00:00', 'issue_reported': 'stalled vehicle', 'latitude': '30.433455', 'longitude': '-97.67912', 'address': '1831 w wells branch pkwy', 'weekday': 'Monday', 'date': '2023-08-28', 'time': '00:25:47'}, {'timestamp': '1693182673000000000', 'traffic_report_id': '566EE6D19FEF04459D959B08349D6C07B3A309A2_1693182673', 'date_time': '2023-08-28 00:31:13+00:00', 'issue_reported': 'traffic hazard', 'latitude': '30.30781', 'longitude': '-97.665765', 'address': '6508 ashland cir', 'weekday': 'Monday', 'date': '2023-08-28', 'time': '00:31:13'}, {'timestamp': '1693183109000000000', 'traffic_report_id': '5527E76C85E5B71C6DEFA5F0099519B1D67B4627_1693183109', 'date_time': '2023-08-28 00:38:29+00:00', 'issue_reported': 'traffic hazard', 'latitude': '30.257985', 'longitude': '-97.601927', 'address': '5000 n sh 130 sb', 'weekday': 'Monday', 'date': '2023-08-28', 'time': '00:38:29'}  ... displaying 10 of 143 total bound parameter sets ...  {'timestamp': '1693267017000000000', 'traffic_report_id': '8334918DA76533B5C14F235F374E327C95035AA3_1693267017', 'date_time': '2023-08-28 23:56:57+00:00', 'issue_reported': 'crash service', 'latitude': '30.159788', 'longitude': '-97.789714', 'address': '9700 s ih 35 sb', 'weekday': 'Monday', 'date': '2023-08-28', 'time': '23:56:57'}, {'timestamp': '1693267163000000000', 'traffic_report_id': '73CA0CCD6FF3D0CA58884DEAAAD9E042EC048A8F_1693267163', 'date_time': '2023-08-28 23:59:23+00:00', 'issue_reported': 'loose livestock', 'latitude': '30.301566', 'longitude': '-97.565464', 'address': 'n fm 973 rd / e braker ln', 'weekday': 'Monday', 'date': '2023-08-28', 'time': '23:59:23'})]
[2023-08-30T21:07:57.358+0000] {subprocess.py:93} INFO - (Background on this error at: https://sqlalche.me/e/14/9h9h)
[2023-08-30T21:07:57.361+0000] {subprocess.py:97} INFO - Command exited with return code 1
[2023-08-30T21:07:57.380+0000] {taskinstance.py:1943} ERROR - Task failed with exception
Traceback (most recent call last):
  File "/home/airflow/.local/lib/python3.8/site-packages/airflow/operators/bash.py", line 210, in execute
    raise AirflowException(
airflow.exceptions.AirflowException: Bash command failed. The command returned a non-zero exit code 1.
[2023-08-30T21:07:57.389+0000] {taskinstance.py:1400} INFO - Marking task as UP_FOR_RETRY. dag_id=traffic_report, task_id=export_data_to_db, execution_date=20230829T000000, start_date=20230830T210756, end_date=20230830T210757
[2023-08-30T21:07:57.475+0000] {standard_task_runner.py:104} ERROR - Failed to execute job 19 for task export_data_to_db (Bash command failed. The command returned a non-zero exit code 1.; 365)
[2023-08-30T21:07:57.507+0000] {local_task_job_runner.py:228} INFO - Task exited with return code 1
[2023-08-30T21:07:57.532+0000] {taskinstance.py:2784} INFO - 0 downstream tasks scheduled from follow-on schedule check
[2023-08-30T21:17:15.113+0000] {logging_mixin.py:151} WARNING - /home/***/.local/lib/python3.8/site-packages/***/utils/sqlalchemy.py:124 DeprecationWarning: The sql_alchemy_conn option in [core] has been moved to the sql_alchemy_conn option in [database] - the old setting has been used, but please update your config.
[2023-08-30T21:17:15.124+0000] {taskinstance.py:1159} INFO - Dependencies all met for dep_context=non-requeueable deps ti=<TaskInstance: traffic_report.export_data_to_db scheduled__2023-08-29T00:00:00+00:00 [queued]>
[2023-08-30T21:17:15.135+0000] {taskinstance.py:1159} INFO - Dependencies all met for dep_context=requeueable deps ti=<TaskInstance: traffic_report.export_data_to_db scheduled__2023-08-29T00:00:00+00:00 [queued]>
[2023-08-30T21:17:15.137+0000] {taskinstance.py:1361} INFO - Starting attempt 1 of 2
[2023-08-30T21:17:15.149+0000] {taskinstance.py:1382} INFO - Executing <Task(BashOperator): export_data_to_db> on 2023-08-29 00:00:00+00:00
[2023-08-30T21:17:15.156+0000] {standard_task_runner.py:57} INFO - Started process 407 to run task
[2023-08-30T21:17:15.162+0000] {standard_task_runner.py:84} INFO - Running: ['***', 'tasks', 'run', 'traffic_report', 'export_data_to_db', 'scheduled__2023-08-29T00:00:00+00:00', '--job-id', '18', '--raw', '--subdir', 'DAGS_FOLDER/traffic_dag.py', '--cfg-path', '/tmp/tmpylto_ut5']
[2023-08-30T21:17:15.167+0000] {standard_task_runner.py:85} INFO - Job 18: Subtask export_data_to_db
[2023-08-30T21:17:15.189+0000] {logging_mixin.py:151} WARNING - /home/***/.local/lib/python3.8/site-packages/***/settings.py:195 DeprecationWarning: The sql_alchemy_conn option in [core] has been moved to the sql_alchemy_conn option in [database] - the old setting has been used, but please update your config.
[2023-08-30T21:17:15.239+0000] {task_command.py:415} INFO - Running <TaskInstance: traffic_report.export_data_to_db scheduled__2023-08-29T00:00:00+00:00 [running]> on host 5b9f14bf20e0
[2023-08-30T21:17:15.255+0000] {logging_mixin.py:151} WARNING - /home/***/.local/lib/python3.8/site-packages/***/utils/sqlalchemy.py:124 DeprecationWarning: The sql_alchemy_conn option in [core] has been moved to the sql_alchemy_conn option in [database] - the old setting has been used, but please update your config.
[2023-08-30T21:17:15.331+0000] {taskinstance.py:1660} INFO - Exporting env vars: AIRFLOW_CTX_DAG_OWNER='***' AIRFLOW_CTX_DAG_ID='traffic_report' AIRFLOW_CTX_TASK_ID='export_data_to_db' AIRFLOW_CTX_EXECUTION_DATE='2023-08-29T00:00:00+00:00' AIRFLOW_CTX_TRY_NUMBER='1' AIRFLOW_CTX_DAG_RUN_ID='scheduled__2023-08-29T00:00:00+00:00'
[2023-08-30T21:17:15.342+0000] {subprocess.py:63} INFO - Tmp dir root location: /tmp
[2023-08-30T21:17:15.344+0000] {subprocess.py:75} INFO - Running command: ['/bin/bash', '-c', 'python /opt/***/dags/data_to_db.py --date 2023-08-29 --connection postgresql+psycopg2://***:***@postgres/***']
[2023-08-30T21:17:15.359+0000] {subprocess.py:86} INFO - Output:
[2023-08-30T21:17:16.097+0000] {subprocess.py:97} INFO - Command exited with return code 0
[2023-08-30T21:17:16.156+0000] {taskinstance.py:1400} INFO - Marking task as SUCCESS. dag_id=traffic_report, task_id=export_data_to_db, execution_date=20230829T000000, start_date=20230830T211715, end_date=20230830T211716
[2023-08-30T21:17:16.224+0000] {local_task_job_runner.py:228} INFO - Task exited with return code 0
[2023-08-30T21:17:16.245+0000] {taskinstance.py:2784} INFO - 0 downstream tasks scheduled from follow-on schedule check
