[2023-08-30T19:33:44.802+0000] {logging_mixin.py:151} WARNING - /home/***/.local/lib/python3.8/site-packages/***/utils/sqlalchemy.py:124 DeprecationWarning: The sql_alchemy_conn option in [core] has been moved to the sql_alchemy_conn option in [database] - the old setting has been used, but please update your config.
[2023-08-30T19:33:44.810+0000] {taskinstance.py:1159} INFO - Dependencies all met for dep_context=non-requeueable deps ti=<TaskInstance: traffic_report.export_data_to_db scheduled__2023-08-29T00:00:00+00:00 [queued]>
[2023-08-30T19:33:44.818+0000] {taskinstance.py:1159} INFO - Dependencies all met for dep_context=requeueable deps ti=<TaskInstance: traffic_report.export_data_to_db scheduled__2023-08-29T00:00:00+00:00 [queued]>
[2023-08-30T19:33:44.819+0000] {taskinstance.py:1361} INFO - Starting attempt 2 of 2
[2023-08-30T19:33:44.830+0000] {taskinstance.py:1382} INFO - Executing <Task(BashOperator): export_data_to_db> on 2023-08-29 00:00:00+00:00
[2023-08-30T19:33:44.836+0000] {standard_task_runner.py:57} INFO - Started process 417 to run task
[2023-08-30T19:33:44.841+0000] {standard_task_runner.py:84} INFO - Running: ['***', 'tasks', 'run', 'traffic_report', 'export_data_to_db', 'scheduled__2023-08-29T00:00:00+00:00', '--job-id', '24', '--raw', '--subdir', 'DAGS_FOLDER/traffic_dag.py', '--cfg-path', '/tmp/tmpl97c85r1']
[2023-08-30T19:33:44.847+0000] {standard_task_runner.py:85} INFO - Job 24: Subtask export_data_to_db
[2023-08-30T19:33:44.863+0000] {logging_mixin.py:151} WARNING - /home/***/.local/lib/python3.8/site-packages/***/settings.py:195 DeprecationWarning: The sql_alchemy_conn option in [core] has been moved to the sql_alchemy_conn option in [database] - the old setting has been used, but please update your config.
[2023-08-30T19:33:44.907+0000] {task_command.py:415} INFO - Running <TaskInstance: traffic_report.export_data_to_db scheduled__2023-08-29T00:00:00+00:00 [running]> on host f6bcf103ff79
[2023-08-30T19:33:44.919+0000] {logging_mixin.py:151} WARNING - /home/***/.local/lib/python3.8/site-packages/***/utils/sqlalchemy.py:124 DeprecationWarning: The sql_alchemy_conn option in [core] has been moved to the sql_alchemy_conn option in [database] - the old setting has been used, but please update your config.
[2023-08-30T19:33:44.982+0000] {taskinstance.py:1660} INFO - Exporting env vars: AIRFLOW_CTX_DAG_OWNER='***' AIRFLOW_CTX_DAG_ID='traffic_report' AIRFLOW_CTX_TASK_ID='export_data_to_db' AIRFLOW_CTX_EXECUTION_DATE='2023-08-29T00:00:00+00:00' AIRFLOW_CTX_TRY_NUMBER='2' AIRFLOW_CTX_DAG_RUN_ID='scheduled__2023-08-29T00:00:00+00:00'
[2023-08-30T19:33:44.984+0000] {subprocess.py:63} INFO - Tmp dir root location: /tmp
[2023-08-30T19:33:44.985+0000] {subprocess.py:75} INFO - Running command: ['/bin/bash', '-c', 'python /opt/***/dags/data_to_db.py --date 2023-08-29 --connection postgresql+psycopg2://***:***@postgres/***']
[2023-08-30T19:33:44.997+0000] {subprocess.py:86} INFO - Output:
[2023-08-30T19:33:45.401+0000] {subprocess.py:93} INFO - Traceback (most recent call last):
[2023-08-30T19:33:45.402+0000] {subprocess.py:93} INFO -   File "/opt/***/dags/data_to_db.py", line 6, in <module>
[2023-08-30T19:33:45.403+0000] {subprocess.py:93} INFO -     from model import Connection, Traffic
[2023-08-30T19:33:45.404+0000] {subprocess.py:93} INFO -   File "/opt/***/dags/model.py", line 5, in <module>
[2023-08-30T19:33:45.406+0000] {subprocess.py:93} INFO -     from geoalchemy2 import Geometry
[2023-08-30T19:33:45.407+0000] {subprocess.py:93} INFO - ModuleNotFoundError: No module named 'geoalchemy2'
[2023-08-30T19:33:45.441+0000] {subprocess.py:97} INFO - Command exited with return code 1
[2023-08-30T19:33:45.456+0000] {taskinstance.py:1943} ERROR - Task failed with exception
Traceback (most recent call last):
  File "/home/airflow/.local/lib/python3.8/site-packages/airflow/operators/bash.py", line 210, in execute
    raise AirflowException(
airflow.exceptions.AirflowException: Bash command failed. The command returned a non-zero exit code 1.
[2023-08-30T19:33:45.462+0000] {taskinstance.py:1400} INFO - Marking task as FAILED. dag_id=traffic_report, task_id=export_data_to_db, execution_date=20230829T000000, start_date=20230830T193344, end_date=20230830T193345
[2023-08-30T19:33:45.472+0000] {standard_task_runner.py:104} ERROR - Failed to execute job 24 for task export_data_to_db (Bash command failed. The command returned a non-zero exit code 1.; 417)
[2023-08-30T19:33:45.494+0000] {local_task_job_runner.py:228} INFO - Task exited with return code 1
[2023-08-30T19:33:45.509+0000] {taskinstance.py:2784} INFO - 0 downstream tasks scheduled from follow-on schedule check
[2023-08-30T19:44:05.376+0000] {logging_mixin.py:151} WARNING - /home/***/.local/lib/python3.8/site-packages/***/utils/sqlalchemy.py:124 DeprecationWarning: The sql_alchemy_conn option in [core] has been moved to the sql_alchemy_conn option in [database] - the old setting has been used, but please update your config.
[2023-08-30T19:44:05.393+0000] {taskinstance.py:1159} INFO - Dependencies all met for dep_context=non-requeueable deps ti=<TaskInstance: traffic_report.export_data_to_db scheduled__2023-08-29T00:00:00+00:00 [queued]>
[2023-08-30T19:44:05.405+0000] {taskinstance.py:1159} INFO - Dependencies all met for dep_context=requeueable deps ti=<TaskInstance: traffic_report.export_data_to_db scheduled__2023-08-29T00:00:00+00:00 [queued]>
[2023-08-30T19:44:05.407+0000] {taskinstance.py:1361} INFO - Starting attempt 2 of 2
[2023-08-30T19:44:05.426+0000] {taskinstance.py:1382} INFO - Executing <Task(BashOperator): export_data_to_db> on 2023-08-29 00:00:00+00:00
[2023-08-30T19:44:05.450+0000] {standard_task_runner.py:57} INFO - Started process 473 to run task
[2023-08-30T19:44:05.474+0000] {standard_task_runner.py:84} INFO - Running: ['***', 'tasks', 'run', 'traffic_report', 'export_data_to_db', 'scheduled__2023-08-29T00:00:00+00:00', '--job-id', '21', '--raw', '--subdir', 'DAGS_FOLDER/traffic_dag.py', '--cfg-path', '/tmp/tmpcm3meqoh']
[2023-08-30T19:44:05.496+0000] {standard_task_runner.py:85} INFO - Job 21: Subtask export_data_to_db
[2023-08-30T19:44:07.971+0000] {logging_mixin.py:151} WARNING - /home/***/.local/lib/python3.8/site-packages/***/settings.py:195 DeprecationWarning: The sql_alchemy_conn option in [core] has been moved to the sql_alchemy_conn option in [database] - the old setting has been used, but please update your config.
[2023-08-30T19:44:11.479+0000] {task_command.py:415} INFO - Running <TaskInstance: traffic_report.export_data_to_db scheduled__2023-08-29T00:00:00+00:00 [running]> on host 81eeb4b7c8a9
[2023-08-30T19:44:11.501+0000] {logging_mixin.py:151} WARNING - /home/***/.local/lib/python3.8/site-packages/***/utils/sqlalchemy.py:124 DeprecationWarning: The sql_alchemy_conn option in [core] has been moved to the sql_alchemy_conn option in [database] - the old setting has been used, but please update your config.
[2023-08-30T19:44:11.620+0000] {taskinstance.py:1660} INFO - Exporting env vars: AIRFLOW_CTX_DAG_OWNER='***' AIRFLOW_CTX_DAG_ID='traffic_report' AIRFLOW_CTX_TASK_ID='export_data_to_db' AIRFLOW_CTX_EXECUTION_DATE='2023-08-29T00:00:00+00:00' AIRFLOW_CTX_TRY_NUMBER='2' AIRFLOW_CTX_DAG_RUN_ID='scheduled__2023-08-29T00:00:00+00:00'
[2023-08-30T19:44:11.623+0000] {subprocess.py:63} INFO - Tmp dir root location: /tmp
[2023-08-30T19:44:11.625+0000] {subprocess.py:75} INFO - Running command: ['/bin/bash', '-c', 'python /opt/***/dags/data_to_db.py --date 2023-08-29 --connection postgresql+psycopg2://***:***@postgres/***']
[2023-08-30T19:44:11.661+0000] {subprocess.py:86} INFO - Output:
[2023-08-30T19:44:13.549+0000] {subprocess.py:93} INFO - Traceback (most recent call last):
[2023-08-30T19:44:13.555+0000] {subprocess.py:93} INFO -   File "/opt/***/dags/data_to_db.py", line 6, in <module>
[2023-08-30T19:44:13.557+0000] {subprocess.py:93} INFO -     from model import Connection, Traffic
[2023-08-30T19:44:13.558+0000] {subprocess.py:93} INFO -   File "/opt/***/dags/model.py", line 5, in <module>
[2023-08-30T19:44:13.559+0000] {subprocess.py:93} INFO -     from geoalchemy2 import Geometry
[2023-08-30T19:44:13.561+0000] {subprocess.py:93} INFO - ModuleNotFoundError: No module named 'geoalchemy2'
[2023-08-30T19:44:13.637+0000] {subprocess.py:97} INFO - Command exited with return code 1
[2023-08-30T19:44:13.712+0000] {taskinstance.py:1943} ERROR - Task failed with exception
Traceback (most recent call last):
  File "/home/airflow/.local/lib/python3.8/site-packages/airflow/operators/bash.py", line 210, in execute
    raise AirflowException(
airflow.exceptions.AirflowException: Bash command failed. The command returned a non-zero exit code 1.
[2023-08-30T19:44:13.729+0000] {taskinstance.py:1400} INFO - Marking task as FAILED. dag_id=traffic_report, task_id=export_data_to_db, execution_date=20230829T000000, start_date=20230830T194405, end_date=20230830T194413
[2023-08-30T19:44:13.746+0000] {standard_task_runner.py:104} ERROR - Failed to execute job 21 for task export_data_to_db (Bash command failed. The command returned a non-zero exit code 1.; 473)
[2023-08-30T19:44:13.810+0000] {local_task_job_runner.py:228} INFO - Task exited with return code 1
[2023-08-30T19:44:13.950+0000] {taskinstance.py:2784} INFO - 0 downstream tasks scheduled from follow-on schedule check
[2023-08-30T19:56:36.806+0000] {logging_mixin.py:151} WARNING - /home/***/.local/lib/python3.8/site-packages/***/utils/sqlalchemy.py:124 DeprecationWarning: The sql_alchemy_conn option in [core] has been moved to the sql_alchemy_conn option in [database] - the old setting has been used, but please update your config.
[2023-08-30T19:56:36.816+0000] {taskinstance.py:1159} INFO - Dependencies all met for dep_context=non-requeueable deps ti=<TaskInstance: traffic_report.export_data_to_db scheduled__2023-08-29T00:00:00+00:00 [queued]>
[2023-08-30T19:56:36.826+0000] {taskinstance.py:1159} INFO - Dependencies all met for dep_context=requeueable deps ti=<TaskInstance: traffic_report.export_data_to_db scheduled__2023-08-29T00:00:00+00:00 [queued]>
[2023-08-30T19:56:36.829+0000] {taskinstance.py:1361} INFO - Starting attempt 2 of 2
[2023-08-30T19:56:36.850+0000] {taskinstance.py:1382} INFO - Executing <Task(BashOperator): export_data_to_db> on 2023-08-29 00:00:00+00:00
[2023-08-30T19:56:36.863+0000] {standard_task_runner.py:84} INFO - Running: ['***', 'tasks', 'run', 'traffic_report', 'export_data_to_db', 'scheduled__2023-08-29T00:00:00+00:00', '--job-id', '25', '--raw', '--subdir', 'DAGS_FOLDER/traffic_dag.py', '--cfg-path', '/tmp/tmp0wc953gn']
[2023-08-30T19:56:36.874+0000] {standard_task_runner.py:85} INFO - Job 25: Subtask export_data_to_db
[2023-08-30T19:56:36.858+0000] {standard_task_runner.py:57} INFO - Started process 197 to run task
[2023-08-30T19:56:36.915+0000] {logging_mixin.py:151} WARNING - /home/***/.local/lib/python3.8/site-packages/***/settings.py:195 DeprecationWarning: The sql_alchemy_conn option in [core] has been moved to the sql_alchemy_conn option in [database] - the old setting has been used, but please update your config.
[2023-08-30T19:56:36.968+0000] {task_command.py:415} INFO - Running <TaskInstance: traffic_report.export_data_to_db scheduled__2023-08-29T00:00:00+00:00 [running]> on host 86f9e97d6c70
[2023-08-30T19:56:37.000+0000] {logging_mixin.py:151} WARNING - /home/***/.local/lib/python3.8/site-packages/***/utils/sqlalchemy.py:124 DeprecationWarning: The sql_alchemy_conn option in [core] has been moved to the sql_alchemy_conn option in [database] - the old setting has been used, but please update your config.
[2023-08-30T19:56:37.085+0000] {taskinstance.py:1660} INFO - Exporting env vars: AIRFLOW_CTX_DAG_OWNER='***' AIRFLOW_CTX_DAG_ID='traffic_report' AIRFLOW_CTX_TASK_ID='export_data_to_db' AIRFLOW_CTX_EXECUTION_DATE='2023-08-29T00:00:00+00:00' AIRFLOW_CTX_TRY_NUMBER='2' AIRFLOW_CTX_DAG_RUN_ID='scheduled__2023-08-29T00:00:00+00:00'
[2023-08-30T19:56:37.087+0000] {subprocess.py:63} INFO - Tmp dir root location: /tmp
[2023-08-30T19:56:37.088+0000] {subprocess.py:75} INFO - Running command: ['/bin/bash', '-c', 'python /opt/***/dags/data_to_db.py --date 2023-08-29 --connection postgresql+psycopg2://***:***@postgres/***']
[2023-08-30T19:56:37.105+0000] {subprocess.py:86} INFO - Output:
[2023-08-30T19:56:37.868+0000] {subprocess.py:93} INFO - Traceback (most recent call last):
[2023-08-30T19:56:37.870+0000] {subprocess.py:93} INFO -   File "/opt/***/dags/data_to_db.py", line 50, in <module>
[2023-08-30T19:56:37.871+0000] {subprocess.py:93} INFO -     main(args.date, args.connection)
[2023-08-30T19:56:37.872+0000] {subprocess.py:93} INFO -   File "/opt/***/dags/data_to_db.py", line 22, in main
[2023-08-30T19:56:37.873+0000] {subprocess.py:93} INFO -     with open(filename, encoding='utf-8') as csvf:
[2023-08-30T19:56:37.874+0000] {subprocess.py:93} INFO - FileNotFoundError: [Errno 2] No such file or directory: '/opt/***/dags/data/dailytraffic_2023-08-28.csv'
[2023-08-30T19:56:37.979+0000] {subprocess.py:97} INFO - Command exited with return code 1
[2023-08-30T19:56:37.996+0000] {taskinstance.py:1943} ERROR - Task failed with exception
Traceback (most recent call last):
  File "/home/airflow/.local/lib/python3.8/site-packages/airflow/operators/bash.py", line 210, in execute
    raise AirflowException(
airflow.exceptions.AirflowException: Bash command failed. The command returned a non-zero exit code 1.
[2023-08-30T19:56:38.004+0000] {taskinstance.py:1400} INFO - Marking task as FAILED. dag_id=traffic_report, task_id=export_data_to_db, execution_date=20230829T000000, start_date=20230830T195636, end_date=20230830T195638
[2023-08-30T19:56:38.022+0000] {standard_task_runner.py:104} ERROR - Failed to execute job 25 for task export_data_to_db (Bash command failed. The command returned a non-zero exit code 1.; 197)
[2023-08-30T19:56:38.077+0000] {local_task_job_runner.py:228} INFO - Task exited with return code 1
[2023-08-30T19:56:38.095+0000] {taskinstance.py:2784} INFO - 0 downstream tasks scheduled from follow-on schedule check
[2023-08-30T20:07:59.056+0000] {logging_mixin.py:151} WARNING - /home/***/.local/lib/python3.8/site-packages/***/utils/sqlalchemy.py:124 DeprecationWarning: The sql_alchemy_conn option in [core] has been moved to the sql_alchemy_conn option in [database] - the old setting has been used, but please update your config.
[2023-08-30T20:07:59.065+0000] {taskinstance.py:1159} INFO - Dependencies all met for dep_context=non-requeueable deps ti=<TaskInstance: traffic_report.export_data_to_db scheduled__2023-08-29T00:00:00+00:00 [queued]>
[2023-08-30T20:07:59.075+0000] {taskinstance.py:1159} INFO - Dependencies all met for dep_context=requeueable deps ti=<TaskInstance: traffic_report.export_data_to_db scheduled__2023-08-29T00:00:00+00:00 [queued]>
[2023-08-30T20:07:59.076+0000] {taskinstance.py:1361} INFO - Starting attempt 2 of 2
[2023-08-30T20:07:59.087+0000] {taskinstance.py:1382} INFO - Executing <Task(BashOperator): export_data_to_db> on 2023-08-29 00:00:00+00:00
[2023-08-30T20:07:59.092+0000] {standard_task_runner.py:57} INFO - Started process 625 to run task
[2023-08-30T20:07:59.095+0000] {standard_task_runner.py:84} INFO - Running: ['***', 'tasks', 'run', 'traffic_report', 'export_data_to_db', 'scheduled__2023-08-29T00:00:00+00:00', '--job-id', '28', '--raw', '--subdir', 'DAGS_FOLDER/traffic_dag.py', '--cfg-path', '/tmp/tmplvda9990']
[2023-08-30T20:07:59.098+0000] {standard_task_runner.py:85} INFO - Job 28: Subtask export_data_to_db
[2023-08-30T20:07:59.115+0000] {logging_mixin.py:151} WARNING - /home/***/.local/lib/python3.8/site-packages/***/settings.py:195 DeprecationWarning: The sql_alchemy_conn option in [core] has been moved to the sql_alchemy_conn option in [database] - the old setting has been used, but please update your config.
[2023-08-30T20:07:59.152+0000] {task_command.py:415} INFO - Running <TaskInstance: traffic_report.export_data_to_db scheduled__2023-08-29T00:00:00+00:00 [running]> on host 3938d7abd9ff
[2023-08-30T20:07:59.164+0000] {logging_mixin.py:151} WARNING - /home/***/.local/lib/python3.8/site-packages/***/utils/sqlalchemy.py:124 DeprecationWarning: The sql_alchemy_conn option in [core] has been moved to the sql_alchemy_conn option in [database] - the old setting has been used, but please update your config.
[2023-08-30T20:07:59.219+0000] {taskinstance.py:1660} INFO - Exporting env vars: AIRFLOW_CTX_DAG_OWNER='***' AIRFLOW_CTX_DAG_ID='traffic_report' AIRFLOW_CTX_TASK_ID='export_data_to_db' AIRFLOW_CTX_EXECUTION_DATE='2023-08-29T00:00:00+00:00' AIRFLOW_CTX_TRY_NUMBER='2' AIRFLOW_CTX_DAG_RUN_ID='scheduled__2023-08-29T00:00:00+00:00'
[2023-08-30T20:07:59.224+0000] {subprocess.py:63} INFO - Tmp dir root location: /tmp
[2023-08-30T20:07:59.225+0000] {subprocess.py:75} INFO - Running command: ['/bin/bash', '-c', 'python /opt/***/dags/data_to_db.py --date 2023-08-29 --connection postgresql+psycopg2://***:***@postgres/***']
[2023-08-30T20:07:59.235+0000] {subprocess.py:86} INFO - Output:
[2023-08-30T20:07:59.835+0000] {subprocess.py:93} INFO - Traceback (most recent call last):
[2023-08-30T20:07:59.838+0000] {subprocess.py:93} INFO -   File "/home/***/.local/lib/python3.8/site-packages/sqlalchemy/engine/base.py", line 1890, in _execute_context
[2023-08-30T20:07:59.839+0000] {subprocess.py:93} INFO -     self.dialect.do_executemany(
[2023-08-30T20:07:59.840+0000] {subprocess.py:93} INFO -   File "/home/***/.local/lib/python3.8/site-packages/sqlalchemy/dialects/postgresql/psycopg2.py", line 982, in do_executemany
[2023-08-30T20:07:59.843+0000] {subprocess.py:93} INFO -     context._psycopg2_fetched_rows = xtras.execute_values(
[2023-08-30T20:07:59.845+0000] {subprocess.py:93} INFO -   File "/home/***/.local/lib/python3.8/site-packages/psycopg2/extras.py", line 1299, in execute_values
[2023-08-30T20:07:59.847+0000] {subprocess.py:93} INFO -     cur.execute(b''.join(parts))
[2023-08-30T20:07:59.848+0000] {subprocess.py:93} INFO - psycopg2.errors.UndefinedFunction: function st_geomfromewkt(unknown) does not exist
[2023-08-30T20:07:59.850+0000] {subprocess.py:93} INFO - LINE 1: ...', '2023-08-28 00:03:52+00:00', 'traffic hazard', ST_GeomFro...
[2023-08-30T20:07:59.851+0000] {subprocess.py:93} INFO -                                                              ^
[2023-08-30T20:07:59.852+0000] {subprocess.py:93} INFO - HINT:  No function matches the given name and argument types. You might need to add explicit type casts.
[2023-08-30T20:07:59.853+0000] {subprocess.py:93} INFO - 
[2023-08-30T20:07:59.855+0000] {subprocess.py:93} INFO - 
[2023-08-30T20:07:59.856+0000] {subprocess.py:93} INFO - The above exception was the direct cause of the following exception:
[2023-08-30T20:07:59.857+0000] {subprocess.py:93} INFO - 
[2023-08-30T20:07:59.859+0000] {subprocess.py:93} INFO - Traceback (most recent call last):
[2023-08-30T20:07:59.860+0000] {subprocess.py:93} INFO -   File "/opt/***/dags/data_to_db.py", line 50, in <module>
[2023-08-30T20:07:59.862+0000] {subprocess.py:93} INFO -     main(args.date, args.connection)
[2023-08-30T20:07:59.863+0000] {subprocess.py:93} INFO -   File "/opt/***/dags/data_to_db.py", line 41, in main
[2023-08-30T20:07:59.864+0000] {subprocess.py:93} INFO -     session.bulk_save_objects(data_insert)
[2023-08-30T20:07:59.865+0000] {subprocess.py:93} INFO -   File "/home/***/.local/lib/python3.8/site-packages/sqlalchemy/orm/session.py", line 3705, in bulk_save_objects
[2023-08-30T20:07:59.866+0000] {subprocess.py:93} INFO -     self._bulk_save_mappings(
[2023-08-30T20:07:59.869+0000] {subprocess.py:93} INFO -   File "/home/***/.local/lib/python3.8/site-packages/sqlalchemy/orm/session.py", line 3913, in _bulk_save_mappings
[2023-08-30T20:07:59.870+0000] {subprocess.py:93} INFO -     transaction.rollback(_capture_exception=True)
[2023-08-30T20:07:59.872+0000] {subprocess.py:93} INFO -   File "/home/***/.local/lib/python3.8/site-packages/sqlalchemy/util/langhelpers.py", line 70, in __exit__
[2023-08-30T20:07:59.873+0000] {subprocess.py:93} INFO -     compat.raise_(
[2023-08-30T20:07:59.875+0000] {subprocess.py:93} INFO -   File "/home/***/.local/lib/python3.8/site-packages/sqlalchemy/util/compat.py", line 211, in raise_
[2023-08-30T20:07:59.880+0000] {subprocess.py:93} INFO -     raise exception
[2023-08-30T20:07:59.883+0000] {subprocess.py:93} INFO -   File "/home/***/.local/lib/python3.8/site-packages/sqlalchemy/orm/session.py", line 3901, in _bulk_save_mappings
[2023-08-30T20:07:59.885+0000] {subprocess.py:93} INFO -     persistence._bulk_insert(
[2023-08-30T20:07:59.889+0000] {subprocess.py:93} INFO -   File "/home/***/.local/lib/python3.8/site-packages/sqlalchemy/orm/persistence.py", line 107, in _bulk_insert
[2023-08-30T20:07:59.891+0000] {subprocess.py:93} INFO -     _emit_insert_statements(
[2023-08-30T20:07:59.893+0000] {subprocess.py:93} INFO -   File "/home/***/.local/lib/python3.8/site-packages/sqlalchemy/orm/persistence.py", line 1097, in _emit_insert_statements
[2023-08-30T20:07:59.895+0000] {subprocess.py:93} INFO -     c = connection._execute_20(
[2023-08-30T20:07:59.896+0000] {subprocess.py:93} INFO -   File "/home/***/.local/lib/python3.8/site-packages/sqlalchemy/engine/base.py", line 1710, in _execute_20
[2023-08-30T20:07:59.898+0000] {subprocess.py:93} INFO -     return meth(self, args_10style, kwargs_10style, execution_options)
[2023-08-30T20:07:59.898+0000] {subprocess.py:93} INFO -   File "/home/***/.local/lib/python3.8/site-packages/sqlalchemy/sql/elements.py", line 334, in _execute_on_connection
[2023-08-30T20:07:59.900+0000] {subprocess.py:93} INFO -     return connection._execute_clauseelement(
[2023-08-30T20:07:59.902+0000] {subprocess.py:93} INFO -   File "/home/***/.local/lib/python3.8/site-packages/sqlalchemy/engine/base.py", line 1577, in _execute_clauseelement
[2023-08-30T20:07:59.904+0000] {subprocess.py:93} INFO -     ret = self._execute_context(
[2023-08-30T20:07:59.907+0000] {subprocess.py:93} INFO -   File "/home/***/.local/lib/python3.8/site-packages/sqlalchemy/engine/base.py", line 1953, in _execute_context
[2023-08-30T20:07:59.909+0000] {subprocess.py:93} INFO -     self._handle_dbapi_exception(
[2023-08-30T20:07:59.910+0000] {subprocess.py:93} INFO -   File "/home/***/.local/lib/python3.8/site-packages/sqlalchemy/engine/base.py", line 2134, in _handle_dbapi_exception
[2023-08-30T20:07:59.912+0000] {subprocess.py:93} INFO -     util.raise_(
[2023-08-30T20:07:59.914+0000] {subprocess.py:93} INFO -   File "/home/***/.local/lib/python3.8/site-packages/sqlalchemy/util/compat.py", line 211, in raise_
[2023-08-30T20:07:59.915+0000] {subprocess.py:93} INFO -     raise exception
[2023-08-30T20:07:59.917+0000] {subprocess.py:93} INFO -   File "/home/***/.local/lib/python3.8/site-packages/sqlalchemy/engine/base.py", line 1890, in _execute_context
[2023-08-30T20:07:59.918+0000] {subprocess.py:93} INFO -     self.dialect.do_executemany(
[2023-08-30T20:07:59.919+0000] {subprocess.py:93} INFO -   File "/home/***/.local/lib/python3.8/site-packages/sqlalchemy/dialects/postgresql/psycopg2.py", line 982, in do_executemany
[2023-08-30T20:07:59.920+0000] {subprocess.py:93} INFO -     context._psycopg2_fetched_rows = xtras.execute_values(
[2023-08-30T20:07:59.922+0000] {subprocess.py:93} INFO -   File "/home/***/.local/lib/python3.8/site-packages/psycopg2/extras.py", line 1299, in execute_values
[2023-08-30T20:07:59.923+0000] {subprocess.py:93} INFO -     cur.execute(b''.join(parts))
[2023-08-30T20:07:59.925+0000] {subprocess.py:93} INFO - sqlalchemy.exc.ProgrammingError: (psycopg2.errors.UndefinedFunction) function st_geomfromewkt(unknown) does not exist
[2023-08-30T20:07:59.926+0000] {subprocess.py:93} INFO - LINE 1: ...', '2023-08-28 00:03:52+00:00', 'traffic hazard', ST_GeomFro...
[2023-08-30T20:07:59.927+0000] {subprocess.py:93} INFO -                                                              ^
[2023-08-30T20:07:59.929+0000] {subprocess.py:93} INFO - HINT:  No function matches the given name and argument types. You might need to add explicit type casts.
[2023-08-30T20:07:59.931+0000] {subprocess.py:93} INFO - 
[2023-08-30T20:07:59.932+0000] {subprocess.py:93} INFO - [SQL: INSERT INTO traffic_report (timestamp, traffic_report_id, date_time, issue_reported, location, latitude, longitude, address, weekday, date, time) VALUES (%(timestamp)s, %(traffic_report_id)s, %(date_time)s, %(issue_reported)s, ST_GeomFromEWKT(%(location)s), %(latitude)s, %(longitude)s, %(address)s, %(weekday)s, %(date)s, %(time)s)]
[2023-08-30T20:07:59.933+0000] {subprocess.py:93} INFO - [parameters: ({'timestamp': '1693181032000000000', 'traffic_report_id': '5378C3D8A9417D31D1ABDB3DA9FFB909420656EB_1693181032', 'date_time': '2023-08-28 00:03:52+00:00', 'issue_reported': 'traffic hazard', 'location': 'POINT(-97.745893 30.399081)', 'latitude': '30.399081', 'longitude': '-97.745893', 'address': '10211-11149 research blvd nb', 'weekday': 'Monday', 'date': '2023-08-28', 'time': '00:03:52'}, {'timestamp': '1693181060000000000', 'traffic_report_id': 'BC4D45844D467B9FBD27DCD0B41FE52D229884C3_1693181060', 'date_time': '2023-08-28 00:04:20+00:00', 'issue_reported': 'traffic hazard', 'location': 'POINT(-97.72848 30.374077)', 'latitude': '30.374077', 'longitude': '-97.72848', 'address': '9000-9098 research blvd sb', 'weekday': 'Monday', 'date': '2023-08-28', 'time': '00:04:20'}, {'timestamp': '1693181080000000000', 'traffic_report_id': 'BE69557045E8D95F6C5BC62BEA729B2E4BC50A7C_1693181080', 'date_time': '2023-08-28 00:04:40+00:00', 'issue_reported': 'stalled vehicle', 'location': 'POINT(-97.657377 30.402212)', 'latitude': '30.402212', 'longitude': '-97.657377', 'address': 'tech ridge blvd / e parmer ln', 'weekday': 'Monday', 'date': '2023-08-28', 'time': '00:04:40'}, {'timestamp': '1693181387000000000', 'traffic_report_id': 'B25B748A59D8B6B5B5AE3E9D985289E795C874ED_1693181387', 'date_time': '2023-08-28 00:09:47+00:00', 'issue_reported': 'crash service', 'location': 'POINT(-97.752877 30.21522)', 'latitude': '30.21522', 'longitude': '-97.752877', 'address': '4108 s ih 35 svrd sb', 'weekday': 'Monday', 'date': '2023-08-28', 'time': '00:09:47'}, {'timestamp': '1693182276000000000', 'traffic_report_id': '91A0461DA8536C97056D3B86390D0BDD472CA52B_1693182276', 'date_time': '2023-08-28 00:24:36+00:00', 'issue_reported': 'traffic hazard', 'location': 'POINT(-97.614943 30.237362)', 'latitude': '30.237362', 'longitude': '-97.614943', 'address': '600-1625 s sh 130 nb', 'weekday': 'Monday', 'date': '2023-08-28', 'time': '00:24:36'}, {'timestamp': '1693182347000000000', 'traffic_report_id': '4A4AB45448022F0C738FE9E310148EA1EB7F856B_1693182347', 'date_time': '2023-08-28 00:25:47+00:00', 'issue_reported': 'stalled vehicle', 'location': 'POINT(-97.67912 30.433455)', 'latitude': '30.433455', 'longitude': '-97.67912', 'address': '1831 w wells branch pkwy', 'weekday': 'Monday', 'date': '2023-08-28', 'time': '00:25:47'}, {'timestamp': '1693182673000000000', 'traffic_report_id': '566EE6D19FEF04459D959B08349D6C07B3A309A2_1693182673', 'date_time': '2023-08-28 00:31:13+00:00', 'issue_reported': 'traffic hazard', 'location': 'POINT(-97.665765 30.30781)', 'latitude': '30.30781', 'longitude': '-97.665765', 'address': '6508 ashland cir', 'weekday': 'Monday', 'date': '2023-08-28', 'time': '00:31:13'}, {'timestamp': '1693183109000000000', 'traffic_report_id': '5527E76C85E5B71C6DEFA5F0099519B1D67B4627_1693183109', 'date_time': '2023-08-28 00:38:29+00:00', 'issue_reported': 'traffic hazard', 'location': 'POINT(-97.601927 30.257985)', 'latitude': '30.257985', 'longitude': '-97.601927', 'address': '5000 n sh 130 sb', 'weekday': 'Monday', 'date': '2023-08-28', 'time': '00:38:29'}  ... displaying 10 of 143 total bound parameter sets ...  {'timestamp': '1693267017000000000', 'traffic_report_id': '8334918DA76533B5C14F235F374E327C95035AA3_1693267017', 'date_time': '2023-08-28 23:56:57+00:00', 'issue_reported': 'crash service', 'location': 'POINT(-97.789714 30.159788)', 'latitude': '30.159788', 'longitude': '-97.789714', 'address': '9700 s ih 35 sb', 'weekday': 'Monday', 'date': '2023-08-28', 'time': '23:56:57'}, {'timestamp': '1693267163000000000', 'traffic_report_id': '73CA0CCD6FF3D0CA58884DEAAAD9E042EC048A8F_1693267163', 'date_time': '2023-08-28 23:59:23+00:00', 'issue_reported': 'loose livestock', 'location': 'POINT(-97.565464 30.301566)', 'latitude': '30.301566', 'longitude': '-97.565464', 'address': 'n fm 973 rd / e braker ln', 'weekday': 'Monday', 'date': '2023-08-28', 'time': '23:59:23'})]
[2023-08-30T20:07:59.935+0000] {subprocess.py:93} INFO - (Background on this error at: https://sqlalche.me/e/14/f405)
[2023-08-30T20:07:59.941+0000] {subprocess.py:97} INFO - Command exited with return code 1
[2023-08-30T20:07:59.968+0000] {taskinstance.py:1943} ERROR - Task failed with exception
Traceback (most recent call last):
  File "/home/airflow/.local/lib/python3.8/site-packages/airflow/operators/bash.py", line 210, in execute
    raise AirflowException(
airflow.exceptions.AirflowException: Bash command failed. The command returned a non-zero exit code 1.
[2023-08-30T20:07:59.972+0000] {taskinstance.py:1400} INFO - Marking task as FAILED. dag_id=traffic_report, task_id=export_data_to_db, execution_date=20230829T000000, start_date=20230830T200759, end_date=20230830T200759
[2023-08-30T20:08:00.013+0000] {standard_task_runner.py:104} ERROR - Failed to execute job 28 for task export_data_to_db (Bash command failed. The command returned a non-zero exit code 1.; 625)
[2023-08-30T20:08:00.037+0000] {local_task_job_runner.py:228} INFO - Task exited with return code 1
[2023-08-30T20:08:00.066+0000] {taskinstance.py:2784} INFO - 0 downstream tasks scheduled from follow-on schedule check
[2023-08-30T20:36:03.698+0000] {logging_mixin.py:151} WARNING - /home/***/.local/lib/python3.8/site-packages/***/utils/sqlalchemy.py:124 DeprecationWarning: The sql_alchemy_conn option in [core] has been moved to the sql_alchemy_conn option in [database] - the old setting has been used, but please update your config.
[2023-08-30T20:36:03.710+0000] {taskinstance.py:1159} INFO - Dependencies all met for dep_context=non-requeueable deps ti=<TaskInstance: traffic_report.export_data_to_db scheduled__2023-08-29T00:00:00+00:00 [queued]>
[2023-08-30T20:36:03.728+0000] {taskinstance.py:1159} INFO - Dependencies all met for dep_context=requeueable deps ti=<TaskInstance: traffic_report.export_data_to_db scheduled__2023-08-29T00:00:00+00:00 [queued]>
[2023-08-30T20:36:03.729+0000] {taskinstance.py:1361} INFO - Starting attempt 2 of 2
[2023-08-30T20:36:03.750+0000] {taskinstance.py:1382} INFO - Executing <Task(BashOperator): export_data_to_db> on 2023-08-29 00:00:00+00:00
[2023-08-30T20:36:03.759+0000] {standard_task_runner.py:57} INFO - Started process 446 to run task
[2023-08-30T20:36:03.777+0000] {standard_task_runner.py:84} INFO - Running: ['***', 'tasks', 'run', 'traffic_report', 'export_data_to_db', 'scheduled__2023-08-29T00:00:00+00:00', '--job-id', '24', '--raw', '--subdir', 'DAGS_FOLDER/traffic_dag.py', '--cfg-path', '/tmp/tmp2i3llg7b']
[2023-08-30T20:36:03.782+0000] {standard_task_runner.py:85} INFO - Job 24: Subtask export_data_to_db
[2023-08-30T20:36:03.805+0000] {logging_mixin.py:151} WARNING - /home/***/.local/lib/python3.8/site-packages/***/settings.py:195 DeprecationWarning: The sql_alchemy_conn option in [core] has been moved to the sql_alchemy_conn option in [database] - the old setting has been used, but please update your config.
[2023-08-30T20:36:03.889+0000] {task_command.py:415} INFO - Running <TaskInstance: traffic_report.export_data_to_db scheduled__2023-08-29T00:00:00+00:00 [running]> on host 961f38e8363e
[2023-08-30T20:36:03.912+0000] {logging_mixin.py:151} WARNING - /home/***/.local/lib/python3.8/site-packages/***/utils/sqlalchemy.py:124 DeprecationWarning: The sql_alchemy_conn option in [core] has been moved to the sql_alchemy_conn option in [database] - the old setting has been used, but please update your config.
[2023-08-30T20:36:03.989+0000] {taskinstance.py:1660} INFO - Exporting env vars: AIRFLOW_CTX_DAG_OWNER='***' AIRFLOW_CTX_DAG_ID='traffic_report' AIRFLOW_CTX_TASK_ID='export_data_to_db' AIRFLOW_CTX_EXECUTION_DATE='2023-08-29T00:00:00+00:00' AIRFLOW_CTX_TRY_NUMBER='2' AIRFLOW_CTX_DAG_RUN_ID='scheduled__2023-08-29T00:00:00+00:00'
[2023-08-30T20:36:03.992+0000] {subprocess.py:63} INFO - Tmp dir root location: /tmp
[2023-08-30T20:36:03.994+0000] {subprocess.py:75} INFO - Running command: ['/bin/bash', '-c', 'python /opt/***/dags/data_to_db.py --date 2023-08-29 --connection postgresql+psycopg2://***:***@postgres/***']
[2023-08-30T20:36:04.013+0000] {subprocess.py:86} INFO - Output:
[2023-08-30T20:36:04.875+0000] {subprocess.py:93} INFO - Traceback (most recent call last):
[2023-08-30T20:36:04.876+0000] {subprocess.py:93} INFO -   File "/home/***/.local/lib/python3.8/site-packages/sqlalchemy/engine/base.py", line 1890, in _execute_context
[2023-08-30T20:36:04.878+0000] {subprocess.py:93} INFO -     self.dialect.do_executemany(
[2023-08-30T20:36:04.880+0000] {subprocess.py:93} INFO -   File "/home/***/.local/lib/python3.8/site-packages/sqlalchemy/dialects/postgresql/psycopg2.py", line 982, in do_executemany
[2023-08-30T20:36:04.881+0000] {subprocess.py:93} INFO -     context._psycopg2_fetched_rows = xtras.execute_values(
[2023-08-30T20:36:04.882+0000] {subprocess.py:93} INFO -   File "/home/***/.local/lib/python3.8/site-packages/psycopg2/extras.py", line 1299, in execute_values
[2023-08-30T20:36:04.884+0000] {subprocess.py:93} INFO -     cur.execute(b''.join(parts))
[2023-08-30T20:36:04.885+0000] {subprocess.py:93} INFO - psycopg2.errors.UndefinedFunction: function st_geomfromewkt(unknown) does not exist
[2023-08-30T20:36:04.886+0000] {subprocess.py:93} INFO - LINE 1: ...', '2023-08-28 00:03:52+00:00', 'traffic hazard', ST_GeomFro...
[2023-08-30T20:36:04.887+0000] {subprocess.py:93} INFO -                                                              ^
[2023-08-30T20:36:04.888+0000] {subprocess.py:93} INFO - HINT:  No function matches the given name and argument types. You might need to add explicit type casts.
[2023-08-30T20:36:04.889+0000] {subprocess.py:93} INFO - 
[2023-08-30T20:36:04.890+0000] {subprocess.py:93} INFO - 
[2023-08-30T20:36:04.891+0000] {subprocess.py:93} INFO - The above exception was the direct cause of the following exception:
[2023-08-30T20:36:04.892+0000] {subprocess.py:93} INFO - 
[2023-08-30T20:36:04.893+0000] {subprocess.py:93} INFO - Traceback (most recent call last):
[2023-08-30T20:36:04.894+0000] {subprocess.py:93} INFO -   File "/opt/***/dags/data_to_db.py", line 50, in <module>
[2023-08-30T20:36:04.895+0000] {subprocess.py:93} INFO -     main(args.date, args.connection)
[2023-08-30T20:36:04.896+0000] {subprocess.py:93} INFO -   File "/opt/***/dags/data_to_db.py", line 41, in main
[2023-08-30T20:36:04.897+0000] {subprocess.py:93} INFO -     session.bulk_save_objects(data_insert)
[2023-08-30T20:36:04.898+0000] {subprocess.py:93} INFO -   File "/home/***/.local/lib/python3.8/site-packages/sqlalchemy/orm/session.py", line 3705, in bulk_save_objects
[2023-08-30T20:36:04.899+0000] {subprocess.py:93} INFO -     self._bulk_save_mappings(
[2023-08-30T20:36:04.900+0000] {subprocess.py:93} INFO -   File "/home/***/.local/lib/python3.8/site-packages/sqlalchemy/orm/session.py", line 3913, in _bulk_save_mappings
[2023-08-30T20:36:04.901+0000] {subprocess.py:93} INFO -     transaction.rollback(_capture_exception=True)
[2023-08-30T20:36:04.903+0000] {subprocess.py:93} INFO -   File "/home/***/.local/lib/python3.8/site-packages/sqlalchemy/util/langhelpers.py", line 70, in __exit__
[2023-08-30T20:36:04.904+0000] {subprocess.py:93} INFO -     compat.raise_(
[2023-08-30T20:36:04.905+0000] {subprocess.py:93} INFO -   File "/home/***/.local/lib/python3.8/site-packages/sqlalchemy/util/compat.py", line 211, in raise_
[2023-08-30T20:36:04.906+0000] {subprocess.py:93} INFO -     raise exception
[2023-08-30T20:36:04.908+0000] {subprocess.py:93} INFO -   File "/home/***/.local/lib/python3.8/site-packages/sqlalchemy/orm/session.py", line 3901, in _bulk_save_mappings
[2023-08-30T20:36:04.909+0000] {subprocess.py:93} INFO -     persistence._bulk_insert(
[2023-08-30T20:36:04.910+0000] {subprocess.py:93} INFO -   File "/home/***/.local/lib/python3.8/site-packages/sqlalchemy/orm/persistence.py", line 107, in _bulk_insert
[2023-08-30T20:36:04.911+0000] {subprocess.py:93} INFO -     _emit_insert_statements(
[2023-08-30T20:36:04.913+0000] {subprocess.py:93} INFO -   File "/home/***/.local/lib/python3.8/site-packages/sqlalchemy/orm/persistence.py", line 1097, in _emit_insert_statements
[2023-08-30T20:36:04.915+0000] {subprocess.py:93} INFO -     c = connection._execute_20(
[2023-08-30T20:36:04.916+0000] {subprocess.py:93} INFO -   File "/home/***/.local/lib/python3.8/site-packages/sqlalchemy/engine/base.py", line 1710, in _execute_20
[2023-08-30T20:36:04.919+0000] {subprocess.py:93} INFO -     return meth(self, args_10style, kwargs_10style, execution_options)
[2023-08-30T20:36:04.920+0000] {subprocess.py:93} INFO -   File "/home/***/.local/lib/python3.8/site-packages/sqlalchemy/sql/elements.py", line 334, in _execute_on_connection
[2023-08-30T20:36:04.921+0000] {subprocess.py:93} INFO -     return connection._execute_clauseelement(
[2023-08-30T20:36:04.922+0000] {subprocess.py:93} INFO -   File "/home/***/.local/lib/python3.8/site-packages/sqlalchemy/engine/base.py", line 1577, in _execute_clauseelement
[2023-08-30T20:36:04.923+0000] {subprocess.py:93} INFO -     ret = self._execute_context(
[2023-08-30T20:36:04.924+0000] {subprocess.py:93} INFO -   File "/home/***/.local/lib/python3.8/site-packages/sqlalchemy/engine/base.py", line 1953, in _execute_context
[2023-08-30T20:36:04.924+0000] {subprocess.py:93} INFO -     self._handle_dbapi_exception(
[2023-08-30T20:36:04.925+0000] {subprocess.py:93} INFO -   File "/home/***/.local/lib/python3.8/site-packages/sqlalchemy/engine/base.py", line 2134, in _handle_dbapi_exception
[2023-08-30T20:36:04.927+0000] {subprocess.py:93} INFO -     util.raise_(
[2023-08-30T20:36:04.928+0000] {subprocess.py:93} INFO -   File "/home/***/.local/lib/python3.8/site-packages/sqlalchemy/util/compat.py", line 211, in raise_
[2023-08-30T20:36:04.929+0000] {subprocess.py:93} INFO -     raise exception
[2023-08-30T20:36:04.930+0000] {subprocess.py:93} INFO -   File "/home/***/.local/lib/python3.8/site-packages/sqlalchemy/engine/base.py", line 1890, in _execute_context
[2023-08-30T20:36:04.931+0000] {subprocess.py:93} INFO -     self.dialect.do_executemany(
[2023-08-30T20:36:04.932+0000] {subprocess.py:93} INFO -   File "/home/***/.local/lib/python3.8/site-packages/sqlalchemy/dialects/postgresql/psycopg2.py", line 982, in do_executemany
[2023-08-30T20:36:04.933+0000] {subprocess.py:93} INFO -     context._psycopg2_fetched_rows = xtras.execute_values(
[2023-08-30T20:36:04.934+0000] {subprocess.py:93} INFO -   File "/home/***/.local/lib/python3.8/site-packages/psycopg2/extras.py", line 1299, in execute_values
[2023-08-30T20:36:04.935+0000] {subprocess.py:93} INFO -     cur.execute(b''.join(parts))
[2023-08-30T20:36:04.936+0000] {subprocess.py:93} INFO - sqlalchemy.exc.ProgrammingError: (psycopg2.errors.UndefinedFunction) function st_geomfromewkt(unknown) does not exist
[2023-08-30T20:36:04.937+0000] {subprocess.py:93} INFO - LINE 1: ...', '2023-08-28 00:03:52+00:00', 'traffic hazard', ST_GeomFro...
[2023-08-30T20:36:04.938+0000] {subprocess.py:93} INFO -                                                              ^
[2023-08-30T20:36:04.939+0000] {subprocess.py:93} INFO - HINT:  No function matches the given name and argument types. You might need to add explicit type casts.
[2023-08-30T20:36:04.939+0000] {subprocess.py:93} INFO - 
[2023-08-30T20:36:04.940+0000] {subprocess.py:93} INFO - [SQL: INSERT INTO traffic_report (timestamp, traffic_report_id, date_time, issue_reported, location, latitude, longitude, address, weekday, date, time) VALUES (%(timestamp)s, %(traffic_report_id)s, %(date_time)s, %(issue_reported)s, ST_GeomFromEWKT(%(location)s), %(latitude)s, %(longitude)s, %(address)s, %(weekday)s, %(date)s, %(time)s)]
[2023-08-30T20:36:04.942+0000] {subprocess.py:93} INFO - [parameters: ({'timestamp': '1693181032000000000', 'traffic_report_id': '5378C3D8A9417D31D1ABDB3DA9FFB909420656EB_1693181032', 'date_time': '2023-08-28 00:03:52+00:00', 'issue_reported': 'traffic hazard', 'location': 'POINT(-97.745893 30.399081)', 'latitude': '30.399081', 'longitude': '-97.745893', 'address': '10211-11149 research blvd nb', 'weekday': 'Monday', 'date': '2023-08-28', 'time': '00:03:52'}, {'timestamp': '1693181060000000000', 'traffic_report_id': 'BC4D45844D467B9FBD27DCD0B41FE52D229884C3_1693181060', 'date_time': '2023-08-28 00:04:20+00:00', 'issue_reported': 'traffic hazard', 'location': 'POINT(-97.72848 30.374077)', 'latitude': '30.374077', 'longitude': '-97.72848', 'address': '9000-9098 research blvd sb', 'weekday': 'Monday', 'date': '2023-08-28', 'time': '00:04:20'}, {'timestamp': '1693181080000000000', 'traffic_report_id': 'BE69557045E8D95F6C5BC62BEA729B2E4BC50A7C_1693181080', 'date_time': '2023-08-28 00:04:40+00:00', 'issue_reported': 'stalled vehicle', 'location': 'POINT(-97.657377 30.402212)', 'latitude': '30.402212', 'longitude': '-97.657377', 'address': 'tech ridge blvd / e parmer ln', 'weekday': 'Monday', 'date': '2023-08-28', 'time': '00:04:40'}, {'timestamp': '1693181387000000000', 'traffic_report_id': 'B25B748A59D8B6B5B5AE3E9D985289E795C874ED_1693181387', 'date_time': '2023-08-28 00:09:47+00:00', 'issue_reported': 'crash service', 'location': 'POINT(-97.752877 30.21522)', 'latitude': '30.21522', 'longitude': '-97.752877', 'address': '4108 s ih 35 svrd sb', 'weekday': 'Monday', 'date': '2023-08-28', 'time': '00:09:47'}, {'timestamp': '1693182276000000000', 'traffic_report_id': '91A0461DA8536C97056D3B86390D0BDD472CA52B_1693182276', 'date_time': '2023-08-28 00:24:36+00:00', 'issue_reported': 'traffic hazard', 'location': 'POINT(-97.614943 30.237362)', 'latitude': '30.237362', 'longitude': '-97.614943', 'address': '600-1625 s sh 130 nb', 'weekday': 'Monday', 'date': '2023-08-28', 'time': '00:24:36'}, {'timestamp': '1693182347000000000', 'traffic_report_id': '4A4AB45448022F0C738FE9E310148EA1EB7F856B_1693182347', 'date_time': '2023-08-28 00:25:47+00:00', 'issue_reported': 'stalled vehicle', 'location': 'POINT(-97.67912 30.433455)', 'latitude': '30.433455', 'longitude': '-97.67912', 'address': '1831 w wells branch pkwy', 'weekday': 'Monday', 'date': '2023-08-28', 'time': '00:25:47'}, {'timestamp': '1693182673000000000', 'traffic_report_id': '566EE6D19FEF04459D959B08349D6C07B3A309A2_1693182673', 'date_time': '2023-08-28 00:31:13+00:00', 'issue_reported': 'traffic hazard', 'location': 'POINT(-97.665765 30.30781)', 'latitude': '30.30781', 'longitude': '-97.665765', 'address': '6508 ashland cir', 'weekday': 'Monday', 'date': '2023-08-28', 'time': '00:31:13'}, {'timestamp': '1693183109000000000', 'traffic_report_id': '5527E76C85E5B71C6DEFA5F0099519B1D67B4627_1693183109', 'date_time': '2023-08-28 00:38:29+00:00', 'issue_reported': 'traffic hazard', 'location': 'POINT(-97.601927 30.257985)', 'latitude': '30.257985', 'longitude': '-97.601927', 'address': '5000 n sh 130 sb', 'weekday': 'Monday', 'date': '2023-08-28', 'time': '00:38:29'}  ... displaying 10 of 143 total bound parameter sets ...  {'timestamp': '1693267017000000000', 'traffic_report_id': '8334918DA76533B5C14F235F374E327C95035AA3_1693267017', 'date_time': '2023-08-28 23:56:57+00:00', 'issue_reported': 'crash service', 'location': 'POINT(-97.789714 30.159788)', 'latitude': '30.159788', 'longitude': '-97.789714', 'address': '9700 s ih 35 sb', 'weekday': 'Monday', 'date': '2023-08-28', 'time': '23:56:57'}, {'timestamp': '1693267163000000000', 'traffic_report_id': '73CA0CCD6FF3D0CA58884DEAAAD9E042EC048A8F_1693267163', 'date_time': '2023-08-28 23:59:23+00:00', 'issue_reported': 'loose livestock', 'location': 'POINT(-97.565464 30.301566)', 'latitude': '30.301566', 'longitude': '-97.565464', 'address': 'n fm 973 rd / e braker ln', 'weekday': 'Monday', 'date': '2023-08-28', 'time': '23:59:23'})]
[2023-08-30T20:36:04.944+0000] {subprocess.py:93} INFO - (Background on this error at: https://sqlalche.me/e/14/f405)
[2023-08-30T20:36:05.029+0000] {subprocess.py:97} INFO - Command exited with return code 1
[2023-08-30T20:36:05.052+0000] {taskinstance.py:1943} ERROR - Task failed with exception
Traceback (most recent call last):
  File "/home/airflow/.local/lib/python3.8/site-packages/airflow/operators/bash.py", line 210, in execute
    raise AirflowException(
airflow.exceptions.AirflowException: Bash command failed. The command returned a non-zero exit code 1.
[2023-08-30T20:36:05.060+0000] {taskinstance.py:1400} INFO - Marking task as FAILED. dag_id=traffic_report, task_id=export_data_to_db, execution_date=20230829T000000, start_date=20230830T203603, end_date=20230830T203605
[2023-08-30T20:36:05.089+0000] {standard_task_runner.py:104} ERROR - Failed to execute job 24 for task export_data_to_db (Bash command failed. The command returned a non-zero exit code 1.; 446)
[2023-08-30T20:36:05.119+0000] {local_task_job_runner.py:228} INFO - Task exited with return code 1
[2023-08-30T20:36:05.142+0000] {taskinstance.py:2784} INFO - 0 downstream tasks scheduled from follow-on schedule check
[2023-08-30T20:50:35.860+0000] {logging_mixin.py:151} WARNING - /home/***/.local/lib/python3.8/site-packages/***/utils/sqlalchemy.py:124 DeprecationWarning: The sql_alchemy_conn option in [core] has been moved to the sql_alchemy_conn option in [database] - the old setting has been used, but please update your config.
[2023-08-30T20:50:35.875+0000] {taskinstance.py:1159} INFO - Dependencies all met for dep_context=non-requeueable deps ti=<TaskInstance: traffic_report.export_data_to_db scheduled__2023-08-29T00:00:00+00:00 [queued]>
[2023-08-30T20:50:35.891+0000] {taskinstance.py:1159} INFO - Dependencies all met for dep_context=requeueable deps ti=<TaskInstance: traffic_report.export_data_to_db scheduled__2023-08-29T00:00:00+00:00 [queued]>
[2023-08-30T20:50:35.894+0000] {taskinstance.py:1361} INFO - Starting attempt 2 of 2
[2023-08-30T20:50:35.919+0000] {taskinstance.py:1382} INFO - Executing <Task(BashOperator): export_data_to_db> on 2023-08-29 00:00:00+00:00
[2023-08-30T20:50:35.927+0000] {standard_task_runner.py:57} INFO - Started process 483 to run task
[2023-08-30T20:50:35.938+0000] {standard_task_runner.py:84} INFO - Running: ['***', 'tasks', 'run', 'traffic_report', 'export_data_to_db', 'scheduled__2023-08-29T00:00:00+00:00', '--job-id', '27', '--raw', '--subdir', 'DAGS_FOLDER/traffic_dag.py', '--cfg-path', '/tmp/tmphkt0falq']
[2023-08-30T20:50:35.952+0000] {standard_task_runner.py:85} INFO - Job 27: Subtask export_data_to_db
[2023-08-30T20:50:36.002+0000] {logging_mixin.py:151} WARNING - /home/***/.local/lib/python3.8/site-packages/***/settings.py:195 DeprecationWarning: The sql_alchemy_conn option in [core] has been moved to the sql_alchemy_conn option in [database] - the old setting has been used, but please update your config.
[2023-08-30T20:50:36.455+0000] {task_command.py:415} INFO - Running <TaskInstance: traffic_report.export_data_to_db scheduled__2023-08-29T00:00:00+00:00 [running]> on host 8f66711a2898
[2023-08-30T20:50:39.099+0000] {logging_mixin.py:151} WARNING - /home/***/.local/lib/python3.8/site-packages/***/utils/sqlalchemy.py:124 DeprecationWarning: The sql_alchemy_conn option in [core] has been moved to the sql_alchemy_conn option in [database] - the old setting has been used, but please update your config.
[2023-08-30T20:50:39.680+0000] {taskinstance.py:1660} INFO - Exporting env vars: AIRFLOW_CTX_DAG_OWNER='***' AIRFLOW_CTX_DAG_ID='traffic_report' AIRFLOW_CTX_TASK_ID='export_data_to_db' AIRFLOW_CTX_EXECUTION_DATE='2023-08-29T00:00:00+00:00' AIRFLOW_CTX_TRY_NUMBER='2' AIRFLOW_CTX_DAG_RUN_ID='scheduled__2023-08-29T00:00:00+00:00'
[2023-08-30T20:50:39.705+0000] {subprocess.py:63} INFO - Tmp dir root location: /tmp
[2023-08-30T20:50:39.708+0000] {subprocess.py:75} INFO - Running command: ['/bin/bash', '-c', 'python /opt/***/dags/data_to_db.py --date 2023-08-29 --connection postgresql+psycopg2://***:***@postgres/***']
[2023-08-30T20:50:39.731+0000] {subprocess.py:86} INFO - Output:
[2023-08-30T20:50:42.833+0000] {subprocess.py:93} INFO - Traceback (most recent call last):
[2023-08-30T20:50:42.835+0000] {subprocess.py:93} INFO -   File "/home/***/.local/lib/python3.8/site-packages/sqlalchemy/engine/base.py", line 1890, in _execute_context
[2023-08-30T20:50:42.836+0000] {subprocess.py:93} INFO -     self.dialect.do_executemany(
[2023-08-30T20:50:42.837+0000] {subprocess.py:93} INFO -   File "/home/***/.local/lib/python3.8/site-packages/sqlalchemy/dialects/postgresql/psycopg2.py", line 982, in do_executemany
[2023-08-30T20:50:42.840+0000] {subprocess.py:93} INFO -     context._psycopg2_fetched_rows = xtras.execute_values(
[2023-08-30T20:50:42.842+0000] {subprocess.py:93} INFO -   File "/home/***/.local/lib/python3.8/site-packages/psycopg2/extras.py", line 1299, in execute_values
[2023-08-30T20:50:42.844+0000] {subprocess.py:93} INFO -     cur.execute(b''.join(parts))
[2023-08-30T20:50:42.852+0000] {subprocess.py:93} INFO - psycopg2.errors.NumericValueOutOfRange: value "1693181032000000000" is out of range for type integer
[2023-08-30T20:50:42.855+0000] {subprocess.py:93} INFO - LINE 1: ... longitude, address, weekday, date, time) VALUES ('169318103...
[2023-08-30T20:50:42.858+0000] {subprocess.py:93} INFO -                                                              ^
[2023-08-30T20:50:42.860+0000] {subprocess.py:93} INFO - 
[2023-08-30T20:50:42.861+0000] {subprocess.py:93} INFO - 
[2023-08-30T20:50:42.863+0000] {subprocess.py:93} INFO - The above exception was the direct cause of the following exception:
[2023-08-30T20:50:42.864+0000] {subprocess.py:93} INFO - 
[2023-08-30T20:50:42.865+0000] {subprocess.py:93} INFO - Traceback (most recent call last):
[2023-08-30T20:50:42.866+0000] {subprocess.py:93} INFO -   File "/opt/***/dags/data_to_db.py", line 49, in <module>
[2023-08-30T20:50:42.869+0000] {subprocess.py:93} INFO -     main(args.date, args.connection)
[2023-08-30T20:50:42.870+0000] {subprocess.py:93} INFO -   File "/opt/***/dags/data_to_db.py", line 40, in main
[2023-08-30T20:50:42.874+0000] {subprocess.py:93} INFO -     session.bulk_save_objects(data_insert)
[2023-08-30T20:50:42.875+0000] {subprocess.py:93} INFO -   File "/home/***/.local/lib/python3.8/site-packages/sqlalchemy/orm/session.py", line 3705, in bulk_save_objects
[2023-08-30T20:50:42.876+0000] {subprocess.py:93} INFO -     self._bulk_save_mappings(
[2023-08-30T20:50:42.877+0000] {subprocess.py:93} INFO -   File "/home/***/.local/lib/python3.8/site-packages/sqlalchemy/orm/session.py", line 3913, in _bulk_save_mappings
[2023-08-30T20:50:42.879+0000] {subprocess.py:93} INFO -     transaction.rollback(_capture_exception=True)
[2023-08-30T20:50:42.881+0000] {subprocess.py:93} INFO -   File "/home/***/.local/lib/python3.8/site-packages/sqlalchemy/util/langhelpers.py", line 70, in __exit__
[2023-08-30T20:50:42.883+0000] {subprocess.py:93} INFO -     compat.raise_(
[2023-08-30T20:50:42.885+0000] {subprocess.py:93} INFO -   File "/home/***/.local/lib/python3.8/site-packages/sqlalchemy/util/compat.py", line 211, in raise_
[2023-08-30T20:50:42.889+0000] {subprocess.py:93} INFO -     raise exception
[2023-08-30T20:50:42.891+0000] {subprocess.py:93} INFO -   File "/home/***/.local/lib/python3.8/site-packages/sqlalchemy/orm/session.py", line 3901, in _bulk_save_mappings
[2023-08-30T20:50:42.894+0000] {subprocess.py:93} INFO -     persistence._bulk_insert(
[2023-08-30T20:50:42.898+0000] {subprocess.py:93} INFO -   File "/home/***/.local/lib/python3.8/site-packages/sqlalchemy/orm/persistence.py", line 107, in _bulk_insert
[2023-08-30T20:50:42.899+0000] {subprocess.py:93} INFO -     _emit_insert_statements(
[2023-08-30T20:50:42.900+0000] {subprocess.py:93} INFO -   File "/home/***/.local/lib/python3.8/site-packages/sqlalchemy/orm/persistence.py", line 1097, in _emit_insert_statements
[2023-08-30T20:50:42.903+0000] {subprocess.py:93} INFO -     c = connection._execute_20(
[2023-08-30T20:50:42.905+0000] {subprocess.py:93} INFO -   File "/home/***/.local/lib/python3.8/site-packages/sqlalchemy/engine/base.py", line 1710, in _execute_20
[2023-08-30T20:50:42.907+0000] {subprocess.py:93} INFO -     return meth(self, args_10style, kwargs_10style, execution_options)
[2023-08-30T20:50:42.908+0000] {subprocess.py:93} INFO -   File "/home/***/.local/lib/python3.8/site-packages/sqlalchemy/sql/elements.py", line 334, in _execute_on_connection
[2023-08-30T20:50:42.910+0000] {subprocess.py:93} INFO -     return connection._execute_clauseelement(
[2023-08-30T20:50:42.911+0000] {subprocess.py:93} INFO -   File "/home/***/.local/lib/python3.8/site-packages/sqlalchemy/engine/base.py", line 1577, in _execute_clauseelement
[2023-08-30T20:50:42.912+0000] {subprocess.py:93} INFO -     ret = self._execute_context(
[2023-08-30T20:50:42.913+0000] {subprocess.py:93} INFO -   File "/home/***/.local/lib/python3.8/site-packages/sqlalchemy/engine/base.py", line 1953, in _execute_context
[2023-08-30T20:50:42.914+0000] {subprocess.py:93} INFO -     self._handle_dbapi_exception(
[2023-08-30T20:50:42.917+0000] {subprocess.py:93} INFO -   File "/home/***/.local/lib/python3.8/site-packages/sqlalchemy/engine/base.py", line 2134, in _handle_dbapi_exception
[2023-08-30T20:50:42.919+0000] {subprocess.py:93} INFO -     util.raise_(
[2023-08-30T20:50:42.920+0000] {subprocess.py:93} INFO -   File "/home/***/.local/lib/python3.8/site-packages/sqlalchemy/util/compat.py", line 211, in raise_
[2023-08-30T20:50:42.922+0000] {subprocess.py:93} INFO -     raise exception
[2023-08-30T20:50:42.924+0000] {subprocess.py:93} INFO -   File "/home/***/.local/lib/python3.8/site-packages/sqlalchemy/engine/base.py", line 1890, in _execute_context
[2023-08-30T20:50:42.925+0000] {subprocess.py:93} INFO -     self.dialect.do_executemany(
[2023-08-30T20:50:42.926+0000] {subprocess.py:93} INFO -   File "/home/***/.local/lib/python3.8/site-packages/sqlalchemy/dialects/postgresql/psycopg2.py", line 982, in do_executemany
[2023-08-30T20:50:42.927+0000] {subprocess.py:93} INFO -     context._psycopg2_fetched_rows = xtras.execute_values(
[2023-08-30T20:50:42.931+0000] {subprocess.py:93} INFO -   File "/home/***/.local/lib/python3.8/site-packages/psycopg2/extras.py", line 1299, in execute_values
[2023-08-30T20:50:42.932+0000] {subprocess.py:93} INFO -     cur.execute(b''.join(parts))
[2023-08-30T20:50:42.934+0000] {subprocess.py:93} INFO - sqlalchemy.exc.DataError: (psycopg2.errors.NumericValueOutOfRange) value "1693181032000000000" is out of range for type integer
[2023-08-30T20:50:42.936+0000] {subprocess.py:93} INFO - LINE 1: ... longitude, address, weekday, date, time) VALUES ('169318103...
[2023-08-30T20:50:42.937+0000] {subprocess.py:93} INFO -                                                              ^
[2023-08-30T20:50:42.938+0000] {subprocess.py:93} INFO - 
[2023-08-30T20:50:42.939+0000] {subprocess.py:93} INFO - [SQL: INSERT INTO traffic_report (timestamp, traffic_report_id, date_time, issue_reported, latitude, longitude, address, weekday, date, time) VALUES (%(timestamp)s, %(traffic_report_id)s, %(date_time)s, %(issue_reported)s, %(latitude)s, %(longitude)s, %(address)s, %(weekday)s, %(date)s, %(time)s)]
[2023-08-30T20:50:42.941+0000] {subprocess.py:93} INFO - [parameters: ({'timestamp': '1693181032000000000', 'traffic_report_id': '5378C3D8A9417D31D1ABDB3DA9FFB909420656EB_1693181032', 'date_time': '2023-08-28 00:03:52+00:00', 'issue_reported': 'traffic hazard', 'latitude': '30.399081', 'longitude': '-97.745893', 'address': '10211-11149 research blvd nb', 'weekday': 'Monday', 'date': '2023-08-28', 'time': '00:03:52'}, {'timestamp': '1693181060000000000', 'traffic_report_id': 'BC4D45844D467B9FBD27DCD0B41FE52D229884C3_1693181060', 'date_time': '2023-08-28 00:04:20+00:00', 'issue_reported': 'traffic hazard', 'latitude': '30.374077', 'longitude': '-97.72848', 'address': '9000-9098 research blvd sb', 'weekday': 'Monday', 'date': '2023-08-28', 'time': '00:04:20'}, {'timestamp': '1693181080000000000', 'traffic_report_id': 'BE69557045E8D95F6C5BC62BEA729B2E4BC50A7C_1693181080', 'date_time': '2023-08-28 00:04:40+00:00', 'issue_reported': 'stalled vehicle', 'latitude': '30.402212', 'longitude': '-97.657377', 'address': 'tech ridge blvd / e parmer ln', 'weekday': 'Monday', 'date': '2023-08-28', 'time': '00:04:40'}, {'timestamp': '1693181387000000000', 'traffic_report_id': 'B25B748A59D8B6B5B5AE3E9D985289E795C874ED_1693181387', 'date_time': '2023-08-28 00:09:47+00:00', 'issue_reported': 'crash service', 'latitude': '30.21522', 'longitude': '-97.752877', 'address': '4108 s ih 35 svrd sb', 'weekday': 'Monday', 'date': '2023-08-28', 'time': '00:09:47'}, {'timestamp': '1693182276000000000', 'traffic_report_id': '91A0461DA8536C97056D3B86390D0BDD472CA52B_1693182276', 'date_time': '2023-08-28 00:24:36+00:00', 'issue_reported': 'traffic hazard', 'latitude': '30.237362', 'longitude': '-97.614943', 'address': '600-1625 s sh 130 nb', 'weekday': 'Monday', 'date': '2023-08-28', 'time': '00:24:36'}, {'timestamp': '1693182347000000000', 'traffic_report_id': '4A4AB45448022F0C738FE9E310148EA1EB7F856B_1693182347', 'date_time': '2023-08-28 00:25:47+00:00', 'issue_reported': 'stalled vehicle', 'latitude': '30.433455', 'longitude': '-97.67912', 'address': '1831 w wells branch pkwy', 'weekday': 'Monday', 'date': '2023-08-28', 'time': '00:25:47'}, {'timestamp': '1693182673000000000', 'traffic_report_id': '566EE6D19FEF04459D959B08349D6C07B3A309A2_1693182673', 'date_time': '2023-08-28 00:31:13+00:00', 'issue_reported': 'traffic hazard', 'latitude': '30.30781', 'longitude': '-97.665765', 'address': '6508 ashland cir', 'weekday': 'Monday', 'date': '2023-08-28', 'time': '00:31:13'}, {'timestamp': '1693183109000000000', 'traffic_report_id': '5527E76C85E5B71C6DEFA5F0099519B1D67B4627_1693183109', 'date_time': '2023-08-28 00:38:29+00:00', 'issue_reported': 'traffic hazard', 'latitude': '30.257985', 'longitude': '-97.601927', 'address': '5000 n sh 130 sb', 'weekday': 'Monday', 'date': '2023-08-28', 'time': '00:38:29'}  ... displaying 10 of 143 total bound parameter sets ...  {'timestamp': '1693267017000000000', 'traffic_report_id': '8334918DA76533B5C14F235F374E327C95035AA3_1693267017', 'date_time': '2023-08-28 23:56:57+00:00', 'issue_reported': 'crash service', 'latitude': '30.159788', 'longitude': '-97.789714', 'address': '9700 s ih 35 sb', 'weekday': 'Monday', 'date': '2023-08-28', 'time': '23:56:57'}, {'timestamp': '1693267163000000000', 'traffic_report_id': '73CA0CCD6FF3D0CA58884DEAAAD9E042EC048A8F_1693267163', 'date_time': '2023-08-28 23:59:23+00:00', 'issue_reported': 'loose livestock', 'latitude': '30.301566', 'longitude': '-97.565464', 'address': 'n fm 973 rd / e braker ln', 'weekday': 'Monday', 'date': '2023-08-28', 'time': '23:59:23'})]
[2023-08-30T20:50:42.943+0000] {subprocess.py:93} INFO - (Background on this error at: https://sqlalche.me/e/14/9h9h)
[2023-08-30T20:50:42.944+0000] {subprocess.py:97} INFO - Command exited with return code 1
[2023-08-30T20:50:42.959+0000] {taskinstance.py:1943} ERROR - Task failed with exception
Traceback (most recent call last):
  File "/home/airflow/.local/lib/python3.8/site-packages/airflow/operators/bash.py", line 210, in execute
    raise AirflowException(
airflow.exceptions.AirflowException: Bash command failed. The command returned a non-zero exit code 1.
[2023-08-30T20:50:42.964+0000] {taskinstance.py:1400} INFO - Marking task as FAILED. dag_id=traffic_report, task_id=export_data_to_db, execution_date=20230829T000000, start_date=20230830T205035, end_date=20230830T205042
[2023-08-30T20:50:42.976+0000] {standard_task_runner.py:104} ERROR - Failed to execute job 27 for task export_data_to_db (Bash command failed. The command returned a non-zero exit code 1.; 483)
[2023-08-30T20:50:43.001+0000] {local_task_job_runner.py:228} INFO - Task exited with return code 1
[2023-08-30T20:50:43.022+0000] {taskinstance.py:2784} INFO - 0 downstream tasks scheduled from follow-on schedule check
[2023-08-30T21:09:59.346+0000] {logging_mixin.py:151} WARNING - /home/***/.local/lib/python3.8/site-packages/***/utils/sqlalchemy.py:124 DeprecationWarning: The sql_alchemy_conn option in [core] has been moved to the sql_alchemy_conn option in [database] - the old setting has been used, but please update your config.
[2023-08-30T21:09:59.367+0000] {taskinstance.py:1159} INFO - Dependencies all met for dep_context=non-requeueable deps ti=<TaskInstance: traffic_report.export_data_to_db scheduled__2023-08-29T00:00:00+00:00 [queued]>
[2023-08-30T21:09:59.377+0000] {taskinstance.py:1159} INFO - Dependencies all met for dep_context=requeueable deps ti=<TaskInstance: traffic_report.export_data_to_db scheduled__2023-08-29T00:00:00+00:00 [queued]>
[2023-08-30T21:09:59.379+0000] {taskinstance.py:1361} INFO - Starting attempt 2 of 2
[2023-08-30T21:09:59.395+0000] {taskinstance.py:1382} INFO - Executing <Task(BashOperator): export_data_to_db> on 2023-08-29 00:00:00+00:00
[2023-08-30T21:09:59.404+0000] {standard_task_runner.py:57} INFO - Started process 448 to run task
[2023-08-30T21:09:59.442+0000] {standard_task_runner.py:84} INFO - Running: ['***', 'tasks', 'run', 'traffic_report', 'export_data_to_db', 'scheduled__2023-08-29T00:00:00+00:00', '--job-id', '25', '--raw', '--subdir', 'DAGS_FOLDER/traffic_dag.py', '--cfg-path', '/tmp/tmpm843m_3j']
[2023-08-30T21:09:59.464+0000] {standard_task_runner.py:85} INFO - Job 25: Subtask export_data_to_db
[2023-08-30T21:09:59.554+0000] {logging_mixin.py:151} WARNING - /home/***/.local/lib/python3.8/site-packages/***/settings.py:195 DeprecationWarning: The sql_alchemy_conn option in [core] has been moved to the sql_alchemy_conn option in [database] - the old setting has been used, but please update your config.
[2023-08-30T21:10:00.141+0000] {task_command.py:415} INFO - Running <TaskInstance: traffic_report.export_data_to_db scheduled__2023-08-29T00:00:00+00:00 [running]> on host cbc745b7550b
[2023-08-30T21:10:00.386+0000] {logging_mixin.py:151} WARNING - /home/***/.local/lib/python3.8/site-packages/***/utils/sqlalchemy.py:124 DeprecationWarning: The sql_alchemy_conn option in [core] has been moved to the sql_alchemy_conn option in [database] - the old setting has been used, but please update your config.
[2023-08-30T21:10:05.055+0000] {taskinstance.py:1660} INFO - Exporting env vars: AIRFLOW_CTX_DAG_OWNER='***' AIRFLOW_CTX_DAG_ID='traffic_report' AIRFLOW_CTX_TASK_ID='export_data_to_db' AIRFLOW_CTX_EXECUTION_DATE='2023-08-29T00:00:00+00:00' AIRFLOW_CTX_TRY_NUMBER='2' AIRFLOW_CTX_DAG_RUN_ID='scheduled__2023-08-29T00:00:00+00:00'
[2023-08-30T21:10:05.098+0000] {subprocess.py:63} INFO - Tmp dir root location: /tmp
[2023-08-30T21:10:05.137+0000] {subprocess.py:75} INFO - Running command: ['/bin/bash', '-c', 'python /opt/***/dags/data_to_db.py --date 2023-08-29 --connection postgresql+psycopg2://***:***@postgres/***']
[2023-08-30T21:10:05.274+0000] {subprocess.py:86} INFO - Output:
[2023-08-30T21:10:30.212+0000] {subprocess.py:93} INFO - Traceback (most recent call last):
[2023-08-30T21:10:30.216+0000] {subprocess.py:93} INFO -   File "/home/***/.local/lib/python3.8/site-packages/sqlalchemy/engine/base.py", line 1890, in _execute_context
[2023-08-30T21:10:30.219+0000] {subprocess.py:93} INFO -     self.dialect.do_executemany(
[2023-08-30T21:10:30.222+0000] {subprocess.py:93} INFO -   File "/home/***/.local/lib/python3.8/site-packages/sqlalchemy/dialects/postgresql/psycopg2.py", line 982, in do_executemany
[2023-08-30T21:10:30.225+0000] {subprocess.py:93} INFO -     context._psycopg2_fetched_rows = xtras.execute_values(
[2023-08-30T21:10:30.227+0000] {subprocess.py:93} INFO -   File "/home/***/.local/lib/python3.8/site-packages/psycopg2/extras.py", line 1299, in execute_values
[2023-08-30T21:10:30.229+0000] {subprocess.py:93} INFO -     cur.execute(b''.join(parts))
[2023-08-30T21:10:30.231+0000] {subprocess.py:93} INFO - psycopg2.errors.StringDataRightTruncation: value too long for type character varying(20)
[2023-08-30T21:10:30.233+0000] {subprocess.py:93} INFO - 
[2023-08-30T21:10:30.235+0000] {subprocess.py:93} INFO - 
[2023-08-30T21:10:30.236+0000] {subprocess.py:93} INFO - The above exception was the direct cause of the following exception:
[2023-08-30T21:10:30.238+0000] {subprocess.py:93} INFO - 
[2023-08-30T21:10:30.240+0000] {subprocess.py:93} INFO - Traceback (most recent call last):
[2023-08-30T21:10:30.242+0000] {subprocess.py:93} INFO -   File "/opt/***/dags/data_to_db.py", line 49, in <module>
[2023-08-30T21:10:30.244+0000] {subprocess.py:93} INFO -     main(args.date, args.connection)
[2023-08-30T21:10:30.246+0000] {subprocess.py:93} INFO -   File "/opt/***/dags/data_to_db.py", line 40, in main
[2023-08-30T21:10:30.248+0000] {subprocess.py:93} INFO -     session.bulk_save_objects(data_insert)
[2023-08-30T21:10:30.253+0000] {subprocess.py:93} INFO -   File "/home/***/.local/lib/python3.8/site-packages/sqlalchemy/orm/session.py", line 3705, in bulk_save_objects
[2023-08-30T21:10:30.255+0000] {subprocess.py:93} INFO -     self._bulk_save_mappings(
[2023-08-30T21:10:30.256+0000] {subprocess.py:93} INFO -   File "/home/***/.local/lib/python3.8/site-packages/sqlalchemy/orm/session.py", line 3913, in _bulk_save_mappings
[2023-08-30T21:10:30.258+0000] {subprocess.py:93} INFO -     transaction.rollback(_capture_exception=True)
[2023-08-30T21:10:30.260+0000] {subprocess.py:93} INFO -   File "/home/***/.local/lib/python3.8/site-packages/sqlalchemy/util/langhelpers.py", line 70, in __exit__
[2023-08-30T21:10:30.261+0000] {subprocess.py:93} INFO -     compat.raise_(
[2023-08-30T21:10:30.263+0000] {subprocess.py:93} INFO -   File "/home/***/.local/lib/python3.8/site-packages/sqlalchemy/util/compat.py", line 211, in raise_
[2023-08-30T21:10:30.265+0000] {subprocess.py:93} INFO -     raise exception
[2023-08-30T21:10:30.268+0000] {subprocess.py:93} INFO -   File "/home/***/.local/lib/python3.8/site-packages/sqlalchemy/orm/session.py", line 3901, in _bulk_save_mappings
[2023-08-30T21:10:30.271+0000] {subprocess.py:93} INFO -     persistence._bulk_insert(
[2023-08-30T21:10:30.272+0000] {subprocess.py:93} INFO -   File "/home/***/.local/lib/python3.8/site-packages/sqlalchemy/orm/persistence.py", line 107, in _bulk_insert
[2023-08-30T21:10:30.273+0000] {subprocess.py:93} INFO -     _emit_insert_statements(
[2023-08-30T21:10:30.275+0000] {subprocess.py:93} INFO -   File "/home/***/.local/lib/python3.8/site-packages/sqlalchemy/orm/persistence.py", line 1097, in _emit_insert_statements
[2023-08-30T21:10:30.276+0000] {subprocess.py:93} INFO -     c = connection._execute_20(
[2023-08-30T21:10:30.277+0000] {subprocess.py:93} INFO -   File "/home/***/.local/lib/python3.8/site-packages/sqlalchemy/engine/base.py", line 1710, in _execute_20
[2023-08-30T21:10:30.283+0000] {subprocess.py:93} INFO -     return meth(self, args_10style, kwargs_10style, execution_options)
[2023-08-30T21:10:30.285+0000] {subprocess.py:93} INFO -   File "/home/***/.local/lib/python3.8/site-packages/sqlalchemy/sql/elements.py", line 334, in _execute_on_connection
[2023-08-30T21:10:30.289+0000] {subprocess.py:93} INFO -     return connection._execute_clauseelement(
[2023-08-30T21:10:30.291+0000] {subprocess.py:93} INFO -   File "/home/***/.local/lib/python3.8/site-packages/sqlalchemy/engine/base.py", line 1577, in _execute_clauseelement
[2023-08-30T21:10:30.295+0000] {subprocess.py:93} INFO -     ret = self._execute_context(
[2023-08-30T21:10:30.297+0000] {subprocess.py:93} INFO -   File "/home/***/.local/lib/python3.8/site-packages/sqlalchemy/engine/base.py", line 1953, in _execute_context
[2023-08-30T21:10:30.301+0000] {subprocess.py:93} INFO -     self._handle_dbapi_exception(
[2023-08-30T21:10:30.310+0000] {subprocess.py:93} INFO -   File "/home/***/.local/lib/python3.8/site-packages/sqlalchemy/engine/base.py", line 2134, in _handle_dbapi_exception
[2023-08-30T21:10:30.315+0000] {subprocess.py:93} INFO -     util.raise_(
[2023-08-30T21:10:30.318+0000] {subprocess.py:93} INFO -   File "/home/***/.local/lib/python3.8/site-packages/sqlalchemy/util/compat.py", line 211, in raise_
[2023-08-30T21:10:30.321+0000] {subprocess.py:93} INFO -     raise exception
[2023-08-30T21:10:30.323+0000] {subprocess.py:93} INFO -   File "/home/***/.local/lib/python3.8/site-packages/sqlalchemy/engine/base.py", line 1890, in _execute_context
[2023-08-30T21:10:30.327+0000] {subprocess.py:93} INFO -     self.dialect.do_executemany(
[2023-08-30T21:10:30.329+0000] {subprocess.py:93} INFO -   File "/home/***/.local/lib/python3.8/site-packages/sqlalchemy/dialects/postgresql/psycopg2.py", line 982, in do_executemany
[2023-08-30T21:10:30.332+0000] {subprocess.py:93} INFO -     context._psycopg2_fetched_rows = xtras.execute_values(
[2023-08-30T21:10:30.335+0000] {subprocess.py:93} INFO -   File "/home/***/.local/lib/python3.8/site-packages/psycopg2/extras.py", line 1299, in execute_values
[2023-08-30T21:10:30.337+0000] {subprocess.py:93} INFO -     cur.execute(b''.join(parts))
[2023-08-30T21:10:30.338+0000] {subprocess.py:93} INFO - sqlalchemy.exc.DataError: (psycopg2.errors.StringDataRightTruncation) value too long for type character varying(20)
[2023-08-30T21:10:30.339+0000] {subprocess.py:93} INFO - 
[2023-08-30T21:10:30.341+0000] {subprocess.py:93} INFO - [SQL: INSERT INTO traffic_report (timestamp, traffic_report_id, date_time, issue_reported, latitude, longitude, address, weekday, date, time) VALUES (%(timestamp)s, %(traffic_report_id)s, %(date_time)s, %(issue_reported)s, %(latitude)s, %(longitude)s, %(address)s, %(weekday)s, %(date)s, %(time)s)]
[2023-08-30T21:10:30.343+0000] {subprocess.py:93} INFO - [parameters: ({'timestamp': '1693181032000000000', 'traffic_report_id': '5378C3D8A9417D31D1ABDB3DA9FFB909420656EB_1693181032', 'date_time': '2023-08-28 00:03:52+00:00', 'issue_reported': 'traffic hazard', 'latitude': '30.399081', 'longitude': '-97.745893', 'address': '10211-11149 research blvd nb', 'weekday': 'Monday', 'date': '2023-08-28', 'time': '00:03:52'}, {'timestamp': '1693181060000000000', 'traffic_report_id': 'BC4D45844D467B9FBD27DCD0B41FE52D229884C3_1693181060', 'date_time': '2023-08-28 00:04:20+00:00', 'issue_reported': 'traffic hazard', 'latitude': '30.374077', 'longitude': '-97.72848', 'address': '9000-9098 research blvd sb', 'weekday': 'Monday', 'date': '2023-08-28', 'time': '00:04:20'}, {'timestamp': '1693181080000000000', 'traffic_report_id': 'BE69557045E8D95F6C5BC62BEA729B2E4BC50A7C_1693181080', 'date_time': '2023-08-28 00:04:40+00:00', 'issue_reported': 'stalled vehicle', 'latitude': '30.402212', 'longitude': '-97.657377', 'address': 'tech ridge blvd / e parmer ln', 'weekday': 'Monday', 'date': '2023-08-28', 'time': '00:04:40'}, {'timestamp': '1693181387000000000', 'traffic_report_id': 'B25B748A59D8B6B5B5AE3E9D985289E795C874ED_1693181387', 'date_time': '2023-08-28 00:09:47+00:00', 'issue_reported': 'crash service', 'latitude': '30.21522', 'longitude': '-97.752877', 'address': '4108 s ih 35 svrd sb', 'weekday': 'Monday', 'date': '2023-08-28', 'time': '00:09:47'}, {'timestamp': '1693182276000000000', 'traffic_report_id': '91A0461DA8536C97056D3B86390D0BDD472CA52B_1693182276', 'date_time': '2023-08-28 00:24:36+00:00', 'issue_reported': 'traffic hazard', 'latitude': '30.237362', 'longitude': '-97.614943', 'address': '600-1625 s sh 130 nb', 'weekday': 'Monday', 'date': '2023-08-28', 'time': '00:24:36'}, {'timestamp': '1693182347000000000', 'traffic_report_id': '4A4AB45448022F0C738FE9E310148EA1EB7F856B_1693182347', 'date_time': '2023-08-28 00:25:47+00:00', 'issue_reported': 'stalled vehicle', 'latitude': '30.433455', 'longitude': '-97.67912', 'address': '1831 w wells branch pkwy', 'weekday': 'Monday', 'date': '2023-08-28', 'time': '00:25:47'}, {'timestamp': '1693182673000000000', 'traffic_report_id': '566EE6D19FEF04459D959B08349D6C07B3A309A2_1693182673', 'date_time': '2023-08-28 00:31:13+00:00', 'issue_reported': 'traffic hazard', 'latitude': '30.30781', 'longitude': '-97.665765', 'address': '6508 ashland cir', 'weekday': 'Monday', 'date': '2023-08-28', 'time': '00:31:13'}, {'timestamp': '1693183109000000000', 'traffic_report_id': '5527E76C85E5B71C6DEFA5F0099519B1D67B4627_1693183109', 'date_time': '2023-08-28 00:38:29+00:00', 'issue_reported': 'traffic hazard', 'latitude': '30.257985', 'longitude': '-97.601927', 'address': '5000 n sh 130 sb', 'weekday': 'Monday', 'date': '2023-08-28', 'time': '00:38:29'}  ... displaying 10 of 143 total bound parameter sets ...  {'timestamp': '1693267017000000000', 'traffic_report_id': '8334918DA76533B5C14F235F374E327C95035AA3_1693267017', 'date_time': '2023-08-28 23:56:57+00:00', 'issue_reported': 'crash service', 'latitude': '30.159788', 'longitude': '-97.789714', 'address': '9700 s ih 35 sb', 'weekday': 'Monday', 'date': '2023-08-28', 'time': '23:56:57'}, {'timestamp': '1693267163000000000', 'traffic_report_id': '73CA0CCD6FF3D0CA58884DEAAAD9E042EC048A8F_1693267163', 'date_time': '2023-08-28 23:59:23+00:00', 'issue_reported': 'loose livestock', 'latitude': '30.301566', 'longitude': '-97.565464', 'address': 'n fm 973 rd / e braker ln', 'weekday': 'Monday', 'date': '2023-08-28', 'time': '23:59:23'})]
[2023-08-30T21:10:30.344+0000] {subprocess.py:93} INFO - (Background on this error at: https://sqlalche.me/e/14/9h9h)
[2023-08-30T21:10:30.421+0000] {subprocess.py:97} INFO - Command exited with return code 1
[2023-08-30T21:10:30.486+0000] {taskinstance.py:1943} ERROR - Task failed with exception
Traceback (most recent call last):
  File "/home/airflow/.local/lib/python3.8/site-packages/airflow/operators/bash.py", line 210, in execute
    raise AirflowException(
airflow.exceptions.AirflowException: Bash command failed. The command returned a non-zero exit code 1.
[2023-08-30T21:10:30.509+0000] {taskinstance.py:1400} INFO - Marking task as FAILED. dag_id=traffic_report, task_id=export_data_to_db, execution_date=20230829T000000, start_date=20230830T210959, end_date=20230830T211030
[2023-08-30T21:10:30.546+0000] {standard_task_runner.py:104} ERROR - Failed to execute job 25 for task export_data_to_db (Bash command failed. The command returned a non-zero exit code 1.; 448)
[2023-08-30T21:10:30.616+0000] {local_task_job_runner.py:228} INFO - Task exited with return code 1
[2023-08-30T21:10:30.641+0000] {taskinstance.py:2784} INFO - 0 downstream tasks scheduled from follow-on schedule check
