[2023-08-30T19:33:42.444+0000] {logging_mixin.py:151} WARNING - /home/***/.local/lib/python3.8/site-packages/***/utils/sqlalchemy.py:124 DeprecationWarning: The sql_alchemy_conn option in [core] has been moved to the sql_alchemy_conn option in [database] - the old setting has been used, but please update your config.
[2023-08-30T19:33:42.453+0000] {taskinstance.py:1159} INFO - Dependencies all met for dep_context=non-requeueable deps ti=<TaskInstance: traffic_report.export_data_to_db scheduled__2023-08-24T00:00:00+00:00 [queued]>
[2023-08-30T19:33:42.459+0000] {taskinstance.py:1159} INFO - Dependencies all met for dep_context=requeueable deps ti=<TaskInstance: traffic_report.export_data_to_db scheduled__2023-08-24T00:00:00+00:00 [queued]>
[2023-08-30T19:33:42.461+0000] {taskinstance.py:1361} INFO - Starting attempt 1 of 2
[2023-08-30T19:33:42.470+0000] {taskinstance.py:1382} INFO - Executing <Task(BashOperator): export_data_to_db> on 2023-08-24 00:00:00+00:00
[2023-08-30T19:33:42.474+0000] {standard_task_runner.py:57} INFO - Started process 401 to run task
[2023-08-30T19:33:42.477+0000] {standard_task_runner.py:84} INFO - Running: ['***', 'tasks', 'run', 'traffic_report', 'export_data_to_db', 'scheduled__2023-08-24T00:00:00+00:00', '--job-id', '20', '--raw', '--subdir', 'DAGS_FOLDER/traffic_dag.py', '--cfg-path', '/tmp/tmpdzg3c06r']
[2023-08-30T19:33:42.480+0000] {standard_task_runner.py:85} INFO - Job 20: Subtask export_data_to_db
[2023-08-30T19:33:42.495+0000] {logging_mixin.py:151} WARNING - /home/***/.local/lib/python3.8/site-packages/***/settings.py:195 DeprecationWarning: The sql_alchemy_conn option in [core] has been moved to the sql_alchemy_conn option in [database] - the old setting has been used, but please update your config.
[2023-08-30T19:33:42.542+0000] {task_command.py:415} INFO - Running <TaskInstance: traffic_report.export_data_to_db scheduled__2023-08-24T00:00:00+00:00 [running]> on host f6bcf103ff79
[2023-08-30T19:33:42.556+0000] {logging_mixin.py:151} WARNING - /home/***/.local/lib/python3.8/site-packages/***/utils/sqlalchemy.py:124 DeprecationWarning: The sql_alchemy_conn option in [core] has been moved to the sql_alchemy_conn option in [database] - the old setting has been used, but please update your config.
[2023-08-30T19:33:42.611+0000] {taskinstance.py:1660} INFO - Exporting env vars: AIRFLOW_CTX_DAG_OWNER='***' AIRFLOW_CTX_DAG_ID='traffic_report' AIRFLOW_CTX_TASK_ID='export_data_to_db' AIRFLOW_CTX_EXECUTION_DATE='2023-08-24T00:00:00+00:00' AIRFLOW_CTX_TRY_NUMBER='1' AIRFLOW_CTX_DAG_RUN_ID='scheduled__2023-08-24T00:00:00+00:00'
[2023-08-30T19:33:42.614+0000] {subprocess.py:63} INFO - Tmp dir root location: /tmp
[2023-08-30T19:33:42.616+0000] {subprocess.py:75} INFO - Running command: ['/bin/bash', '-c', 'python /opt/***/dags/data_to_db.py --date 2023-08-24 --connection postgresql+psycopg2://***:***@postgres/***']
[2023-08-30T19:33:42.625+0000] {subprocess.py:86} INFO - Output:
[2023-08-30T19:33:42.965+0000] {subprocess.py:93} INFO - Traceback (most recent call last):
[2023-08-30T19:33:42.966+0000] {subprocess.py:93} INFO -   File "/opt/***/dags/data_to_db.py", line 6, in <module>
[2023-08-30T19:33:42.967+0000] {subprocess.py:93} INFO -     from model import Connection, Traffic
[2023-08-30T19:33:42.968+0000] {subprocess.py:93} INFO -   File "/opt/***/dags/model.py", line 5, in <module>
[2023-08-30T19:33:42.970+0000] {subprocess.py:93} INFO -     from geoalchemy2 import Geometry
[2023-08-30T19:33:42.971+0000] {subprocess.py:93} INFO - ModuleNotFoundError: No module named 'geoalchemy2'
[2023-08-30T19:33:42.989+0000] {subprocess.py:97} INFO - Command exited with return code 1
[2023-08-30T19:33:43.001+0000] {taskinstance.py:1943} ERROR - Task failed with exception
Traceback (most recent call last):
  File "/home/airflow/.local/lib/python3.8/site-packages/airflow/operators/bash.py", line 210, in execute
    raise AirflowException(
airflow.exceptions.AirflowException: Bash command failed. The command returned a non-zero exit code 1.
[2023-08-30T19:33:43.005+0000] {taskinstance.py:1400} INFO - Marking task as UP_FOR_RETRY. dag_id=traffic_report, task_id=export_data_to_db, execution_date=20230824T000000, start_date=20230830T193342, end_date=20230830T193343
[2023-08-30T19:33:43.019+0000] {standard_task_runner.py:104} ERROR - Failed to execute job 20 for task export_data_to_db (Bash command failed. The command returned a non-zero exit code 1.; 401)
[2023-08-30T19:33:43.071+0000] {local_task_job_runner.py:228} INFO - Task exited with return code 1
[2023-08-30T19:33:43.087+0000] {taskinstance.py:2784} INFO - 0 downstream tasks scheduled from follow-on schedule check
[2023-08-30T19:42:02.045+0000] {logging_mixin.py:151} WARNING - /home/***/.local/lib/python3.8/site-packages/***/utils/sqlalchemy.py:124 DeprecationWarning: The sql_alchemy_conn option in [core] has been moved to the sql_alchemy_conn option in [database] - the old setting has been used, but please update your config.
[2023-08-30T19:42:02.061+0000] {taskinstance.py:1159} INFO - Dependencies all met for dep_context=non-requeueable deps ti=<TaskInstance: traffic_report.export_data_to_db scheduled__2023-08-24T00:00:00+00:00 [queued]>
[2023-08-30T19:42:02.071+0000] {taskinstance.py:1159} INFO - Dependencies all met for dep_context=requeueable deps ti=<TaskInstance: traffic_report.export_data_to_db scheduled__2023-08-24T00:00:00+00:00 [queued]>
[2023-08-30T19:42:02.074+0000] {taskinstance.py:1361} INFO - Starting attempt 1 of 2
[2023-08-30T19:42:02.086+0000] {taskinstance.py:1382} INFO - Executing <Task(BashOperator): export_data_to_db> on 2023-08-24 00:00:00+00:00
[2023-08-30T19:42:02.096+0000] {standard_task_runner.py:57} INFO - Started process 380 to run task
[2023-08-30T19:42:02.099+0000] {standard_task_runner.py:84} INFO - Running: ['***', 'tasks', 'run', 'traffic_report', 'export_data_to_db', 'scheduled__2023-08-24T00:00:00+00:00', '--job-id', '19', '--raw', '--subdir', 'DAGS_FOLDER/traffic_dag.py', '--cfg-path', '/tmp/tmpv32car3s']
[2023-08-30T19:42:02.104+0000] {standard_task_runner.py:85} INFO - Job 19: Subtask export_data_to_db
[2023-08-30T19:42:02.127+0000] {logging_mixin.py:151} WARNING - /home/***/.local/lib/python3.8/site-packages/***/settings.py:195 DeprecationWarning: The sql_alchemy_conn option in [core] has been moved to the sql_alchemy_conn option in [database] - the old setting has been used, but please update your config.
[2023-08-30T19:42:02.191+0000] {task_command.py:415} INFO - Running <TaskInstance: traffic_report.export_data_to_db scheduled__2023-08-24T00:00:00+00:00 [running]> on host 81eeb4b7c8a9
[2023-08-30T19:42:02.206+0000] {logging_mixin.py:151} WARNING - /home/***/.local/lib/python3.8/site-packages/***/utils/sqlalchemy.py:124 DeprecationWarning: The sql_alchemy_conn option in [core] has been moved to the sql_alchemy_conn option in [database] - the old setting has been used, but please update your config.
[2023-08-30T19:42:02.286+0000] {taskinstance.py:1660} INFO - Exporting env vars: AIRFLOW_CTX_DAG_OWNER='***' AIRFLOW_CTX_DAG_ID='traffic_report' AIRFLOW_CTX_TASK_ID='export_data_to_db' AIRFLOW_CTX_EXECUTION_DATE='2023-08-24T00:00:00+00:00' AIRFLOW_CTX_TRY_NUMBER='1' AIRFLOW_CTX_DAG_RUN_ID='scheduled__2023-08-24T00:00:00+00:00'
[2023-08-30T19:42:02.293+0000] {subprocess.py:63} INFO - Tmp dir root location: /tmp
[2023-08-30T19:42:02.295+0000] {subprocess.py:75} INFO - Running command: ['/bin/bash', '-c', 'python /opt/***/dags/data_to_db.py --date 2023-08-24 --connection postgresql+psycopg2://***:***@postgres/***']
[2023-08-30T19:42:02.312+0000] {subprocess.py:86} INFO - Output:
[2023-08-30T19:42:02.880+0000] {subprocess.py:93} INFO - Traceback (most recent call last):
[2023-08-30T19:42:02.882+0000] {subprocess.py:93} INFO -   File "/opt/***/dags/data_to_db.py", line 6, in <module>
[2023-08-30T19:42:02.884+0000] {subprocess.py:93} INFO -     from model import Connection, Traffic
[2023-08-30T19:42:02.885+0000] {subprocess.py:93} INFO -   File "/opt/***/dags/model.py", line 5, in <module>
[2023-08-30T19:42:02.889+0000] {subprocess.py:93} INFO -     from geoalchemy2 import Geometry
[2023-08-30T19:42:02.890+0000] {subprocess.py:93} INFO - ModuleNotFoundError: No module named 'geoalchemy2'
[2023-08-30T19:42:02.926+0000] {subprocess.py:97} INFO - Command exited with return code 1
[2023-08-30T19:42:02.947+0000] {taskinstance.py:1943} ERROR - Task failed with exception
Traceback (most recent call last):
  File "/home/airflow/.local/lib/python3.8/site-packages/airflow/operators/bash.py", line 210, in execute
    raise AirflowException(
airflow.exceptions.AirflowException: Bash command failed. The command returned a non-zero exit code 1.
[2023-08-30T19:42:02.954+0000] {taskinstance.py:1400} INFO - Marking task as UP_FOR_RETRY. dag_id=traffic_report, task_id=export_data_to_db, execution_date=20230824T000000, start_date=20230830T194202, end_date=20230830T194202
[2023-08-30T19:42:02.979+0000] {standard_task_runner.py:104} ERROR - Failed to execute job 19 for task export_data_to_db (Bash command failed. The command returned a non-zero exit code 1.; 380)
[2023-08-30T19:42:03.001+0000] {local_task_job_runner.py:228} INFO - Task exited with return code 1
[2023-08-30T19:42:03.020+0000] {taskinstance.py:2784} INFO - 0 downstream tasks scheduled from follow-on schedule check
[2023-08-30T19:51:05.588+0000] {logging_mixin.py:151} WARNING - /home/***/.local/lib/python3.8/site-packages/***/utils/sqlalchemy.py:124 DeprecationWarning: The sql_alchemy_conn option in [core] has been moved to the sql_alchemy_conn option in [database] - the old setting has been used, but please update your config.
[2023-08-30T19:51:05.598+0000] {taskinstance.py:1159} INFO - Dependencies all met for dep_context=non-requeueable deps ti=<TaskInstance: traffic_report.export_data_to_db scheduled__2023-08-24T00:00:00+00:00 [queued]>
[2023-08-30T19:51:05.617+0000] {taskinstance.py:1159} INFO - Dependencies all met for dep_context=requeueable deps ti=<TaskInstance: traffic_report.export_data_to_db scheduled__2023-08-24T00:00:00+00:00 [queued]>
[2023-08-30T19:51:05.618+0000] {taskinstance.py:1361} INFO - Starting attempt 1 of 2
[2023-08-30T19:51:05.636+0000] {taskinstance.py:1382} INFO - Executing <Task(BashOperator): export_data_to_db> on 2023-08-24 00:00:00+00:00
[2023-08-30T19:51:05.646+0000] {standard_task_runner.py:57} INFO - Started process 358 to run task
[2023-08-30T19:51:05.659+0000] {standard_task_runner.py:84} INFO - Running: ['***', 'tasks', 'run', 'traffic_report', 'export_data_to_db', 'scheduled__2023-08-24T00:00:00+00:00', '--job-id', '15', '--raw', '--subdir', 'DAGS_FOLDER/traffic_dag.py', '--cfg-path', '/tmp/tmpxm5dsgz0']
[2023-08-30T19:51:05.663+0000] {standard_task_runner.py:85} INFO - Job 15: Subtask export_data_to_db
[2023-08-30T19:51:06.061+0000] {logging_mixin.py:151} WARNING - /home/***/.local/lib/python3.8/site-packages/***/settings.py:195 DeprecationWarning: The sql_alchemy_conn option in [core] has been moved to the sql_alchemy_conn option in [database] - the old setting has been used, but please update your config.
[2023-08-30T19:51:07.076+0000] {task_command.py:415} INFO - Running <TaskInstance: traffic_report.export_data_to_db scheduled__2023-08-24T00:00:00+00:00 [running]> on host 206ecb1dc8df
[2023-08-30T19:51:07.186+0000] {logging_mixin.py:151} WARNING - /home/***/.local/lib/python3.8/site-packages/***/utils/sqlalchemy.py:124 DeprecationWarning: The sql_alchemy_conn option in [core] has been moved to the sql_alchemy_conn option in [database] - the old setting has been used, but please update your config.
[2023-08-30T19:51:14.273+0000] {taskinstance.py:1660} INFO - Exporting env vars: AIRFLOW_CTX_DAG_OWNER='***' AIRFLOW_CTX_DAG_ID='traffic_report' AIRFLOW_CTX_TASK_ID='export_data_to_db' AIRFLOW_CTX_EXECUTION_DATE='2023-08-24T00:00:00+00:00' AIRFLOW_CTX_TRY_NUMBER='1' AIRFLOW_CTX_DAG_RUN_ID='scheduled__2023-08-24T00:00:00+00:00'
[2023-08-30T19:51:14.509+0000] {subprocess.py:63} INFO - Tmp dir root location: /tmp
[2023-08-30T19:51:14.675+0000] {subprocess.py:75} INFO - Running command: ['/bin/bash', '-c', 'python /opt/***/dags/data_to_db.py --date 2023-08-24 --connection postgresql+psycopg2://***:***@postgres/***']
[2023-08-30T19:51:14.989+0000] {subprocess.py:86} INFO - Output:
[2023-08-30T19:51:33.980+0000] {subprocess.py:93} INFO - Traceback (most recent call last):
[2023-08-30T19:51:33.989+0000] {subprocess.py:93} INFO -   File "/opt/***/dags/data_to_db.py", line 50, in <module>
[2023-08-30T19:51:34.003+0000] {subprocess.py:93} INFO -     main(args.date, args.connection)
[2023-08-30T19:51:34.005+0000] {subprocess.py:93} INFO -   File "/opt/***/dags/data_to_db.py", line 22, in main
[2023-08-30T19:51:34.006+0000] {subprocess.py:93} INFO -     with open(filename, encoding='utf-8') as csvf:
[2023-08-30T19:51:34.008+0000] {subprocess.py:93} INFO - FileNotFoundError: [Errno 2] No such file or directory: '/opt/***/dags/data/traffic_2023-08-23.csv'
[2023-08-30T19:51:34.107+0000] {subprocess.py:97} INFO - Command exited with return code 1
[2023-08-30T19:51:34.152+0000] {taskinstance.py:1943} ERROR - Task failed with exception
Traceback (most recent call last):
  File "/home/airflow/.local/lib/python3.8/site-packages/airflow/operators/bash.py", line 210, in execute
    raise AirflowException(
airflow.exceptions.AirflowException: Bash command failed. The command returned a non-zero exit code 1.
[2023-08-30T19:51:34.163+0000] {taskinstance.py:1400} INFO - Marking task as UP_FOR_RETRY. dag_id=traffic_report, task_id=export_data_to_db, execution_date=20230824T000000, start_date=20230830T195105, end_date=20230830T195134
[2023-08-30T19:51:34.193+0000] {standard_task_runner.py:104} ERROR - Failed to execute job 15 for task export_data_to_db (Bash command failed. The command returned a non-zero exit code 1.; 358)
[2023-08-30T19:51:34.223+0000] {local_task_job_runner.py:228} INFO - Task exited with return code 1
[2023-08-30T19:51:34.245+0000] {taskinstance.py:2784} INFO - 0 downstream tasks scheduled from follow-on schedule check
[2023-08-30T19:54:33.294+0000] {logging_mixin.py:151} WARNING - /home/***/.local/lib/python3.8/site-packages/***/utils/sqlalchemy.py:124 DeprecationWarning: The sql_alchemy_conn option in [core] has been moved to the sql_alchemy_conn option in [database] - the old setting has been used, but please update your config.
[2023-08-30T19:54:33.306+0000] {taskinstance.py:1159} INFO - Dependencies all met for dep_context=non-requeueable deps ti=<TaskInstance: traffic_report.export_data_to_db scheduled__2023-08-24T00:00:00+00:00 [queued]>
[2023-08-30T19:54:33.334+0000] {taskinstance.py:1159} INFO - Dependencies all met for dep_context=requeueable deps ti=<TaskInstance: traffic_report.export_data_to_db scheduled__2023-08-24T00:00:00+00:00 [queued]>
[2023-08-30T19:54:33.336+0000] {taskinstance.py:1361} INFO - Starting attempt 1 of 2
[2023-08-30T19:54:33.366+0000] {taskinstance.py:1382} INFO - Executing <Task(BashOperator): export_data_to_db> on 2023-08-24 00:00:00+00:00
[2023-08-30T19:54:33.372+0000] {standard_task_runner.py:57} INFO - Started process 315 to run task
[2023-08-30T19:54:33.383+0000] {standard_task_runner.py:84} INFO - Running: ['***', 'tasks', 'run', 'traffic_report', 'export_data_to_db', 'scheduled__2023-08-24T00:00:00+00:00', '--job-id', '14', '--raw', '--subdir', 'DAGS_FOLDER/traffic_dag.py', '--cfg-path', '/tmp/tmp6wphek6_']
[2023-08-30T19:54:33.388+0000] {standard_task_runner.py:85} INFO - Job 14: Subtask export_data_to_db
[2023-08-30T19:54:33.416+0000] {logging_mixin.py:151} WARNING - /home/***/.local/lib/python3.8/site-packages/***/settings.py:195 DeprecationWarning: The sql_alchemy_conn option in [core] has been moved to the sql_alchemy_conn option in [database] - the old setting has been used, but please update your config.
[2023-08-30T19:54:33.468+0000] {task_command.py:415} INFO - Running <TaskInstance: traffic_report.export_data_to_db scheduled__2023-08-24T00:00:00+00:00 [running]> on host 86f9e97d6c70
[2023-08-30T19:54:33.490+0000] {logging_mixin.py:151} WARNING - /home/***/.local/lib/python3.8/site-packages/***/utils/sqlalchemy.py:124 DeprecationWarning: The sql_alchemy_conn option in [core] has been moved to the sql_alchemy_conn option in [database] - the old setting has been used, but please update your config.
[2023-08-30T19:54:33.573+0000] {taskinstance.py:1660} INFO - Exporting env vars: AIRFLOW_CTX_DAG_OWNER='***' AIRFLOW_CTX_DAG_ID='traffic_report' AIRFLOW_CTX_TASK_ID='export_data_to_db' AIRFLOW_CTX_EXECUTION_DATE='2023-08-24T00:00:00+00:00' AIRFLOW_CTX_TRY_NUMBER='1' AIRFLOW_CTX_DAG_RUN_ID='scheduled__2023-08-24T00:00:00+00:00'
[2023-08-30T19:54:33.582+0000] {subprocess.py:63} INFO - Tmp dir root location: /tmp
[2023-08-30T19:54:33.584+0000] {subprocess.py:75} INFO - Running command: ['/bin/bash', '-c', 'python /opt/***/dags/data_to_db.py --date 2023-08-24 --connection postgresql+psycopg2://***:***@postgres/***']
[2023-08-30T19:54:33.598+0000] {subprocess.py:86} INFO - Output:
[2023-08-30T19:54:34.559+0000] {subprocess.py:93} INFO - Traceback (most recent call last):
[2023-08-30T19:54:34.561+0000] {subprocess.py:93} INFO -   File "/home/***/.local/lib/python3.8/site-packages/sqlalchemy/engine/base.py", line 1910, in _execute_context
[2023-08-30T19:54:34.563+0000] {subprocess.py:93} INFO -     self.dialect.do_execute(
[2023-08-30T19:54:34.564+0000] {subprocess.py:93} INFO -   File "/home/***/.local/lib/python3.8/site-packages/sqlalchemy/engine/default.py", line 736, in do_execute
[2023-08-30T19:54:34.566+0000] {subprocess.py:93} INFO -     cursor.execute(statement, parameters)
[2023-08-30T19:54:34.567+0000] {subprocess.py:93} INFO - psycopg2.errors.UndefinedTable: relation "traffic_report" does not exist
[2023-08-30T19:54:34.568+0000] {subprocess.py:93} INFO - LINE 1: DELETE FROM traffic_report where date_time >= timestamp '202...
[2023-08-30T19:54:34.569+0000] {subprocess.py:93} INFO -                     ^
[2023-08-30T19:54:34.571+0000] {subprocess.py:93} INFO - 
[2023-08-30T19:54:34.572+0000] {subprocess.py:93} INFO - 
[2023-08-30T19:54:34.573+0000] {subprocess.py:93} INFO - The above exception was the direct cause of the following exception:
[2023-08-30T19:54:34.575+0000] {subprocess.py:93} INFO - 
[2023-08-30T19:54:34.579+0000] {subprocess.py:93} INFO - Traceback (most recent call last):
[2023-08-30T19:54:34.581+0000] {subprocess.py:93} INFO -   File "/opt/***/dags/data_to_db.py", line 50, in <module>
[2023-08-30T19:54:34.583+0000] {subprocess.py:93} INFO -     main(args.date, args.connection)
[2023-08-30T19:54:34.585+0000] {subprocess.py:93} INFO -   File "/opt/***/dags/data_to_db.py", line 40, in main
[2023-08-30T19:54:34.586+0000] {subprocess.py:93} INFO -     session.execute("DELETE FROM traffic_report where date_time >= timestamp '{} 00:00:00' and date_time < timestamp'{} 00:00:00'".format(yesterday, fetch_date))
[2023-08-30T19:54:34.588+0000] {subprocess.py:93} INFO -   File "/home/***/.local/lib/python3.8/site-packages/sqlalchemy/orm/session.py", line 1717, in execute
[2023-08-30T19:54:34.590+0000] {subprocess.py:93} INFO -     result = conn._execute_20(statement, params or {}, execution_options)
[2023-08-30T19:54:34.591+0000] {subprocess.py:93} INFO -   File "/home/***/.local/lib/python3.8/site-packages/sqlalchemy/engine/base.py", line 1710, in _execute_20
[2023-08-30T19:54:34.593+0000] {subprocess.py:93} INFO -     return meth(self, args_10style, kwargs_10style, execution_options)
[2023-08-30T19:54:34.595+0000] {subprocess.py:93} INFO -   File "/home/***/.local/lib/python3.8/site-packages/sqlalchemy/sql/elements.py", line 334, in _execute_on_connection
[2023-08-30T19:54:34.596+0000] {subprocess.py:93} INFO -     return connection._execute_clauseelement(
[2023-08-30T19:54:34.598+0000] {subprocess.py:93} INFO -   File "/home/***/.local/lib/python3.8/site-packages/sqlalchemy/engine/base.py", line 1577, in _execute_clauseelement
[2023-08-30T19:54:34.599+0000] {subprocess.py:93} INFO -     ret = self._execute_context(
[2023-08-30T19:54:34.600+0000] {subprocess.py:93} INFO -   File "/home/***/.local/lib/python3.8/site-packages/sqlalchemy/engine/base.py", line 1953, in _execute_context
[2023-08-30T19:54:34.602+0000] {subprocess.py:93} INFO -     self._handle_dbapi_exception(
[2023-08-30T19:54:34.604+0000] {subprocess.py:93} INFO -   File "/home/***/.local/lib/python3.8/site-packages/sqlalchemy/engine/base.py", line 2134, in _handle_dbapi_exception
[2023-08-30T19:54:34.605+0000] {subprocess.py:93} INFO -     util.raise_(
[2023-08-30T19:54:34.614+0000] {subprocess.py:93} INFO -   File "/home/***/.local/lib/python3.8/site-packages/sqlalchemy/util/compat.py", line 211, in raise_
[2023-08-30T19:54:34.617+0000] {subprocess.py:93} INFO -     raise exception
[2023-08-30T19:54:34.629+0000] {subprocess.py:93} INFO -   File "/home/***/.local/lib/python3.8/site-packages/sqlalchemy/engine/base.py", line 1910, in _execute_context
[2023-08-30T19:54:34.642+0000] {subprocess.py:93} INFO -     self.dialect.do_execute(
[2023-08-30T19:54:34.643+0000] {subprocess.py:93} INFO -   File "/home/***/.local/lib/python3.8/site-packages/sqlalchemy/engine/default.py", line 736, in do_execute
[2023-08-30T19:54:34.652+0000] {subprocess.py:93} INFO -     cursor.execute(statement, parameters)
[2023-08-30T19:54:34.659+0000] {subprocess.py:93} INFO - sqlalchemy.exc.ProgrammingError: (psycopg2.errors.UndefinedTable) relation "traffic_report" does not exist
[2023-08-30T19:54:34.661+0000] {subprocess.py:93} INFO - LINE 1: DELETE FROM traffic_report where date_time >= timestamp '202...
[2023-08-30T19:54:34.663+0000] {subprocess.py:93} INFO -                     ^
[2023-08-30T19:54:34.664+0000] {subprocess.py:93} INFO - 
[2023-08-30T19:54:34.665+0000] {subprocess.py:93} INFO - [SQL: DELETE FROM traffic_report where date_time >= timestamp '2023-08-23 00:00:00' and date_time < timestamp'2023-08-24 00:00:00']
[2023-08-30T19:54:34.666+0000] {subprocess.py:93} INFO - (Background on this error at: https://sqlalche.me/e/14/f405)
[2023-08-30T19:54:34.781+0000] {subprocess.py:97} INFO - Command exited with return code 1
[2023-08-30T19:54:34.798+0000] {taskinstance.py:1943} ERROR - Task failed with exception
Traceback (most recent call last):
  File "/home/airflow/.local/lib/python3.8/site-packages/airflow/operators/bash.py", line 210, in execute
    raise AirflowException(
airflow.exceptions.AirflowException: Bash command failed. The command returned a non-zero exit code 1.
[2023-08-30T19:54:34.802+0000] {taskinstance.py:1400} INFO - Marking task as UP_FOR_RETRY. dag_id=traffic_report, task_id=export_data_to_db, execution_date=20230824T000000, start_date=20230830T195433, end_date=20230830T195434
[2023-08-30T19:54:34.816+0000] {standard_task_runner.py:104} ERROR - Failed to execute job 14 for task export_data_to_db (Bash command failed. The command returned a non-zero exit code 1.; 315)
[2023-08-30T19:54:34.855+0000] {local_task_job_runner.py:228} INFO - Task exited with return code 1
[2023-08-30T19:54:34.876+0000] {taskinstance.py:2784} INFO - 0 downstream tasks scheduled from follow-on schedule check
[2023-08-30T20:05:58.327+0000] {logging_mixin.py:151} WARNING - /home/***/.local/lib/python3.8/site-packages/***/utils/sqlalchemy.py:124 DeprecationWarning: The sql_alchemy_conn option in [core] has been moved to the sql_alchemy_conn option in [database] - the old setting has been used, but please update your config.
[2023-08-30T20:05:58.340+0000] {taskinstance.py:1159} INFO - Dependencies all met for dep_context=non-requeueable deps ti=<TaskInstance: traffic_report.export_data_to_db scheduled__2023-08-24T00:00:00+00:00 [queued]>
[2023-08-30T20:05:58.366+0000] {taskinstance.py:1159} INFO - Dependencies all met for dep_context=requeueable deps ti=<TaskInstance: traffic_report.export_data_to_db scheduled__2023-08-24T00:00:00+00:00 [queued]>
[2023-08-30T20:05:58.369+0000] {taskinstance.py:1361} INFO - Starting attempt 1 of 2
[2023-08-30T20:05:58.397+0000] {taskinstance.py:1382} INFO - Executing <Task(BashOperator): export_data_to_db> on 2023-08-24 00:00:00+00:00
[2023-08-30T20:05:58.402+0000] {standard_task_runner.py:57} INFO - Started process 540 to run task
[2023-08-30T20:05:58.408+0000] {standard_task_runner.py:84} INFO - Running: ['***', 'tasks', 'run', 'traffic_report', 'export_data_to_db', 'scheduled__2023-08-24T00:00:00+00:00', '--job-id', '24', '--raw', '--subdir', 'DAGS_FOLDER/traffic_dag.py', '--cfg-path', '/tmp/tmpkciq9dv9']
[2023-08-30T20:05:58.412+0000] {standard_task_runner.py:85} INFO - Job 24: Subtask export_data_to_db
[2023-08-30T20:05:58.437+0000] {logging_mixin.py:151} WARNING - /home/***/.local/lib/python3.8/site-packages/***/settings.py:195 DeprecationWarning: The sql_alchemy_conn option in [core] has been moved to the sql_alchemy_conn option in [database] - the old setting has been used, but please update your config.
[2023-08-30T20:05:58.486+0000] {task_command.py:415} INFO - Running <TaskInstance: traffic_report.export_data_to_db scheduled__2023-08-24T00:00:00+00:00 [running]> on host 3938d7abd9ff
[2023-08-30T20:05:58.506+0000] {logging_mixin.py:151} WARNING - /home/***/.local/lib/python3.8/site-packages/***/utils/sqlalchemy.py:124 DeprecationWarning: The sql_alchemy_conn option in [core] has been moved to the sql_alchemy_conn option in [database] - the old setting has been used, but please update your config.
[2023-08-30T20:05:58.566+0000] {taskinstance.py:1660} INFO - Exporting env vars: AIRFLOW_CTX_DAG_OWNER='***' AIRFLOW_CTX_DAG_ID='traffic_report' AIRFLOW_CTX_TASK_ID='export_data_to_db' AIRFLOW_CTX_EXECUTION_DATE='2023-08-24T00:00:00+00:00' AIRFLOW_CTX_TRY_NUMBER='1' AIRFLOW_CTX_DAG_RUN_ID='scheduled__2023-08-24T00:00:00+00:00'
[2023-08-30T20:05:58.569+0000] {subprocess.py:63} INFO - Tmp dir root location: /tmp
[2023-08-30T20:05:58.571+0000] {subprocess.py:75} INFO - Running command: ['/bin/bash', '-c', 'python /opt/***/dags/data_to_db.py --date 2023-08-24 --connection postgresql+psycopg2://***:***@postgres/***']
[2023-08-30T20:05:58.582+0000] {subprocess.py:86} INFO - Output:
[2023-08-30T20:05:59.236+0000] {subprocess.py:93} INFO - Traceback (most recent call last):
[2023-08-30T20:05:59.238+0000] {subprocess.py:93} INFO -   File "/home/***/.local/lib/python3.8/site-packages/sqlalchemy/engine/base.py", line 1890, in _execute_context
[2023-08-30T20:05:59.240+0000] {subprocess.py:93} INFO -     self.dialect.do_executemany(
[2023-08-30T20:05:59.241+0000] {subprocess.py:93} INFO -   File "/home/***/.local/lib/python3.8/site-packages/sqlalchemy/dialects/postgresql/psycopg2.py", line 982, in do_executemany
[2023-08-30T20:05:59.242+0000] {subprocess.py:93} INFO -     context._psycopg2_fetched_rows = xtras.execute_values(
[2023-08-30T20:05:59.243+0000] {subprocess.py:93} INFO -   File "/home/***/.local/lib/python3.8/site-packages/psycopg2/extras.py", line 1299, in execute_values
[2023-08-30T20:05:59.246+0000] {subprocess.py:93} INFO -     cur.execute(b''.join(parts))
[2023-08-30T20:05:59.247+0000] {subprocess.py:93} INFO - psycopg2.errors.UndefinedFunction: function st_geomfromewkt(unknown) does not exist
[2023-08-30T20:05:59.249+0000] {subprocess.py:93} INFO - LINE 1: ...3', '2023-08-23 00:03:13+00:00', 'crash service', ST_GeomFro...
[2023-08-30T20:05:59.250+0000] {subprocess.py:93} INFO -                                                              ^
[2023-08-30T20:05:59.251+0000] {subprocess.py:93} INFO - HINT:  No function matches the given name and argument types. You might need to add explicit type casts.
[2023-08-30T20:05:59.253+0000] {subprocess.py:93} INFO - 
[2023-08-30T20:05:59.255+0000] {subprocess.py:93} INFO - 
[2023-08-30T20:05:59.256+0000] {subprocess.py:93} INFO - The above exception was the direct cause of the following exception:
[2023-08-30T20:05:59.257+0000] {subprocess.py:93} INFO - 
[2023-08-30T20:05:59.258+0000] {subprocess.py:93} INFO - Traceback (most recent call last):
[2023-08-30T20:05:59.261+0000] {subprocess.py:93} INFO -   File "/opt/***/dags/data_to_db.py", line 50, in <module>
[2023-08-30T20:05:59.262+0000] {subprocess.py:93} INFO -     main(args.date, args.connection)
[2023-08-30T20:05:59.263+0000] {subprocess.py:93} INFO -   File "/opt/***/dags/data_to_db.py", line 41, in main
[2023-08-30T20:05:59.265+0000] {subprocess.py:93} INFO -     session.bulk_save_objects(data_insert)
[2023-08-30T20:05:59.266+0000] {subprocess.py:93} INFO -   File "/home/***/.local/lib/python3.8/site-packages/sqlalchemy/orm/session.py", line 3705, in bulk_save_objects
[2023-08-30T20:05:59.268+0000] {subprocess.py:93} INFO -     self._bulk_save_mappings(
[2023-08-30T20:05:59.270+0000] {subprocess.py:93} INFO -   File "/home/***/.local/lib/python3.8/site-packages/sqlalchemy/orm/session.py", line 3913, in _bulk_save_mappings
[2023-08-30T20:05:59.272+0000] {subprocess.py:93} INFO -     transaction.rollback(_capture_exception=True)
[2023-08-30T20:05:59.273+0000] {subprocess.py:93} INFO -   File "/home/***/.local/lib/python3.8/site-packages/sqlalchemy/util/langhelpers.py", line 70, in __exit__
[2023-08-30T20:05:59.274+0000] {subprocess.py:93} INFO -     compat.raise_(
[2023-08-30T20:05:59.276+0000] {subprocess.py:93} INFO -   File "/home/***/.local/lib/python3.8/site-packages/sqlalchemy/util/compat.py", line 211, in raise_
[2023-08-30T20:05:59.277+0000] {subprocess.py:93} INFO -     raise exception
[2023-08-30T20:05:59.279+0000] {subprocess.py:93} INFO -   File "/home/***/.local/lib/python3.8/site-packages/sqlalchemy/orm/session.py", line 3901, in _bulk_save_mappings
[2023-08-30T20:05:59.280+0000] {subprocess.py:93} INFO -     persistence._bulk_insert(
[2023-08-30T20:05:59.282+0000] {subprocess.py:93} INFO -   File "/home/***/.local/lib/python3.8/site-packages/sqlalchemy/orm/persistence.py", line 107, in _bulk_insert
[2023-08-30T20:05:59.283+0000] {subprocess.py:93} INFO -     _emit_insert_statements(
[2023-08-30T20:05:59.284+0000] {subprocess.py:93} INFO -   File "/home/***/.local/lib/python3.8/site-packages/sqlalchemy/orm/persistence.py", line 1097, in _emit_insert_statements
[2023-08-30T20:05:59.285+0000] {subprocess.py:93} INFO -     c = connection._execute_20(
[2023-08-30T20:05:59.287+0000] {subprocess.py:93} INFO -   File "/home/***/.local/lib/python3.8/site-packages/sqlalchemy/engine/base.py", line 1710, in _execute_20
[2023-08-30T20:05:59.290+0000] {subprocess.py:93} INFO -     return meth(self, args_10style, kwargs_10style, execution_options)
[2023-08-30T20:05:59.291+0000] {subprocess.py:93} INFO -   File "/home/***/.local/lib/python3.8/site-packages/sqlalchemy/sql/elements.py", line 334, in _execute_on_connection
[2023-08-30T20:05:59.292+0000] {subprocess.py:93} INFO -     return connection._execute_clauseelement(
[2023-08-30T20:05:59.296+0000] {subprocess.py:93} INFO -   File "/home/***/.local/lib/python3.8/site-packages/sqlalchemy/engine/base.py", line 1577, in _execute_clauseelement
[2023-08-30T20:05:59.297+0000] {subprocess.py:93} INFO -     ret = self._execute_context(
[2023-08-30T20:05:59.298+0000] {subprocess.py:93} INFO -   File "/home/***/.local/lib/python3.8/site-packages/sqlalchemy/engine/base.py", line 1953, in _execute_context
[2023-08-30T20:05:59.299+0000] {subprocess.py:93} INFO -     self._handle_dbapi_exception(
[2023-08-30T20:05:59.300+0000] {subprocess.py:93} INFO -   File "/home/***/.local/lib/python3.8/site-packages/sqlalchemy/engine/base.py", line 2134, in _handle_dbapi_exception
[2023-08-30T20:05:59.301+0000] {subprocess.py:93} INFO -     util.raise_(
[2023-08-30T20:05:59.304+0000] {subprocess.py:93} INFO -   File "/home/***/.local/lib/python3.8/site-packages/sqlalchemy/util/compat.py", line 211, in raise_
[2023-08-30T20:05:59.305+0000] {subprocess.py:93} INFO -     raise exception
[2023-08-30T20:05:59.306+0000] {subprocess.py:93} INFO -   File "/home/***/.local/lib/python3.8/site-packages/sqlalchemy/engine/base.py", line 1890, in _execute_context
[2023-08-30T20:05:59.307+0000] {subprocess.py:93} INFO -     self.dialect.do_executemany(
[2023-08-30T20:05:59.308+0000] {subprocess.py:93} INFO -   File "/home/***/.local/lib/python3.8/site-packages/sqlalchemy/dialects/postgresql/psycopg2.py", line 982, in do_executemany
[2023-08-30T20:05:59.309+0000] {subprocess.py:93} INFO -     context._psycopg2_fetched_rows = xtras.execute_values(
[2023-08-30T20:05:59.310+0000] {subprocess.py:93} INFO -   File "/home/***/.local/lib/python3.8/site-packages/psycopg2/extras.py", line 1299, in execute_values
[2023-08-30T20:05:59.311+0000] {subprocess.py:93} INFO -     cur.execute(b''.join(parts))
[2023-08-30T20:05:59.314+0000] {subprocess.py:93} INFO - sqlalchemy.exc.ProgrammingError: (psycopg2.errors.UndefinedFunction) function st_geomfromewkt(unknown) does not exist
[2023-08-30T20:05:59.316+0000] {subprocess.py:93} INFO - LINE 1: ...3', '2023-08-23 00:03:13+00:00', 'crash service', ST_GeomFro...
[2023-08-30T20:05:59.317+0000] {subprocess.py:93} INFO -                                                              ^
[2023-08-30T20:05:59.318+0000] {subprocess.py:93} INFO - HINT:  No function matches the given name and argument types. You might need to add explicit type casts.
[2023-08-30T20:05:59.319+0000] {subprocess.py:93} INFO - 
[2023-08-30T20:05:59.320+0000] {subprocess.py:93} INFO - [SQL: INSERT INTO traffic_report (timestamp, traffic_report_id, date_time, issue_reported, location, latitude, longitude, address, weekday, date, time) VALUES (%(timestamp)s, %(traffic_report_id)s, %(date_time)s, %(issue_reported)s, ST_GeomFromEWKT(%(location)s), %(latitude)s, %(longitude)s, %(address)s, %(weekday)s, %(date)s, %(time)s)]
[2023-08-30T20:05:59.322+0000] {subprocess.py:93} INFO - [parameters: ({'timestamp': '1692748993000000000', 'traffic_report_id': '9A6B59DA46371D86EB75259C956AEE4B580C0119_1692748993', 'date_time': '2023-08-23 00:03:13+00:00', 'issue_reported': 'crash service', 'location': 'POINT(-97.738909 30.193169)', 'latitude': '30.193169', 'longitude': '-97.738909', 'address': 'nuckols crossing rd / e stassney ln', 'weekday': 'Wednesday', 'date': '2023-08-23', 'time': '00:03:13'}, {'timestamp': '1692749009000000000', 'traffic_report_id': '634DE0A75896238BFD3F5886F6062F00DA3D0B56_1692749009', 'date_time': '2023-08-23 00:03:29+00:00', 'issue_reported': 'traffic hazard', 'location': 'POINT(-97.790941 30.167145)', 'latitude': '30.167145', 'longitude': '-97.790941', 'address': 'w slaughter ln / cullen ln', 'weekday': 'Wednesday', 'date': '2023-08-23', 'time': '00:03:29'}, {'timestamp': '1692749887000000000', 'traffic_report_id': 'EBA90709ED04EB27E4A042727D7DD308E44389E4_1692749887', 'date_time': '2023-08-23 00:18:07+00:00', 'issue_reported': 'crash urgent', 'location': 'POINT(-97.691583 30.370783)', 'latitude': '30.370783', 'longitude': '-97.691583', 'address': '600 masterson pass', 'weekday': 'Wednesday', 'date': '2023-08-23', 'time': '00:18:07'}, {'timestamp': '1692751163000000000', 'traffic_report_id': '9D634E9D726305D5B9A7D2E527F6C49DD3603F4F_1692751163', 'date_time': '2023-08-23 00:39:23+00:00', 'issue_reported': 'collision with injury', 'location': 'POINT(-97.61178 30.102795)', 'latitude': '30.102795', 'longitude': '-97.61178', 'address': 'fm 812 rd / doyle rd', 'weekday': 'Wednesday', 'date': '2023-08-23', 'time': '00:39:23'}, {'timestamp': '1692751987000000000', 'traffic_report_id': '301F839B74B67350B1BDC01050369AEC1F36E0D2_1692751987', 'date_time': '2023-08-23 00:53:07+00:00', 'issue_reported': 'traffic hazard', 'location': 'POINT(-97.691413 30.328075)', 'latitude': '30.328075', 'longitude': '-97.691413', 'address': '1308 fairbanks dr', 'weekday': 'Wednesday', 'date': '2023-08-23', 'time': '00:53:07'}, {'timestamp': '1692752143000000000', 'traffic_report_id': '2B80090196FBBD61985EA7F2FC5C2F6AA4E1F134_1692752143', 'date_time': '2023-08-23 00:55:43+00:00', 'issue_reported': 'traffic hazard', 'location': 'POINT(-97.728493 30.235959)', 'latitude': '30.235959', 'longitude': '-97.728493', 'address': 'burton dr / woodland ave', 'weekday': 'Wednesday', 'date': '2023-08-23', 'time': '00:55:43'}, {'timestamp': '1692753489000000000', 'traffic_report_id': '1E768A21723E530122240FA219BFF8C3365F40B2_1692753489', 'date_time': '2023-08-23 01:18:09+00:00', 'issue_reported': 'traffic hazard', 'location': 'POINT(-97.708554 30.310245)', 'latitude': '30.310245', 'longitude': '-97.708554', 'address': '5201-5217 cameron rd', 'weekday': 'Wednesday', 'date': '2023-08-23', 'time': '01:18:09'}, {'timestamp': '1692753535000000000', 'traffic_report_id': '509F6CCBC5A85A0D07F32BFF32186163BA8301B8_1692753535', 'date_time': '2023-08-23 01:18:55+00:00', 'issue_reported': 'crash service', 'location': 'POINT(-97.73408 30.26906)', 'latitude': '30.26906', 'longitude': '-97.73408', 'address': '900 n ih 35 svrd sb', 'weekday': 'Wednesday', 'date': '2023-08-23', 'time': '01:18:55'}  ... displaying 10 of 146 total bound parameter sets ...  {'timestamp': '1692834773000000000', 'traffic_report_id': '3C457CE18C2E37A4437E0201076AD638367EF0EA_1692834773', 'date_time': '2023-08-23 23:52:53+00:00', 'issue_reported': 'crash service', 'location': 'POINT(-97.774726 30.183637)', 'latitude': '30.183637', 'longitude': '-97.774726', 'address': '7301 s ih 35 svrd nb', 'weekday': 'Wednesday', 'date': '2023-08-23', 'time': '23:52:53'}, {'timestamp': '1692834818000000000', 'traffic_report_id': '0F23EB04FA3D66BCE3CB03DE0629AC1B4FD32BBB_1692834818', 'date_time': '2023-08-23 23:53:38+00:00', 'issue_reported': 'crash urgent', 'location': 'POINT(-97.742505 30.443741)', 'latitude': '30.443741', 'longitude': '-97.742505', 'address': '6101-6217 mc neil dr', 'weekday': 'Wednesday', 'date': '2023-08-23', 'time': '23:53:38'})]
[2023-08-30T20:05:59.323+0000] {subprocess.py:93} INFO - (Background on this error at: https://sqlalche.me/e/14/f405)
[2023-08-30T20:05:59.333+0000] {subprocess.py:97} INFO - Command exited with return code 1
[2023-08-30T20:05:59.351+0000] {taskinstance.py:1943} ERROR - Task failed with exception
Traceback (most recent call last):
  File "/home/airflow/.local/lib/python3.8/site-packages/airflow/operators/bash.py", line 210, in execute
    raise AirflowException(
airflow.exceptions.AirflowException: Bash command failed. The command returned a non-zero exit code 1.
[2023-08-30T20:05:59.355+0000] {taskinstance.py:1400} INFO - Marking task as UP_FOR_RETRY. dag_id=traffic_report, task_id=export_data_to_db, execution_date=20230824T000000, start_date=20230830T200558, end_date=20230830T200559
[2023-08-30T20:05:59.368+0000] {standard_task_runner.py:104} ERROR - Failed to execute job 24 for task export_data_to_db (Bash command failed. The command returned a non-zero exit code 1.; 540)
[2023-08-30T20:05:59.386+0000] {local_task_job_runner.py:228} INFO - Task exited with return code 1
[2023-08-30T20:05:59.403+0000] {taskinstance.py:2784} INFO - 0 downstream tasks scheduled from follow-on schedule check
[2023-08-30T20:33:59.759+0000] {logging_mixin.py:151} WARNING - /home/***/.local/lib/python3.8/site-packages/***/utils/sqlalchemy.py:124 DeprecationWarning: The sql_alchemy_conn option in [core] has been moved to the sql_alchemy_conn option in [database] - the old setting has been used, but please update your config.
[2023-08-30T20:33:59.771+0000] {taskinstance.py:1159} INFO - Dependencies all met for dep_context=non-requeueable deps ti=<TaskInstance: traffic_report.export_data_to_db scheduled__2023-08-24T00:00:00+00:00 [queued]>
[2023-08-30T20:33:59.787+0000] {taskinstance.py:1159} INFO - Dependencies all met for dep_context=requeueable deps ti=<TaskInstance: traffic_report.export_data_to_db scheduled__2023-08-24T00:00:00+00:00 [queued]>
[2023-08-30T20:33:59.788+0000] {taskinstance.py:1361} INFO - Starting attempt 1 of 2
[2023-08-30T20:33:59.815+0000] {taskinstance.py:1382} INFO - Executing <Task(BashOperator): export_data_to_db> on 2023-08-24 00:00:00+00:00
[2023-08-30T20:33:59.821+0000] {standard_task_runner.py:57} INFO - Started process 341 to run task
[2023-08-30T20:33:59.828+0000] {standard_task_runner.py:84} INFO - Running: ['***', 'tasks', 'run', 'traffic_report', 'export_data_to_db', 'scheduled__2023-08-24T00:00:00+00:00', '--job-id', '21', '--raw', '--subdir', 'DAGS_FOLDER/traffic_dag.py', '--cfg-path', '/tmp/tmphvnrnsjy']
[2023-08-30T20:33:59.833+0000] {standard_task_runner.py:85} INFO - Job 21: Subtask export_data_to_db
[2023-08-30T20:33:59.852+0000] {logging_mixin.py:151} WARNING - /home/***/.local/lib/python3.8/site-packages/***/settings.py:195 DeprecationWarning: The sql_alchemy_conn option in [core] has been moved to the sql_alchemy_conn option in [database] - the old setting has been used, but please update your config.
[2023-08-30T20:33:59.928+0000] {task_command.py:415} INFO - Running <TaskInstance: traffic_report.export_data_to_db scheduled__2023-08-24T00:00:00+00:00 [running]> on host 961f38e8363e
[2023-08-30T20:33:59.945+0000] {logging_mixin.py:151} WARNING - /home/***/.local/lib/python3.8/site-packages/***/utils/sqlalchemy.py:124 DeprecationWarning: The sql_alchemy_conn option in [core] has been moved to the sql_alchemy_conn option in [database] - the old setting has been used, but please update your config.
[2023-08-30T20:34:00.041+0000] {taskinstance.py:1660} INFO - Exporting env vars: AIRFLOW_CTX_DAG_OWNER='***' AIRFLOW_CTX_DAG_ID='traffic_report' AIRFLOW_CTX_TASK_ID='export_data_to_db' AIRFLOW_CTX_EXECUTION_DATE='2023-08-24T00:00:00+00:00' AIRFLOW_CTX_TRY_NUMBER='1' AIRFLOW_CTX_DAG_RUN_ID='scheduled__2023-08-24T00:00:00+00:00'
[2023-08-30T20:34:00.045+0000] {subprocess.py:63} INFO - Tmp dir root location: /tmp
[2023-08-30T20:34:00.047+0000] {subprocess.py:75} INFO - Running command: ['/bin/bash', '-c', 'python /opt/***/dags/data_to_db.py --date 2023-08-24 --connection postgresql+psycopg2://***:***@postgres/***']
[2023-08-30T20:34:00.073+0000] {subprocess.py:86} INFO - Output:
[2023-08-30T20:34:01.060+0000] {subprocess.py:93} INFO - Traceback (most recent call last):
[2023-08-30T20:34:01.062+0000] {subprocess.py:93} INFO -   File "/home/***/.local/lib/python3.8/site-packages/sqlalchemy/engine/base.py", line 1890, in _execute_context
[2023-08-30T20:34:01.063+0000] {subprocess.py:93} INFO -     self.dialect.do_executemany(
[2023-08-30T20:34:01.064+0000] {subprocess.py:93} INFO -   File "/home/***/.local/lib/python3.8/site-packages/sqlalchemy/dialects/postgresql/psycopg2.py", line 982, in do_executemany
[2023-08-30T20:34:01.071+0000] {subprocess.py:93} INFO -     context._psycopg2_fetched_rows = xtras.execute_values(
[2023-08-30T20:34:01.075+0000] {subprocess.py:93} INFO -   File "/home/***/.local/lib/python3.8/site-packages/psycopg2/extras.py", line 1299, in execute_values
[2023-08-30T20:34:01.078+0000] {subprocess.py:93} INFO -     cur.execute(b''.join(parts))
[2023-08-30T20:34:01.079+0000] {subprocess.py:93} INFO - psycopg2.errors.UndefinedFunction: function st_geomfromewkt(unknown) does not exist
[2023-08-30T20:34:01.081+0000] {subprocess.py:93} INFO - LINE 1: ...3', '2023-08-23 00:03:13+00:00', 'crash service', ST_GeomFro...
[2023-08-30T20:34:01.086+0000] {subprocess.py:93} INFO -                                                              ^
[2023-08-30T20:34:01.087+0000] {subprocess.py:93} INFO - HINT:  No function matches the given name and argument types. You might need to add explicit type casts.
[2023-08-30T20:34:01.089+0000] {subprocess.py:93} INFO - 
[2023-08-30T20:34:01.090+0000] {subprocess.py:93} INFO - 
[2023-08-30T20:34:01.091+0000] {subprocess.py:93} INFO - The above exception was the direct cause of the following exception:
[2023-08-30T20:34:01.093+0000] {subprocess.py:93} INFO - 
[2023-08-30T20:34:01.094+0000] {subprocess.py:93} INFO - Traceback (most recent call last):
[2023-08-30T20:34:01.095+0000] {subprocess.py:93} INFO -   File "/opt/***/dags/data_to_db.py", line 50, in <module>
[2023-08-30T20:34:01.097+0000] {subprocess.py:93} INFO -     main(args.date, args.connection)
[2023-08-30T20:34:01.099+0000] {subprocess.py:93} INFO -   File "/opt/***/dags/data_to_db.py", line 41, in main
[2023-08-30T20:34:01.102+0000] {subprocess.py:93} INFO -     session.bulk_save_objects(data_insert)
[2023-08-30T20:34:01.106+0000] {subprocess.py:93} INFO -   File "/home/***/.local/lib/python3.8/site-packages/sqlalchemy/orm/session.py", line 3705, in bulk_save_objects
[2023-08-30T20:34:01.109+0000] {subprocess.py:93} INFO -     self._bulk_save_mappings(
[2023-08-30T20:34:01.112+0000] {subprocess.py:93} INFO -   File "/home/***/.local/lib/python3.8/site-packages/sqlalchemy/orm/session.py", line 3913, in _bulk_save_mappings
[2023-08-30T20:34:01.113+0000] {subprocess.py:93} INFO -     transaction.rollback(_capture_exception=True)
[2023-08-30T20:34:01.115+0000] {subprocess.py:93} INFO -   File "/home/***/.local/lib/python3.8/site-packages/sqlalchemy/util/langhelpers.py", line 70, in __exit__
[2023-08-30T20:34:01.116+0000] {subprocess.py:93} INFO -     compat.raise_(
[2023-08-30T20:34:01.117+0000] {subprocess.py:93} INFO -   File "/home/***/.local/lib/python3.8/site-packages/sqlalchemy/util/compat.py", line 211, in raise_
[2023-08-30T20:34:01.118+0000] {subprocess.py:93} INFO -     raise exception
[2023-08-30T20:34:01.119+0000] {subprocess.py:93} INFO -   File "/home/***/.local/lib/python3.8/site-packages/sqlalchemy/orm/session.py", line 3901, in _bulk_save_mappings
[2023-08-30T20:34:01.123+0000] {subprocess.py:93} INFO -     persistence._bulk_insert(
[2023-08-30T20:34:01.139+0000] {subprocess.py:93} INFO -   File "/home/***/.local/lib/python3.8/site-packages/sqlalchemy/orm/persistence.py", line 107, in _bulk_insert
[2023-08-30T20:34:01.145+0000] {subprocess.py:93} INFO -     _emit_insert_statements(
[2023-08-30T20:34:01.147+0000] {subprocess.py:93} INFO -   File "/home/***/.local/lib/python3.8/site-packages/sqlalchemy/orm/persistence.py", line 1097, in _emit_insert_statements
[2023-08-30T20:34:01.150+0000] {subprocess.py:93} INFO -     c = connection._execute_20(
[2023-08-30T20:34:01.151+0000] {subprocess.py:93} INFO -   File "/home/***/.local/lib/python3.8/site-packages/sqlalchemy/engine/base.py", line 1710, in _execute_20
[2023-08-30T20:34:01.155+0000] {subprocess.py:93} INFO -     return meth(self, args_10style, kwargs_10style, execution_options)
[2023-08-30T20:34:01.158+0000] {subprocess.py:93} INFO -   File "/home/***/.local/lib/python3.8/site-packages/sqlalchemy/sql/elements.py", line 334, in _execute_on_connection
[2023-08-30T20:34:01.160+0000] {subprocess.py:93} INFO -     return connection._execute_clauseelement(
[2023-08-30T20:34:01.161+0000] {subprocess.py:93} INFO -   File "/home/***/.local/lib/python3.8/site-packages/sqlalchemy/engine/base.py", line 1577, in _execute_clauseelement
[2023-08-30T20:34:01.163+0000] {subprocess.py:93} INFO -     ret = self._execute_context(
[2023-08-30T20:34:01.165+0000] {subprocess.py:93} INFO -   File "/home/***/.local/lib/python3.8/site-packages/sqlalchemy/engine/base.py", line 1953, in _execute_context
[2023-08-30T20:34:01.167+0000] {subprocess.py:93} INFO -     self._handle_dbapi_exception(
[2023-08-30T20:34:01.172+0000] {subprocess.py:93} INFO -   File "/home/***/.local/lib/python3.8/site-packages/sqlalchemy/engine/base.py", line 2134, in _handle_dbapi_exception
[2023-08-30T20:34:01.174+0000] {subprocess.py:93} INFO -     util.raise_(
[2023-08-30T20:34:01.176+0000] {subprocess.py:93} INFO -   File "/home/***/.local/lib/python3.8/site-packages/sqlalchemy/util/compat.py", line 211, in raise_
[2023-08-30T20:34:01.177+0000] {subprocess.py:93} INFO -     raise exception
[2023-08-30T20:34:01.180+0000] {subprocess.py:93} INFO -   File "/home/***/.local/lib/python3.8/site-packages/sqlalchemy/engine/base.py", line 1890, in _execute_context
[2023-08-30T20:34:01.183+0000] {subprocess.py:93} INFO -     self.dialect.do_executemany(
[2023-08-30T20:34:01.185+0000] {subprocess.py:93} INFO -   File "/home/***/.local/lib/python3.8/site-packages/sqlalchemy/dialects/postgresql/psycopg2.py", line 982, in do_executemany
[2023-08-30T20:34:01.186+0000] {subprocess.py:93} INFO -     context._psycopg2_fetched_rows = xtras.execute_values(
[2023-08-30T20:34:01.187+0000] {subprocess.py:93} INFO -   File "/home/***/.local/lib/python3.8/site-packages/psycopg2/extras.py", line 1299, in execute_values
[2023-08-30T20:34:01.193+0000] {subprocess.py:93} INFO -     cur.execute(b''.join(parts))
[2023-08-30T20:34:01.195+0000] {subprocess.py:93} INFO - sqlalchemy.exc.ProgrammingError: (psycopg2.errors.UndefinedFunction) function st_geomfromewkt(unknown) does not exist
[2023-08-30T20:34:01.197+0000] {subprocess.py:93} INFO - LINE 1: ...3', '2023-08-23 00:03:13+00:00', 'crash service', ST_GeomFro...
[2023-08-30T20:34:01.200+0000] {subprocess.py:93} INFO -                                                              ^
[2023-08-30T20:34:01.205+0000] {subprocess.py:93} INFO - HINT:  No function matches the given name and argument types. You might need to add explicit type casts.
[2023-08-30T20:34:01.209+0000] {subprocess.py:93} INFO - 
[2023-08-30T20:34:01.213+0000] {subprocess.py:93} INFO - [SQL: INSERT INTO traffic_report (timestamp, traffic_report_id, date_time, issue_reported, location, latitude, longitude, address, weekday, date, time) VALUES (%(timestamp)s, %(traffic_report_id)s, %(date_time)s, %(issue_reported)s, ST_GeomFromEWKT(%(location)s), %(latitude)s, %(longitude)s, %(address)s, %(weekday)s, %(date)s, %(time)s)]
[2023-08-30T20:34:01.216+0000] {subprocess.py:93} INFO - [parameters: ({'timestamp': '1692748993000000000', 'traffic_report_id': '9A6B59DA46371D86EB75259C956AEE4B580C0119_1692748993', 'date_time': '2023-08-23 00:03:13+00:00', 'issue_reported': 'crash service', 'location': 'POINT(-97.738909 30.193169)', 'latitude': '30.193169', 'longitude': '-97.738909', 'address': 'nuckols crossing rd / e stassney ln', 'weekday': 'Wednesday', 'date': '2023-08-23', 'time': '00:03:13'}, {'timestamp': '1692749009000000000', 'traffic_report_id': '634DE0A75896238BFD3F5886F6062F00DA3D0B56_1692749009', 'date_time': '2023-08-23 00:03:29+00:00', 'issue_reported': 'traffic hazard', 'location': 'POINT(-97.790941 30.167145)', 'latitude': '30.167145', 'longitude': '-97.790941', 'address': 'w slaughter ln / cullen ln', 'weekday': 'Wednesday', 'date': '2023-08-23', 'time': '00:03:29'}, {'timestamp': '1692749887000000000', 'traffic_report_id': 'EBA90709ED04EB27E4A042727D7DD308E44389E4_1692749887', 'date_time': '2023-08-23 00:18:07+00:00', 'issue_reported': 'crash urgent', 'location': 'POINT(-97.691583 30.370783)', 'latitude': '30.370783', 'longitude': '-97.691583', 'address': '600 masterson pass', 'weekday': 'Wednesday', 'date': '2023-08-23', 'time': '00:18:07'}, {'timestamp': '1692751163000000000', 'traffic_report_id': '9D634E9D726305D5B9A7D2E527F6C49DD3603F4F_1692751163', 'date_time': '2023-08-23 00:39:23+00:00', 'issue_reported': 'collision with injury', 'location': 'POINT(-97.61178 30.102795)', 'latitude': '30.102795', 'longitude': '-97.61178', 'address': 'fm 812 rd / doyle rd', 'weekday': 'Wednesday', 'date': '2023-08-23', 'time': '00:39:23'}, {'timestamp': '1692751987000000000', 'traffic_report_id': '301F839B74B67350B1BDC01050369AEC1F36E0D2_1692751987', 'date_time': '2023-08-23 00:53:07+00:00', 'issue_reported': 'traffic hazard', 'location': 'POINT(-97.691413 30.328075)', 'latitude': '30.328075', 'longitude': '-97.691413', 'address': '1308 fairbanks dr', 'weekday': 'Wednesday', 'date': '2023-08-23', 'time': '00:53:07'}, {'timestamp': '1692752143000000000', 'traffic_report_id': '2B80090196FBBD61985EA7F2FC5C2F6AA4E1F134_1692752143', 'date_time': '2023-08-23 00:55:43+00:00', 'issue_reported': 'traffic hazard', 'location': 'POINT(-97.728493 30.235959)', 'latitude': '30.235959', 'longitude': '-97.728493', 'address': 'burton dr / woodland ave', 'weekday': 'Wednesday', 'date': '2023-08-23', 'time': '00:55:43'}, {'timestamp': '1692753489000000000', 'traffic_report_id': '1E768A21723E530122240FA219BFF8C3365F40B2_1692753489', 'date_time': '2023-08-23 01:18:09+00:00', 'issue_reported': 'traffic hazard', 'location': 'POINT(-97.708554 30.310245)', 'latitude': '30.310245', 'longitude': '-97.708554', 'address': '5201-5217 cameron rd', 'weekday': 'Wednesday', 'date': '2023-08-23', 'time': '01:18:09'}, {'timestamp': '1692753535000000000', 'traffic_report_id': '509F6CCBC5A85A0D07F32BFF32186163BA8301B8_1692753535', 'date_time': '2023-08-23 01:18:55+00:00', 'issue_reported': 'crash service', 'location': 'POINT(-97.73408 30.26906)', 'latitude': '30.26906', 'longitude': '-97.73408', 'address': '900 n ih 35 svrd sb', 'weekday': 'Wednesday', 'date': '2023-08-23', 'time': '01:18:55'}  ... displaying 10 of 146 total bound parameter sets ...  {'timestamp': '1692834773000000000', 'traffic_report_id': '3C457CE18C2E37A4437E0201076AD638367EF0EA_1692834773', 'date_time': '2023-08-23 23:52:53+00:00', 'issue_reported': 'crash service', 'location': 'POINT(-97.774726 30.183637)', 'latitude': '30.183637', 'longitude': '-97.774726', 'address': '7301 s ih 35 svrd nb', 'weekday': 'Wednesday', 'date': '2023-08-23', 'time': '23:52:53'}, {'timestamp': '1692834818000000000', 'traffic_report_id': '0F23EB04FA3D66BCE3CB03DE0629AC1B4FD32BBB_1692834818', 'date_time': '2023-08-23 23:53:38+00:00', 'issue_reported': 'crash urgent', 'location': 'POINT(-97.742505 30.443741)', 'latitude': '30.443741', 'longitude': '-97.742505', 'address': '6101-6217 mc neil dr', 'weekday': 'Wednesday', 'date': '2023-08-23', 'time': '23:53:38'})]
[2023-08-30T20:34:01.218+0000] {subprocess.py:93} INFO - (Background on this error at: https://sqlalche.me/e/14/f405)
[2023-08-30T20:34:01.239+0000] {subprocess.py:97} INFO - Command exited with return code 1
[2023-08-30T20:34:01.272+0000] {taskinstance.py:1943} ERROR - Task failed with exception
Traceback (most recent call last):
  File "/home/airflow/.local/lib/python3.8/site-packages/airflow/operators/bash.py", line 210, in execute
    raise AirflowException(
airflow.exceptions.AirflowException: Bash command failed. The command returned a non-zero exit code 1.
[2023-08-30T20:34:01.284+0000] {taskinstance.py:1400} INFO - Marking task as UP_FOR_RETRY. dag_id=traffic_report, task_id=export_data_to_db, execution_date=20230824T000000, start_date=20230830T203359, end_date=20230830T203401
[2023-08-30T20:34:01.348+0000] {standard_task_runner.py:104} ERROR - Failed to execute job 21 for task export_data_to_db (Bash command failed. The command returned a non-zero exit code 1.; 341)
[2023-08-30T20:34:01.366+0000] {local_task_job_runner.py:228} INFO - Task exited with return code 1
[2023-08-30T20:34:01.422+0000] {taskinstance.py:2784} INFO - 0 downstream tasks scheduled from follow-on schedule check
[2023-08-30T20:48:32.607+0000] {logging_mixin.py:151} WARNING - /home/***/.local/lib/python3.8/site-packages/***/utils/sqlalchemy.py:124 DeprecationWarning: The sql_alchemy_conn option in [core] has been moved to the sql_alchemy_conn option in [database] - the old setting has been used, but please update your config.
[2023-08-30T20:48:32.618+0000] {taskinstance.py:1159} INFO - Dependencies all met for dep_context=non-requeueable deps ti=<TaskInstance: traffic_report.export_data_to_db scheduled__2023-08-24T00:00:00+00:00 [queued]>
[2023-08-30T20:48:32.629+0000] {taskinstance.py:1159} INFO - Dependencies all met for dep_context=requeueable deps ti=<TaskInstance: traffic_report.export_data_to_db scheduled__2023-08-24T00:00:00+00:00 [queued]>
[2023-08-30T20:48:32.631+0000] {taskinstance.py:1361} INFO - Starting attempt 1 of 2
[2023-08-30T20:48:32.643+0000] {taskinstance.py:1382} INFO - Executing <Task(BashOperator): export_data_to_db> on 2023-08-24 00:00:00+00:00
[2023-08-30T20:48:32.651+0000] {standard_task_runner.py:57} INFO - Started process 393 to run task
[2023-08-30T20:48:32.662+0000] {standard_task_runner.py:84} INFO - Running: ['***', 'tasks', 'run', 'traffic_report', 'export_data_to_db', 'scheduled__2023-08-24T00:00:00+00:00', '--job-id', '21', '--raw', '--subdir', 'DAGS_FOLDER/traffic_dag.py', '--cfg-path', '/tmp/tmp73l6mjow']
[2023-08-30T20:48:32.665+0000] {standard_task_runner.py:85} INFO - Job 21: Subtask export_data_to_db
[2023-08-30T20:48:32.685+0000] {logging_mixin.py:151} WARNING - /home/***/.local/lib/python3.8/site-packages/***/settings.py:195 DeprecationWarning: The sql_alchemy_conn option in [core] has been moved to the sql_alchemy_conn option in [database] - the old setting has been used, but please update your config.
[2023-08-30T20:48:32.737+0000] {task_command.py:415} INFO - Running <TaskInstance: traffic_report.export_data_to_db scheduled__2023-08-24T00:00:00+00:00 [running]> on host 8f66711a2898
[2023-08-30T20:48:32.762+0000] {logging_mixin.py:151} WARNING - /home/***/.local/lib/python3.8/site-packages/***/utils/sqlalchemy.py:124 DeprecationWarning: The sql_alchemy_conn option in [core] has been moved to the sql_alchemy_conn option in [database] - the old setting has been used, but please update your config.
[2023-08-30T20:48:32.840+0000] {taskinstance.py:1660} INFO - Exporting env vars: AIRFLOW_CTX_DAG_OWNER='***' AIRFLOW_CTX_DAG_ID='traffic_report' AIRFLOW_CTX_TASK_ID='export_data_to_db' AIRFLOW_CTX_EXECUTION_DATE='2023-08-24T00:00:00+00:00' AIRFLOW_CTX_TRY_NUMBER='1' AIRFLOW_CTX_DAG_RUN_ID='scheduled__2023-08-24T00:00:00+00:00'
[2023-08-30T20:48:32.844+0000] {subprocess.py:63} INFO - Tmp dir root location: /tmp
[2023-08-30T20:48:32.848+0000] {subprocess.py:75} INFO - Running command: ['/bin/bash', '-c', 'python /opt/***/dags/data_to_db.py --date 2023-08-24 --connection postgresql+psycopg2://***:***@postgres/***']
[2023-08-30T20:48:32.861+0000] {subprocess.py:86} INFO - Output:
[2023-08-30T20:48:33.514+0000] {subprocess.py:93} INFO - Traceback (most recent call last):
[2023-08-30T20:48:33.515+0000] {subprocess.py:93} INFO -   File "/home/***/.local/lib/python3.8/site-packages/sqlalchemy/engine/base.py", line 1890, in _execute_context
[2023-08-30T20:48:33.516+0000] {subprocess.py:93} INFO -     self.dialect.do_executemany(
[2023-08-30T20:48:33.517+0000] {subprocess.py:93} INFO -   File "/home/***/.local/lib/python3.8/site-packages/sqlalchemy/dialects/postgresql/psycopg2.py", line 982, in do_executemany
[2023-08-30T20:48:33.518+0000] {subprocess.py:93} INFO -     context._psycopg2_fetched_rows = xtras.execute_values(
[2023-08-30T20:48:33.520+0000] {subprocess.py:93} INFO -   File "/home/***/.local/lib/python3.8/site-packages/psycopg2/extras.py", line 1299, in execute_values
[2023-08-30T20:48:33.523+0000] {subprocess.py:93} INFO -     cur.execute(b''.join(parts))
[2023-08-30T20:48:33.525+0000] {subprocess.py:93} INFO - psycopg2.errors.NumericValueOutOfRange: value "1692748993000000000" is out of range for type integer
[2023-08-30T20:48:33.532+0000] {subprocess.py:93} INFO - LINE 1: ... longitude, address, weekday, date, time) VALUES ('169274899...
[2023-08-30T20:48:33.537+0000] {subprocess.py:93} INFO -                                                              ^
[2023-08-30T20:48:33.538+0000] {subprocess.py:93} INFO - 
[2023-08-30T20:48:33.539+0000] {subprocess.py:93} INFO - 
[2023-08-30T20:48:33.542+0000] {subprocess.py:93} INFO - The above exception was the direct cause of the following exception:
[2023-08-30T20:48:33.543+0000] {subprocess.py:93} INFO - 
[2023-08-30T20:48:33.543+0000] {subprocess.py:93} INFO - Traceback (most recent call last):
[2023-08-30T20:48:33.545+0000] {subprocess.py:93} INFO -   File "/opt/***/dags/data_to_db.py", line 49, in <module>
[2023-08-30T20:48:33.546+0000] {subprocess.py:93} INFO -     main(args.date, args.connection)
[2023-08-30T20:48:33.550+0000] {subprocess.py:93} INFO -   File "/opt/***/dags/data_to_db.py", line 40, in main
[2023-08-30T20:48:33.552+0000] {subprocess.py:93} INFO -     session.bulk_save_objects(data_insert)
[2023-08-30T20:48:33.553+0000] {subprocess.py:93} INFO -   File "/home/***/.local/lib/python3.8/site-packages/sqlalchemy/orm/session.py", line 3705, in bulk_save_objects
[2023-08-30T20:48:33.555+0000] {subprocess.py:93} INFO -     self._bulk_save_mappings(
[2023-08-30T20:48:33.557+0000] {subprocess.py:93} INFO -   File "/home/***/.local/lib/python3.8/site-packages/sqlalchemy/orm/session.py", line 3913, in _bulk_save_mappings
[2023-08-30T20:48:33.559+0000] {subprocess.py:93} INFO -     transaction.rollback(_capture_exception=True)
[2023-08-30T20:48:33.559+0000] {subprocess.py:93} INFO -   File "/home/***/.local/lib/python3.8/site-packages/sqlalchemy/util/langhelpers.py", line 70, in __exit__
[2023-08-30T20:48:33.561+0000] {subprocess.py:93} INFO -     compat.raise_(
[2023-08-30T20:48:33.565+0000] {subprocess.py:93} INFO -   File "/home/***/.local/lib/python3.8/site-packages/sqlalchemy/util/compat.py", line 211, in raise_
[2023-08-30T20:48:33.566+0000] {subprocess.py:93} INFO -     raise exception
[2023-08-30T20:48:33.567+0000] {subprocess.py:93} INFO -   File "/home/***/.local/lib/python3.8/site-packages/sqlalchemy/orm/session.py", line 3901, in _bulk_save_mappings
[2023-08-30T20:48:33.569+0000] {subprocess.py:93} INFO -     persistence._bulk_insert(
[2023-08-30T20:48:33.571+0000] {subprocess.py:93} INFO -   File "/home/***/.local/lib/python3.8/site-packages/sqlalchemy/orm/persistence.py", line 107, in _bulk_insert
[2023-08-30T20:48:33.572+0000] {subprocess.py:93} INFO -     _emit_insert_statements(
[2023-08-30T20:48:33.576+0000] {subprocess.py:93} INFO -   File "/home/***/.local/lib/python3.8/site-packages/sqlalchemy/orm/persistence.py", line 1097, in _emit_insert_statements
[2023-08-30T20:48:33.579+0000] {subprocess.py:93} INFO -     c = connection._execute_20(
[2023-08-30T20:48:33.583+0000] {subprocess.py:93} INFO -   File "/home/***/.local/lib/python3.8/site-packages/sqlalchemy/engine/base.py", line 1710, in _execute_20
[2023-08-30T20:48:33.585+0000] {subprocess.py:93} INFO -     return meth(self, args_10style, kwargs_10style, execution_options)
[2023-08-30T20:48:33.586+0000] {subprocess.py:93} INFO -   File "/home/***/.local/lib/python3.8/site-packages/sqlalchemy/sql/elements.py", line 334, in _execute_on_connection
[2023-08-30T20:48:33.587+0000] {subprocess.py:93} INFO -     return connection._execute_clauseelement(
[2023-08-30T20:48:33.589+0000] {subprocess.py:93} INFO -   File "/home/***/.local/lib/python3.8/site-packages/sqlalchemy/engine/base.py", line 1577, in _execute_clauseelement
[2023-08-30T20:48:33.590+0000] {subprocess.py:93} INFO -     ret = self._execute_context(
[2023-08-30T20:48:33.591+0000] {subprocess.py:93} INFO -   File "/home/***/.local/lib/python3.8/site-packages/sqlalchemy/engine/base.py", line 1953, in _execute_context
[2023-08-30T20:48:33.593+0000] {subprocess.py:93} INFO -     self._handle_dbapi_exception(
[2023-08-30T20:48:33.595+0000] {subprocess.py:93} INFO -   File "/home/***/.local/lib/python3.8/site-packages/sqlalchemy/engine/base.py", line 2134, in _handle_dbapi_exception
[2023-08-30T20:48:33.597+0000] {subprocess.py:93} INFO -     util.raise_(
[2023-08-30T20:48:33.599+0000] {subprocess.py:93} INFO -   File "/home/***/.local/lib/python3.8/site-packages/sqlalchemy/util/compat.py", line 211, in raise_
[2023-08-30T20:48:33.601+0000] {subprocess.py:93} INFO -     raise exception
[2023-08-30T20:48:33.602+0000] {subprocess.py:93} INFO -   File "/home/***/.local/lib/python3.8/site-packages/sqlalchemy/engine/base.py", line 1890, in _execute_context
[2023-08-30T20:48:33.606+0000] {subprocess.py:93} INFO -     self.dialect.do_executemany(
[2023-08-30T20:48:33.609+0000] {subprocess.py:93} INFO -   File "/home/***/.local/lib/python3.8/site-packages/sqlalchemy/dialects/postgresql/psycopg2.py", line 982, in do_executemany
[2023-08-30T20:48:33.611+0000] {subprocess.py:93} INFO -     context._psycopg2_fetched_rows = xtras.execute_values(
[2023-08-30T20:48:33.612+0000] {subprocess.py:93} INFO -   File "/home/***/.local/lib/python3.8/site-packages/psycopg2/extras.py", line 1299, in execute_values
[2023-08-30T20:48:33.613+0000] {subprocess.py:93} INFO -     cur.execute(b''.join(parts))
[2023-08-30T20:48:33.616+0000] {subprocess.py:93} INFO - sqlalchemy.exc.DataError: (psycopg2.errors.NumericValueOutOfRange) value "1692748993000000000" is out of range for type integer
[2023-08-30T20:48:33.618+0000] {subprocess.py:93} INFO - LINE 1: ... longitude, address, weekday, date, time) VALUES ('169274899...
[2023-08-30T20:48:33.620+0000] {subprocess.py:93} INFO -                                                              ^
[2023-08-30T20:48:33.621+0000] {subprocess.py:93} INFO - 
[2023-08-30T20:48:33.625+0000] {subprocess.py:93} INFO - [SQL: INSERT INTO traffic_report (timestamp, traffic_report_id, date_time, issue_reported, latitude, longitude, address, weekday, date, time) VALUES (%(timestamp)s, %(traffic_report_id)s, %(date_time)s, %(issue_reported)s, %(latitude)s, %(longitude)s, %(address)s, %(weekday)s, %(date)s, %(time)s)]
[2023-08-30T20:48:33.637+0000] {subprocess.py:93} INFO - [parameters: ({'timestamp': '1692748993000000000', 'traffic_report_id': '9A6B59DA46371D86EB75259C956AEE4B580C0119_1692748993', 'date_time': '2023-08-23 00:03:13+00:00', 'issue_reported': 'crash service', 'latitude': '30.193169', 'longitude': '-97.738909', 'address': 'nuckols crossing rd / e stassney ln', 'weekday': 'Wednesday', 'date': '2023-08-23', 'time': '00:03:13'}, {'timestamp': '1692749009000000000', 'traffic_report_id': '634DE0A75896238BFD3F5886F6062F00DA3D0B56_1692749009', 'date_time': '2023-08-23 00:03:29+00:00', 'issue_reported': 'traffic hazard', 'latitude': '30.167145', 'longitude': '-97.790941', 'address': 'w slaughter ln / cullen ln', 'weekday': 'Wednesday', 'date': '2023-08-23', 'time': '00:03:29'}, {'timestamp': '1692749887000000000', 'traffic_report_id': 'EBA90709ED04EB27E4A042727D7DD308E44389E4_1692749887', 'date_time': '2023-08-23 00:18:07+00:00', 'issue_reported': 'crash urgent', 'latitude': '30.370783', 'longitude': '-97.691583', 'address': '600 masterson pass', 'weekday': 'Wednesday', 'date': '2023-08-23', 'time': '00:18:07'}, {'timestamp': '1692751163000000000', 'traffic_report_id': '9D634E9D726305D5B9A7D2E527F6C49DD3603F4F_1692751163', 'date_time': '2023-08-23 00:39:23+00:00', 'issue_reported': 'collision with injury', 'latitude': '30.102795', 'longitude': '-97.61178', 'address': 'fm 812 rd / doyle rd', 'weekday': 'Wednesday', 'date': '2023-08-23', 'time': '00:39:23'}, {'timestamp': '1692751987000000000', 'traffic_report_id': '301F839B74B67350B1BDC01050369AEC1F36E0D2_1692751987', 'date_time': '2023-08-23 00:53:07+00:00', 'issue_reported': 'traffic hazard', 'latitude': '30.328075', 'longitude': '-97.691413', 'address': '1308 fairbanks dr', 'weekday': 'Wednesday', 'date': '2023-08-23', 'time': '00:53:07'}, {'timestamp': '1692752143000000000', 'traffic_report_id': '2B80090196FBBD61985EA7F2FC5C2F6AA4E1F134_1692752143', 'date_time': '2023-08-23 00:55:43+00:00', 'issue_reported': 'traffic hazard', 'latitude': '30.235959', 'longitude': '-97.728493', 'address': 'burton dr / woodland ave', 'weekday': 'Wednesday', 'date': '2023-08-23', 'time': '00:55:43'}, {'timestamp': '1692753489000000000', 'traffic_report_id': '1E768A21723E530122240FA219BFF8C3365F40B2_1692753489', 'date_time': '2023-08-23 01:18:09+00:00', 'issue_reported': 'traffic hazard', 'latitude': '30.310245', 'longitude': '-97.708554', 'address': '5201-5217 cameron rd', 'weekday': 'Wednesday', 'date': '2023-08-23', 'time': '01:18:09'}, {'timestamp': '1692753535000000000', 'traffic_report_id': '509F6CCBC5A85A0D07F32BFF32186163BA8301B8_1692753535', 'date_time': '2023-08-23 01:18:55+00:00', 'issue_reported': 'crash service', 'latitude': '30.26906', 'longitude': '-97.73408', 'address': '900 n ih 35 svrd sb', 'weekday': 'Wednesday', 'date': '2023-08-23', 'time': '01:18:55'}  ... displaying 10 of 146 total bound parameter sets ...  {'timestamp': '1692834773000000000', 'traffic_report_id': '3C457CE18C2E37A4437E0201076AD638367EF0EA_1692834773', 'date_time': '2023-08-23 23:52:53+00:00', 'issue_reported': 'crash service', 'latitude': '30.183637', 'longitude': '-97.774726', 'address': '7301 s ih 35 svrd nb', 'weekday': 'Wednesday', 'date': '2023-08-23', 'time': '23:52:53'}, {'timestamp': '1692834818000000000', 'traffic_report_id': '0F23EB04FA3D66BCE3CB03DE0629AC1B4FD32BBB_1692834818', 'date_time': '2023-08-23 23:53:38+00:00', 'issue_reported': 'crash urgent', 'latitude': '30.443741', 'longitude': '-97.742505', 'address': '6101-6217 mc neil dr', 'weekday': 'Wednesday', 'date': '2023-08-23', 'time': '23:53:38'})]
[2023-08-30T20:48:33.652+0000] {subprocess.py:93} INFO - (Background on this error at: https://sqlalche.me/e/14/9h9h)
[2023-08-30T20:48:33.666+0000] {subprocess.py:97} INFO - Command exited with return code 1
[2023-08-30T20:48:33.693+0000] {taskinstance.py:1943} ERROR - Task failed with exception
Traceback (most recent call last):
  File "/home/airflow/.local/lib/python3.8/site-packages/airflow/operators/bash.py", line 210, in execute
    raise AirflowException(
airflow.exceptions.AirflowException: Bash command failed. The command returned a non-zero exit code 1.
[2023-08-30T20:48:33.697+0000] {taskinstance.py:1400} INFO - Marking task as UP_FOR_RETRY. dag_id=traffic_report, task_id=export_data_to_db, execution_date=20230824T000000, start_date=20230830T204832, end_date=20230830T204833
[2023-08-30T20:48:33.710+0000] {standard_task_runner.py:104} ERROR - Failed to execute job 21 for task export_data_to_db (Bash command failed. The command returned a non-zero exit code 1.; 393)
[2023-08-30T20:48:33.757+0000] {local_task_job_runner.py:228} INFO - Task exited with return code 1
[2023-08-30T20:48:33.788+0000] {taskinstance.py:2784} INFO - 0 downstream tasks scheduled from follow-on schedule check
[2023-08-30T21:07:56.293+0000] {logging_mixin.py:151} WARNING - /home/***/.local/lib/python3.8/site-packages/***/utils/sqlalchemy.py:124 DeprecationWarning: The sql_alchemy_conn option in [core] has been moved to the sql_alchemy_conn option in [database] - the old setting has been used, but please update your config.
[2023-08-30T21:07:56.309+0000] {taskinstance.py:1159} INFO - Dependencies all met for dep_context=non-requeueable deps ti=<TaskInstance: traffic_report.export_data_to_db scheduled__2023-08-24T00:00:00+00:00 [queued]>
[2023-08-30T21:07:56.320+0000] {taskinstance.py:1159} INFO - Dependencies all met for dep_context=requeueable deps ti=<TaskInstance: traffic_report.export_data_to_db scheduled__2023-08-24T00:00:00+00:00 [queued]>
[2023-08-30T21:07:56.323+0000] {taskinstance.py:1361} INFO - Starting attempt 1 of 2
[2023-08-30T21:07:56.341+0000] {taskinstance.py:1382} INFO - Executing <Task(BashOperator): export_data_to_db> on 2023-08-24 00:00:00+00:00
[2023-08-30T21:07:56.345+0000] {standard_task_runner.py:57} INFO - Started process 368 to run task
[2023-08-30T21:07:56.354+0000] {standard_task_runner.py:84} INFO - Running: ['***', 'tasks', 'run', 'traffic_report', 'export_data_to_db', 'scheduled__2023-08-24T00:00:00+00:00', '--job-id', '21', '--raw', '--subdir', 'DAGS_FOLDER/traffic_dag.py', '--cfg-path', '/tmp/tmplpuqlro_']
[2023-08-30T21:07:56.357+0000] {standard_task_runner.py:85} INFO - Job 21: Subtask export_data_to_db
[2023-08-30T21:07:56.379+0000] {logging_mixin.py:151} WARNING - /home/***/.local/lib/python3.8/site-packages/***/settings.py:195 DeprecationWarning: The sql_alchemy_conn option in [core] has been moved to the sql_alchemy_conn option in [database] - the old setting has been used, but please update your config.
[2023-08-30T21:07:56.435+0000] {task_command.py:415} INFO - Running <TaskInstance: traffic_report.export_data_to_db scheduled__2023-08-24T00:00:00+00:00 [running]> on host cbc745b7550b
[2023-08-30T21:07:56.451+0000] {logging_mixin.py:151} WARNING - /home/***/.local/lib/python3.8/site-packages/***/utils/sqlalchemy.py:124 DeprecationWarning: The sql_alchemy_conn option in [core] has been moved to the sql_alchemy_conn option in [database] - the old setting has been used, but please update your config.
[2023-08-30T21:07:56.548+0000] {taskinstance.py:1660} INFO - Exporting env vars: AIRFLOW_CTX_DAG_OWNER='***' AIRFLOW_CTX_DAG_ID='traffic_report' AIRFLOW_CTX_TASK_ID='export_data_to_db' AIRFLOW_CTX_EXECUTION_DATE='2023-08-24T00:00:00+00:00' AIRFLOW_CTX_TRY_NUMBER='1' AIRFLOW_CTX_DAG_RUN_ID='scheduled__2023-08-24T00:00:00+00:00'
[2023-08-30T21:07:56.551+0000] {subprocess.py:63} INFO - Tmp dir root location: /tmp
[2023-08-30T21:07:56.553+0000] {subprocess.py:75} INFO - Running command: ['/bin/bash', '-c', 'python /opt/***/dags/data_to_db.py --date 2023-08-24 --connection postgresql+psycopg2://***:***@postgres/***']
[2023-08-30T21:07:56.568+0000] {subprocess.py:86} INFO - Output:
[2023-08-30T21:07:57.346+0000] {subprocess.py:93} INFO - Traceback (most recent call last):
[2023-08-30T21:07:57.350+0000] {subprocess.py:93} INFO -   File "/home/***/.local/lib/python3.8/site-packages/sqlalchemy/engine/base.py", line 1890, in _execute_context
[2023-08-30T21:07:57.353+0000] {subprocess.py:93} INFO -     self.dialect.do_executemany(
[2023-08-30T21:07:57.355+0000] {subprocess.py:93} INFO -   File "/home/***/.local/lib/python3.8/site-packages/sqlalchemy/dialects/postgresql/psycopg2.py", line 982, in do_executemany
[2023-08-30T21:07:57.357+0000] {subprocess.py:93} INFO -     context._psycopg2_fetched_rows = xtras.execute_values(
[2023-08-30T21:07:57.358+0000] {subprocess.py:93} INFO -   File "/home/***/.local/lib/python3.8/site-packages/psycopg2/extras.py", line 1299, in execute_values
[2023-08-30T21:07:57.362+0000] {subprocess.py:93} INFO -     cur.execute(b''.join(parts))
[2023-08-30T21:07:57.364+0000] {subprocess.py:93} INFO - psycopg2.errors.StringDataRightTruncation: value too long for type character varying(20)
[2023-08-30T21:07:57.371+0000] {subprocess.py:93} INFO - 
[2023-08-30T21:07:57.373+0000] {subprocess.py:93} INFO - 
[2023-08-30T21:07:57.377+0000] {subprocess.py:93} INFO - The above exception was the direct cause of the following exception:
[2023-08-30T21:07:57.379+0000] {subprocess.py:93} INFO - 
[2023-08-30T21:07:57.382+0000] {subprocess.py:93} INFO - Traceback (most recent call last):
[2023-08-30T21:07:57.384+0000] {subprocess.py:93} INFO -   File "/opt/***/dags/data_to_db.py", line 49, in <module>
[2023-08-30T21:07:57.385+0000] {subprocess.py:93} INFO -     main(args.date, args.connection)
[2023-08-30T21:07:57.386+0000] {subprocess.py:93} INFO -   File "/opt/***/dags/data_to_db.py", line 40, in main
[2023-08-30T21:07:57.387+0000] {subprocess.py:93} INFO -     session.bulk_save_objects(data_insert)
[2023-08-30T21:07:57.388+0000] {subprocess.py:93} INFO -   File "/home/***/.local/lib/python3.8/site-packages/sqlalchemy/orm/session.py", line 3705, in bulk_save_objects
[2023-08-30T21:07:57.390+0000] {subprocess.py:93} INFO -     self._bulk_save_mappings(
[2023-08-30T21:07:57.391+0000] {subprocess.py:93} INFO -   File "/home/***/.local/lib/python3.8/site-packages/sqlalchemy/orm/session.py", line 3913, in _bulk_save_mappings
[2023-08-30T21:07:57.392+0000] {subprocess.py:93} INFO -     transaction.rollback(_capture_exception=True)
[2023-08-30T21:07:57.393+0000] {subprocess.py:93} INFO -   File "/home/***/.local/lib/python3.8/site-packages/sqlalchemy/util/langhelpers.py", line 70, in __exit__
[2023-08-30T21:07:57.393+0000] {subprocess.py:93} INFO -     compat.raise_(
[2023-08-30T21:07:57.397+0000] {subprocess.py:93} INFO -   File "/home/***/.local/lib/python3.8/site-packages/sqlalchemy/util/compat.py", line 211, in raise_
[2023-08-30T21:07:57.399+0000] {subprocess.py:93} INFO -     raise exception
[2023-08-30T21:07:57.400+0000] {subprocess.py:93} INFO -   File "/home/***/.local/lib/python3.8/site-packages/sqlalchemy/orm/session.py", line 3901, in _bulk_save_mappings
[2023-08-30T21:07:57.402+0000] {subprocess.py:93} INFO -     persistence._bulk_insert(
[2023-08-30T21:07:57.404+0000] {subprocess.py:93} INFO -   File "/home/***/.local/lib/python3.8/site-packages/sqlalchemy/orm/persistence.py", line 107, in _bulk_insert
[2023-08-30T21:07:57.404+0000] {subprocess.py:93} INFO -     _emit_insert_statements(
[2023-08-30T21:07:57.406+0000] {subprocess.py:93} INFO -   File "/home/***/.local/lib/python3.8/site-packages/sqlalchemy/orm/persistence.py", line 1097, in _emit_insert_statements
[2023-08-30T21:07:57.409+0000] {subprocess.py:93} INFO -     c = connection._execute_20(
[2023-08-30T21:07:57.411+0000] {subprocess.py:93} INFO -   File "/home/***/.local/lib/python3.8/site-packages/sqlalchemy/engine/base.py", line 1710, in _execute_20
[2023-08-30T21:07:57.415+0000] {subprocess.py:93} INFO -     return meth(self, args_10style, kwargs_10style, execution_options)
[2023-08-30T21:07:57.417+0000] {subprocess.py:93} INFO -   File "/home/***/.local/lib/python3.8/site-packages/sqlalchemy/sql/elements.py", line 334, in _execute_on_connection
[2023-08-30T21:07:57.419+0000] {subprocess.py:93} INFO -     return connection._execute_clauseelement(
[2023-08-30T21:07:57.421+0000] {subprocess.py:93} INFO -   File "/home/***/.local/lib/python3.8/site-packages/sqlalchemy/engine/base.py", line 1577, in _execute_clauseelement
[2023-08-30T21:07:57.423+0000] {subprocess.py:93} INFO -     ret = self._execute_context(
[2023-08-30T21:07:57.424+0000] {subprocess.py:93} INFO -   File "/home/***/.local/lib/python3.8/site-packages/sqlalchemy/engine/base.py", line 1953, in _execute_context
[2023-08-30T21:07:57.427+0000] {subprocess.py:93} INFO -     self._handle_dbapi_exception(
[2023-08-30T21:07:57.429+0000] {subprocess.py:93} INFO -   File "/home/***/.local/lib/python3.8/site-packages/sqlalchemy/engine/base.py", line 2134, in _handle_dbapi_exception
[2023-08-30T21:07:57.431+0000] {subprocess.py:93} INFO -     util.raise_(
[2023-08-30T21:07:57.432+0000] {subprocess.py:93} INFO -   File "/home/***/.local/lib/python3.8/site-packages/sqlalchemy/util/compat.py", line 211, in raise_
[2023-08-30T21:07:57.434+0000] {subprocess.py:93} INFO -     raise exception
[2023-08-30T21:07:57.436+0000] {subprocess.py:93} INFO -   File "/home/***/.local/lib/python3.8/site-packages/sqlalchemy/engine/base.py", line 1890, in _execute_context
[2023-08-30T21:07:57.437+0000] {subprocess.py:93} INFO -     self.dialect.do_executemany(
[2023-08-30T21:07:57.440+0000] {subprocess.py:93} INFO -   File "/home/***/.local/lib/python3.8/site-packages/sqlalchemy/dialects/postgresql/psycopg2.py", line 982, in do_executemany
[2023-08-30T21:07:57.441+0000] {subprocess.py:93} INFO -     context._psycopg2_fetched_rows = xtras.execute_values(
[2023-08-30T21:07:57.443+0000] {subprocess.py:93} INFO -   File "/home/***/.local/lib/python3.8/site-packages/psycopg2/extras.py", line 1299, in execute_values
[2023-08-30T21:07:57.444+0000] {subprocess.py:93} INFO -     cur.execute(b''.join(parts))
[2023-08-30T21:07:57.445+0000] {subprocess.py:93} INFO - sqlalchemy.exc.DataError: (psycopg2.errors.StringDataRightTruncation) value too long for type character varying(20)
[2023-08-30T21:07:57.446+0000] {subprocess.py:93} INFO - 
[2023-08-30T21:07:57.448+0000] {subprocess.py:93} INFO - [SQL: INSERT INTO traffic_report (timestamp, traffic_report_id, date_time, issue_reported, latitude, longitude, address, weekday, date, time) VALUES (%(timestamp)s, %(traffic_report_id)s, %(date_time)s, %(issue_reported)s, %(latitude)s, %(longitude)s, %(address)s, %(weekday)s, %(date)s, %(time)s)]
[2023-08-30T21:07:57.449+0000] {subprocess.py:93} INFO - [parameters: ({'timestamp': '1692748993000000000', 'traffic_report_id': '9A6B59DA46371D86EB75259C956AEE4B580C0119_1692748993', 'date_time': '2023-08-23 00:03:13+00:00', 'issue_reported': 'crash service', 'latitude': '30.193169', 'longitude': '-97.738909', 'address': 'nuckols crossing rd / e stassney ln', 'weekday': 'Wednesday', 'date': '2023-08-23', 'time': '00:03:13'}, {'timestamp': '1692749009000000000', 'traffic_report_id': '634DE0A75896238BFD3F5886F6062F00DA3D0B56_1692749009', 'date_time': '2023-08-23 00:03:29+00:00', 'issue_reported': 'traffic hazard', 'latitude': '30.167145', 'longitude': '-97.790941', 'address': 'w slaughter ln / cullen ln', 'weekday': 'Wednesday', 'date': '2023-08-23', 'time': '00:03:29'}, {'timestamp': '1692749887000000000', 'traffic_report_id': 'EBA90709ED04EB27E4A042727D7DD308E44389E4_1692749887', 'date_time': '2023-08-23 00:18:07+00:00', 'issue_reported': 'crash urgent', 'latitude': '30.370783', 'longitude': '-97.691583', 'address': '600 masterson pass', 'weekday': 'Wednesday', 'date': '2023-08-23', 'time': '00:18:07'}, {'timestamp': '1692751163000000000', 'traffic_report_id': '9D634E9D726305D5B9A7D2E527F6C49DD3603F4F_1692751163', 'date_time': '2023-08-23 00:39:23+00:00', 'issue_reported': 'collision with injury', 'latitude': '30.102795', 'longitude': '-97.61178', 'address': 'fm 812 rd / doyle rd', 'weekday': 'Wednesday', 'date': '2023-08-23', 'time': '00:39:23'}, {'timestamp': '1692751987000000000', 'traffic_report_id': '301F839B74B67350B1BDC01050369AEC1F36E0D2_1692751987', 'date_time': '2023-08-23 00:53:07+00:00', 'issue_reported': 'traffic hazard', 'latitude': '30.328075', 'longitude': '-97.691413', 'address': '1308 fairbanks dr', 'weekday': 'Wednesday', 'date': '2023-08-23', 'time': '00:53:07'}, {'timestamp': '1692752143000000000', 'traffic_report_id': '2B80090196FBBD61985EA7F2FC5C2F6AA4E1F134_1692752143', 'date_time': '2023-08-23 00:55:43+00:00', 'issue_reported': 'traffic hazard', 'latitude': '30.235959', 'longitude': '-97.728493', 'address': 'burton dr / woodland ave', 'weekday': 'Wednesday', 'date': '2023-08-23', 'time': '00:55:43'}, {'timestamp': '1692753489000000000', 'traffic_report_id': '1E768A21723E530122240FA219BFF8C3365F40B2_1692753489', 'date_time': '2023-08-23 01:18:09+00:00', 'issue_reported': 'traffic hazard', 'latitude': '30.310245', 'longitude': '-97.708554', 'address': '5201-5217 cameron rd', 'weekday': 'Wednesday', 'date': '2023-08-23', 'time': '01:18:09'}, {'timestamp': '1692753535000000000', 'traffic_report_id': '509F6CCBC5A85A0D07F32BFF32186163BA8301B8_1692753535', 'date_time': '2023-08-23 01:18:55+00:00', 'issue_reported': 'crash service', 'latitude': '30.26906', 'longitude': '-97.73408', 'address': '900 n ih 35 svrd sb', 'weekday': 'Wednesday', 'date': '2023-08-23', 'time': '01:18:55'}  ... displaying 10 of 146 total bound parameter sets ...  {'timestamp': '1692834773000000000', 'traffic_report_id': '3C457CE18C2E37A4437E0201076AD638367EF0EA_1692834773', 'date_time': '2023-08-23 23:52:53+00:00', 'issue_reported': 'crash service', 'latitude': '30.183637', 'longitude': '-97.774726', 'address': '7301 s ih 35 svrd nb', 'weekday': 'Wednesday', 'date': '2023-08-23', 'time': '23:52:53'}, {'timestamp': '1692834818000000000', 'traffic_report_id': '0F23EB04FA3D66BCE3CB03DE0629AC1B4FD32BBB_1692834818', 'date_time': '2023-08-23 23:53:38+00:00', 'issue_reported': 'crash urgent', 'latitude': '30.443741', 'longitude': '-97.742505', 'address': '6101-6217 mc neil dr', 'weekday': 'Wednesday', 'date': '2023-08-23', 'time': '23:53:38'})]
[2023-08-30T21:07:57.453+0000] {subprocess.py:93} INFO - (Background on this error at: https://sqlalche.me/e/14/9h9h)
[2023-08-30T21:07:57.454+0000] {subprocess.py:97} INFO - Command exited with return code 1
[2023-08-30T21:07:57.470+0000] {taskinstance.py:1943} ERROR - Task failed with exception
Traceback (most recent call last):
  File "/home/airflow/.local/lib/python3.8/site-packages/airflow/operators/bash.py", line 210, in execute
    raise AirflowException(
airflow.exceptions.AirflowException: Bash command failed. The command returned a non-zero exit code 1.
[2023-08-30T21:07:57.475+0000] {taskinstance.py:1400} INFO - Marking task as UP_FOR_RETRY. dag_id=traffic_report, task_id=export_data_to_db, execution_date=20230824T000000, start_date=20230830T210756, end_date=20230830T210757
[2023-08-30T21:07:57.494+0000] {standard_task_runner.py:104} ERROR - Failed to execute job 21 for task export_data_to_db (Bash command failed. The command returned a non-zero exit code 1.; 368)
[2023-08-30T21:07:57.532+0000] {local_task_job_runner.py:228} INFO - Task exited with return code 1
[2023-08-30T21:07:57.551+0000] {taskinstance.py:2784} INFO - 0 downstream tasks scheduled from follow-on schedule check
[2023-08-30T21:17:16.068+0000] {logging_mixin.py:151} WARNING - /home/***/.local/lib/python3.8/site-packages/***/utils/sqlalchemy.py:124 DeprecationWarning: The sql_alchemy_conn option in [core] has been moved to the sql_alchemy_conn option in [database] - the old setting has been used, but please update your config.
[2023-08-30T21:17:16.082+0000] {taskinstance.py:1159} INFO - Dependencies all met for dep_context=non-requeueable deps ti=<TaskInstance: traffic_report.export_data_to_db scheduled__2023-08-24T00:00:00+00:00 [queued]>
[2023-08-30T21:17:16.098+0000] {taskinstance.py:1159} INFO - Dependencies all met for dep_context=requeueable deps ti=<TaskInstance: traffic_report.export_data_to_db scheduled__2023-08-24T00:00:00+00:00 [queued]>
[2023-08-30T21:17:16.106+0000] {taskinstance.py:1361} INFO - Starting attempt 1 of 2
[2023-08-30T21:17:16.134+0000] {taskinstance.py:1382} INFO - Executing <Task(BashOperator): export_data_to_db> on 2023-08-24 00:00:00+00:00
[2023-08-30T21:17:16.144+0000] {standard_task_runner.py:57} INFO - Started process 421 to run task
[2023-08-30T21:17:16.147+0000] {standard_task_runner.py:84} INFO - Running: ['***', 'tasks', 'run', 'traffic_report', 'export_data_to_db', 'scheduled__2023-08-24T00:00:00+00:00', '--job-id', '21', '--raw', '--subdir', 'DAGS_FOLDER/traffic_dag.py', '--cfg-path', '/tmp/tmp34z7ezte']
[2023-08-30T21:17:16.150+0000] {standard_task_runner.py:85} INFO - Job 21: Subtask export_data_to_db
[2023-08-30T21:17:16.165+0000] {logging_mixin.py:151} WARNING - /home/***/.local/lib/python3.8/site-packages/***/settings.py:195 DeprecationWarning: The sql_alchemy_conn option in [core] has been moved to the sql_alchemy_conn option in [database] - the old setting has been used, but please update your config.
[2023-08-30T21:17:16.215+0000] {task_command.py:415} INFO - Running <TaskInstance: traffic_report.export_data_to_db scheduled__2023-08-24T00:00:00+00:00 [running]> on host 5b9f14bf20e0
[2023-08-30T21:17:16.241+0000] {logging_mixin.py:151} WARNING - /home/***/.local/lib/python3.8/site-packages/***/utils/sqlalchemy.py:124 DeprecationWarning: The sql_alchemy_conn option in [core] has been moved to the sql_alchemy_conn option in [database] - the old setting has been used, but please update your config.
[2023-08-30T21:17:16.317+0000] {taskinstance.py:1660} INFO - Exporting env vars: AIRFLOW_CTX_DAG_OWNER='***' AIRFLOW_CTX_DAG_ID='traffic_report' AIRFLOW_CTX_TASK_ID='export_data_to_db' AIRFLOW_CTX_EXECUTION_DATE='2023-08-24T00:00:00+00:00' AIRFLOW_CTX_TRY_NUMBER='1' AIRFLOW_CTX_DAG_RUN_ID='scheduled__2023-08-24T00:00:00+00:00'
[2023-08-30T21:17:16.320+0000] {subprocess.py:63} INFO - Tmp dir root location: /tmp
[2023-08-30T21:17:16.322+0000] {subprocess.py:75} INFO - Running command: ['/bin/bash', '-c', 'python /opt/***/dags/data_to_db.py --date 2023-08-24 --connection postgresql+psycopg2://***:***@postgres/***']
[2023-08-30T21:17:16.333+0000] {subprocess.py:86} INFO - Output:
[2023-08-30T21:17:16.753+0000] {subprocess.py:97} INFO - Command exited with return code 0
[2023-08-30T21:17:16.777+0000] {taskinstance.py:1400} INFO - Marking task as SUCCESS. dag_id=traffic_report, task_id=export_data_to_db, execution_date=20230824T000000, start_date=20230830T211716, end_date=20230830T211716
[2023-08-30T21:17:16.807+0000] {local_task_job_runner.py:228} INFO - Task exited with return code 0
[2023-08-30T21:17:16.822+0000] {taskinstance.py:2784} INFO - 0 downstream tasks scheduled from follow-on schedule check
