[2023-08-30T19:31:42.298+0000] {logging_mixin.py:151} WARNING - /home/***/.local/lib/python3.8/site-packages/***/utils/sqlalchemy.py:124 DeprecationWarning: The sql_alchemy_conn option in [core] has been moved to the sql_alchemy_conn option in [database] - the old setting has been used, but please update your config.
[2023-08-30T19:31:42.309+0000] {taskinstance.py:1159} INFO - Dependencies all met for dep_context=non-requeueable deps ti=<TaskInstance: traffic_report.export_data_to_db scheduled__2023-08-28T00:00:00+00:00 [queued]>
[2023-08-30T19:31:42.317+0000] {taskinstance.py:1159} INFO - Dependencies all met for dep_context=requeueable deps ti=<TaskInstance: traffic_report.export_data_to_db scheduled__2023-08-28T00:00:00+00:00 [queued]>
[2023-08-30T19:31:42.319+0000] {taskinstance.py:1361} INFO - Starting attempt 1 of 2
[2023-08-30T19:31:42.332+0000] {taskinstance.py:1382} INFO - Executing <Task(BashOperator): export_data_to_db> on 2023-08-28 00:00:00+00:00
[2023-08-30T19:31:42.337+0000] {standard_task_runner.py:57} INFO - Started process 307 to run task
[2023-08-30T19:31:42.341+0000] {standard_task_runner.py:84} INFO - Running: ['***', 'tasks', 'run', 'traffic_report', 'export_data_to_db', 'scheduled__2023-08-28T00:00:00+00:00', '--job-id', '13', '--raw', '--subdir', 'DAGS_FOLDER/traffic_dag.py', '--cfg-path', '/tmp/tmpfzqwu2zg']
[2023-08-30T19:31:42.344+0000] {standard_task_runner.py:85} INFO - Job 13: Subtask export_data_to_db
[2023-08-30T19:31:42.363+0000] {logging_mixin.py:151} WARNING - /home/***/.local/lib/python3.8/site-packages/***/settings.py:195 DeprecationWarning: The sql_alchemy_conn option in [core] has been moved to the sql_alchemy_conn option in [database] - the old setting has been used, but please update your config.
[2023-08-30T19:31:42.407+0000] {task_command.py:415} INFO - Running <TaskInstance: traffic_report.export_data_to_db scheduled__2023-08-28T00:00:00+00:00 [running]> on host f6bcf103ff79
[2023-08-30T19:31:42.421+0000] {logging_mixin.py:151} WARNING - /home/***/.local/lib/python3.8/site-packages/***/utils/sqlalchemy.py:124 DeprecationWarning: The sql_alchemy_conn option in [core] has been moved to the sql_alchemy_conn option in [database] - the old setting has been used, but please update your config.
[2023-08-30T19:31:42.489+0000] {taskinstance.py:1660} INFO - Exporting env vars: AIRFLOW_CTX_DAG_OWNER='***' AIRFLOW_CTX_DAG_ID='traffic_report' AIRFLOW_CTX_TASK_ID='export_data_to_db' AIRFLOW_CTX_EXECUTION_DATE='2023-08-28T00:00:00+00:00' AIRFLOW_CTX_TRY_NUMBER='1' AIRFLOW_CTX_DAG_RUN_ID='scheduled__2023-08-28T00:00:00+00:00'
[2023-08-30T19:31:42.493+0000] {subprocess.py:63} INFO - Tmp dir root location: /tmp
[2023-08-30T19:31:42.499+0000] {subprocess.py:75} INFO - Running command: ['/bin/bash', '-c', 'python /opt/***/dags/data_to_db.py --date 2023-08-28 --connection postgresql+psycopg2://***:***@postgres/***']
[2023-08-30T19:31:42.513+0000] {subprocess.py:86} INFO - Output:
[2023-08-30T19:31:43.054+0000] {subprocess.py:93} INFO - Traceback (most recent call last):
[2023-08-30T19:31:43.055+0000] {subprocess.py:93} INFO -   File "/opt/***/dags/data_to_db.py", line 6, in <module>
[2023-08-30T19:31:43.057+0000] {subprocess.py:93} INFO -     from model import Connection, Traffic
[2023-08-30T19:31:43.058+0000] {subprocess.py:93} INFO -   File "/opt/***/dags/model.py", line 5, in <module>
[2023-08-30T19:31:43.059+0000] {subprocess.py:93} INFO -     from geoalchemy2 import Geometry
[2023-08-30T19:31:43.060+0000] {subprocess.py:93} INFO - ModuleNotFoundError: No module named 'geoalchemy2'
[2023-08-30T19:31:43.101+0000] {subprocess.py:97} INFO - Command exited with return code 1
[2023-08-30T19:31:43.121+0000] {taskinstance.py:1943} ERROR - Task failed with exception
Traceback (most recent call last):
  File "/home/airflow/.local/lib/python3.8/site-packages/airflow/operators/bash.py", line 210, in execute
    raise AirflowException(
airflow.exceptions.AirflowException: Bash command failed. The command returned a non-zero exit code 1.
[2023-08-30T19:31:43.128+0000] {taskinstance.py:1400} INFO - Marking task as UP_FOR_RETRY. dag_id=traffic_report, task_id=export_data_to_db, execution_date=20230828T000000, start_date=20230830T193142, end_date=20230830T193143
[2023-08-30T19:31:43.155+0000] {standard_task_runner.py:104} ERROR - Failed to execute job 13 for task export_data_to_db (Bash command failed. The command returned a non-zero exit code 1.; 307)
[2023-08-30T19:31:43.200+0000] {local_task_job_runner.py:228} INFO - Task exited with return code 1
[2023-08-30T19:31:43.222+0000] {taskinstance.py:2784} INFO - 0 downstream tasks scheduled from follow-on schedule check
[2023-08-30T19:42:02.051+0000] {logging_mixin.py:151} WARNING - /home/***/.local/lib/python3.8/site-packages/***/utils/sqlalchemy.py:124 DeprecationWarning: The sql_alchemy_conn option in [core] has been moved to the sql_alchemy_conn option in [database] - the old setting has been used, but please update your config.
[2023-08-30T19:42:02.065+0000] {taskinstance.py:1159} INFO - Dependencies all met for dep_context=non-requeueable deps ti=<TaskInstance: traffic_report.export_data_to_db scheduled__2023-08-28T00:00:00+00:00 [queued]>
[2023-08-30T19:42:02.077+0000] {taskinstance.py:1159} INFO - Dependencies all met for dep_context=requeueable deps ti=<TaskInstance: traffic_report.export_data_to_db scheduled__2023-08-28T00:00:00+00:00 [queued]>
[2023-08-30T19:42:02.078+0000] {taskinstance.py:1361} INFO - Starting attempt 1 of 2
[2023-08-30T19:42:02.092+0000] {taskinstance.py:1382} INFO - Executing <Task(BashOperator): export_data_to_db> on 2023-08-28 00:00:00+00:00
[2023-08-30T19:42:02.098+0000] {standard_task_runner.py:57} INFO - Started process 382 to run task
[2023-08-30T19:42:02.106+0000] {standard_task_runner.py:84} INFO - Running: ['***', 'tasks', 'run', 'traffic_report', 'export_data_to_db', 'scheduled__2023-08-28T00:00:00+00:00', '--job-id', '18', '--raw', '--subdir', 'DAGS_FOLDER/traffic_dag.py', '--cfg-path', '/tmp/tmpc44l8o4b']
[2023-08-30T19:42:02.115+0000] {standard_task_runner.py:85} INFO - Job 18: Subtask export_data_to_db
[2023-08-30T19:42:02.139+0000] {logging_mixin.py:151} WARNING - /home/***/.local/lib/python3.8/site-packages/***/settings.py:195 DeprecationWarning: The sql_alchemy_conn option in [core] has been moved to the sql_alchemy_conn option in [database] - the old setting has been used, but please update your config.
[2023-08-30T19:42:02.197+0000] {task_command.py:415} INFO - Running <TaskInstance: traffic_report.export_data_to_db scheduled__2023-08-28T00:00:00+00:00 [running]> on host 81eeb4b7c8a9
[2023-08-30T19:42:02.215+0000] {logging_mixin.py:151} WARNING - /home/***/.local/lib/python3.8/site-packages/***/utils/sqlalchemy.py:124 DeprecationWarning: The sql_alchemy_conn option in [core] has been moved to the sql_alchemy_conn option in [database] - the old setting has been used, but please update your config.
[2023-08-30T19:42:02.295+0000] {taskinstance.py:1660} INFO - Exporting env vars: AIRFLOW_CTX_DAG_OWNER='***' AIRFLOW_CTX_DAG_ID='traffic_report' AIRFLOW_CTX_TASK_ID='export_data_to_db' AIRFLOW_CTX_EXECUTION_DATE='2023-08-28T00:00:00+00:00' AIRFLOW_CTX_TRY_NUMBER='1' AIRFLOW_CTX_DAG_RUN_ID='scheduled__2023-08-28T00:00:00+00:00'
[2023-08-30T19:42:02.297+0000] {subprocess.py:63} INFO - Tmp dir root location: /tmp
[2023-08-30T19:42:02.299+0000] {subprocess.py:75} INFO - Running command: ['/bin/bash', '-c', 'python /opt/***/dags/data_to_db.py --date 2023-08-28 --connection postgresql+psycopg2://***:***@postgres/***']
[2023-08-30T19:42:02.317+0000] {subprocess.py:86} INFO - Output:
[2023-08-30T19:42:02.880+0000] {subprocess.py:93} INFO - Traceback (most recent call last):
[2023-08-30T19:42:02.882+0000] {subprocess.py:93} INFO -   File "/opt/***/dags/data_to_db.py", line 6, in <module>
[2023-08-30T19:42:02.885+0000] {subprocess.py:93} INFO -     from model import Connection, Traffic
[2023-08-30T19:42:02.888+0000] {subprocess.py:93} INFO -   File "/opt/***/dags/model.py", line 5, in <module>
[2023-08-30T19:42:02.889+0000] {subprocess.py:93} INFO -     from geoalchemy2 import Geometry
[2023-08-30T19:42:02.890+0000] {subprocess.py:93} INFO - ModuleNotFoundError: No module named 'geoalchemy2'
[2023-08-30T19:42:02.933+0000] {subprocess.py:97} INFO - Command exited with return code 1
[2023-08-30T19:42:02.947+0000] {taskinstance.py:1943} ERROR - Task failed with exception
Traceback (most recent call last):
  File "/home/airflow/.local/lib/python3.8/site-packages/airflow/operators/bash.py", line 210, in execute
    raise AirflowException(
airflow.exceptions.AirflowException: Bash command failed. The command returned a non-zero exit code 1.
[2023-08-30T19:42:02.952+0000] {taskinstance.py:1400} INFO - Marking task as UP_FOR_RETRY. dag_id=traffic_report, task_id=export_data_to_db, execution_date=20230828T000000, start_date=20230830T194202, end_date=20230830T194202
[2023-08-30T19:42:02.970+0000] {standard_task_runner.py:104} ERROR - Failed to execute job 18 for task export_data_to_db (Bash command failed. The command returned a non-zero exit code 1.; 382)
[2023-08-30T19:42:02.998+0000] {local_task_job_runner.py:228} INFO - Task exited with return code 1
[2023-08-30T19:42:03.016+0000] {taskinstance.py:2784} INFO - 0 downstream tasks scheduled from follow-on schedule check
[2023-08-30T19:51:05.588+0000] {logging_mixin.py:151} WARNING - /home/***/.local/lib/python3.8/site-packages/***/utils/sqlalchemy.py:124 DeprecationWarning: The sql_alchemy_conn option in [core] has been moved to the sql_alchemy_conn option in [database] - the old setting has been used, but please update your config.
[2023-08-30T19:51:05.606+0000] {taskinstance.py:1159} INFO - Dependencies all met for dep_context=non-requeueable deps ti=<TaskInstance: traffic_report.export_data_to_db scheduled__2023-08-28T00:00:00+00:00 [queued]>
[2023-08-30T19:51:05.616+0000] {taskinstance.py:1159} INFO - Dependencies all met for dep_context=requeueable deps ti=<TaskInstance: traffic_report.export_data_to_db scheduled__2023-08-28T00:00:00+00:00 [queued]>
[2023-08-30T19:51:05.618+0000] {taskinstance.py:1361} INFO - Starting attempt 1 of 2
[2023-08-30T19:51:05.636+0000] {taskinstance.py:1382} INFO - Executing <Task(BashOperator): export_data_to_db> on 2023-08-28 00:00:00+00:00
[2023-08-30T19:51:05.643+0000] {standard_task_runner.py:57} INFO - Started process 357 to run task
[2023-08-30T19:51:05.652+0000] {standard_task_runner.py:84} INFO - Running: ['***', 'tasks', 'run', 'traffic_report', 'export_data_to_db', 'scheduled__2023-08-28T00:00:00+00:00', '--job-id', '16', '--raw', '--subdir', 'DAGS_FOLDER/traffic_dag.py', '--cfg-path', '/tmp/tmpx62az7fd']
[2023-08-30T19:51:05.662+0000] {standard_task_runner.py:85} INFO - Job 16: Subtask export_data_to_db
[2023-08-30T19:51:06.060+0000] {logging_mixin.py:151} WARNING - /home/***/.local/lib/python3.8/site-packages/***/settings.py:195 DeprecationWarning: The sql_alchemy_conn option in [core] has been moved to the sql_alchemy_conn option in [database] - the old setting has been used, but please update your config.
[2023-08-30T19:51:08.288+0000] {task_command.py:415} INFO - Running <TaskInstance: traffic_report.export_data_to_db scheduled__2023-08-28T00:00:00+00:00 [running]> on host 206ecb1dc8df
[2023-08-30T19:51:08.602+0000] {logging_mixin.py:151} WARNING - /home/***/.local/lib/python3.8/site-packages/***/utils/sqlalchemy.py:124 DeprecationWarning: The sql_alchemy_conn option in [core] has been moved to the sql_alchemy_conn option in [database] - the old setting has been used, but please update your config.
[2023-08-30T19:51:22.791+0000] {taskinstance.py:1660} INFO - Exporting env vars: AIRFLOW_CTX_DAG_OWNER='***' AIRFLOW_CTX_DAG_ID='traffic_report' AIRFLOW_CTX_TASK_ID='export_data_to_db' AIRFLOW_CTX_EXECUTION_DATE='2023-08-28T00:00:00+00:00' AIRFLOW_CTX_TRY_NUMBER='1' AIRFLOW_CTX_DAG_RUN_ID='scheduled__2023-08-28T00:00:00+00:00'
[2023-08-30T19:51:22.837+0000] {subprocess.py:63} INFO - Tmp dir root location: /tmp
[2023-08-30T19:51:22.841+0000] {subprocess.py:75} INFO - Running command: ['/bin/bash', '-c', 'python /opt/***/dags/data_to_db.py --date 2023-08-28 --connection postgresql+psycopg2://***:***@postgres/***']
[2023-08-30T19:51:22.857+0000] {subprocess.py:86} INFO - Output:
[2023-08-30T19:51:33.980+0000] {subprocess.py:93} INFO - Traceback (most recent call last):
[2023-08-30T19:51:33.987+0000] {subprocess.py:93} INFO -   File "/opt/***/dags/data_to_db.py", line 50, in <module>
[2023-08-30T19:51:33.996+0000] {subprocess.py:93} INFO -     main(args.date, args.connection)
[2023-08-30T19:51:34.000+0000] {subprocess.py:93} INFO -   File "/opt/***/dags/data_to_db.py", line 22, in main
[2023-08-30T19:51:34.002+0000] {subprocess.py:93} INFO -     with open(filename, encoding='utf-8') as csvf:
[2023-08-30T19:51:34.004+0000] {subprocess.py:93} INFO - FileNotFoundError: [Errno 2] No such file or directory: '/opt/***/dags/data/traffic_2023-08-27.csv'
[2023-08-30T19:51:34.138+0000] {subprocess.py:97} INFO - Command exited with return code 1
[2023-08-30T19:51:34.171+0000] {taskinstance.py:1943} ERROR - Task failed with exception
Traceback (most recent call last):
  File "/home/airflow/.local/lib/python3.8/site-packages/airflow/operators/bash.py", line 210, in execute
    raise AirflowException(
airflow.exceptions.AirflowException: Bash command failed. The command returned a non-zero exit code 1.
[2023-08-30T19:51:34.183+0000] {taskinstance.py:1400} INFO - Marking task as UP_FOR_RETRY. dag_id=traffic_report, task_id=export_data_to_db, execution_date=20230828T000000, start_date=20230830T195105, end_date=20230830T195134
[2023-08-30T19:51:34.213+0000] {standard_task_runner.py:104} ERROR - Failed to execute job 16 for task export_data_to_db (Bash command failed. The command returned a non-zero exit code 1.; 357)
[2023-08-30T19:51:34.261+0000] {local_task_job_runner.py:228} INFO - Task exited with return code 1
[2023-08-30T19:51:34.291+0000] {taskinstance.py:2784} INFO - 0 downstream tasks scheduled from follow-on schedule check
[2023-08-30T19:54:33.279+0000] {logging_mixin.py:151} WARNING - /home/***/.local/lib/python3.8/site-packages/***/utils/sqlalchemy.py:124 DeprecationWarning: The sql_alchemy_conn option in [core] has been moved to the sql_alchemy_conn option in [database] - the old setting has been used, but please update your config.
[2023-08-30T19:54:33.305+0000] {taskinstance.py:1159} INFO - Dependencies all met for dep_context=non-requeueable deps ti=<TaskInstance: traffic_report.export_data_to_db scheduled__2023-08-28T00:00:00+00:00 [queued]>
[2023-08-30T19:54:33.325+0000] {taskinstance.py:1159} INFO - Dependencies all met for dep_context=requeueable deps ti=<TaskInstance: traffic_report.export_data_to_db scheduled__2023-08-28T00:00:00+00:00 [queued]>
[2023-08-30T19:54:33.334+0000] {taskinstance.py:1361} INFO - Starting attempt 1 of 2
[2023-08-30T19:54:33.356+0000] {taskinstance.py:1382} INFO - Executing <Task(BashOperator): export_data_to_db> on 2023-08-28 00:00:00+00:00
[2023-08-30T19:54:33.362+0000] {standard_task_runner.py:57} INFO - Started process 313 to run task
[2023-08-30T19:54:33.368+0000] {standard_task_runner.py:84} INFO - Running: ['***', 'tasks', 'run', 'traffic_report', 'export_data_to_db', 'scheduled__2023-08-28T00:00:00+00:00', '--job-id', '17', '--raw', '--subdir', 'DAGS_FOLDER/traffic_dag.py', '--cfg-path', '/tmp/tmp3bz1x2ux']
[2023-08-30T19:54:33.373+0000] {standard_task_runner.py:85} INFO - Job 17: Subtask export_data_to_db
[2023-08-30T19:54:33.405+0000] {logging_mixin.py:151} WARNING - /home/***/.local/lib/python3.8/site-packages/***/settings.py:195 DeprecationWarning: The sql_alchemy_conn option in [core] has been moved to the sql_alchemy_conn option in [database] - the old setting has been used, but please update your config.
[2023-08-30T19:54:33.473+0000] {task_command.py:415} INFO - Running <TaskInstance: traffic_report.export_data_to_db scheduled__2023-08-28T00:00:00+00:00 [running]> on host 86f9e97d6c70
[2023-08-30T19:54:33.496+0000] {logging_mixin.py:151} WARNING - /home/***/.local/lib/python3.8/site-packages/***/utils/sqlalchemy.py:124 DeprecationWarning: The sql_alchemy_conn option in [core] has been moved to the sql_alchemy_conn option in [database] - the old setting has been used, but please update your config.
[2023-08-30T19:54:33.572+0000] {taskinstance.py:1660} INFO - Exporting env vars: AIRFLOW_CTX_DAG_OWNER='***' AIRFLOW_CTX_DAG_ID='traffic_report' AIRFLOW_CTX_TASK_ID='export_data_to_db' AIRFLOW_CTX_EXECUTION_DATE='2023-08-28T00:00:00+00:00' AIRFLOW_CTX_TRY_NUMBER='1' AIRFLOW_CTX_DAG_RUN_ID='scheduled__2023-08-28T00:00:00+00:00'
[2023-08-30T19:54:33.575+0000] {subprocess.py:63} INFO - Tmp dir root location: /tmp
[2023-08-30T19:54:33.577+0000] {subprocess.py:75} INFO - Running command: ['/bin/bash', '-c', 'python /opt/***/dags/data_to_db.py --date 2023-08-28 --connection postgresql+psycopg2://***:***@postgres/***']
[2023-08-30T19:54:33.602+0000] {subprocess.py:86} INFO - Output:
[2023-08-30T19:54:34.567+0000] {subprocess.py:93} INFO - Traceback (most recent call last):
[2023-08-30T19:54:34.569+0000] {subprocess.py:93} INFO -   File "/home/***/.local/lib/python3.8/site-packages/sqlalchemy/engine/base.py", line 1910, in _execute_context
[2023-08-30T19:54:34.572+0000] {subprocess.py:93} INFO -     self.dialect.do_execute(
[2023-08-30T19:54:34.573+0000] {subprocess.py:93} INFO -   File "/home/***/.local/lib/python3.8/site-packages/sqlalchemy/engine/default.py", line 736, in do_execute
[2023-08-30T19:54:34.574+0000] {subprocess.py:93} INFO -     cursor.execute(statement, parameters)
[2023-08-30T19:54:34.577+0000] {subprocess.py:93} INFO - psycopg2.errors.UndefinedTable: relation "traffic_report" does not exist
[2023-08-30T19:54:34.579+0000] {subprocess.py:93} INFO - LINE 1: DELETE FROM traffic_report where date_time >= timestamp '202...
[2023-08-30T19:54:34.580+0000] {subprocess.py:93} INFO -                     ^
[2023-08-30T19:54:34.580+0000] {subprocess.py:93} INFO - 
[2023-08-30T19:54:34.581+0000] {subprocess.py:93} INFO - 
[2023-08-30T19:54:34.582+0000] {subprocess.py:93} INFO - The above exception was the direct cause of the following exception:
[2023-08-30T19:54:34.584+0000] {subprocess.py:93} INFO - 
[2023-08-30T19:54:34.586+0000] {subprocess.py:93} INFO - Traceback (most recent call last):
[2023-08-30T19:54:34.587+0000] {subprocess.py:93} INFO -   File "/opt/***/dags/data_to_db.py", line 50, in <module>
[2023-08-30T19:54:34.589+0000] {subprocess.py:93} INFO -     main(args.date, args.connection)
[2023-08-30T19:54:34.591+0000] {subprocess.py:93} INFO -   File "/opt/***/dags/data_to_db.py", line 40, in main
[2023-08-30T19:54:34.592+0000] {subprocess.py:93} INFO -     session.execute("DELETE FROM traffic_report where date_time >= timestamp '{} 00:00:00' and date_time < timestamp'{} 00:00:00'".format(yesterday, fetch_date))
[2023-08-30T19:54:34.593+0000] {subprocess.py:93} INFO -   File "/home/***/.local/lib/python3.8/site-packages/sqlalchemy/orm/session.py", line 1717, in execute
[2023-08-30T19:54:34.594+0000] {subprocess.py:93} INFO -     result = conn._execute_20(statement, params or {}, execution_options)
[2023-08-30T19:54:34.596+0000] {subprocess.py:93} INFO -   File "/home/***/.local/lib/python3.8/site-packages/sqlalchemy/engine/base.py", line 1710, in _execute_20
[2023-08-30T19:54:34.597+0000] {subprocess.py:93} INFO -     return meth(self, args_10style, kwargs_10style, execution_options)
[2023-08-30T19:54:34.600+0000] {subprocess.py:93} INFO -   File "/home/***/.local/lib/python3.8/site-packages/sqlalchemy/sql/elements.py", line 334, in _execute_on_connection
[2023-08-30T19:54:34.601+0000] {subprocess.py:93} INFO -     return connection._execute_clauseelement(
[2023-08-30T19:54:34.604+0000] {subprocess.py:93} INFO -   File "/home/***/.local/lib/python3.8/site-packages/sqlalchemy/engine/base.py", line 1577, in _execute_clauseelement
[2023-08-30T19:54:34.607+0000] {subprocess.py:93} INFO -     ret = self._execute_context(
[2023-08-30T19:54:34.608+0000] {subprocess.py:93} INFO -   File "/home/***/.local/lib/python3.8/site-packages/sqlalchemy/engine/base.py", line 1953, in _execute_context
[2023-08-30T19:54:34.609+0000] {subprocess.py:93} INFO -     self._handle_dbapi_exception(
[2023-08-30T19:54:34.610+0000] {subprocess.py:93} INFO -   File "/home/***/.local/lib/python3.8/site-packages/sqlalchemy/engine/base.py", line 2134, in _handle_dbapi_exception
[2023-08-30T19:54:34.618+0000] {subprocess.py:93} INFO -     util.raise_(
[2023-08-30T19:54:34.630+0000] {subprocess.py:93} INFO -   File "/home/***/.local/lib/python3.8/site-packages/sqlalchemy/util/compat.py", line 211, in raise_
[2023-08-30T19:54:34.633+0000] {subprocess.py:93} INFO -     raise exception
[2023-08-30T19:54:34.635+0000] {subprocess.py:93} INFO -   File "/home/***/.local/lib/python3.8/site-packages/sqlalchemy/engine/base.py", line 1910, in _execute_context
[2023-08-30T19:54:34.637+0000] {subprocess.py:93} INFO -     self.dialect.do_execute(
[2023-08-30T19:54:34.644+0000] {subprocess.py:93} INFO -   File "/home/***/.local/lib/python3.8/site-packages/sqlalchemy/engine/default.py", line 736, in do_execute
[2023-08-30T19:54:34.648+0000] {subprocess.py:93} INFO -     cursor.execute(statement, parameters)
[2023-08-30T19:54:34.649+0000] {subprocess.py:93} INFO - sqlalchemy.exc.ProgrammingError: (psycopg2.errors.UndefinedTable) relation "traffic_report" does not exist
[2023-08-30T19:54:34.651+0000] {subprocess.py:93} INFO - LINE 1: DELETE FROM traffic_report where date_time >= timestamp '202...
[2023-08-30T19:54:34.651+0000] {subprocess.py:93} INFO -                     ^
[2023-08-30T19:54:34.652+0000] {subprocess.py:93} INFO - 
[2023-08-30T19:54:34.656+0000] {subprocess.py:93} INFO - [SQL: DELETE FROM traffic_report where date_time >= timestamp '2023-08-27 00:00:00' and date_time < timestamp'2023-08-28 00:00:00']
[2023-08-30T19:54:34.659+0000] {subprocess.py:93} INFO - (Background on this error at: https://sqlalche.me/e/14/f405)
[2023-08-30T19:54:34.762+0000] {subprocess.py:97} INFO - Command exited with return code 1
[2023-08-30T19:54:34.783+0000] {taskinstance.py:1943} ERROR - Task failed with exception
Traceback (most recent call last):
  File "/home/airflow/.local/lib/python3.8/site-packages/airflow/operators/bash.py", line 210, in execute
    raise AirflowException(
airflow.exceptions.AirflowException: Bash command failed. The command returned a non-zero exit code 1.
[2023-08-30T19:54:34.788+0000] {taskinstance.py:1400} INFO - Marking task as UP_FOR_RETRY. dag_id=traffic_report, task_id=export_data_to_db, execution_date=20230828T000000, start_date=20230830T195433, end_date=20230830T195434
[2023-08-30T19:54:34.810+0000] {standard_task_runner.py:104} ERROR - Failed to execute job 17 for task export_data_to_db (Bash command failed. The command returned a non-zero exit code 1.; 313)
[2023-08-30T19:54:34.829+0000] {local_task_job_runner.py:228} INFO - Task exited with return code 1
[2023-08-30T19:54:34.848+0000] {taskinstance.py:2784} INFO - 0 downstream tasks scheduled from follow-on schedule check
[2023-08-30T20:05:58.306+0000] {logging_mixin.py:151} WARNING - /home/***/.local/lib/python3.8/site-packages/***/utils/sqlalchemy.py:124 DeprecationWarning: The sql_alchemy_conn option in [core] has been moved to the sql_alchemy_conn option in [database] - the old setting has been used, but please update your config.
[2023-08-30T20:05:58.320+0000] {taskinstance.py:1159} INFO - Dependencies all met for dep_context=non-requeueable deps ti=<TaskInstance: traffic_report.export_data_to_db scheduled__2023-08-28T00:00:00+00:00 [queued]>
[2023-08-30T20:05:58.337+0000] {taskinstance.py:1159} INFO - Dependencies all met for dep_context=requeueable deps ti=<TaskInstance: traffic_report.export_data_to_db scheduled__2023-08-28T00:00:00+00:00 [queued]>
[2023-08-30T20:05:58.338+0000] {taskinstance.py:1361} INFO - Starting attempt 1 of 2
[2023-08-30T20:05:58.350+0000] {taskinstance.py:1382} INFO - Executing <Task(BashOperator): export_data_to_db> on 2023-08-28 00:00:00+00:00
[2023-08-30T20:05:58.357+0000] {standard_task_runner.py:57} INFO - Started process 539 to run task
[2023-08-30T20:05:58.360+0000] {standard_task_runner.py:84} INFO - Running: ['***', 'tasks', 'run', 'traffic_report', 'export_data_to_db', 'scheduled__2023-08-28T00:00:00+00:00', '--job-id', '23', '--raw', '--subdir', 'DAGS_FOLDER/traffic_dag.py', '--cfg-path', '/tmp/tmpuz68hhoh']
[2023-08-30T20:05:58.364+0000] {standard_task_runner.py:85} INFO - Job 23: Subtask export_data_to_db
[2023-08-30T20:05:58.385+0000] {logging_mixin.py:151} WARNING - /home/***/.local/lib/python3.8/site-packages/***/settings.py:195 DeprecationWarning: The sql_alchemy_conn option in [core] has been moved to the sql_alchemy_conn option in [database] - the old setting has been used, but please update your config.
[2023-08-30T20:05:58.446+0000] {task_command.py:415} INFO - Running <TaskInstance: traffic_report.export_data_to_db scheduled__2023-08-28T00:00:00+00:00 [running]> on host 3938d7abd9ff
[2023-08-30T20:05:58.470+0000] {logging_mixin.py:151} WARNING - /home/***/.local/lib/python3.8/site-packages/***/utils/sqlalchemy.py:124 DeprecationWarning: The sql_alchemy_conn option in [core] has been moved to the sql_alchemy_conn option in [database] - the old setting has been used, but please update your config.
[2023-08-30T20:05:58.535+0000] {taskinstance.py:1660} INFO - Exporting env vars: AIRFLOW_CTX_DAG_OWNER='***' AIRFLOW_CTX_DAG_ID='traffic_report' AIRFLOW_CTX_TASK_ID='export_data_to_db' AIRFLOW_CTX_EXECUTION_DATE='2023-08-28T00:00:00+00:00' AIRFLOW_CTX_TRY_NUMBER='1' AIRFLOW_CTX_DAG_RUN_ID='scheduled__2023-08-28T00:00:00+00:00'
[2023-08-30T20:05:58.537+0000] {subprocess.py:63} INFO - Tmp dir root location: /tmp
[2023-08-30T20:05:58.539+0000] {subprocess.py:75} INFO - Running command: ['/bin/bash', '-c', 'python /opt/***/dags/data_to_db.py --date 2023-08-28 --connection postgresql+psycopg2://***:***@postgres/***']
[2023-08-30T20:05:58.551+0000] {subprocess.py:86} INFO - Output:
[2023-08-30T20:05:59.181+0000] {subprocess.py:93} INFO - Traceback (most recent call last):
[2023-08-30T20:05:59.183+0000] {subprocess.py:93} INFO -   File "/home/***/.local/lib/python3.8/site-packages/sqlalchemy/engine/base.py", line 1890, in _execute_context
[2023-08-30T20:05:59.184+0000] {subprocess.py:93} INFO -     self.dialect.do_executemany(
[2023-08-30T20:05:59.185+0000] {subprocess.py:93} INFO -   File "/home/***/.local/lib/python3.8/site-packages/sqlalchemy/dialects/postgresql/psycopg2.py", line 982, in do_executemany
[2023-08-30T20:05:59.186+0000] {subprocess.py:93} INFO -     context._psycopg2_fetched_rows = xtras.execute_values(
[2023-08-30T20:05:59.187+0000] {subprocess.py:93} INFO -   File "/home/***/.local/lib/python3.8/site-packages/psycopg2/extras.py", line 1299, in execute_values
[2023-08-30T20:05:59.189+0000] {subprocess.py:93} INFO -     cur.execute(b''.join(parts))
[2023-08-30T20:05:59.190+0000] {subprocess.py:93} INFO - psycopg2.errors.UndefinedFunction: function st_geomfromewkt(unknown) does not exist
[2023-08-30T20:05:59.192+0000] {subprocess.py:93} INFO - LINE 1: ...35', '2023-08-27 00:00:35+00:00', 'crash urgent', ST_GeomFro...
[2023-08-30T20:05:59.193+0000] {subprocess.py:93} INFO -                                                              ^
[2023-08-30T20:05:59.194+0000] {subprocess.py:93} INFO - HINT:  No function matches the given name and argument types. You might need to add explicit type casts.
[2023-08-30T20:05:59.195+0000] {subprocess.py:93} INFO - 
[2023-08-30T20:05:59.195+0000] {subprocess.py:93} INFO - 
[2023-08-30T20:05:59.197+0000] {subprocess.py:93} INFO - The above exception was the direct cause of the following exception:
[2023-08-30T20:05:59.199+0000] {subprocess.py:93} INFO - 
[2023-08-30T20:05:59.200+0000] {subprocess.py:93} INFO - Traceback (most recent call last):
[2023-08-30T20:05:59.201+0000] {subprocess.py:93} INFO -   File "/opt/***/dags/data_to_db.py", line 50, in <module>
[2023-08-30T20:05:59.202+0000] {subprocess.py:93} INFO -     main(args.date, args.connection)
[2023-08-30T20:05:59.204+0000] {subprocess.py:93} INFO -   File "/opt/***/dags/data_to_db.py", line 41, in main
[2023-08-30T20:05:59.206+0000] {subprocess.py:93} INFO -     session.bulk_save_objects(data_insert)
[2023-08-30T20:05:59.207+0000] {subprocess.py:93} INFO -   File "/home/***/.local/lib/python3.8/site-packages/sqlalchemy/orm/session.py", line 3705, in bulk_save_objects
[2023-08-30T20:05:59.208+0000] {subprocess.py:93} INFO -     self._bulk_save_mappings(
[2023-08-30T20:05:59.210+0000] {subprocess.py:93} INFO -   File "/home/***/.local/lib/python3.8/site-packages/sqlalchemy/orm/session.py", line 3913, in _bulk_save_mappings
[2023-08-30T20:05:59.212+0000] {subprocess.py:93} INFO -     transaction.rollback(_capture_exception=True)
[2023-08-30T20:05:59.212+0000] {subprocess.py:93} INFO -   File "/home/***/.local/lib/python3.8/site-packages/sqlalchemy/util/langhelpers.py", line 70, in __exit__
[2023-08-30T20:05:59.213+0000] {subprocess.py:93} INFO -     compat.raise_(
[2023-08-30T20:05:59.214+0000] {subprocess.py:93} INFO -   File "/home/***/.local/lib/python3.8/site-packages/sqlalchemy/util/compat.py", line 211, in raise_
[2023-08-30T20:05:59.216+0000] {subprocess.py:93} INFO -     raise exception
[2023-08-30T20:05:59.217+0000] {subprocess.py:93} INFO -   File "/home/***/.local/lib/python3.8/site-packages/sqlalchemy/orm/session.py", line 3901, in _bulk_save_mappings
[2023-08-30T20:05:59.219+0000] {subprocess.py:93} INFO -     persistence._bulk_insert(
[2023-08-30T20:05:59.219+0000] {subprocess.py:93} INFO -   File "/home/***/.local/lib/python3.8/site-packages/sqlalchemy/orm/persistence.py", line 107, in _bulk_insert
[2023-08-30T20:05:59.221+0000] {subprocess.py:93} INFO -     _emit_insert_statements(
[2023-08-30T20:05:59.222+0000] {subprocess.py:93} INFO -   File "/home/***/.local/lib/python3.8/site-packages/sqlalchemy/orm/persistence.py", line 1097, in _emit_insert_statements
[2023-08-30T20:05:59.224+0000] {subprocess.py:93} INFO -     c = connection._execute_20(
[2023-08-30T20:05:59.225+0000] {subprocess.py:93} INFO -   File "/home/***/.local/lib/python3.8/site-packages/sqlalchemy/engine/base.py", line 1710, in _execute_20
[2023-08-30T20:05:59.226+0000] {subprocess.py:93} INFO -     return meth(self, args_10style, kwargs_10style, execution_options)
[2023-08-30T20:05:59.227+0000] {subprocess.py:93} INFO -   File "/home/***/.local/lib/python3.8/site-packages/sqlalchemy/sql/elements.py", line 334, in _execute_on_connection
[2023-08-30T20:05:59.228+0000] {subprocess.py:93} INFO -     return connection._execute_clauseelement(
[2023-08-30T20:05:59.230+0000] {subprocess.py:93} INFO -   File "/home/***/.local/lib/python3.8/site-packages/sqlalchemy/engine/base.py", line 1577, in _execute_clauseelement
[2023-08-30T20:05:59.233+0000] {subprocess.py:93} INFO -     ret = self._execute_context(
[2023-08-30T20:05:59.235+0000] {subprocess.py:93} INFO -   File "/home/***/.local/lib/python3.8/site-packages/sqlalchemy/engine/base.py", line 1953, in _execute_context
[2023-08-30T20:05:59.236+0000] {subprocess.py:93} INFO -     self._handle_dbapi_exception(
[2023-08-30T20:05:59.237+0000] {subprocess.py:93} INFO -   File "/home/***/.local/lib/python3.8/site-packages/sqlalchemy/engine/base.py", line 2134, in _handle_dbapi_exception
[2023-08-30T20:05:59.238+0000] {subprocess.py:93} INFO -     util.raise_(
[2023-08-30T20:05:59.239+0000] {subprocess.py:93} INFO -   File "/home/***/.local/lib/python3.8/site-packages/sqlalchemy/util/compat.py", line 211, in raise_
[2023-08-30T20:05:59.240+0000] {subprocess.py:93} INFO -     raise exception
[2023-08-30T20:05:59.243+0000] {subprocess.py:93} INFO -   File "/home/***/.local/lib/python3.8/site-packages/sqlalchemy/engine/base.py", line 1890, in _execute_context
[2023-08-30T20:05:59.246+0000] {subprocess.py:93} INFO -     self.dialect.do_executemany(
[2023-08-30T20:05:59.248+0000] {subprocess.py:93} INFO -   File "/home/***/.local/lib/python3.8/site-packages/sqlalchemy/dialects/postgresql/psycopg2.py", line 982, in do_executemany
[2023-08-30T20:05:59.250+0000] {subprocess.py:93} INFO -     context._psycopg2_fetched_rows = xtras.execute_values(
[2023-08-30T20:05:59.254+0000] {subprocess.py:93} INFO -   File "/home/***/.local/lib/python3.8/site-packages/psycopg2/extras.py", line 1299, in execute_values
[2023-08-30T20:05:59.257+0000] {subprocess.py:93} INFO -     cur.execute(b''.join(parts))
[2023-08-30T20:05:59.265+0000] {subprocess.py:93} INFO - sqlalchemy.exc.ProgrammingError: (psycopg2.errors.UndefinedFunction) function st_geomfromewkt(unknown) does not exist
[2023-08-30T20:05:59.273+0000] {subprocess.py:93} INFO - LINE 1: ...35', '2023-08-27 00:00:35+00:00', 'crash urgent', ST_GeomFro...
[2023-08-30T20:05:59.276+0000] {subprocess.py:93} INFO -                                                              ^
[2023-08-30T20:05:59.278+0000] {subprocess.py:93} INFO - HINT:  No function matches the given name and argument types. You might need to add explicit type casts.
[2023-08-30T20:05:59.280+0000] {subprocess.py:93} INFO - 
[2023-08-30T20:05:59.282+0000] {subprocess.py:93} INFO - [SQL: INSERT INTO traffic_report (timestamp, traffic_report_id, date_time, issue_reported, location, latitude, longitude, address, weekday, date, time) VALUES (%(timestamp)s, %(traffic_report_id)s, %(date_time)s, %(issue_reported)s, ST_GeomFromEWKT(%(location)s), %(latitude)s, %(longitude)s, %(address)s, %(weekday)s, %(date)s, %(time)s)]
[2023-08-30T20:05:59.284+0000] {subprocess.py:93} INFO - [parameters: ({'timestamp': '1693094435000000000', 'traffic_report_id': '67DE6A669490F0E6BF9D405BA4C66A2CD17CC2FF_1693094435', 'date_time': '2023-08-27 00:00:35+00:00', 'issue_reported': 'crash urgent', 'location': 'POINT(-97.818156 30.461507)', 'latitude': '30.461507', 'longitude': '-97.818156', 'address': '12109-12131 n fm 620 rd', 'weekday': 'Sunday', 'date': '2023-08-27', 'time': '00:00:35'}, {'timestamp': '1693095284000000000', 'traffic_report_id': '5F5898E4726001663BA5A126B313B03B1AED3F07_1693095284', 'date_time': '2023-08-27 00:14:44+00:00', 'issue_reported': 'collision', 'location': 'POINT(-97.525802 30.345376)', 'latitude': '30.345376', 'longitude': '-97.525802', 'address': '12700-13009 ceder st', 'weekday': 'Sunday', 'date': '2023-08-27', 'time': '00:14:44'}, {'timestamp': '1693096268000000000', 'traffic_report_id': '64C84E952453CD25D3097C7CFB8BA8178A0D109F_1693096268', 'date_time': '2023-08-27 00:31:08+00:00', 'issue_reported': 'traffic hazard', 'location': 'POINT(-97.710022 30.346057)', 'latitude': '30.346057', 'longitude': '-97.710022', 'address': '600-709 w anderson ln svrd eb', 'weekday': 'Sunday', 'date': '2023-08-27', 'time': '00:31:08'}, {'timestamp': '1693096480000000000', 'traffic_report_id': 'EBA90709ED04EB27E4A042727D7DD308E44389E4_1693096480', 'date_time': '2023-08-27 00:34:40+00:00', 'issue_reported': 'crash urgent', 'location': 'POINT(-97.747224 30.450467)', 'latitude': '30.450467', 'longitude': '-97.747224', 'address': '6900 w parmer ln', 'weekday': 'Sunday', 'date': '2023-08-27', 'time': '00:34:40'}, {'timestamp': '1693096984000000000', 'traffic_report_id': '619683DB9EF9D4649743EE1DEDDB3923D6E5F704_1693096984', 'date_time': '2023-08-27 00:43:04+00:00', 'issue_reported': 'crash service', 'location': 'POINT(-97.712607 30.229429)', 'latitude': '30.229429', 'longitude': '-97.712607', 'address': '5353-5513 e riverside dr', 'weekday': 'Sunday', 'date': '2023-08-27', 'time': '00:43:04'}, {'timestamp': '1693097145000000000', 'traffic_report_id': '0EB7B29E307538E202BD733E1DF3A34884C5B5A8_1693097145', 'date_time': '2023-08-27 00:45:45+00:00', 'issue_reported': 'loose livestock', 'location': 'POINT(-97.616031 30.142508)', 'latitude': '30.142508', 'longitude': '-97.616031', 'address': '7941-7948 elroy rd', 'weekday': 'Sunday', 'date': '2023-08-27', 'time': '00:45:45'}, {'timestamp': '1693097737000000000', 'traffic_report_id': '2D97D80F5AF467CAF6A638D16C539634E7B1B7A1_1693097737', 'date_time': '2023-08-27 00:55:37+00:00', 'issue_reported': 'crash urgent', 'location': 'POINT(-97.712013 30.373957)', 'latitude': '30.373957', 'longitude': '-97.712013', 'address': '1652 rutland dr', 'weekday': 'Sunday', 'date': '2023-08-27', 'time': '00:55:37'}, {'timestamp': '1693097880000000000', 'traffic_report_id': '34C643598EAB0FE1BC1726E196C36057904DDA13_1693097880', 'date_time': '2023-08-27 00:58:00+00:00', 'issue_reported': 'traffic hazard', 'location': 'POINT(-97.806435 30.378758)', 'latitude': '30.378758', 'longitude': '-97.806435', 'address': '8000 fm 2222 rd', 'weekday': 'Sunday', 'date': '2023-08-27', 'time': '00:58:00'}  ... displaying 10 of 126 total bound parameter sets ...  {'timestamp': '1693179923000000000', 'traffic_report_id': 'E6BA73DC9533E190C71BFC3877414870457F1533_1693179923', 'date_time': '2023-08-27 23:45:23+00:00', 'issue_reported': 'crash urgent', 'location': 'POINT(-97.826954 30.236933)', 'latitude': '30.236933', 'longitude': '-97.826954', 'address': 'w us 290 hwy svrd wb', 'weekday': 'Sunday', 'date': '2023-08-27', 'time': '23:45:23'}, {'timestamp': '1693179950000000000', 'traffic_report_id': '5D22A80605A592F60F2CDE0BF0D59FF70A54A329_1693179950', 'date_time': '2023-08-27 23:45:50+00:00', 'issue_reported': 'traffic hazard', 'location': 'POINT(-97.777543 30.268903)', 'latitude': '30.268903', 'longitude': '-97.777543', 'address': '600 s mopac expy svrd sb', 'weekday': 'Sunday', 'date': '2023-08-27', 'time': '23:45:50'})]
[2023-08-30T20:05:59.287+0000] {subprocess.py:93} INFO - (Background on this error at: https://sqlalche.me/e/14/f405)
[2023-08-30T20:05:59.291+0000] {subprocess.py:97} INFO - Command exited with return code 1
[2023-08-30T20:05:59.311+0000] {taskinstance.py:1943} ERROR - Task failed with exception
Traceback (most recent call last):
  File "/home/airflow/.local/lib/python3.8/site-packages/airflow/operators/bash.py", line 210, in execute
    raise AirflowException(
airflow.exceptions.AirflowException: Bash command failed. The command returned a non-zero exit code 1.
[2023-08-30T20:05:59.319+0000] {taskinstance.py:1400} INFO - Marking task as UP_FOR_RETRY. dag_id=traffic_report, task_id=export_data_to_db, execution_date=20230828T000000, start_date=20230830T200558, end_date=20230830T200559
[2023-08-30T20:05:59.343+0000] {standard_task_runner.py:104} ERROR - Failed to execute job 23 for task export_data_to_db (Bash command failed. The command returned a non-zero exit code 1.; 539)
[2023-08-30T20:05:59.387+0000] {local_task_job_runner.py:228} INFO - Task exited with return code 1
[2023-08-30T20:05:59.404+0000] {taskinstance.py:2784} INFO - 0 downstream tasks scheduled from follow-on schedule check
[2023-08-30T20:33:59.755+0000] {logging_mixin.py:151} WARNING - /home/***/.local/lib/python3.8/site-packages/***/utils/sqlalchemy.py:124 DeprecationWarning: The sql_alchemy_conn option in [core] has been moved to the sql_alchemy_conn option in [database] - the old setting has been used, but please update your config.
[2023-08-30T20:33:59.770+0000] {taskinstance.py:1159} INFO - Dependencies all met for dep_context=non-requeueable deps ti=<TaskInstance: traffic_report.export_data_to_db scheduled__2023-08-28T00:00:00+00:00 [queued]>
[2023-08-30T20:33:59.784+0000] {taskinstance.py:1159} INFO - Dependencies all met for dep_context=requeueable deps ti=<TaskInstance: traffic_report.export_data_to_db scheduled__2023-08-28T00:00:00+00:00 [queued]>
[2023-08-30T20:33:59.785+0000] {taskinstance.py:1361} INFO - Starting attempt 1 of 2
[2023-08-30T20:33:59.810+0000] {taskinstance.py:1382} INFO - Executing <Task(BashOperator): export_data_to_db> on 2023-08-28 00:00:00+00:00
[2023-08-30T20:33:59.820+0000] {standard_task_runner.py:57} INFO - Started process 340 to run task
[2023-08-30T20:33:59.825+0000] {standard_task_runner.py:84} INFO - Running: ['***', 'tasks', 'run', 'traffic_report', 'export_data_to_db', 'scheduled__2023-08-28T00:00:00+00:00', '--job-id', '17', '--raw', '--subdir', 'DAGS_FOLDER/traffic_dag.py', '--cfg-path', '/tmp/tmprx5frmgf']
[2023-08-30T20:33:59.830+0000] {standard_task_runner.py:85} INFO - Job 17: Subtask export_data_to_db
[2023-08-30T20:33:59.865+0000] {logging_mixin.py:151} WARNING - /home/***/.local/lib/python3.8/site-packages/***/settings.py:195 DeprecationWarning: The sql_alchemy_conn option in [core] has been moved to the sql_alchemy_conn option in [database] - the old setting has been used, but please update your config.
[2023-08-30T20:33:59.919+0000] {task_command.py:415} INFO - Running <TaskInstance: traffic_report.export_data_to_db scheduled__2023-08-28T00:00:00+00:00 [running]> on host 961f38e8363e
[2023-08-30T20:33:59.943+0000] {logging_mixin.py:151} WARNING - /home/***/.local/lib/python3.8/site-packages/***/utils/sqlalchemy.py:124 DeprecationWarning: The sql_alchemy_conn option in [core] has been moved to the sql_alchemy_conn option in [database] - the old setting has been used, but please update your config.
[2023-08-30T20:34:00.038+0000] {taskinstance.py:1660} INFO - Exporting env vars: AIRFLOW_CTX_DAG_OWNER='***' AIRFLOW_CTX_DAG_ID='traffic_report' AIRFLOW_CTX_TASK_ID='export_data_to_db' AIRFLOW_CTX_EXECUTION_DATE='2023-08-28T00:00:00+00:00' AIRFLOW_CTX_TRY_NUMBER='1' AIRFLOW_CTX_DAG_RUN_ID='scheduled__2023-08-28T00:00:00+00:00'
[2023-08-30T20:34:00.045+0000] {subprocess.py:63} INFO - Tmp dir root location: /tmp
[2023-08-30T20:34:00.047+0000] {subprocess.py:75} INFO - Running command: ['/bin/bash', '-c', 'python /opt/***/dags/data_to_db.py --date 2023-08-28 --connection postgresql+psycopg2://***:***@postgres/***']
[2023-08-30T20:34:00.066+0000] {subprocess.py:86} INFO - Output:
[2023-08-30T20:34:01.099+0000] {subprocess.py:93} INFO - Traceback (most recent call last):
[2023-08-30T20:34:01.102+0000] {subprocess.py:93} INFO -   File "/home/***/.local/lib/python3.8/site-packages/sqlalchemy/engine/base.py", line 1890, in _execute_context
[2023-08-30T20:34:01.103+0000] {subprocess.py:93} INFO -     self.dialect.do_executemany(
[2023-08-30T20:34:01.104+0000] {subprocess.py:93} INFO -   File "/home/***/.local/lib/python3.8/site-packages/sqlalchemy/dialects/postgresql/psycopg2.py", line 982, in do_executemany
[2023-08-30T20:34:01.105+0000] {subprocess.py:93} INFO -     context._psycopg2_fetched_rows = xtras.execute_values(
[2023-08-30T20:34:01.107+0000] {subprocess.py:93} INFO -   File "/home/***/.local/lib/python3.8/site-packages/psycopg2/extras.py", line 1299, in execute_values
[2023-08-30T20:34:01.109+0000] {subprocess.py:93} INFO -     cur.execute(b''.join(parts))
[2023-08-30T20:34:01.111+0000] {subprocess.py:93} INFO - psycopg2.errors.UndefinedFunction: function st_geomfromewkt(unknown) does not exist
[2023-08-30T20:34:01.112+0000] {subprocess.py:93} INFO - LINE 1: ...35', '2023-08-27 00:00:35+00:00', 'crash urgent', ST_GeomFro...
[2023-08-30T20:34:01.113+0000] {subprocess.py:93} INFO -                                                              ^
[2023-08-30T20:34:01.115+0000] {subprocess.py:93} INFO - HINT:  No function matches the given name and argument types. You might need to add explicit type casts.
[2023-08-30T20:34:01.117+0000] {subprocess.py:93} INFO - 
[2023-08-30T20:34:01.118+0000] {subprocess.py:93} INFO - 
[2023-08-30T20:34:01.119+0000] {subprocess.py:93} INFO - The above exception was the direct cause of the following exception:
[2023-08-30T20:34:01.120+0000] {subprocess.py:93} INFO - 
[2023-08-30T20:34:01.121+0000] {subprocess.py:93} INFO - Traceback (most recent call last):
[2023-08-30T20:34:01.124+0000] {subprocess.py:93} INFO -   File "/opt/***/dags/data_to_db.py", line 50, in <module>
[2023-08-30T20:34:01.126+0000] {subprocess.py:93} INFO -     main(args.date, args.connection)
[2023-08-30T20:34:01.128+0000] {subprocess.py:93} INFO -   File "/opt/***/dags/data_to_db.py", line 41, in main
[2023-08-30T20:34:01.131+0000] {subprocess.py:93} INFO -     session.bulk_save_objects(data_insert)
[2023-08-30T20:34:01.132+0000] {subprocess.py:93} INFO -   File "/home/***/.local/lib/python3.8/site-packages/sqlalchemy/orm/session.py", line 3705, in bulk_save_objects
[2023-08-30T20:34:01.136+0000] {subprocess.py:93} INFO -     self._bulk_save_mappings(
[2023-08-30T20:34:01.138+0000] {subprocess.py:93} INFO -   File "/home/***/.local/lib/python3.8/site-packages/sqlalchemy/orm/session.py", line 3913, in _bulk_save_mappings
[2023-08-30T20:34:01.140+0000] {subprocess.py:93} INFO -     transaction.rollback(_capture_exception=True)
[2023-08-30T20:34:01.144+0000] {subprocess.py:93} INFO -   File "/home/***/.local/lib/python3.8/site-packages/sqlalchemy/util/langhelpers.py", line 70, in __exit__
[2023-08-30T20:34:01.146+0000] {subprocess.py:93} INFO -     compat.raise_(
[2023-08-30T20:34:01.147+0000] {subprocess.py:93} INFO -   File "/home/***/.local/lib/python3.8/site-packages/sqlalchemy/util/compat.py", line 211, in raise_
[2023-08-30T20:34:01.148+0000] {subprocess.py:93} INFO -     raise exception
[2023-08-30T20:34:01.150+0000] {subprocess.py:93} INFO -   File "/home/***/.local/lib/python3.8/site-packages/sqlalchemy/orm/session.py", line 3901, in _bulk_save_mappings
[2023-08-30T20:34:01.154+0000] {subprocess.py:93} INFO -     persistence._bulk_insert(
[2023-08-30T20:34:01.156+0000] {subprocess.py:93} INFO -   File "/home/***/.local/lib/python3.8/site-packages/sqlalchemy/orm/persistence.py", line 107, in _bulk_insert
[2023-08-30T20:34:01.157+0000] {subprocess.py:93} INFO -     _emit_insert_statements(
[2023-08-30T20:34:01.158+0000] {subprocess.py:93} INFO -   File "/home/***/.local/lib/python3.8/site-packages/sqlalchemy/orm/persistence.py", line 1097, in _emit_insert_statements
[2023-08-30T20:34:01.160+0000] {subprocess.py:93} INFO -     c = connection._execute_20(
[2023-08-30T20:34:01.164+0000] {subprocess.py:93} INFO -   File "/home/***/.local/lib/python3.8/site-packages/sqlalchemy/engine/base.py", line 1710, in _execute_20
[2023-08-30T20:34:01.165+0000] {subprocess.py:93} INFO -     return meth(self, args_10style, kwargs_10style, execution_options)
[2023-08-30T20:34:01.166+0000] {subprocess.py:93} INFO -   File "/home/***/.local/lib/python3.8/site-packages/sqlalchemy/sql/elements.py", line 334, in _execute_on_connection
[2023-08-30T20:34:01.170+0000] {subprocess.py:93} INFO -     return connection._execute_clauseelement(
[2023-08-30T20:34:01.172+0000] {subprocess.py:93} INFO -   File "/home/***/.local/lib/python3.8/site-packages/sqlalchemy/engine/base.py", line 1577, in _execute_clauseelement
[2023-08-30T20:34:01.174+0000] {subprocess.py:93} INFO -     ret = self._execute_context(
[2023-08-30T20:34:01.176+0000] {subprocess.py:93} INFO -   File "/home/***/.local/lib/python3.8/site-packages/sqlalchemy/engine/base.py", line 1953, in _execute_context
[2023-08-30T20:34:01.177+0000] {subprocess.py:93} INFO -     self._handle_dbapi_exception(
[2023-08-30T20:34:01.178+0000] {subprocess.py:93} INFO -   File "/home/***/.local/lib/python3.8/site-packages/sqlalchemy/engine/base.py", line 2134, in _handle_dbapi_exception
[2023-08-30T20:34:01.179+0000] {subprocess.py:93} INFO -     util.raise_(
[2023-08-30T20:34:01.183+0000] {subprocess.py:93} INFO -   File "/home/***/.local/lib/python3.8/site-packages/sqlalchemy/util/compat.py", line 211, in raise_
[2023-08-30T20:34:01.186+0000] {subprocess.py:93} INFO -     raise exception
[2023-08-30T20:34:01.188+0000] {subprocess.py:93} INFO -   File "/home/***/.local/lib/python3.8/site-packages/sqlalchemy/engine/base.py", line 1890, in _execute_context
[2023-08-30T20:34:01.189+0000] {subprocess.py:93} INFO -     self.dialect.do_executemany(
[2023-08-30T20:34:01.191+0000] {subprocess.py:93} INFO -   File "/home/***/.local/lib/python3.8/site-packages/sqlalchemy/dialects/postgresql/psycopg2.py", line 982, in do_executemany
[2023-08-30T20:34:01.192+0000] {subprocess.py:93} INFO -     context._psycopg2_fetched_rows = xtras.execute_values(
[2023-08-30T20:34:01.194+0000] {subprocess.py:93} INFO -   File "/home/***/.local/lib/python3.8/site-packages/psycopg2/extras.py", line 1299, in execute_values
[2023-08-30T20:34:01.196+0000] {subprocess.py:93} INFO -     cur.execute(b''.join(parts))
[2023-08-30T20:34:01.197+0000] {subprocess.py:93} INFO - sqlalchemy.exc.ProgrammingError: (psycopg2.errors.UndefinedFunction) function st_geomfromewkt(unknown) does not exist
[2023-08-30T20:34:01.203+0000] {subprocess.py:93} INFO - LINE 1: ...35', '2023-08-27 00:00:35+00:00', 'crash urgent', ST_GeomFro...
[2023-08-30T20:34:01.206+0000] {subprocess.py:93} INFO -                                                              ^
[2023-08-30T20:34:01.209+0000] {subprocess.py:93} INFO - HINT:  No function matches the given name and argument types. You might need to add explicit type casts.
[2023-08-30T20:34:01.216+0000] {subprocess.py:93} INFO - 
[2023-08-30T20:34:01.219+0000] {subprocess.py:93} INFO - [SQL: INSERT INTO traffic_report (timestamp, traffic_report_id, date_time, issue_reported, location, latitude, longitude, address, weekday, date, time) VALUES (%(timestamp)s, %(traffic_report_id)s, %(date_time)s, %(issue_reported)s, ST_GeomFromEWKT(%(location)s), %(latitude)s, %(longitude)s, %(address)s, %(weekday)s, %(date)s, %(time)s)]
[2023-08-30T20:34:01.226+0000] {subprocess.py:93} INFO - [parameters: ({'timestamp': '1693094435000000000', 'traffic_report_id': '67DE6A669490F0E6BF9D405BA4C66A2CD17CC2FF_1693094435', 'date_time': '2023-08-27 00:00:35+00:00', 'issue_reported': 'crash urgent', 'location': 'POINT(-97.818156 30.461507)', 'latitude': '30.461507', 'longitude': '-97.818156', 'address': '12109-12131 n fm 620 rd', 'weekday': 'Sunday', 'date': '2023-08-27', 'time': '00:00:35'}, {'timestamp': '1693095284000000000', 'traffic_report_id': '5F5898E4726001663BA5A126B313B03B1AED3F07_1693095284', 'date_time': '2023-08-27 00:14:44+00:00', 'issue_reported': 'collision', 'location': 'POINT(-97.525802 30.345376)', 'latitude': '30.345376', 'longitude': '-97.525802', 'address': '12700-13009 ceder st', 'weekday': 'Sunday', 'date': '2023-08-27', 'time': '00:14:44'}, {'timestamp': '1693096268000000000', 'traffic_report_id': '64C84E952453CD25D3097C7CFB8BA8178A0D109F_1693096268', 'date_time': '2023-08-27 00:31:08+00:00', 'issue_reported': 'traffic hazard', 'location': 'POINT(-97.710022 30.346057)', 'latitude': '30.346057', 'longitude': '-97.710022', 'address': '600-709 w anderson ln svrd eb', 'weekday': 'Sunday', 'date': '2023-08-27', 'time': '00:31:08'}, {'timestamp': '1693096480000000000', 'traffic_report_id': 'EBA90709ED04EB27E4A042727D7DD308E44389E4_1693096480', 'date_time': '2023-08-27 00:34:40+00:00', 'issue_reported': 'crash urgent', 'location': 'POINT(-97.747224 30.450467)', 'latitude': '30.450467', 'longitude': '-97.747224', 'address': '6900 w parmer ln', 'weekday': 'Sunday', 'date': '2023-08-27', 'time': '00:34:40'}, {'timestamp': '1693096984000000000', 'traffic_report_id': '619683DB9EF9D4649743EE1DEDDB3923D6E5F704_1693096984', 'date_time': '2023-08-27 00:43:04+00:00', 'issue_reported': 'crash service', 'location': 'POINT(-97.712607 30.229429)', 'latitude': '30.229429', 'longitude': '-97.712607', 'address': '5353-5513 e riverside dr', 'weekday': 'Sunday', 'date': '2023-08-27', 'time': '00:43:04'}, {'timestamp': '1693097145000000000', 'traffic_report_id': '0EB7B29E307538E202BD733E1DF3A34884C5B5A8_1693097145', 'date_time': '2023-08-27 00:45:45+00:00', 'issue_reported': 'loose livestock', 'location': 'POINT(-97.616031 30.142508)', 'latitude': '30.142508', 'longitude': '-97.616031', 'address': '7941-7948 elroy rd', 'weekday': 'Sunday', 'date': '2023-08-27', 'time': '00:45:45'}, {'timestamp': '1693097737000000000', 'traffic_report_id': '2D97D80F5AF467CAF6A638D16C539634E7B1B7A1_1693097737', 'date_time': '2023-08-27 00:55:37+00:00', 'issue_reported': 'crash urgent', 'location': 'POINT(-97.712013 30.373957)', 'latitude': '30.373957', 'longitude': '-97.712013', 'address': '1652 rutland dr', 'weekday': 'Sunday', 'date': '2023-08-27', 'time': '00:55:37'}, {'timestamp': '1693097880000000000', 'traffic_report_id': '34C643598EAB0FE1BC1726E196C36057904DDA13_1693097880', 'date_time': '2023-08-27 00:58:00+00:00', 'issue_reported': 'traffic hazard', 'location': 'POINT(-97.806435 30.378758)', 'latitude': '30.378758', 'longitude': '-97.806435', 'address': '8000 fm 2222 rd', 'weekday': 'Sunday', 'date': '2023-08-27', 'time': '00:58:00'}  ... displaying 10 of 126 total bound parameter sets ...  {'timestamp': '1693179923000000000', 'traffic_report_id': 'E6BA73DC9533E190C71BFC3877414870457F1533_1693179923', 'date_time': '2023-08-27 23:45:23+00:00', 'issue_reported': 'crash urgent', 'location': 'POINT(-97.826954 30.236933)', 'latitude': '30.236933', 'longitude': '-97.826954', 'address': 'w us 290 hwy svrd wb', 'weekday': 'Sunday', 'date': '2023-08-27', 'time': '23:45:23'}, {'timestamp': '1693179950000000000', 'traffic_report_id': '5D22A80605A592F60F2CDE0BF0D59FF70A54A329_1693179950', 'date_time': '2023-08-27 23:45:50+00:00', 'issue_reported': 'traffic hazard', 'location': 'POINT(-97.777543 30.268903)', 'latitude': '30.268903', 'longitude': '-97.777543', 'address': '600 s mopac expy svrd sb', 'weekday': 'Sunday', 'date': '2023-08-27', 'time': '23:45:50'})]
[2023-08-30T20:34:01.229+0000] {subprocess.py:93} INFO - (Background on this error at: https://sqlalche.me/e/14/f405)
[2023-08-30T20:34:01.325+0000] {subprocess.py:97} INFO - Command exited with return code 1
[2023-08-30T20:34:01.340+0000] {taskinstance.py:1943} ERROR - Task failed with exception
Traceback (most recent call last):
  File "/home/airflow/.local/lib/python3.8/site-packages/airflow/operators/bash.py", line 210, in execute
    raise AirflowException(
airflow.exceptions.AirflowException: Bash command failed. The command returned a non-zero exit code 1.
[2023-08-30T20:34:01.345+0000] {taskinstance.py:1400} INFO - Marking task as UP_FOR_RETRY. dag_id=traffic_report, task_id=export_data_to_db, execution_date=20230828T000000, start_date=20230830T203359, end_date=20230830T203401
[2023-08-30T20:34:01.364+0000] {standard_task_runner.py:104} ERROR - Failed to execute job 17 for task export_data_to_db (Bash command failed. The command returned a non-zero exit code 1.; 340)
[2023-08-30T20:34:01.406+0000] {local_task_job_runner.py:228} INFO - Task exited with return code 1
[2023-08-30T20:34:01.435+0000] {taskinstance.py:2784} INFO - 0 downstream tasks scheduled from follow-on schedule check
[2023-08-30T20:48:32.602+0000] {logging_mixin.py:151} WARNING - /home/***/.local/lib/python3.8/site-packages/***/utils/sqlalchemy.py:124 DeprecationWarning: The sql_alchemy_conn option in [core] has been moved to the sql_alchemy_conn option in [database] - the old setting has been used, but please update your config.
[2023-08-30T20:48:32.616+0000] {taskinstance.py:1159} INFO - Dependencies all met for dep_context=non-requeueable deps ti=<TaskInstance: traffic_report.export_data_to_db scheduled__2023-08-28T00:00:00+00:00 [queued]>
[2023-08-30T20:48:32.626+0000] {taskinstance.py:1159} INFO - Dependencies all met for dep_context=requeueable deps ti=<TaskInstance: traffic_report.export_data_to_db scheduled__2023-08-28T00:00:00+00:00 [queued]>
[2023-08-30T20:48:32.627+0000] {taskinstance.py:1361} INFO - Starting attempt 1 of 2
[2023-08-30T20:48:32.643+0000] {taskinstance.py:1382} INFO - Executing <Task(BashOperator): export_data_to_db> on 2023-08-28 00:00:00+00:00
[2023-08-30T20:48:32.648+0000] {standard_task_runner.py:57} INFO - Started process 392 to run task
[2023-08-30T20:48:32.653+0000] {standard_task_runner.py:84} INFO - Running: ['***', 'tasks', 'run', 'traffic_report', 'export_data_to_db', 'scheduled__2023-08-28T00:00:00+00:00', '--job-id', '16', '--raw', '--subdir', 'DAGS_FOLDER/traffic_dag.py', '--cfg-path', '/tmp/tmpe_uuf94b']
[2023-08-30T20:48:32.656+0000] {standard_task_runner.py:85} INFO - Job 16: Subtask export_data_to_db
[2023-08-30T20:48:32.681+0000] {logging_mixin.py:151} WARNING - /home/***/.local/lib/python3.8/site-packages/***/settings.py:195 DeprecationWarning: The sql_alchemy_conn option in [core] has been moved to the sql_alchemy_conn option in [database] - the old setting has been used, but please update your config.
[2023-08-30T20:48:32.739+0000] {task_command.py:415} INFO - Running <TaskInstance: traffic_report.export_data_to_db scheduled__2023-08-28T00:00:00+00:00 [running]> on host 8f66711a2898
[2023-08-30T20:48:32.757+0000] {logging_mixin.py:151} WARNING - /home/***/.local/lib/python3.8/site-packages/***/utils/sqlalchemy.py:124 DeprecationWarning: The sql_alchemy_conn option in [core] has been moved to the sql_alchemy_conn option in [database] - the old setting has been used, but please update your config.
[2023-08-30T20:48:32.832+0000] {taskinstance.py:1660} INFO - Exporting env vars: AIRFLOW_CTX_DAG_OWNER='***' AIRFLOW_CTX_DAG_ID='traffic_report' AIRFLOW_CTX_TASK_ID='export_data_to_db' AIRFLOW_CTX_EXECUTION_DATE='2023-08-28T00:00:00+00:00' AIRFLOW_CTX_TRY_NUMBER='1' AIRFLOW_CTX_DAG_RUN_ID='scheduled__2023-08-28T00:00:00+00:00'
[2023-08-30T20:48:32.844+0000] {subprocess.py:63} INFO - Tmp dir root location: /tmp
[2023-08-30T20:48:32.847+0000] {subprocess.py:75} INFO - Running command: ['/bin/bash', '-c', 'python /opt/***/dags/data_to_db.py --date 2023-08-28 --connection postgresql+psycopg2://***:***@postgres/***']
[2023-08-30T20:48:32.867+0000] {subprocess.py:86} INFO - Output:
[2023-08-30T20:48:33.515+0000] {subprocess.py:93} INFO - Traceback (most recent call last):
[2023-08-30T20:48:33.518+0000] {subprocess.py:93} INFO -   File "/home/***/.local/lib/python3.8/site-packages/sqlalchemy/engine/base.py", line 1890, in _execute_context
[2023-08-30T20:48:33.520+0000] {subprocess.py:93} INFO -     self.dialect.do_executemany(
[2023-08-30T20:48:33.523+0000] {subprocess.py:93} INFO -   File "/home/***/.local/lib/python3.8/site-packages/sqlalchemy/dialects/postgresql/psycopg2.py", line 982, in do_executemany
[2023-08-30T20:48:33.525+0000] {subprocess.py:93} INFO -     context._psycopg2_fetched_rows = xtras.execute_values(
[2023-08-30T20:48:33.533+0000] {subprocess.py:93} INFO -   File "/home/***/.local/lib/python3.8/site-packages/psycopg2/extras.py", line 1299, in execute_values
[2023-08-30T20:48:33.537+0000] {subprocess.py:93} INFO -     cur.execute(b''.join(parts))
[2023-08-30T20:48:33.538+0000] {subprocess.py:93} INFO - psycopg2.errors.NumericValueOutOfRange: value "1693094435000000000" is out of range for type integer
[2023-08-30T20:48:33.547+0000] {subprocess.py:93} INFO - LINE 1: ... longitude, address, weekday, date, time) VALUES ('169309443...
[2023-08-30T20:48:33.548+0000] {subprocess.py:93} INFO -                                                              ^
[2023-08-30T20:48:33.551+0000] {subprocess.py:93} INFO - 
[2023-08-30T20:48:33.554+0000] {subprocess.py:93} INFO - 
[2023-08-30T20:48:33.559+0000] {subprocess.py:93} INFO - The above exception was the direct cause of the following exception:
[2023-08-30T20:48:33.560+0000] {subprocess.py:93} INFO - 
[2023-08-30T20:48:33.562+0000] {subprocess.py:93} INFO - Traceback (most recent call last):
[2023-08-30T20:48:33.564+0000] {subprocess.py:93} INFO -   File "/opt/***/dags/data_to_db.py", line 49, in <module>
[2023-08-30T20:48:33.566+0000] {subprocess.py:93} INFO -     main(args.date, args.connection)
[2023-08-30T20:48:33.568+0000] {subprocess.py:93} INFO -   File "/opt/***/dags/data_to_db.py", line 40, in main
[2023-08-30T20:48:33.570+0000] {subprocess.py:93} INFO -     session.bulk_save_objects(data_insert)
[2023-08-30T20:48:33.572+0000] {subprocess.py:93} INFO -   File "/home/***/.local/lib/python3.8/site-packages/sqlalchemy/orm/session.py", line 3705, in bulk_save_objects
[2023-08-30T20:48:33.574+0000] {subprocess.py:93} INFO -     self._bulk_save_mappings(
[2023-08-30T20:48:33.576+0000] {subprocess.py:93} INFO -   File "/home/***/.local/lib/python3.8/site-packages/sqlalchemy/orm/session.py", line 3913, in _bulk_save_mappings
[2023-08-30T20:48:33.578+0000] {subprocess.py:93} INFO -     transaction.rollback(_capture_exception=True)
[2023-08-30T20:48:33.583+0000] {subprocess.py:93} INFO -   File "/home/***/.local/lib/python3.8/site-packages/sqlalchemy/util/langhelpers.py", line 70, in __exit__
[2023-08-30T20:48:33.585+0000] {subprocess.py:93} INFO -     compat.raise_(
[2023-08-30T20:48:33.586+0000] {subprocess.py:93} INFO -   File "/home/***/.local/lib/python3.8/site-packages/sqlalchemy/util/compat.py", line 211, in raise_
[2023-08-30T20:48:33.588+0000] {subprocess.py:93} INFO -     raise exception
[2023-08-30T20:48:33.590+0000] {subprocess.py:93} INFO -   File "/home/***/.local/lib/python3.8/site-packages/sqlalchemy/orm/session.py", line 3901, in _bulk_save_mappings
[2023-08-30T20:48:33.591+0000] {subprocess.py:93} INFO -     persistence._bulk_insert(
[2023-08-30T20:48:33.592+0000] {subprocess.py:93} INFO -   File "/home/***/.local/lib/python3.8/site-packages/sqlalchemy/orm/persistence.py", line 107, in _bulk_insert
[2023-08-30T20:48:33.593+0000] {subprocess.py:93} INFO -     _emit_insert_statements(
[2023-08-30T20:48:33.595+0000] {subprocess.py:93} INFO -   File "/home/***/.local/lib/python3.8/site-packages/sqlalchemy/orm/persistence.py", line 1097, in _emit_insert_statements
[2023-08-30T20:48:33.596+0000] {subprocess.py:93} INFO -     c = connection._execute_20(
[2023-08-30T20:48:33.598+0000] {subprocess.py:93} INFO -   File "/home/***/.local/lib/python3.8/site-packages/sqlalchemy/engine/base.py", line 1710, in _execute_20
[2023-08-30T20:48:33.599+0000] {subprocess.py:93} INFO -     return meth(self, args_10style, kwargs_10style, execution_options)
[2023-08-30T20:48:33.602+0000] {subprocess.py:93} INFO -   File "/home/***/.local/lib/python3.8/site-packages/sqlalchemy/sql/elements.py", line 334, in _execute_on_connection
[2023-08-30T20:48:33.603+0000] {subprocess.py:93} INFO -     return connection._execute_clauseelement(
[2023-08-30T20:48:33.605+0000] {subprocess.py:93} INFO -   File "/home/***/.local/lib/python3.8/site-packages/sqlalchemy/engine/base.py", line 1577, in _execute_clauseelement
[2023-08-30T20:48:33.606+0000] {subprocess.py:93} INFO -     ret = self._execute_context(
[2023-08-30T20:48:33.608+0000] {subprocess.py:93} INFO -   File "/home/***/.local/lib/python3.8/site-packages/sqlalchemy/engine/base.py", line 1953, in _execute_context
[2023-08-30T20:48:33.609+0000] {subprocess.py:93} INFO -     self._handle_dbapi_exception(
[2023-08-30T20:48:33.610+0000] {subprocess.py:93} INFO -   File "/home/***/.local/lib/python3.8/site-packages/sqlalchemy/engine/base.py", line 2134, in _handle_dbapi_exception
[2023-08-30T20:48:33.612+0000] {subprocess.py:93} INFO -     util.raise_(
[2023-08-30T20:48:33.613+0000] {subprocess.py:93} INFO -   File "/home/***/.local/lib/python3.8/site-packages/sqlalchemy/util/compat.py", line 211, in raise_
[2023-08-30T20:48:33.616+0000] {subprocess.py:93} INFO -     raise exception
[2023-08-30T20:48:33.618+0000] {subprocess.py:93} INFO -   File "/home/***/.local/lib/python3.8/site-packages/sqlalchemy/engine/base.py", line 1890, in _execute_context
[2023-08-30T20:48:33.620+0000] {subprocess.py:93} INFO -     self.dialect.do_executemany(
[2023-08-30T20:48:33.621+0000] {subprocess.py:93} INFO -   File "/home/***/.local/lib/python3.8/site-packages/sqlalchemy/dialects/postgresql/psycopg2.py", line 982, in do_executemany
[2023-08-30T20:48:33.624+0000] {subprocess.py:93} INFO -     context._psycopg2_fetched_rows = xtras.execute_values(
[2023-08-30T20:48:33.625+0000] {subprocess.py:93} INFO -   File "/home/***/.local/lib/python3.8/site-packages/psycopg2/extras.py", line 1299, in execute_values
[2023-08-30T20:48:33.626+0000] {subprocess.py:93} INFO -     cur.execute(b''.join(parts))
[2023-08-30T20:48:33.627+0000] {subprocess.py:93} INFO - sqlalchemy.exc.DataError: (psycopg2.errors.NumericValueOutOfRange) value "1693094435000000000" is out of range for type integer
[2023-08-30T20:48:33.629+0000] {subprocess.py:93} INFO - LINE 1: ... longitude, address, weekday, date, time) VALUES ('169309443...
[2023-08-30T20:48:33.630+0000] {subprocess.py:93} INFO -                                                              ^
[2023-08-30T20:48:33.631+0000] {subprocess.py:93} INFO - 
[2023-08-30T20:48:33.633+0000] {subprocess.py:93} INFO - [SQL: INSERT INTO traffic_report (timestamp, traffic_report_id, date_time, issue_reported, latitude, longitude, address, weekday, date, time) VALUES (%(timestamp)s, %(traffic_report_id)s, %(date_time)s, %(issue_reported)s, %(latitude)s, %(longitude)s, %(address)s, %(weekday)s, %(date)s, %(time)s)]
[2023-08-30T20:48:33.634+0000] {subprocess.py:93} INFO - [parameters: ({'timestamp': '1693094435000000000', 'traffic_report_id': '67DE6A669490F0E6BF9D405BA4C66A2CD17CC2FF_1693094435', 'date_time': '2023-08-27 00:00:35+00:00', 'issue_reported': 'crash urgent', 'latitude': '30.461507', 'longitude': '-97.818156', 'address': '12109-12131 n fm 620 rd', 'weekday': 'Sunday', 'date': '2023-08-27', 'time': '00:00:35'}, {'timestamp': '1693095284000000000', 'traffic_report_id': '5F5898E4726001663BA5A126B313B03B1AED3F07_1693095284', 'date_time': '2023-08-27 00:14:44+00:00', 'issue_reported': 'collision', 'latitude': '30.345376', 'longitude': '-97.525802', 'address': '12700-13009 ceder st', 'weekday': 'Sunday', 'date': '2023-08-27', 'time': '00:14:44'}, {'timestamp': '1693096268000000000', 'traffic_report_id': '64C84E952453CD25D3097C7CFB8BA8178A0D109F_1693096268', 'date_time': '2023-08-27 00:31:08+00:00', 'issue_reported': 'traffic hazard', 'latitude': '30.346057', 'longitude': '-97.710022', 'address': '600-709 w anderson ln svrd eb', 'weekday': 'Sunday', 'date': '2023-08-27', 'time': '00:31:08'}, {'timestamp': '1693096480000000000', 'traffic_report_id': 'EBA90709ED04EB27E4A042727D7DD308E44389E4_1693096480', 'date_time': '2023-08-27 00:34:40+00:00', 'issue_reported': 'crash urgent', 'latitude': '30.450467', 'longitude': '-97.747224', 'address': '6900 w parmer ln', 'weekday': 'Sunday', 'date': '2023-08-27', 'time': '00:34:40'}, {'timestamp': '1693096984000000000', 'traffic_report_id': '619683DB9EF9D4649743EE1DEDDB3923D6E5F704_1693096984', 'date_time': '2023-08-27 00:43:04+00:00', 'issue_reported': 'crash service', 'latitude': '30.229429', 'longitude': '-97.712607', 'address': '5353-5513 e riverside dr', 'weekday': 'Sunday', 'date': '2023-08-27', 'time': '00:43:04'}, {'timestamp': '1693097145000000000', 'traffic_report_id': '0EB7B29E307538E202BD733E1DF3A34884C5B5A8_1693097145', 'date_time': '2023-08-27 00:45:45+00:00', 'issue_reported': 'loose livestock', 'latitude': '30.142508', 'longitude': '-97.616031', 'address': '7941-7948 elroy rd', 'weekday': 'Sunday', 'date': '2023-08-27', 'time': '00:45:45'}, {'timestamp': '1693097737000000000', 'traffic_report_id': '2D97D80F5AF467CAF6A638D16C539634E7B1B7A1_1693097737', 'date_time': '2023-08-27 00:55:37+00:00', 'issue_reported': 'crash urgent', 'latitude': '30.373957', 'longitude': '-97.712013', 'address': '1652 rutland dr', 'weekday': 'Sunday', 'date': '2023-08-27', 'time': '00:55:37'}, {'timestamp': '1693097880000000000', 'traffic_report_id': '34C643598EAB0FE1BC1726E196C36057904DDA13_1693097880', 'date_time': '2023-08-27 00:58:00+00:00', 'issue_reported': 'traffic hazard', 'latitude': '30.378758', 'longitude': '-97.806435', 'address': '8000 fm 2222 rd', 'weekday': 'Sunday', 'date': '2023-08-27', 'time': '00:58:00'}  ... displaying 10 of 126 total bound parameter sets ...  {'timestamp': '1693179923000000000', 'traffic_report_id': 'E6BA73DC9533E190C71BFC3877414870457F1533_1693179923', 'date_time': '2023-08-27 23:45:23+00:00', 'issue_reported': 'crash urgent', 'latitude': '30.236933', 'longitude': '-97.826954', 'address': 'w us 290 hwy svrd wb', 'weekday': 'Sunday', 'date': '2023-08-27', 'time': '23:45:23'}, {'timestamp': '1693179950000000000', 'traffic_report_id': '5D22A80605A592F60F2CDE0BF0D59FF70A54A329_1693179950', 'date_time': '2023-08-27 23:45:50+00:00', 'issue_reported': 'traffic hazard', 'latitude': '30.268903', 'longitude': '-97.777543', 'address': '600 s mopac expy svrd sb', 'weekday': 'Sunday', 'date': '2023-08-27', 'time': '23:45:50'})]
[2023-08-30T20:48:33.635+0000] {subprocess.py:93} INFO - (Background on this error at: https://sqlalche.me/e/14/9h9h)
[2023-08-30T20:48:33.637+0000] {subprocess.py:97} INFO - Command exited with return code 1
[2023-08-30T20:48:33.668+0000] {taskinstance.py:1943} ERROR - Task failed with exception
Traceback (most recent call last):
  File "/home/airflow/.local/lib/python3.8/site-packages/airflow/operators/bash.py", line 210, in execute
    raise AirflowException(
airflow.exceptions.AirflowException: Bash command failed. The command returned a non-zero exit code 1.
[2023-08-30T20:48:33.672+0000] {taskinstance.py:1400} INFO - Marking task as UP_FOR_RETRY. dag_id=traffic_report, task_id=export_data_to_db, execution_date=20230828T000000, start_date=20230830T204832, end_date=20230830T204833
[2023-08-30T20:48:33.691+0000] {standard_task_runner.py:104} ERROR - Failed to execute job 16 for task export_data_to_db (Bash command failed. The command returned a non-zero exit code 1.; 392)
[2023-08-30T20:48:33.716+0000] {local_task_job_runner.py:228} INFO - Task exited with return code 1
[2023-08-30T20:48:33.742+0000] {taskinstance.py:2784} INFO - 0 downstream tasks scheduled from follow-on schedule check
[2023-08-30T21:07:56.277+0000] {logging_mixin.py:151} WARNING - /home/***/.local/lib/python3.8/site-packages/***/utils/sqlalchemy.py:124 DeprecationWarning: The sql_alchemy_conn option in [core] has been moved to the sql_alchemy_conn option in [database] - the old setting has been used, but please update your config.
[2023-08-30T21:07:56.287+0000] {taskinstance.py:1159} INFO - Dependencies all met for dep_context=non-requeueable deps ti=<TaskInstance: traffic_report.export_data_to_db scheduled__2023-08-28T00:00:00+00:00 [queued]>
[2023-08-30T21:07:56.296+0000] {taskinstance.py:1159} INFO - Dependencies all met for dep_context=requeueable deps ti=<TaskInstance: traffic_report.export_data_to_db scheduled__2023-08-28T00:00:00+00:00 [queued]>
[2023-08-30T21:07:56.297+0000] {taskinstance.py:1361} INFO - Starting attempt 1 of 2
[2023-08-30T21:07:56.311+0000] {taskinstance.py:1382} INFO - Executing <Task(BashOperator): export_data_to_db> on 2023-08-28 00:00:00+00:00
[2023-08-30T21:07:56.318+0000] {standard_task_runner.py:57} INFO - Started process 364 to run task
[2023-08-30T21:07:56.323+0000] {standard_task_runner.py:84} INFO - Running: ['***', 'tasks', 'run', 'traffic_report', 'export_data_to_db', 'scheduled__2023-08-28T00:00:00+00:00', '--job-id', '18', '--raw', '--subdir', 'DAGS_FOLDER/traffic_dag.py', '--cfg-path', '/tmp/tmp1a95_ngz']
[2023-08-30T21:07:56.329+0000] {standard_task_runner.py:85} INFO - Job 18: Subtask export_data_to_db
[2023-08-30T21:07:56.353+0000] {logging_mixin.py:151} WARNING - /home/***/.local/lib/python3.8/site-packages/***/settings.py:195 DeprecationWarning: The sql_alchemy_conn option in [core] has been moved to the sql_alchemy_conn option in [database] - the old setting has been used, but please update your config.
[2023-08-30T21:07:56.416+0000] {task_command.py:415} INFO - Running <TaskInstance: traffic_report.export_data_to_db scheduled__2023-08-28T00:00:00+00:00 [running]> on host cbc745b7550b
[2023-08-30T21:07:56.439+0000] {logging_mixin.py:151} WARNING - /home/***/.local/lib/python3.8/site-packages/***/utils/sqlalchemy.py:124 DeprecationWarning: The sql_alchemy_conn option in [core] has been moved to the sql_alchemy_conn option in [database] - the old setting has been used, but please update your config.
[2023-08-30T21:07:56.527+0000] {taskinstance.py:1660} INFO - Exporting env vars: AIRFLOW_CTX_DAG_OWNER='***' AIRFLOW_CTX_DAG_ID='traffic_report' AIRFLOW_CTX_TASK_ID='export_data_to_db' AIRFLOW_CTX_EXECUTION_DATE='2023-08-28T00:00:00+00:00' AIRFLOW_CTX_TRY_NUMBER='1' AIRFLOW_CTX_DAG_RUN_ID='scheduled__2023-08-28T00:00:00+00:00'
[2023-08-30T21:07:56.531+0000] {subprocess.py:63} INFO - Tmp dir root location: /tmp
[2023-08-30T21:07:56.532+0000] {subprocess.py:75} INFO - Running command: ['/bin/bash', '-c', 'python /opt/***/dags/data_to_db.py --date 2023-08-28 --connection postgresql+psycopg2://***:***@postgres/***']
[2023-08-30T21:07:56.560+0000] {subprocess.py:86} INFO - Output:
[2023-08-30T21:07:57.270+0000] {subprocess.py:93} INFO - Traceback (most recent call last):
[2023-08-30T21:07:57.275+0000] {subprocess.py:93} INFO -   File "/home/***/.local/lib/python3.8/site-packages/sqlalchemy/engine/base.py", line 1890, in _execute_context
[2023-08-30T21:07:57.277+0000] {subprocess.py:93} INFO -     self.dialect.do_executemany(
[2023-08-30T21:07:57.280+0000] {subprocess.py:93} INFO -   File "/home/***/.local/lib/python3.8/site-packages/sqlalchemy/dialects/postgresql/psycopg2.py", line 982, in do_executemany
[2023-08-30T21:07:57.283+0000] {subprocess.py:93} INFO -     context._psycopg2_fetched_rows = xtras.execute_values(
[2023-08-30T21:07:57.285+0000] {subprocess.py:93} INFO -   File "/home/***/.local/lib/python3.8/site-packages/psycopg2/extras.py", line 1299, in execute_values
[2023-08-30T21:07:57.288+0000] {subprocess.py:93} INFO -     cur.execute(b''.join(parts))
[2023-08-30T21:07:57.289+0000] {subprocess.py:93} INFO - psycopg2.errors.StringDataRightTruncation: value too long for type character varying(20)
[2023-08-30T21:07:57.291+0000] {subprocess.py:93} INFO - 
[2023-08-30T21:07:57.292+0000] {subprocess.py:93} INFO - 
[2023-08-30T21:07:57.294+0000] {subprocess.py:93} INFO - The above exception was the direct cause of the following exception:
[2023-08-30T21:07:57.295+0000] {subprocess.py:93} INFO - 
[2023-08-30T21:07:57.296+0000] {subprocess.py:93} INFO - Traceback (most recent call last):
[2023-08-30T21:07:57.297+0000] {subprocess.py:93} INFO -   File "/opt/***/dags/data_to_db.py", line 49, in <module>
[2023-08-30T21:07:57.299+0000] {subprocess.py:93} INFO -     main(args.date, args.connection)
[2023-08-30T21:07:57.300+0000] {subprocess.py:93} INFO -   File "/opt/***/dags/data_to_db.py", line 40, in main
[2023-08-30T21:07:57.302+0000] {subprocess.py:93} INFO -     session.bulk_save_objects(data_insert)
[2023-08-30T21:07:57.303+0000] {subprocess.py:93} INFO -   File "/home/***/.local/lib/python3.8/site-packages/sqlalchemy/orm/session.py", line 3705, in bulk_save_objects
[2023-08-30T21:07:57.305+0000] {subprocess.py:93} INFO -     self._bulk_save_mappings(
[2023-08-30T21:07:57.306+0000] {subprocess.py:93} INFO -   File "/home/***/.local/lib/python3.8/site-packages/sqlalchemy/orm/session.py", line 3913, in _bulk_save_mappings
[2023-08-30T21:07:57.308+0000] {subprocess.py:93} INFO -     transaction.rollback(_capture_exception=True)
[2023-08-30T21:07:57.309+0000] {subprocess.py:93} INFO -   File "/home/***/.local/lib/python3.8/site-packages/sqlalchemy/util/langhelpers.py", line 70, in __exit__
[2023-08-30T21:07:57.310+0000] {subprocess.py:93} INFO -     compat.raise_(
[2023-08-30T21:07:57.311+0000] {subprocess.py:93} INFO -   File "/home/***/.local/lib/python3.8/site-packages/sqlalchemy/util/compat.py", line 211, in raise_
[2023-08-30T21:07:57.315+0000] {subprocess.py:93} INFO -     raise exception
[2023-08-30T21:07:57.317+0000] {subprocess.py:93} INFO -   File "/home/***/.local/lib/python3.8/site-packages/sqlalchemy/orm/session.py", line 3901, in _bulk_save_mappings
[2023-08-30T21:07:57.319+0000] {subprocess.py:93} INFO -     persistence._bulk_insert(
[2023-08-30T21:07:57.320+0000] {subprocess.py:93} INFO -   File "/home/***/.local/lib/python3.8/site-packages/sqlalchemy/orm/persistence.py", line 107, in _bulk_insert
[2023-08-30T21:07:57.321+0000] {subprocess.py:93} INFO -     _emit_insert_statements(
[2023-08-30T21:07:57.323+0000] {subprocess.py:93} INFO -   File "/home/***/.local/lib/python3.8/site-packages/sqlalchemy/orm/persistence.py", line 1097, in _emit_insert_statements
[2023-08-30T21:07:57.326+0000] {subprocess.py:93} INFO -     c = connection._execute_20(
[2023-08-30T21:07:57.327+0000] {subprocess.py:93} INFO -   File "/home/***/.local/lib/python3.8/site-packages/sqlalchemy/engine/base.py", line 1710, in _execute_20
[2023-08-30T21:07:57.328+0000] {subprocess.py:93} INFO -     return meth(self, args_10style, kwargs_10style, execution_options)
[2023-08-30T21:07:57.329+0000] {subprocess.py:93} INFO -   File "/home/***/.local/lib/python3.8/site-packages/sqlalchemy/sql/elements.py", line 334, in _execute_on_connection
[2023-08-30T21:07:57.330+0000] {subprocess.py:93} INFO -     return connection._execute_clauseelement(
[2023-08-30T21:07:57.331+0000] {subprocess.py:93} INFO -   File "/home/***/.local/lib/python3.8/site-packages/sqlalchemy/engine/base.py", line 1577, in _execute_clauseelement
[2023-08-30T21:07:57.333+0000] {subprocess.py:93} INFO -     ret = self._execute_context(
[2023-08-30T21:07:57.334+0000] {subprocess.py:93} INFO -   File "/home/***/.local/lib/python3.8/site-packages/sqlalchemy/engine/base.py", line 1953, in _execute_context
[2023-08-30T21:07:57.335+0000] {subprocess.py:93} INFO -     self._handle_dbapi_exception(
[2023-08-30T21:07:57.336+0000] {subprocess.py:93} INFO -   File "/home/***/.local/lib/python3.8/site-packages/sqlalchemy/engine/base.py", line 2134, in _handle_dbapi_exception
[2023-08-30T21:07:57.338+0000] {subprocess.py:93} INFO -     util.raise_(
[2023-08-30T21:07:57.339+0000] {subprocess.py:93} INFO -   File "/home/***/.local/lib/python3.8/site-packages/sqlalchemy/util/compat.py", line 211, in raise_
[2023-08-30T21:07:57.341+0000] {subprocess.py:93} INFO -     raise exception
[2023-08-30T21:07:57.342+0000] {subprocess.py:93} INFO -   File "/home/***/.local/lib/python3.8/site-packages/sqlalchemy/engine/base.py", line 1890, in _execute_context
[2023-08-30T21:07:57.344+0000] {subprocess.py:93} INFO -     self.dialect.do_executemany(
[2023-08-30T21:07:57.346+0000] {subprocess.py:93} INFO -   File "/home/***/.local/lib/python3.8/site-packages/sqlalchemy/dialects/postgresql/psycopg2.py", line 982, in do_executemany
[2023-08-30T21:07:57.352+0000] {subprocess.py:93} INFO -     context._psycopg2_fetched_rows = xtras.execute_values(
[2023-08-30T21:07:57.354+0000] {subprocess.py:93} INFO -   File "/home/***/.local/lib/python3.8/site-packages/psycopg2/extras.py", line 1299, in execute_values
[2023-08-30T21:07:57.359+0000] {subprocess.py:93} INFO -     cur.execute(b''.join(parts))
[2023-08-30T21:07:57.361+0000] {subprocess.py:93} INFO - sqlalchemy.exc.DataError: (psycopg2.errors.StringDataRightTruncation) value too long for type character varying(20)
[2023-08-30T21:07:57.364+0000] {subprocess.py:93} INFO - 
[2023-08-30T21:07:57.369+0000] {subprocess.py:93} INFO - [SQL: INSERT INTO traffic_report (timestamp, traffic_report_id, date_time, issue_reported, latitude, longitude, address, weekday, date, time) VALUES (%(timestamp)s, %(traffic_report_id)s, %(date_time)s, %(issue_reported)s, %(latitude)s, %(longitude)s, %(address)s, %(weekday)s, %(date)s, %(time)s)]
[2023-08-30T21:07:57.371+0000] {subprocess.py:93} INFO - [parameters: ({'timestamp': '1693094435000000000', 'traffic_report_id': '67DE6A669490F0E6BF9D405BA4C66A2CD17CC2FF_1693094435', 'date_time': '2023-08-27 00:00:35+00:00', 'issue_reported': 'crash urgent', 'latitude': '30.461507', 'longitude': '-97.818156', 'address': '12109-12131 n fm 620 rd', 'weekday': 'Sunday', 'date': '2023-08-27', 'time': '00:00:35'}, {'timestamp': '1693095284000000000', 'traffic_report_id': '5F5898E4726001663BA5A126B313B03B1AED3F07_1693095284', 'date_time': '2023-08-27 00:14:44+00:00', 'issue_reported': 'collision', 'latitude': '30.345376', 'longitude': '-97.525802', 'address': '12700-13009 ceder st', 'weekday': 'Sunday', 'date': '2023-08-27', 'time': '00:14:44'}, {'timestamp': '1693096268000000000', 'traffic_report_id': '64C84E952453CD25D3097C7CFB8BA8178A0D109F_1693096268', 'date_time': '2023-08-27 00:31:08+00:00', 'issue_reported': 'traffic hazard', 'latitude': '30.346057', 'longitude': '-97.710022', 'address': '600-709 w anderson ln svrd eb', 'weekday': 'Sunday', 'date': '2023-08-27', 'time': '00:31:08'}, {'timestamp': '1693096480000000000', 'traffic_report_id': 'EBA90709ED04EB27E4A042727D7DD308E44389E4_1693096480', 'date_time': '2023-08-27 00:34:40+00:00', 'issue_reported': 'crash urgent', 'latitude': '30.450467', 'longitude': '-97.747224', 'address': '6900 w parmer ln', 'weekday': 'Sunday', 'date': '2023-08-27', 'time': '00:34:40'}, {'timestamp': '1693096984000000000', 'traffic_report_id': '619683DB9EF9D4649743EE1DEDDB3923D6E5F704_1693096984', 'date_time': '2023-08-27 00:43:04+00:00', 'issue_reported': 'crash service', 'latitude': '30.229429', 'longitude': '-97.712607', 'address': '5353-5513 e riverside dr', 'weekday': 'Sunday', 'date': '2023-08-27', 'time': '00:43:04'}, {'timestamp': '1693097145000000000', 'traffic_report_id': '0EB7B29E307538E202BD733E1DF3A34884C5B5A8_1693097145', 'date_time': '2023-08-27 00:45:45+00:00', 'issue_reported': 'loose livestock', 'latitude': '30.142508', 'longitude': '-97.616031', 'address': '7941-7948 elroy rd', 'weekday': 'Sunday', 'date': '2023-08-27', 'time': '00:45:45'}, {'timestamp': '1693097737000000000', 'traffic_report_id': '2D97D80F5AF467CAF6A638D16C539634E7B1B7A1_1693097737', 'date_time': '2023-08-27 00:55:37+00:00', 'issue_reported': 'crash urgent', 'latitude': '30.373957', 'longitude': '-97.712013', 'address': '1652 rutland dr', 'weekday': 'Sunday', 'date': '2023-08-27', 'time': '00:55:37'}, {'timestamp': '1693097880000000000', 'traffic_report_id': '34C643598EAB0FE1BC1726E196C36057904DDA13_1693097880', 'date_time': '2023-08-27 00:58:00+00:00', 'issue_reported': 'traffic hazard', 'latitude': '30.378758', 'longitude': '-97.806435', 'address': '8000 fm 2222 rd', 'weekday': 'Sunday', 'date': '2023-08-27', 'time': '00:58:00'}  ... displaying 10 of 126 total bound parameter sets ...  {'timestamp': '1693179923000000000', 'traffic_report_id': 'E6BA73DC9533E190C71BFC3877414870457F1533_1693179923', 'date_time': '2023-08-27 23:45:23+00:00', 'issue_reported': 'crash urgent', 'latitude': '30.236933', 'longitude': '-97.826954', 'address': 'w us 290 hwy svrd wb', 'weekday': 'Sunday', 'date': '2023-08-27', 'time': '23:45:23'}, {'timestamp': '1693179950000000000', 'traffic_report_id': '5D22A80605A592F60F2CDE0BF0D59FF70A54A329_1693179950', 'date_time': '2023-08-27 23:45:50+00:00', 'issue_reported': 'traffic hazard', 'latitude': '30.268903', 'longitude': '-97.777543', 'address': '600 s mopac expy svrd sb', 'weekday': 'Sunday', 'date': '2023-08-27', 'time': '23:45:50'})]
[2023-08-30T21:07:57.377+0000] {subprocess.py:93} INFO - (Background on this error at: https://sqlalche.me/e/14/9h9h)
[2023-08-30T21:07:57.379+0000] {subprocess.py:97} INFO - Command exited with return code 1
[2023-08-30T21:07:57.404+0000] {taskinstance.py:1943} ERROR - Task failed with exception
Traceback (most recent call last):
  File "/home/airflow/.local/lib/python3.8/site-packages/airflow/operators/bash.py", line 210, in execute
    raise AirflowException(
airflow.exceptions.AirflowException: Bash command failed. The command returned a non-zero exit code 1.
[2023-08-30T21:07:57.412+0000] {taskinstance.py:1400} INFO - Marking task as UP_FOR_RETRY. dag_id=traffic_report, task_id=export_data_to_db, execution_date=20230828T000000, start_date=20230830T210756, end_date=20230830T210757
[2023-08-30T21:07:57.478+0000] {standard_task_runner.py:104} ERROR - Failed to execute job 18 for task export_data_to_db (Bash command failed. The command returned a non-zero exit code 1.; 364)
[2023-08-30T21:07:57.507+0000] {local_task_job_runner.py:228} INFO - Task exited with return code 1
[2023-08-30T21:07:57.535+0000] {taskinstance.py:2784} INFO - 0 downstream tasks scheduled from follow-on schedule check
[2023-08-30T21:17:15.113+0000] {logging_mixin.py:151} WARNING - /home/***/.local/lib/python3.8/site-packages/***/utils/sqlalchemy.py:124 DeprecationWarning: The sql_alchemy_conn option in [core] has been moved to the sql_alchemy_conn option in [database] - the old setting has been used, but please update your config.
[2023-08-30T21:17:15.127+0000] {taskinstance.py:1159} INFO - Dependencies all met for dep_context=non-requeueable deps ti=<TaskInstance: traffic_report.export_data_to_db scheduled__2023-08-28T00:00:00+00:00 [queued]>
[2023-08-30T21:17:15.138+0000] {taskinstance.py:1159} INFO - Dependencies all met for dep_context=requeueable deps ti=<TaskInstance: traffic_report.export_data_to_db scheduled__2023-08-28T00:00:00+00:00 [queued]>
[2023-08-30T21:17:15.139+0000] {taskinstance.py:1361} INFO - Starting attempt 1 of 2
[2023-08-30T21:17:15.149+0000] {taskinstance.py:1382} INFO - Executing <Task(BashOperator): export_data_to_db> on 2023-08-28 00:00:00+00:00
[2023-08-30T21:17:15.156+0000] {standard_task_runner.py:57} INFO - Started process 406 to run task
[2023-08-30T21:17:15.162+0000] {standard_task_runner.py:84} INFO - Running: ['***', 'tasks', 'run', 'traffic_report', 'export_data_to_db', 'scheduled__2023-08-28T00:00:00+00:00', '--job-id', '16', '--raw', '--subdir', 'DAGS_FOLDER/traffic_dag.py', '--cfg-path', '/tmp/tmpx2uxahxn']
[2023-08-30T21:17:15.167+0000] {standard_task_runner.py:85} INFO - Job 16: Subtask export_data_to_db
[2023-08-30T21:17:15.186+0000] {logging_mixin.py:151} WARNING - /home/***/.local/lib/python3.8/site-packages/***/settings.py:195 DeprecationWarning: The sql_alchemy_conn option in [core] has been moved to the sql_alchemy_conn option in [database] - the old setting has been used, but please update your config.
[2023-08-30T21:17:15.238+0000] {task_command.py:415} INFO - Running <TaskInstance: traffic_report.export_data_to_db scheduled__2023-08-28T00:00:00+00:00 [running]> on host 5b9f14bf20e0
[2023-08-30T21:17:15.254+0000] {logging_mixin.py:151} WARNING - /home/***/.local/lib/python3.8/site-packages/***/utils/sqlalchemy.py:124 DeprecationWarning: The sql_alchemy_conn option in [core] has been moved to the sql_alchemy_conn option in [database] - the old setting has been used, but please update your config.
[2023-08-30T21:17:15.335+0000] {taskinstance.py:1660} INFO - Exporting env vars: AIRFLOW_CTX_DAG_OWNER='***' AIRFLOW_CTX_DAG_ID='traffic_report' AIRFLOW_CTX_TASK_ID='export_data_to_db' AIRFLOW_CTX_EXECUTION_DATE='2023-08-28T00:00:00+00:00' AIRFLOW_CTX_TRY_NUMBER='1' AIRFLOW_CTX_DAG_RUN_ID='scheduled__2023-08-28T00:00:00+00:00'
[2023-08-30T21:17:15.342+0000] {subprocess.py:63} INFO - Tmp dir root location: /tmp
[2023-08-30T21:17:15.344+0000] {subprocess.py:75} INFO - Running command: ['/bin/bash', '-c', 'python /opt/***/dags/data_to_db.py --date 2023-08-28 --connection postgresql+psycopg2://***:***@postgres/***']
[2023-08-30T21:17:15.362+0000] {subprocess.py:86} INFO - Output:
[2023-08-30T21:17:16.106+0000] {subprocess.py:97} INFO - Command exited with return code 0
[2023-08-30T21:17:16.156+0000] {taskinstance.py:1400} INFO - Marking task as SUCCESS. dag_id=traffic_report, task_id=export_data_to_db, execution_date=20230828T000000, start_date=20230830T211715, end_date=20230830T211716
[2023-08-30T21:17:16.222+0000] {local_task_job_runner.py:228} INFO - Task exited with return code 0
[2023-08-30T21:17:16.244+0000] {taskinstance.py:2784} INFO - 0 downstream tasks scheduled from follow-on schedule check
