[2023-08-29T19:48:58.823+0000] {logging_mixin.py:151} WARNING - /home/***/.local/lib/python3.8/site-packages/***/utils/sqlalchemy.py:124 DeprecationWarning: The sql_alchemy_conn option in [core] has been moved to the sql_alchemy_conn option in [database] - the old setting has been used, but please update your config.
[2023-08-29T19:48:58.834+0000] {taskinstance.py:1159} INFO - Dependencies all met for dep_context=non-requeueable deps ti=<TaskInstance: traffic_report.import_data_to_csv scheduled__2023-08-27T00:00:00+00:00 [queued]>
[2023-08-29T19:48:58.845+0000] {taskinstance.py:1159} INFO - Dependencies all met for dep_context=requeueable deps ti=<TaskInstance: traffic_report.import_data_to_csv scheduled__2023-08-27T00:00:00+00:00 [queued]>
[2023-08-29T19:48:58.847+0000] {taskinstance.py:1361} INFO - Starting attempt 2 of 2
[2023-08-29T19:48:58.864+0000] {taskinstance.py:1382} INFO - Executing <Task(BashOperator): import_data_to_csv> on 2023-08-27 00:00:00+00:00
[2023-08-29T19:48:58.876+0000] {standard_task_runner.py:57} INFO - Started process 611 to run task
[2023-08-29T19:48:58.902+0000] {standard_task_runner.py:84} INFO - Running: ['***', 'tasks', 'run', 'traffic_report', 'import_data_to_csv', 'scheduled__2023-08-27T00:00:00+00:00', '--job-id', '28', '--raw', '--subdir', 'DAGS_FOLDER/traffic_dag.py', '--cfg-path', '/tmp/tmpf1o13584']
[2023-08-29T19:48:58.999+0000] {standard_task_runner.py:85} INFO - Job 28: Subtask import_data_to_csv
[2023-08-29T19:48:59.115+0000] {logging_mixin.py:151} WARNING - /home/***/.local/lib/python3.8/site-packages/***/settings.py:195 DeprecationWarning: The sql_alchemy_conn option in [core] has been moved to the sql_alchemy_conn option in [database] - the old setting has been used, but please update your config.
[2023-08-29T19:49:00.731+0000] {task_command.py:415} INFO - Running <TaskInstance: traffic_report.import_data_to_csv scheduled__2023-08-27T00:00:00+00:00 [running]> on host e69093e17de8
[2023-08-29T19:49:00.669+0000] {logging_mixin.py:151} WARNING - /home/***/.local/lib/python3.8/site-packages/***/utils/sqlalchemy.py:124 DeprecationWarning: The sql_alchemy_conn option in [core] has been moved to the sql_alchemy_conn option in [database] - the old setting has been used, but please update your config.
[2023-08-29T19:49:00.785+0000] {taskinstance.py:1660} INFO - Exporting env vars: AIRFLOW_CTX_DAG_OWNER='***' AIRFLOW_CTX_DAG_ID='traffic_report' AIRFLOW_CTX_TASK_ID='import_data_to_csv' AIRFLOW_CTX_EXECUTION_DATE='2023-08-27T00:00:00+00:00' AIRFLOW_CTX_TRY_NUMBER='2' AIRFLOW_CTX_DAG_RUN_ID='scheduled__2023-08-27T00:00:00+00:00'
[2023-08-29T19:49:00.792+0000] {subprocess.py:63} INFO - Tmp dir root location: /tmp
[2023-08-29T19:49:00.799+0000] {subprocess.py:75} INFO - Running command: ['/bin/bash', '-c', 'python /Users/jinee.hira/Dropbox/virtual_envs/austin-flow/***/dags/data_ingestion.py --date 2023-08-27']
[2023-08-29T19:49:00.836+0000] {subprocess.py:86} INFO - Output:
[2023-08-29T19:49:01.475+0000] {subprocess.py:93} INFO - python: can't open file '/Users/jinee.hira/Dropbox/virtual_envs/austin-flow/***/dags/data_ingestion.py': [Errno 2] No such file or directory
[2023-08-29T19:49:01.493+0000] {subprocess.py:97} INFO - Command exited with return code 2
[2023-08-29T19:49:01.577+0000] {taskinstance.py:1943} ERROR - Task failed with exception
Traceback (most recent call last):
  File "/home/airflow/.local/lib/python3.8/site-packages/airflow/operators/bash.py", line 210, in execute
    raise AirflowException(
airflow.exceptions.AirflowException: Bash command failed. The command returned a non-zero exit code 2.
[2023-08-29T19:49:01.595+0000] {taskinstance.py:1400} INFO - Marking task as FAILED. dag_id=traffic_report, task_id=import_data_to_csv, execution_date=20230827T000000, start_date=20230829T194858, end_date=20230829T194901
[2023-08-29T19:49:01.647+0000] {standard_task_runner.py:104} ERROR - Failed to execute job 28 for task import_data_to_csv (Bash command failed. The command returned a non-zero exit code 2.; 611)
[2023-08-29T19:49:01.668+0000] {local_task_job_runner.py:228} INFO - Task exited with return code 1
[2023-08-29T19:49:01.729+0000] {taskinstance.py:2784} INFO - 0 downstream tasks scheduled from follow-on schedule check
[2023-08-30T19:01:48.657+0000] {logging_mixin.py:151} WARNING - /home/***/.local/lib/python3.8/site-packages/***/utils/sqlalchemy.py:124 DeprecationWarning: The sql_alchemy_conn option in [core] has been moved to the sql_alchemy_conn option in [database] - the old setting has been used, but please update your config.
[2023-08-30T19:01:48.675+0000] {taskinstance.py:1159} INFO - Dependencies all met for dep_context=non-requeueable deps ti=<TaskInstance: traffic_report.import_data_to_csv scheduled__2023-08-27T00:00:00+00:00 [queued]>
[2023-08-30T19:01:48.688+0000] {taskinstance.py:1159} INFO - Dependencies all met for dep_context=requeueable deps ti=<TaskInstance: traffic_report.import_data_to_csv scheduled__2023-08-27T00:00:00+00:00 [queued]>
[2023-08-30T19:01:48.690+0000] {taskinstance.py:1361} INFO - Starting attempt 2 of 2
[2023-08-30T19:01:48.710+0000] {taskinstance.py:1382} INFO - Executing <Task(BashOperator): import_data_to_csv> on 2023-08-27 00:00:00+00:00
[2023-08-30T19:01:48.720+0000] {standard_task_runner.py:57} INFO - Started process 716 to run task
[2023-08-30T19:01:48.730+0000] {standard_task_runner.py:84} INFO - Running: ['***', 'tasks', 'run', 'traffic_report', 'import_data_to_csv', 'scheduled__2023-08-27T00:00:00+00:00', '--job-id', '16', '--raw', '--subdir', 'DAGS_FOLDER/traffic_dag.py', '--cfg-path', '/tmp/tmpbkuj0mtm']
[2023-08-30T19:01:48.736+0000] {standard_task_runner.py:85} INFO - Job 16: Subtask import_data_to_csv
[2023-08-30T19:01:51.146+0000] {logging_mixin.py:151} WARNING - /home/***/.local/lib/python3.8/site-packages/***/settings.py:195 DeprecationWarning: The sql_alchemy_conn option in [core] has been moved to the sql_alchemy_conn option in [database] - the old setting has been used, but please update your config.
[2023-08-30T19:01:54.598+0000] {task_command.py:415} INFO - Running <TaskInstance: traffic_report.import_data_to_csv scheduled__2023-08-27T00:00:00+00:00 [running]> on host 5e7fbf8b7901
[2023-08-30T19:01:54.841+0000] {logging_mixin.py:151} WARNING - /home/***/.local/lib/python3.8/site-packages/***/utils/sqlalchemy.py:124 DeprecationWarning: The sql_alchemy_conn option in [core] has been moved to the sql_alchemy_conn option in [database] - the old setting has been used, but please update your config.
[2023-08-30T19:01:55.095+0000] {taskinstance.py:1660} INFO - Exporting env vars: AIRFLOW_CTX_DAG_OWNER='***' AIRFLOW_CTX_DAG_ID='traffic_report' AIRFLOW_CTX_TASK_ID='import_data_to_csv' AIRFLOW_CTX_EXECUTION_DATE='2023-08-27T00:00:00+00:00' AIRFLOW_CTX_TRY_NUMBER='2' AIRFLOW_CTX_DAG_RUN_ID='scheduled__2023-08-27T00:00:00+00:00'
[2023-08-30T19:01:55.179+0000] {subprocess.py:63} INFO - Tmp dir root location: /tmp
[2023-08-30T19:01:55.188+0000] {subprocess.py:75} INFO - Running command: ['/bin/bash', '-c', 'python /Users/jinee.hira/Dropbox/virtual_envs/austin-flow/***/dags/data_ingestion.py --date 2023-08-27']
[2023-08-30T19:01:55.217+0000] {subprocess.py:86} INFO - Output:
[2023-08-30T19:02:06.224+0000] {subprocess.py:93} INFO - python: can't open file '/Users/jinee.hira/Dropbox/virtual_envs/austin-flow/***/dags/data_ingestion.py': [Errno 2] No such file or directory
[2023-08-30T19:02:06.231+0000] {subprocess.py:97} INFO - Command exited with return code 2
[2023-08-30T19:02:06.250+0000] {taskinstance.py:1943} ERROR - Task failed with exception
Traceback (most recent call last):
  File "/home/airflow/.local/lib/python3.8/site-packages/airflow/operators/bash.py", line 210, in execute
    raise AirflowException(
airflow.exceptions.AirflowException: Bash command failed. The command returned a non-zero exit code 2.
[2023-08-30T19:02:06.256+0000] {taskinstance.py:1400} INFO - Marking task as FAILED. dag_id=traffic_report, task_id=import_data_to_csv, execution_date=20230827T000000, start_date=20230830T190148, end_date=20230830T190206
[2023-08-30T19:02:06.278+0000] {standard_task_runner.py:104} ERROR - Failed to execute job 16 for task import_data_to_csv (Bash command failed. The command returned a non-zero exit code 2.; 716)
[2023-08-30T19:02:06.307+0000] {local_task_job_runner.py:228} INFO - Task exited with return code 1
[2023-08-30T19:02:06.340+0000] {taskinstance.py:2784} INFO - 0 downstream tasks scheduled from follow-on schedule check
[2023-08-30T19:22:01.976+0000] {logging_mixin.py:151} WARNING - /home/***/.local/lib/python3.8/site-packages/***/utils/sqlalchemy.py:124 DeprecationWarning: The sql_alchemy_conn option in [core] has been moved to the sql_alchemy_conn option in [database] - the old setting has been used, but please update your config.
[2023-08-30T19:22:02.001+0000] {taskinstance.py:1159} INFO - Dependencies all met for dep_context=non-requeueable deps ti=<TaskInstance: traffic_report.import_data_to_csv scheduled__2023-08-27T00:00:00+00:00 [queued]>
[2023-08-30T19:22:02.024+0000] {taskinstance.py:1159} INFO - Dependencies all met for dep_context=requeueable deps ti=<TaskInstance: traffic_report.import_data_to_csv scheduled__2023-08-27T00:00:00+00:00 [queued]>
[2023-08-30T19:22:02.027+0000] {taskinstance.py:1361} INFO - Starting attempt 2 of 2
[2023-08-30T19:22:02.055+0000] {taskinstance.py:1382} INFO - Executing <Task(BashOperator): import_data_to_csv> on 2023-08-27 00:00:00+00:00
[2023-08-30T19:22:02.062+0000] {standard_task_runner.py:57} INFO - Started process 348 to run task
[2023-08-30T19:22:02.068+0000] {standard_task_runner.py:84} INFO - Running: ['***', 'tasks', 'run', 'traffic_report', 'import_data_to_csv', 'scheduled__2023-08-27T00:00:00+00:00', '--job-id', '14', '--raw', '--subdir', 'DAGS_FOLDER/traffic_dag.py', '--cfg-path', '/tmp/tmpnvofnqly']
[2023-08-30T19:22:02.086+0000] {standard_task_runner.py:85} INFO - Job 14: Subtask import_data_to_csv
[2023-08-30T19:22:02.153+0000] {logging_mixin.py:151} WARNING - /home/***/.local/lib/python3.8/site-packages/***/settings.py:195 DeprecationWarning: The sql_alchemy_conn option in [core] has been moved to the sql_alchemy_conn option in [database] - the old setting has been used, but please update your config.
[2023-08-30T19:22:02.251+0000] {task_command.py:415} INFO - Running <TaskInstance: traffic_report.import_data_to_csv scheduled__2023-08-27T00:00:00+00:00 [running]> on host 884d86529f65
[2023-08-30T19:22:02.270+0000] {logging_mixin.py:151} WARNING - /home/***/.local/lib/python3.8/site-packages/***/utils/sqlalchemy.py:124 DeprecationWarning: The sql_alchemy_conn option in [core] has been moved to the sql_alchemy_conn option in [database] - the old setting has been used, but please update your config.
[2023-08-30T19:22:02.355+0000] {taskinstance.py:1660} INFO - Exporting env vars: AIRFLOW_CTX_DAG_OWNER='***' AIRFLOW_CTX_DAG_ID='traffic_report' AIRFLOW_CTX_TASK_ID='import_data_to_csv' AIRFLOW_CTX_EXECUTION_DATE='2023-08-27T00:00:00+00:00' AIRFLOW_CTX_TRY_NUMBER='2' AIRFLOW_CTX_DAG_RUN_ID='scheduled__2023-08-27T00:00:00+00:00'
[2023-08-30T19:22:02.370+0000] {subprocess.py:63} INFO - Tmp dir root location: /tmp
[2023-08-30T19:22:02.373+0000] {subprocess.py:75} INFO - Running command: ['/bin/bash', '-c', 'python ./dags/data_ingestion.py --date 2023-08-27']
[2023-08-30T19:22:02.408+0000] {subprocess.py:86} INFO - Output:
[2023-08-30T19:22:04.244+0000] {subprocess.py:93} INFO - python: can't open file './dags/data_ingestion.py': [Errno 2] No such file or directory
[2023-08-30T19:22:04.257+0000] {subprocess.py:97} INFO - Command exited with return code 2
[2023-08-30T19:22:04.358+0000] {taskinstance.py:1943} ERROR - Task failed with exception
Traceback (most recent call last):
  File "/home/airflow/.local/lib/python3.8/site-packages/airflow/operators/bash.py", line 210, in execute
    raise AirflowException(
airflow.exceptions.AirflowException: Bash command failed. The command returned a non-zero exit code 2.
[2023-08-30T19:22:04.375+0000] {taskinstance.py:1400} INFO - Marking task as FAILED. dag_id=traffic_report, task_id=import_data_to_csv, execution_date=20230827T000000, start_date=20230830T192202, end_date=20230830T192204
[2023-08-30T19:22:04.431+0000] {standard_task_runner.py:104} ERROR - Failed to execute job 14 for task import_data_to_csv (Bash command failed. The command returned a non-zero exit code 2.; 348)
[2023-08-30T19:22:04.555+0000] {local_task_job_runner.py:228} INFO - Task exited with return code 1
[2023-08-30T19:22:04.628+0000] {taskinstance.py:2784} INFO - 0 downstream tasks scheduled from follow-on schedule check
