[2023-08-30T19:33:44.802+0000] {logging_mixin.py:151} WARNING - /home/***/.local/lib/python3.8/site-packages/***/utils/sqlalchemy.py:124 DeprecationWarning: The sql_alchemy_conn option in [core] has been moved to the sql_alchemy_conn option in [database] - the old setting has been used, but please update your config.
[2023-08-30T19:33:44.810+0000] {taskinstance.py:1159} INFO - Dependencies all met for dep_context=non-requeueable deps ti=<TaskInstance: traffic_report.export_data_to_db scheduled__2023-08-26T00:00:00+00:00 [queued]>
[2023-08-30T19:33:44.818+0000] {taskinstance.py:1159} INFO - Dependencies all met for dep_context=requeueable deps ti=<TaskInstance: traffic_report.export_data_to_db scheduled__2023-08-26T00:00:00+00:00 [queued]>
[2023-08-30T19:33:44.819+0000] {taskinstance.py:1361} INFO - Starting attempt 2 of 2
[2023-08-30T19:33:44.831+0000] {taskinstance.py:1382} INFO - Executing <Task(BashOperator): export_data_to_db> on 2023-08-26 00:00:00+00:00
[2023-08-30T19:33:44.835+0000] {standard_task_runner.py:57} INFO - Started process 416 to run task
[2023-08-30T19:33:44.839+0000] {standard_task_runner.py:84} INFO - Running: ['***', 'tasks', 'run', 'traffic_report', 'export_data_to_db', 'scheduled__2023-08-26T00:00:00+00:00', '--job-id', '25', '--raw', '--subdir', 'DAGS_FOLDER/traffic_dag.py', '--cfg-path', '/tmp/tmprwa1_k1t']
[2023-08-30T19:33:44.843+0000] {standard_task_runner.py:85} INFO - Job 25: Subtask export_data_to_db
[2023-08-30T19:33:44.871+0000] {logging_mixin.py:151} WARNING - /home/***/.local/lib/python3.8/site-packages/***/settings.py:195 DeprecationWarning: The sql_alchemy_conn option in [core] has been moved to the sql_alchemy_conn option in [database] - the old setting has been used, but please update your config.
[2023-08-30T19:33:44.930+0000] {task_command.py:415} INFO - Running <TaskInstance: traffic_report.export_data_to_db scheduled__2023-08-26T00:00:00+00:00 [running]> on host f6bcf103ff79
[2023-08-30T19:33:44.947+0000] {logging_mixin.py:151} WARNING - /home/***/.local/lib/python3.8/site-packages/***/utils/sqlalchemy.py:124 DeprecationWarning: The sql_alchemy_conn option in [core] has been moved to the sql_alchemy_conn option in [database] - the old setting has been used, but please update your config.
[2023-08-30T19:33:45.006+0000] {taskinstance.py:1660} INFO - Exporting env vars: AIRFLOW_CTX_DAG_OWNER='***' AIRFLOW_CTX_DAG_ID='traffic_report' AIRFLOW_CTX_TASK_ID='export_data_to_db' AIRFLOW_CTX_EXECUTION_DATE='2023-08-26T00:00:00+00:00' AIRFLOW_CTX_TRY_NUMBER='2' AIRFLOW_CTX_DAG_RUN_ID='scheduled__2023-08-26T00:00:00+00:00'
[2023-08-30T19:33:45.008+0000] {subprocess.py:63} INFO - Tmp dir root location: /tmp
[2023-08-30T19:33:45.010+0000] {subprocess.py:75} INFO - Running command: ['/bin/bash', '-c', 'python /opt/***/dags/data_to_db.py --date 2023-08-26 --connection postgresql+psycopg2://***:***@postgres/***']
[2023-08-30T19:33:45.021+0000] {subprocess.py:86} INFO - Output:
[2023-08-30T19:33:45.406+0000] {subprocess.py:93} INFO - Traceback (most recent call last):
[2023-08-30T19:33:45.408+0000] {subprocess.py:93} INFO -   File "/opt/***/dags/data_to_db.py", line 6, in <module>
[2023-08-30T19:33:45.409+0000] {subprocess.py:93} INFO -     from model import Connection, Traffic
[2023-08-30T19:33:45.410+0000] {subprocess.py:93} INFO -   File "/opt/***/dags/model.py", line 5, in <module>
[2023-08-30T19:33:45.411+0000] {subprocess.py:93} INFO -     from geoalchemy2 import Geometry
[2023-08-30T19:33:45.412+0000] {subprocess.py:93} INFO - ModuleNotFoundError: No module named 'geoalchemy2'
[2023-08-30T19:33:45.439+0000] {subprocess.py:97} INFO - Command exited with return code 1
[2023-08-30T19:33:45.457+0000] {taskinstance.py:1943} ERROR - Task failed with exception
Traceback (most recent call last):
  File "/home/airflow/.local/lib/python3.8/site-packages/airflow/operators/bash.py", line 210, in execute
    raise AirflowException(
airflow.exceptions.AirflowException: Bash command failed. The command returned a non-zero exit code 1.
[2023-08-30T19:33:45.461+0000] {taskinstance.py:1400} INFO - Marking task as FAILED. dag_id=traffic_report, task_id=export_data_to_db, execution_date=20230826T000000, start_date=20230830T193344, end_date=20230830T193345
[2023-08-30T19:33:45.472+0000] {standard_task_runner.py:104} ERROR - Failed to execute job 25 for task export_data_to_db (Bash command failed. The command returned a non-zero exit code 1.; 416)
[2023-08-30T19:33:45.494+0000] {local_task_job_runner.py:228} INFO - Task exited with return code 1
[2023-08-30T19:33:45.511+0000] {taskinstance.py:2784} INFO - 0 downstream tasks scheduled from follow-on schedule check
[2023-08-30T19:44:05.373+0000] {logging_mixin.py:151} WARNING - /home/***/.local/lib/python3.8/site-packages/***/utils/sqlalchemy.py:124 DeprecationWarning: The sql_alchemy_conn option in [core] has been moved to the sql_alchemy_conn option in [database] - the old setting has been used, but please update your config.
[2023-08-30T19:44:05.390+0000] {taskinstance.py:1159} INFO - Dependencies all met for dep_context=non-requeueable deps ti=<TaskInstance: traffic_report.export_data_to_db scheduled__2023-08-26T00:00:00+00:00 [queued]>
[2023-08-30T19:44:05.407+0000] {taskinstance.py:1159} INFO - Dependencies all met for dep_context=requeueable deps ti=<TaskInstance: traffic_report.export_data_to_db scheduled__2023-08-26T00:00:00+00:00 [queued]>
[2023-08-30T19:44:05.408+0000] {taskinstance.py:1361} INFO - Starting attempt 2 of 2
[2023-08-30T19:44:05.443+0000] {taskinstance.py:1382} INFO - Executing <Task(BashOperator): export_data_to_db> on 2023-08-26 00:00:00+00:00
[2023-08-30T19:44:05.473+0000] {standard_task_runner.py:57} INFO - Started process 474 to run task
[2023-08-30T19:44:05.489+0000] {standard_task_runner.py:84} INFO - Running: ['***', 'tasks', 'run', 'traffic_report', 'export_data_to_db', 'scheduled__2023-08-26T00:00:00+00:00', '--job-id', '23', '--raw', '--subdir', 'DAGS_FOLDER/traffic_dag.py', '--cfg-path', '/tmp/tmp_z8st83v']
[2023-08-30T19:44:05.496+0000] {standard_task_runner.py:85} INFO - Job 23: Subtask export_data_to_db
[2023-08-30T19:44:06.980+0000] {logging_mixin.py:151} WARNING - /home/***/.local/lib/python3.8/site-packages/***/settings.py:195 DeprecationWarning: The sql_alchemy_conn option in [core] has been moved to the sql_alchemy_conn option in [database] - the old setting has been used, but please update your config.
[2023-08-30T19:44:11.444+0000] {task_command.py:415} INFO - Running <TaskInstance: traffic_report.export_data_to_db scheduled__2023-08-26T00:00:00+00:00 [running]> on host 81eeb4b7c8a9
[2023-08-30T19:44:11.474+0000] {logging_mixin.py:151} WARNING - /home/***/.local/lib/python3.8/site-packages/***/utils/sqlalchemy.py:124 DeprecationWarning: The sql_alchemy_conn option in [core] has been moved to the sql_alchemy_conn option in [database] - the old setting has been used, but please update your config.
[2023-08-30T19:44:11.589+0000] {taskinstance.py:1660} INFO - Exporting env vars: AIRFLOW_CTX_DAG_OWNER='***' AIRFLOW_CTX_DAG_ID='traffic_report' AIRFLOW_CTX_TASK_ID='export_data_to_db' AIRFLOW_CTX_EXECUTION_DATE='2023-08-26T00:00:00+00:00' AIRFLOW_CTX_TRY_NUMBER='2' AIRFLOW_CTX_DAG_RUN_ID='scheduled__2023-08-26T00:00:00+00:00'
[2023-08-30T19:44:11.593+0000] {subprocess.py:63} INFO - Tmp dir root location: /tmp
[2023-08-30T19:44:11.595+0000] {subprocess.py:75} INFO - Running command: ['/bin/bash', '-c', 'python /opt/***/dags/data_to_db.py --date 2023-08-26 --connection postgresql+psycopg2://***:***@postgres/***']
[2023-08-30T19:44:11.608+0000] {subprocess.py:86} INFO - Output:
[2023-08-30T19:44:13.658+0000] {subprocess.py:93} INFO - Traceback (most recent call last):
[2023-08-30T19:44:13.660+0000] {subprocess.py:93} INFO -   File "/opt/***/dags/data_to_db.py", line 6, in <module>
[2023-08-30T19:44:13.662+0000] {subprocess.py:93} INFO -     from model import Connection, Traffic
[2023-08-30T19:44:13.664+0000] {subprocess.py:93} INFO -   File "/opt/***/dags/model.py", line 5, in <module>
[2023-08-30T19:44:13.666+0000] {subprocess.py:93} INFO -     from geoalchemy2 import Geometry
[2023-08-30T19:44:13.668+0000] {subprocess.py:93} INFO - ModuleNotFoundError: No module named 'geoalchemy2'
[2023-08-30T19:44:13.699+0000] {subprocess.py:97} INFO - Command exited with return code 1
[2023-08-30T19:44:13.721+0000] {taskinstance.py:1943} ERROR - Task failed with exception
Traceback (most recent call last):
  File "/home/airflow/.local/lib/python3.8/site-packages/airflow/operators/bash.py", line 210, in execute
    raise AirflowException(
airflow.exceptions.AirflowException: Bash command failed. The command returned a non-zero exit code 1.
[2023-08-30T19:44:13.730+0000] {taskinstance.py:1400} INFO - Marking task as FAILED. dag_id=traffic_report, task_id=export_data_to_db, execution_date=20230826T000000, start_date=20230830T194405, end_date=20230830T194413
[2023-08-30T19:44:13.750+0000] {standard_task_runner.py:104} ERROR - Failed to execute job 23 for task export_data_to_db (Bash command failed. The command returned a non-zero exit code 1.; 474)
[2023-08-30T19:44:13.827+0000] {local_task_job_runner.py:228} INFO - Task exited with return code 1
[2023-08-30T19:44:13.946+0000] {taskinstance.py:2784} INFO - 0 downstream tasks scheduled from follow-on schedule check
[2023-08-30T19:56:36.074+0000] {logging_mixin.py:151} WARNING - /home/***/.local/lib/python3.8/site-packages/***/utils/sqlalchemy.py:124 DeprecationWarning: The sql_alchemy_conn option in [core] has been moved to the sql_alchemy_conn option in [database] - the old setting has been used, but please update your config.
[2023-08-30T19:56:36.086+0000] {taskinstance.py:1159} INFO - Dependencies all met for dep_context=non-requeueable deps ti=<TaskInstance: traffic_report.export_data_to_db scheduled__2023-08-26T00:00:00+00:00 [queued]>
[2023-08-30T19:56:36.103+0000] {taskinstance.py:1159} INFO - Dependencies all met for dep_context=requeueable deps ti=<TaskInstance: traffic_report.export_data_to_db scheduled__2023-08-26T00:00:00+00:00 [queued]>
[2023-08-30T19:56:36.105+0000] {taskinstance.py:1361} INFO - Starting attempt 2 of 2
[2023-08-30T19:56:36.128+0000] {taskinstance.py:1382} INFO - Executing <Task(BashOperator): export_data_to_db> on 2023-08-26 00:00:00+00:00
[2023-08-30T19:56:36.134+0000] {standard_task_runner.py:57} INFO - Started process 187 to run task
[2023-08-30T19:56:36.158+0000] {standard_task_runner.py:84} INFO - Running: ['***', 'tasks', 'run', 'traffic_report', 'export_data_to_db', 'scheduled__2023-08-26T00:00:00+00:00', '--job-id', '21', '--raw', '--subdir', 'DAGS_FOLDER/traffic_dag.py', '--cfg-path', '/tmp/tmpn7z1pz9l']
[2023-08-30T19:56:36.167+0000] {standard_task_runner.py:85} INFO - Job 21: Subtask export_data_to_db
[2023-08-30T19:56:36.206+0000] {logging_mixin.py:151} WARNING - /home/***/.local/lib/python3.8/site-packages/***/settings.py:195 DeprecationWarning: The sql_alchemy_conn option in [core] has been moved to the sql_alchemy_conn option in [database] - the old setting has been used, but please update your config.
[2023-08-30T19:56:36.358+0000] {task_command.py:415} INFO - Running <TaskInstance: traffic_report.export_data_to_db scheduled__2023-08-26T00:00:00+00:00 [running]> on host 86f9e97d6c70
[2023-08-30T19:56:36.397+0000] {logging_mixin.py:151} WARNING - /home/***/.local/lib/python3.8/site-packages/***/utils/sqlalchemy.py:124 DeprecationWarning: The sql_alchemy_conn option in [core] has been moved to the sql_alchemy_conn option in [database] - the old setting has been used, but please update your config.
[2023-08-30T19:56:36.480+0000] {taskinstance.py:1660} INFO - Exporting env vars: AIRFLOW_CTX_DAG_OWNER='***' AIRFLOW_CTX_DAG_ID='traffic_report' AIRFLOW_CTX_TASK_ID='export_data_to_db' AIRFLOW_CTX_EXECUTION_DATE='2023-08-26T00:00:00+00:00' AIRFLOW_CTX_TRY_NUMBER='2' AIRFLOW_CTX_DAG_RUN_ID='scheduled__2023-08-26T00:00:00+00:00'
[2023-08-30T19:56:36.489+0000] {subprocess.py:63} INFO - Tmp dir root location: /tmp
[2023-08-30T19:56:36.492+0000] {subprocess.py:75} INFO - Running command: ['/bin/bash', '-c', 'python /opt/***/dags/data_to_db.py --date 2023-08-26 --connection postgresql+psycopg2://***:***@postgres/***']
[2023-08-30T19:56:36.509+0000] {subprocess.py:86} INFO - Output:
[2023-08-30T19:56:37.595+0000] {subprocess.py:93} INFO - Traceback (most recent call last):
[2023-08-30T19:56:37.597+0000] {subprocess.py:93} INFO -   File "/opt/***/dags/data_to_db.py", line 50, in <module>
[2023-08-30T19:56:37.598+0000] {subprocess.py:93} INFO -     main(args.date, args.connection)
[2023-08-30T19:56:37.599+0000] {subprocess.py:93} INFO -   File "/opt/***/dags/data_to_db.py", line 22, in main
[2023-08-30T19:56:37.600+0000] {subprocess.py:93} INFO -     with open(filename, encoding='utf-8') as csvf:
[2023-08-30T19:56:37.601+0000] {subprocess.py:93} INFO - FileNotFoundError: [Errno 2] No such file or directory: '/opt/***/dags/data/dailytraffic_2023-08-25.csv'
[2023-08-30T19:56:37.821+0000] {subprocess.py:97} INFO - Command exited with return code 1
[2023-08-30T19:56:37.835+0000] {taskinstance.py:1943} ERROR - Task failed with exception
Traceback (most recent call last):
  File "/home/airflow/.local/lib/python3.8/site-packages/airflow/operators/bash.py", line 210, in execute
    raise AirflowException(
airflow.exceptions.AirflowException: Bash command failed. The command returned a non-zero exit code 1.
[2023-08-30T19:56:37.839+0000] {taskinstance.py:1400} INFO - Marking task as FAILED. dag_id=traffic_report, task_id=export_data_to_db, execution_date=20230826T000000, start_date=20230830T195636, end_date=20230830T195637
[2023-08-30T19:56:37.886+0000] {standard_task_runner.py:104} ERROR - Failed to execute job 21 for task export_data_to_db (Bash command failed. The command returned a non-zero exit code 1.; 187)
[2023-08-30T19:56:37.916+0000] {local_task_job_runner.py:228} INFO - Task exited with return code 1
[2023-08-30T19:56:37.947+0000] {taskinstance.py:2784} INFO - 0 downstream tasks scheduled from follow-on schedule check
[2023-08-30T20:07:59.052+0000] {logging_mixin.py:151} WARNING - /home/***/.local/lib/python3.8/site-packages/***/utils/sqlalchemy.py:124 DeprecationWarning: The sql_alchemy_conn option in [core] has been moved to the sql_alchemy_conn option in [database] - the old setting has been used, but please update your config.
[2023-08-30T20:07:59.060+0000] {taskinstance.py:1159} INFO - Dependencies all met for dep_context=non-requeueable deps ti=<TaskInstance: traffic_report.export_data_to_db scheduled__2023-08-26T00:00:00+00:00 [queued]>
[2023-08-30T20:07:59.066+0000] {taskinstance.py:1159} INFO - Dependencies all met for dep_context=requeueable deps ti=<TaskInstance: traffic_report.export_data_to_db scheduled__2023-08-26T00:00:00+00:00 [queued]>
[2023-08-30T20:07:59.068+0000] {taskinstance.py:1361} INFO - Starting attempt 2 of 2
[2023-08-30T20:07:59.078+0000] {taskinstance.py:1382} INFO - Executing <Task(BashOperator): export_data_to_db> on 2023-08-26 00:00:00+00:00
[2023-08-30T20:07:59.082+0000] {standard_task_runner.py:57} INFO - Started process 623 to run task
[2023-08-30T20:07:59.087+0000] {standard_task_runner.py:84} INFO - Running: ['***', 'tasks', 'run', 'traffic_report', 'export_data_to_db', 'scheduled__2023-08-26T00:00:00+00:00', '--job-id', '26', '--raw', '--subdir', 'DAGS_FOLDER/traffic_dag.py', '--cfg-path', '/tmp/tmpfwgjowjr']
[2023-08-30T20:07:59.091+0000] {standard_task_runner.py:85} INFO - Job 26: Subtask export_data_to_db
[2023-08-30T20:07:59.106+0000] {logging_mixin.py:151} WARNING - /home/***/.local/lib/python3.8/site-packages/***/settings.py:195 DeprecationWarning: The sql_alchemy_conn option in [core] has been moved to the sql_alchemy_conn option in [database] - the old setting has been used, but please update your config.
[2023-08-30T20:07:59.140+0000] {task_command.py:415} INFO - Running <TaskInstance: traffic_report.export_data_to_db scheduled__2023-08-26T00:00:00+00:00 [running]> on host 3938d7abd9ff
[2023-08-30T20:07:59.154+0000] {logging_mixin.py:151} WARNING - /home/***/.local/lib/python3.8/site-packages/***/utils/sqlalchemy.py:124 DeprecationWarning: The sql_alchemy_conn option in [core] has been moved to the sql_alchemy_conn option in [database] - the old setting has been used, but please update your config.
[2023-08-30T20:07:59.202+0000] {taskinstance.py:1660} INFO - Exporting env vars: AIRFLOW_CTX_DAG_OWNER='***' AIRFLOW_CTX_DAG_ID='traffic_report' AIRFLOW_CTX_TASK_ID='export_data_to_db' AIRFLOW_CTX_EXECUTION_DATE='2023-08-26T00:00:00+00:00' AIRFLOW_CTX_TRY_NUMBER='2' AIRFLOW_CTX_DAG_RUN_ID='scheduled__2023-08-26T00:00:00+00:00'
[2023-08-30T20:07:59.207+0000] {subprocess.py:63} INFO - Tmp dir root location: /tmp
[2023-08-30T20:07:59.209+0000] {subprocess.py:75} INFO - Running command: ['/bin/bash', '-c', 'python /opt/***/dags/data_to_db.py --date 2023-08-26 --connection postgresql+psycopg2://***:***@postgres/***']
[2023-08-30T20:07:59.220+0000] {subprocess.py:86} INFO - Output:
[2023-08-30T20:07:59.864+0000] {subprocess.py:93} INFO - Traceback (most recent call last):
[2023-08-30T20:07:59.866+0000] {subprocess.py:93} INFO -   File "/home/***/.local/lib/python3.8/site-packages/sqlalchemy/engine/base.py", line 1890, in _execute_context
[2023-08-30T20:07:59.867+0000] {subprocess.py:93} INFO -     self.dialect.do_executemany(
[2023-08-30T20:07:59.869+0000] {subprocess.py:93} INFO -   File "/home/***/.local/lib/python3.8/site-packages/sqlalchemy/dialects/postgresql/psycopg2.py", line 982, in do_executemany
[2023-08-30T20:07:59.870+0000] {subprocess.py:93} INFO -     context._psycopg2_fetched_rows = xtras.execute_values(
[2023-08-30T20:07:59.873+0000] {subprocess.py:93} INFO -   File "/home/***/.local/lib/python3.8/site-packages/psycopg2/extras.py", line 1299, in execute_values
[2023-08-30T20:07:59.875+0000] {subprocess.py:93} INFO -     cur.execute(b''.join(parts))
[2023-08-30T20:07:59.880+0000] {subprocess.py:93} INFO - psycopg2.errors.UndefinedFunction: function st_geomfromewkt(unknown) does not exist
[2023-08-30T20:07:59.882+0000] {subprocess.py:93} INFO - LINE 1: ...96', '2023-08-25 00:01:36+00:00', 'crash urgent', ST_GeomFro...
[2023-08-30T20:07:59.884+0000] {subprocess.py:93} INFO -                                                              ^
[2023-08-30T20:07:59.887+0000] {subprocess.py:93} INFO - HINT:  No function matches the given name and argument types. You might need to add explicit type casts.
[2023-08-30T20:07:59.889+0000] {subprocess.py:93} INFO - 
[2023-08-30T20:07:59.891+0000] {subprocess.py:93} INFO - 
[2023-08-30T20:07:59.893+0000] {subprocess.py:93} INFO - The above exception was the direct cause of the following exception:
[2023-08-30T20:07:59.895+0000] {subprocess.py:93} INFO - 
[2023-08-30T20:07:59.896+0000] {subprocess.py:93} INFO - Traceback (most recent call last):
[2023-08-30T20:07:59.898+0000] {subprocess.py:93} INFO -   File "/opt/***/dags/data_to_db.py", line 50, in <module>
[2023-08-30T20:07:59.899+0000] {subprocess.py:93} INFO -     main(args.date, args.connection)
[2023-08-30T20:07:59.900+0000] {subprocess.py:93} INFO -   File "/opt/***/dags/data_to_db.py", line 41, in main
[2023-08-30T20:07:59.902+0000] {subprocess.py:93} INFO -     session.bulk_save_objects(data_insert)
[2023-08-30T20:07:59.903+0000] {subprocess.py:93} INFO -   File "/home/***/.local/lib/python3.8/site-packages/sqlalchemy/orm/session.py", line 3705, in bulk_save_objects
[2023-08-30T20:07:59.908+0000] {subprocess.py:93} INFO -     self._bulk_save_mappings(
[2023-08-30T20:07:59.909+0000] {subprocess.py:93} INFO -   File "/home/***/.local/lib/python3.8/site-packages/sqlalchemy/orm/session.py", line 3913, in _bulk_save_mappings
[2023-08-30T20:07:59.911+0000] {subprocess.py:93} INFO -     transaction.rollback(_capture_exception=True)
[2023-08-30T20:07:59.913+0000] {subprocess.py:93} INFO -   File "/home/***/.local/lib/python3.8/site-packages/sqlalchemy/util/langhelpers.py", line 70, in __exit__
[2023-08-30T20:07:59.914+0000] {subprocess.py:93} INFO -     compat.raise_(
[2023-08-30T20:07:59.915+0000] {subprocess.py:93} INFO -   File "/home/***/.local/lib/python3.8/site-packages/sqlalchemy/util/compat.py", line 211, in raise_
[2023-08-30T20:07:59.917+0000] {subprocess.py:93} INFO -     raise exception
[2023-08-30T20:07:59.918+0000] {subprocess.py:93} INFO -   File "/home/***/.local/lib/python3.8/site-packages/sqlalchemy/orm/session.py", line 3901, in _bulk_save_mappings
[2023-08-30T20:07:59.919+0000] {subprocess.py:93} INFO -     persistence._bulk_insert(
[2023-08-30T20:07:59.921+0000] {subprocess.py:93} INFO -   File "/home/***/.local/lib/python3.8/site-packages/sqlalchemy/orm/persistence.py", line 107, in _bulk_insert
[2023-08-30T20:07:59.922+0000] {subprocess.py:93} INFO -     _emit_insert_statements(
[2023-08-30T20:07:59.923+0000] {subprocess.py:93} INFO -   File "/home/***/.local/lib/python3.8/site-packages/sqlalchemy/orm/persistence.py", line 1097, in _emit_insert_statements
[2023-08-30T20:07:59.926+0000] {subprocess.py:93} INFO -     c = connection._execute_20(
[2023-08-30T20:07:59.928+0000] {subprocess.py:93} INFO -   File "/home/***/.local/lib/python3.8/site-packages/sqlalchemy/engine/base.py", line 1710, in _execute_20
[2023-08-30T20:07:59.930+0000] {subprocess.py:93} INFO -     return meth(self, args_10style, kwargs_10style, execution_options)
[2023-08-30T20:07:59.931+0000] {subprocess.py:93} INFO -   File "/home/***/.local/lib/python3.8/site-packages/sqlalchemy/sql/elements.py", line 334, in _execute_on_connection
[2023-08-30T20:07:59.932+0000] {subprocess.py:93} INFO -     return connection._execute_clauseelement(
[2023-08-30T20:07:59.933+0000] {subprocess.py:93} INFO -   File "/home/***/.local/lib/python3.8/site-packages/sqlalchemy/engine/base.py", line 1577, in _execute_clauseelement
[2023-08-30T20:07:59.934+0000] {subprocess.py:93} INFO -     ret = self._execute_context(
[2023-08-30T20:07:59.935+0000] {subprocess.py:93} INFO -   File "/home/***/.local/lib/python3.8/site-packages/sqlalchemy/engine/base.py", line 1953, in _execute_context
[2023-08-30T20:07:59.937+0000] {subprocess.py:93} INFO -     self._handle_dbapi_exception(
[2023-08-30T20:07:59.949+0000] {subprocess.py:93} INFO -   File "/home/***/.local/lib/python3.8/site-packages/sqlalchemy/engine/base.py", line 2134, in _handle_dbapi_exception
[2023-08-30T20:07:59.951+0000] {subprocess.py:93} INFO -     util.raise_(
[2023-08-30T20:07:59.952+0000] {subprocess.py:93} INFO -   File "/home/***/.local/lib/python3.8/site-packages/sqlalchemy/util/compat.py", line 211, in raise_
[2023-08-30T20:07:59.954+0000] {subprocess.py:93} INFO -     raise exception
[2023-08-30T20:07:59.956+0000] {subprocess.py:93} INFO -   File "/home/***/.local/lib/python3.8/site-packages/sqlalchemy/engine/base.py", line 1890, in _execute_context
[2023-08-30T20:07:59.957+0000] {subprocess.py:93} INFO -     self.dialect.do_executemany(
[2023-08-30T20:07:59.959+0000] {subprocess.py:93} INFO -   File "/home/***/.local/lib/python3.8/site-packages/sqlalchemy/dialects/postgresql/psycopg2.py", line 982, in do_executemany
[2023-08-30T20:07:59.960+0000] {subprocess.py:93} INFO -     context._psycopg2_fetched_rows = xtras.execute_values(
[2023-08-30T20:07:59.961+0000] {subprocess.py:93} INFO -   File "/home/***/.local/lib/python3.8/site-packages/psycopg2/extras.py", line 1299, in execute_values
[2023-08-30T20:07:59.962+0000] {subprocess.py:93} INFO -     cur.execute(b''.join(parts))
[2023-08-30T20:07:59.964+0000] {subprocess.py:93} INFO - sqlalchemy.exc.ProgrammingError: (psycopg2.errors.UndefinedFunction) function st_geomfromewkt(unknown) does not exist
[2023-08-30T20:07:59.965+0000] {subprocess.py:93} INFO - LINE 1: ...96', '2023-08-25 00:01:36+00:00', 'crash urgent', ST_GeomFro...
[2023-08-30T20:07:59.967+0000] {subprocess.py:93} INFO -                                                              ^
[2023-08-30T20:07:59.968+0000] {subprocess.py:93} INFO - HINT:  No function matches the given name and argument types. You might need to add explicit type casts.
[2023-08-30T20:07:59.969+0000] {subprocess.py:93} INFO - 
[2023-08-30T20:07:59.970+0000] {subprocess.py:93} INFO - [SQL: INSERT INTO traffic_report (timestamp, traffic_report_id, date_time, issue_reported, location, latitude, longitude, address, weekday, date, time) VALUES (%(timestamp)s, %(traffic_report_id)s, %(date_time)s, %(issue_reported)s, ST_GeomFromEWKT(%(location)s), %(latitude)s, %(longitude)s, %(address)s, %(weekday)s, %(date)s, %(time)s)]
[2023-08-30T20:07:59.971+0000] {subprocess.py:93} INFO - [parameters: ({'timestamp': '1692921696000000000', 'traffic_report_id': 'B74E9CAD775D997FC742B45E1BA7BD5295D63D13_1692921696', 'date_time': '2023-08-25 00:01:36+00:00', 'issue_reported': 'crash urgent', 'location': 'POINT(-97.688698 30.24078)', 'latitude': '30.24078', 'longitude': '-97.688698', 'address': '247-317 bastrop hwy nb', 'weekday': 'Friday', 'date': '2023-08-25', 'time': '00:01:36'}, {'timestamp': '1692922515000000000', 'traffic_report_id': '59E221A4758B17362BDEAE901C5A8F58057468B2_1692922515', 'date_time': '2023-08-25 00:15:15+00:00', 'issue_reported': 'crash service', 'location': 'POINT(-97.735003 30.265881)', 'latitude': '30.265881', 'longitude': '-97.735003', 'address': 'e 6th st / n ih 35 svrd sb', 'weekday': 'Friday', 'date': '2023-08-25', 'time': '00:15:15'}, {'timestamp': '1692922987000000000', 'traffic_report_id': '757578FBF23FFA4D748E0800DD7C424A46FEB0CC_1692922987', 'date_time': '2023-08-25 00:23:07+00:00', 'issue_reported': 'crash service', 'location': 'POINT(-97.848308 30.396327)', 'latitude': '30.396327', 'longitude': '-97.848308', 'address': '11004 fm 2222 rd', 'weekday': 'Friday', 'date': '2023-08-25', 'time': '00:23:07'}, {'timestamp': '1692923103000000000', 'traffic_report_id': 'C60D81F35D8BE966FA0437E43F1FEFF777C6E121_1692923103', 'date_time': '2023-08-25 00:25:03+00:00', 'issue_reported': 'stalled vehicle', 'location': 'POINT(-97.758168 30.307093)', 'latitude': '30.307093', 'longitude': '-97.758168', 'address': 'w 35th to mopac sb ramp', 'weekday': 'Friday', 'date': '2023-08-25', 'time': '00:25:03'}, {'timestamp': '1692923525000000000', 'traffic_report_id': '89CA91E6C9B28BDCFB629B12758F955D21072594_1692923525', 'date_time': '2023-08-25 00:32:05+00:00', 'issue_reported': 'traffic hazard', 'location': 'POINT(-97.731593 30.330871)', 'latitude': '30.330871', 'longitude': '-97.731593', 'address': 'w koenig ln / woodrow ave', 'weekday': 'Friday', 'date': '2023-08-25', 'time': '00:32:05'}, {'timestamp': '1692923984000000000', 'traffic_report_id': '3B987A82043F7DF95B5784095B5CE3BB870DC709_1692923984', 'date_time': '2023-08-25 00:39:44+00:00', 'issue_reported': 'collision', 'location': 'POINT(-97.694708 30.107487)', 'latitude': '30.107487', 'longitude': '-97.694708', 'address': '9800-blk s us 183 hwy', 'weekday': 'Friday', 'date': '2023-08-25', 'time': '00:39:44'}, {'timestamp': '1692924072000000000', 'traffic_report_id': 'E6602176F26DD0C5FB721FDED265EC8570F686E7_1692924072', 'date_time': '2023-08-25 00:41:12+00:00', 'issue_reported': 'traffic hazard', 'location': 'POINT(-97.743207 30.26303)', 'latitude': '30.26303', 'longitude': '-97.743207', 'address': 'brazos st / e cesar chavez st', 'weekday': 'Friday', 'date': '2023-08-25', 'time': '00:41:12'}, {'timestamp': '1692924987000000000', 'traffic_report_id': '6DF29A0769E84AF53CC4F71A6017FCF41AD0148D_1692924987', 'date_time': '2023-08-25 00:56:27+00:00', 'issue_reported': 'crash service', 'location': 'POINT(-97.748872 30.420458)', 'latitude': '30.420458', 'longitude': '-97.748872', 'address': '11750 research blvd svrd sb', 'weekday': 'Friday', 'date': '2023-08-25', 'time': '00:56:27'}  ... displaying 10 of 149 total bound parameter sets ...  {'timestamp': '1693007033000000000', 'traffic_report_id': '3E9459D66B2BF63A0F4CFDDC2B117A444BCD6A95_1693007033', 'date_time': '2023-08-25 23:43:53+00:00', 'issue_reported': 'crash service', 'location': 'POINT(-97.638781 30.206611)', 'latitude': '30.206611', 'longitude': '-97.638781', 'address': '2900-3148 s fm 973 rd', 'weekday': 'Friday', 'date': '2023-08-25', 'time': '23:43:53'}, {'timestamp': '1693007481000000000', 'traffic_report_id': '7CA48B0569F515A124807357262BB8714E81FCA3_1693007481', 'date_time': '2023-08-25 23:51:21+00:00', 'issue_reported': 'collision', 'location': 'POINT(-97.60157 30.257618)', 'latitude': '30.257618', 'longitude': '-97.60157', 'address': '5000-7475 n sh 130 nb', 'weekday': 'Friday', 'date': '2023-08-25', 'time': '23:51:21'})]
[2023-08-30T20:07:59.975+0000] {subprocess.py:93} INFO - (Background on this error at: https://sqlalche.me/e/14/f405)
[2023-08-30T20:08:00.052+0000] {subprocess.py:97} INFO - Command exited with return code 1
[2023-08-30T20:08:00.070+0000] {taskinstance.py:1943} ERROR - Task failed with exception
Traceback (most recent call last):
  File "/home/airflow/.local/lib/python3.8/site-packages/airflow/operators/bash.py", line 210, in execute
    raise AirflowException(
airflow.exceptions.AirflowException: Bash command failed. The command returned a non-zero exit code 1.
[2023-08-30T20:08:00.076+0000] {taskinstance.py:1400} INFO - Marking task as FAILED. dag_id=traffic_report, task_id=export_data_to_db, execution_date=20230826T000000, start_date=20230830T200759, end_date=20230830T200800
[2023-08-30T20:08:00.097+0000] {standard_task_runner.py:104} ERROR - Failed to execute job 26 for task export_data_to_db (Bash command failed. The command returned a non-zero exit code 1.; 623)
[2023-08-30T20:08:00.149+0000] {local_task_job_runner.py:228} INFO - Task exited with return code 1
[2023-08-30T20:08:00.175+0000] {taskinstance.py:2784} INFO - 0 downstream tasks scheduled from follow-on schedule check
[2023-08-30T20:36:03.680+0000] {logging_mixin.py:151} WARNING - /home/***/.local/lib/python3.8/site-packages/***/utils/sqlalchemy.py:124 DeprecationWarning: The sql_alchemy_conn option in [core] has been moved to the sql_alchemy_conn option in [database] - the old setting has been used, but please update your config.
[2023-08-30T20:36:03.692+0000] {taskinstance.py:1159} INFO - Dependencies all met for dep_context=non-requeueable deps ti=<TaskInstance: traffic_report.export_data_to_db scheduled__2023-08-26T00:00:00+00:00 [queued]>
[2023-08-30T20:36:03.706+0000] {taskinstance.py:1159} INFO - Dependencies all met for dep_context=requeueable deps ti=<TaskInstance: traffic_report.export_data_to_db scheduled__2023-08-26T00:00:00+00:00 [queued]>
[2023-08-30T20:36:03.707+0000] {taskinstance.py:1361} INFO - Starting attempt 2 of 2
[2023-08-30T20:36:03.720+0000] {taskinstance.py:1382} INFO - Executing <Task(BashOperator): export_data_to_db> on 2023-08-26 00:00:00+00:00
[2023-08-30T20:36:03.724+0000] {standard_task_runner.py:57} INFO - Started process 444 to run task
[2023-08-30T20:36:03.728+0000] {standard_task_runner.py:84} INFO - Running: ['***', 'tasks', 'run', 'traffic_report', 'export_data_to_db', 'scheduled__2023-08-26T00:00:00+00:00', '--job-id', '22', '--raw', '--subdir', 'DAGS_FOLDER/traffic_dag.py', '--cfg-path', '/tmp/tmpw2xpvn5t']
[2023-08-30T20:36:03.736+0000] {standard_task_runner.py:85} INFO - Job 22: Subtask export_data_to_db
[2023-08-30T20:36:03.764+0000] {logging_mixin.py:151} WARNING - /home/***/.local/lib/python3.8/site-packages/***/settings.py:195 DeprecationWarning: The sql_alchemy_conn option in [core] has been moved to the sql_alchemy_conn option in [database] - the old setting has been used, but please update your config.
[2023-08-30T20:36:03.834+0000] {task_command.py:415} INFO - Running <TaskInstance: traffic_report.export_data_to_db scheduled__2023-08-26T00:00:00+00:00 [running]> on host 961f38e8363e
[2023-08-30T20:36:03.877+0000] {logging_mixin.py:151} WARNING - /home/***/.local/lib/python3.8/site-packages/***/utils/sqlalchemy.py:124 DeprecationWarning: The sql_alchemy_conn option in [core] has been moved to the sql_alchemy_conn option in [database] - the old setting has been used, but please update your config.
[2023-08-30T20:36:03.962+0000] {taskinstance.py:1660} INFO - Exporting env vars: AIRFLOW_CTX_DAG_OWNER='***' AIRFLOW_CTX_DAG_ID='traffic_report' AIRFLOW_CTX_TASK_ID='export_data_to_db' AIRFLOW_CTX_EXECUTION_DATE='2023-08-26T00:00:00+00:00' AIRFLOW_CTX_TRY_NUMBER='2' AIRFLOW_CTX_DAG_RUN_ID='scheduled__2023-08-26T00:00:00+00:00'
[2023-08-30T20:36:03.965+0000] {subprocess.py:63} INFO - Tmp dir root location: /tmp
[2023-08-30T20:36:03.969+0000] {subprocess.py:75} INFO - Running command: ['/bin/bash', '-c', 'python /opt/***/dags/data_to_db.py --date 2023-08-26 --connection postgresql+psycopg2://***:***@postgres/***']
[2023-08-30T20:36:03.996+0000] {subprocess.py:86} INFO - Output:
[2023-08-30T20:36:04.740+0000] {subprocess.py:93} INFO - Traceback (most recent call last):
[2023-08-30T20:36:04.741+0000] {subprocess.py:93} INFO -   File "/home/***/.local/lib/python3.8/site-packages/sqlalchemy/engine/base.py", line 1890, in _execute_context
[2023-08-30T20:36:04.747+0000] {subprocess.py:93} INFO -     self.dialect.do_executemany(
[2023-08-30T20:36:04.748+0000] {subprocess.py:93} INFO -   File "/home/***/.local/lib/python3.8/site-packages/sqlalchemy/dialects/postgresql/psycopg2.py", line 982, in do_executemany
[2023-08-30T20:36:04.749+0000] {subprocess.py:93} INFO -     context._psycopg2_fetched_rows = xtras.execute_values(
[2023-08-30T20:36:04.752+0000] {subprocess.py:93} INFO -   File "/home/***/.local/lib/python3.8/site-packages/psycopg2/extras.py", line 1299, in execute_values
[2023-08-30T20:36:04.755+0000] {subprocess.py:93} INFO -     cur.execute(b''.join(parts))
[2023-08-30T20:36:04.756+0000] {subprocess.py:93} INFO - psycopg2.errors.UndefinedFunction: function st_geomfromewkt(unknown) does not exist
[2023-08-30T20:36:04.757+0000] {subprocess.py:93} INFO - LINE 1: ...96', '2023-08-25 00:01:36+00:00', 'crash urgent', ST_GeomFro...
[2023-08-30T20:36:04.758+0000] {subprocess.py:93} INFO -                                                              ^
[2023-08-30T20:36:04.759+0000] {subprocess.py:93} INFO - HINT:  No function matches the given name and argument types. You might need to add explicit type casts.
[2023-08-30T20:36:04.760+0000] {subprocess.py:93} INFO - 
[2023-08-30T20:36:04.763+0000] {subprocess.py:93} INFO - 
[2023-08-30T20:36:04.765+0000] {subprocess.py:93} INFO - The above exception was the direct cause of the following exception:
[2023-08-30T20:36:04.766+0000] {subprocess.py:93} INFO - 
[2023-08-30T20:36:04.767+0000] {subprocess.py:93} INFO - Traceback (most recent call last):
[2023-08-30T20:36:04.768+0000] {subprocess.py:93} INFO -   File "/opt/***/dags/data_to_db.py", line 50, in <module>
[2023-08-30T20:36:04.769+0000] {subprocess.py:93} INFO -     main(args.date, args.connection)
[2023-08-30T20:36:04.770+0000] {subprocess.py:93} INFO -   File "/opt/***/dags/data_to_db.py", line 41, in main
[2023-08-30T20:36:04.771+0000] {subprocess.py:93} INFO -     session.bulk_save_objects(data_insert)
[2023-08-30T20:36:04.772+0000] {subprocess.py:93} INFO -   File "/home/***/.local/lib/python3.8/site-packages/sqlalchemy/orm/session.py", line 3705, in bulk_save_objects
[2023-08-30T20:36:04.773+0000] {subprocess.py:93} INFO -     self._bulk_save_mappings(
[2023-08-30T20:36:04.773+0000] {subprocess.py:93} INFO -   File "/home/***/.local/lib/python3.8/site-packages/sqlalchemy/orm/session.py", line 3913, in _bulk_save_mappings
[2023-08-30T20:36:04.774+0000] {subprocess.py:93} INFO -     transaction.rollback(_capture_exception=True)
[2023-08-30T20:36:04.775+0000] {subprocess.py:93} INFO -   File "/home/***/.local/lib/python3.8/site-packages/sqlalchemy/util/langhelpers.py", line 70, in __exit__
[2023-08-30T20:36:04.776+0000] {subprocess.py:93} INFO -     compat.raise_(
[2023-08-30T20:36:04.777+0000] {subprocess.py:93} INFO -   File "/home/***/.local/lib/python3.8/site-packages/sqlalchemy/util/compat.py", line 211, in raise_
[2023-08-30T20:36:04.778+0000] {subprocess.py:93} INFO -     raise exception
[2023-08-30T20:36:04.779+0000] {subprocess.py:93} INFO -   File "/home/***/.local/lib/python3.8/site-packages/sqlalchemy/orm/session.py", line 3901, in _bulk_save_mappings
[2023-08-30T20:36:04.781+0000] {subprocess.py:93} INFO -     persistence._bulk_insert(
[2023-08-30T20:36:04.783+0000] {subprocess.py:93} INFO -   File "/home/***/.local/lib/python3.8/site-packages/sqlalchemy/orm/persistence.py", line 107, in _bulk_insert
[2023-08-30T20:36:04.784+0000] {subprocess.py:93} INFO -     _emit_insert_statements(
[2023-08-30T20:36:04.785+0000] {subprocess.py:93} INFO -   File "/home/***/.local/lib/python3.8/site-packages/sqlalchemy/orm/persistence.py", line 1097, in _emit_insert_statements
[2023-08-30T20:36:04.786+0000] {subprocess.py:93} INFO -     c = connection._execute_20(
[2023-08-30T20:36:04.787+0000] {subprocess.py:93} INFO -   File "/home/***/.local/lib/python3.8/site-packages/sqlalchemy/engine/base.py", line 1710, in _execute_20
[2023-08-30T20:36:04.788+0000] {subprocess.py:93} INFO -     return meth(self, args_10style, kwargs_10style, execution_options)
[2023-08-30T20:36:04.789+0000] {subprocess.py:93} INFO -   File "/home/***/.local/lib/python3.8/site-packages/sqlalchemy/sql/elements.py", line 334, in _execute_on_connection
[2023-08-30T20:36:04.790+0000] {subprocess.py:93} INFO -     return connection._execute_clauseelement(
[2023-08-30T20:36:04.791+0000] {subprocess.py:93} INFO -   File "/home/***/.local/lib/python3.8/site-packages/sqlalchemy/engine/base.py", line 1577, in _execute_clauseelement
[2023-08-30T20:36:04.792+0000] {subprocess.py:93} INFO -     ret = self._execute_context(
[2023-08-30T20:36:04.793+0000] {subprocess.py:93} INFO -   File "/home/***/.local/lib/python3.8/site-packages/sqlalchemy/engine/base.py", line 1953, in _execute_context
[2023-08-30T20:36:04.794+0000] {subprocess.py:93} INFO -     self._handle_dbapi_exception(
[2023-08-30T20:36:04.795+0000] {subprocess.py:93} INFO -   File "/home/***/.local/lib/python3.8/site-packages/sqlalchemy/engine/base.py", line 2134, in _handle_dbapi_exception
[2023-08-30T20:36:04.797+0000] {subprocess.py:93} INFO -     util.raise_(
[2023-08-30T20:36:04.798+0000] {subprocess.py:93} INFO -   File "/home/***/.local/lib/python3.8/site-packages/sqlalchemy/util/compat.py", line 211, in raise_
[2023-08-30T20:36:04.799+0000] {subprocess.py:93} INFO -     raise exception
[2023-08-30T20:36:04.800+0000] {subprocess.py:93} INFO -   File "/home/***/.local/lib/python3.8/site-packages/sqlalchemy/engine/base.py", line 1890, in _execute_context
[2023-08-30T20:36:04.801+0000] {subprocess.py:93} INFO -     self.dialect.do_executemany(
[2023-08-30T20:36:04.802+0000] {subprocess.py:93} INFO -   File "/home/***/.local/lib/python3.8/site-packages/sqlalchemy/dialects/postgresql/psycopg2.py", line 982, in do_executemany
[2023-08-30T20:36:04.803+0000] {subprocess.py:93} INFO -     context._psycopg2_fetched_rows = xtras.execute_values(
[2023-08-30T20:36:04.804+0000] {subprocess.py:93} INFO -   File "/home/***/.local/lib/python3.8/site-packages/psycopg2/extras.py", line 1299, in execute_values
[2023-08-30T20:36:04.806+0000] {subprocess.py:93} INFO -     cur.execute(b''.join(parts))
[2023-08-30T20:36:04.806+0000] {subprocess.py:93} INFO - sqlalchemy.exc.ProgrammingError: (psycopg2.errors.UndefinedFunction) function st_geomfromewkt(unknown) does not exist
[2023-08-30T20:36:04.808+0000] {subprocess.py:93} INFO - LINE 1: ...96', '2023-08-25 00:01:36+00:00', 'crash urgent', ST_GeomFro...
[2023-08-30T20:36:04.809+0000] {subprocess.py:93} INFO -                                                              ^
[2023-08-30T20:36:04.810+0000] {subprocess.py:93} INFO - HINT:  No function matches the given name and argument types. You might need to add explicit type casts.
[2023-08-30T20:36:04.811+0000] {subprocess.py:93} INFO - 
[2023-08-30T20:36:04.812+0000] {subprocess.py:93} INFO - [SQL: INSERT INTO traffic_report (timestamp, traffic_report_id, date_time, issue_reported, location, latitude, longitude, address, weekday, date, time) VALUES (%(timestamp)s, %(traffic_report_id)s, %(date_time)s, %(issue_reported)s, ST_GeomFromEWKT(%(location)s), %(latitude)s, %(longitude)s, %(address)s, %(weekday)s, %(date)s, %(time)s)]
[2023-08-30T20:36:04.813+0000] {subprocess.py:93} INFO - [parameters: ({'timestamp': '1692921696000000000', 'traffic_report_id': 'B74E9CAD775D997FC742B45E1BA7BD5295D63D13_1692921696', 'date_time': '2023-08-25 00:01:36+00:00', 'issue_reported': 'crash urgent', 'location': 'POINT(-97.688698 30.24078)', 'latitude': '30.24078', 'longitude': '-97.688698', 'address': '247-317 bastrop hwy nb', 'weekday': 'Friday', 'date': '2023-08-25', 'time': '00:01:36'}, {'timestamp': '1692922515000000000', 'traffic_report_id': '59E221A4758B17362BDEAE901C5A8F58057468B2_1692922515', 'date_time': '2023-08-25 00:15:15+00:00', 'issue_reported': 'crash service', 'location': 'POINT(-97.735003 30.265881)', 'latitude': '30.265881', 'longitude': '-97.735003', 'address': 'e 6th st / n ih 35 svrd sb', 'weekday': 'Friday', 'date': '2023-08-25', 'time': '00:15:15'}, {'timestamp': '1692922987000000000', 'traffic_report_id': '757578FBF23FFA4D748E0800DD7C424A46FEB0CC_1692922987', 'date_time': '2023-08-25 00:23:07+00:00', 'issue_reported': 'crash service', 'location': 'POINT(-97.848308 30.396327)', 'latitude': '30.396327', 'longitude': '-97.848308', 'address': '11004 fm 2222 rd', 'weekday': 'Friday', 'date': '2023-08-25', 'time': '00:23:07'}, {'timestamp': '1692923103000000000', 'traffic_report_id': 'C60D81F35D8BE966FA0437E43F1FEFF777C6E121_1692923103', 'date_time': '2023-08-25 00:25:03+00:00', 'issue_reported': 'stalled vehicle', 'location': 'POINT(-97.758168 30.307093)', 'latitude': '30.307093', 'longitude': '-97.758168', 'address': 'w 35th to mopac sb ramp', 'weekday': 'Friday', 'date': '2023-08-25', 'time': '00:25:03'}, {'timestamp': '1692923525000000000', 'traffic_report_id': '89CA91E6C9B28BDCFB629B12758F955D21072594_1692923525', 'date_time': '2023-08-25 00:32:05+00:00', 'issue_reported': 'traffic hazard', 'location': 'POINT(-97.731593 30.330871)', 'latitude': '30.330871', 'longitude': '-97.731593', 'address': 'w koenig ln / woodrow ave', 'weekday': 'Friday', 'date': '2023-08-25', 'time': '00:32:05'}, {'timestamp': '1692923984000000000', 'traffic_report_id': '3B987A82043F7DF95B5784095B5CE3BB870DC709_1692923984', 'date_time': '2023-08-25 00:39:44+00:00', 'issue_reported': 'collision', 'location': 'POINT(-97.694708 30.107487)', 'latitude': '30.107487', 'longitude': '-97.694708', 'address': '9800-blk s us 183 hwy', 'weekday': 'Friday', 'date': '2023-08-25', 'time': '00:39:44'}, {'timestamp': '1692924072000000000', 'traffic_report_id': 'E6602176F26DD0C5FB721FDED265EC8570F686E7_1692924072', 'date_time': '2023-08-25 00:41:12+00:00', 'issue_reported': 'traffic hazard', 'location': 'POINT(-97.743207 30.26303)', 'latitude': '30.26303', 'longitude': '-97.743207', 'address': 'brazos st / e cesar chavez st', 'weekday': 'Friday', 'date': '2023-08-25', 'time': '00:41:12'}, {'timestamp': '1692924987000000000', 'traffic_report_id': '6DF29A0769E84AF53CC4F71A6017FCF41AD0148D_1692924987', 'date_time': '2023-08-25 00:56:27+00:00', 'issue_reported': 'crash service', 'location': 'POINT(-97.748872 30.420458)', 'latitude': '30.420458', 'longitude': '-97.748872', 'address': '11750 research blvd svrd sb', 'weekday': 'Friday', 'date': '2023-08-25', 'time': '00:56:27'}  ... displaying 10 of 149 total bound parameter sets ...  {'timestamp': '1693007033000000000', 'traffic_report_id': '3E9459D66B2BF63A0F4CFDDC2B117A444BCD6A95_1693007033', 'date_time': '2023-08-25 23:43:53+00:00', 'issue_reported': 'crash service', 'location': 'POINT(-97.638781 30.206611)', 'latitude': '30.206611', 'longitude': '-97.638781', 'address': '2900-3148 s fm 973 rd', 'weekday': 'Friday', 'date': '2023-08-25', 'time': '23:43:53'}, {'timestamp': '1693007481000000000', 'traffic_report_id': '7CA48B0569F515A124807357262BB8714E81FCA3_1693007481', 'date_time': '2023-08-25 23:51:21+00:00', 'issue_reported': 'collision', 'location': 'POINT(-97.60157 30.257618)', 'latitude': '30.257618', 'longitude': '-97.60157', 'address': '5000-7475 n sh 130 nb', 'weekday': 'Friday', 'date': '2023-08-25', 'time': '23:51:21'})]
[2023-08-30T20:36:04.815+0000] {subprocess.py:93} INFO - (Background on this error at: https://sqlalche.me/e/14/f405)
[2023-08-30T20:36:04.862+0000] {subprocess.py:97} INFO - Command exited with return code 1
[2023-08-30T20:36:04.883+0000] {taskinstance.py:1943} ERROR - Task failed with exception
Traceback (most recent call last):
  File "/home/airflow/.local/lib/python3.8/site-packages/airflow/operators/bash.py", line 210, in execute
    raise AirflowException(
airflow.exceptions.AirflowException: Bash command failed. The command returned a non-zero exit code 1.
[2023-08-30T20:36:04.894+0000] {taskinstance.py:1400} INFO - Marking task as FAILED. dag_id=traffic_report, task_id=export_data_to_db, execution_date=20230826T000000, start_date=20230830T203603, end_date=20230830T203604
[2023-08-30T20:36:04.960+0000] {standard_task_runner.py:104} ERROR - Failed to execute job 22 for task export_data_to_db (Bash command failed. The command returned a non-zero exit code 1.; 444)
[2023-08-30T20:36:04.996+0000] {local_task_job_runner.py:228} INFO - Task exited with return code 1
[2023-08-30T20:36:05.026+0000] {taskinstance.py:2784} INFO - 0 downstream tasks scheduled from follow-on schedule check
[2023-08-30T20:50:35.784+0000] {logging_mixin.py:151} WARNING - /home/***/.local/lib/python3.8/site-packages/***/utils/sqlalchemy.py:124 DeprecationWarning: The sql_alchemy_conn option in [core] has been moved to the sql_alchemy_conn option in [database] - the old setting has been used, but please update your config.
[2023-08-30T20:50:35.801+0000] {taskinstance.py:1159} INFO - Dependencies all met for dep_context=non-requeueable deps ti=<TaskInstance: traffic_report.export_data_to_db scheduled__2023-08-26T00:00:00+00:00 [queued]>
[2023-08-30T20:50:35.820+0000] {taskinstance.py:1159} INFO - Dependencies all met for dep_context=requeueable deps ti=<TaskInstance: traffic_report.export_data_to_db scheduled__2023-08-26T00:00:00+00:00 [queued]>
[2023-08-30T20:50:35.821+0000] {taskinstance.py:1361} INFO - Starting attempt 2 of 2
[2023-08-30T20:50:35.842+0000] {taskinstance.py:1382} INFO - Executing <Task(BashOperator): export_data_to_db> on 2023-08-26 00:00:00+00:00
[2023-08-30T20:50:35.847+0000] {standard_task_runner.py:57} INFO - Started process 480 to run task
[2023-08-30T20:50:35.858+0000] {standard_task_runner.py:84} INFO - Running: ['***', 'tasks', 'run', 'traffic_report', 'export_data_to_db', 'scheduled__2023-08-26T00:00:00+00:00', '--job-id', '25', '--raw', '--subdir', 'DAGS_FOLDER/traffic_dag.py', '--cfg-path', '/tmp/tmpemu63n_4']
[2023-08-30T20:50:35.862+0000] {standard_task_runner.py:85} INFO - Job 25: Subtask export_data_to_db
[2023-08-30T20:50:35.896+0000] {logging_mixin.py:151} WARNING - /home/***/.local/lib/python3.8/site-packages/***/settings.py:195 DeprecationWarning: The sql_alchemy_conn option in [core] has been moved to the sql_alchemy_conn option in [database] - the old setting has been used, but please update your config.
[2023-08-30T20:50:35.976+0000] {task_command.py:415} INFO - Running <TaskInstance: traffic_report.export_data_to_db scheduled__2023-08-26T00:00:00+00:00 [running]> on host 8f66711a2898
[2023-08-30T20:50:36.013+0000] {logging_mixin.py:151} WARNING - /home/***/.local/lib/python3.8/site-packages/***/utils/sqlalchemy.py:124 DeprecationWarning: The sql_alchemy_conn option in [core] has been moved to the sql_alchemy_conn option in [database] - the old setting has been used, but please update your config.
[2023-08-30T20:50:39.254+0000] {taskinstance.py:1660} INFO - Exporting env vars: AIRFLOW_CTX_DAG_OWNER='***' AIRFLOW_CTX_DAG_ID='traffic_report' AIRFLOW_CTX_TASK_ID='export_data_to_db' AIRFLOW_CTX_EXECUTION_DATE='2023-08-26T00:00:00+00:00' AIRFLOW_CTX_TRY_NUMBER='2' AIRFLOW_CTX_DAG_RUN_ID='scheduled__2023-08-26T00:00:00+00:00'
[2023-08-30T20:50:39.371+0000] {subprocess.py:63} INFO - Tmp dir root location: /tmp
[2023-08-30T20:50:39.421+0000] {subprocess.py:75} INFO - Running command: ['/bin/bash', '-c', 'python /opt/***/dags/data_to_db.py --date 2023-08-26 --connection postgresql+psycopg2://***:***@postgres/***']
[2023-08-30T20:50:39.507+0000] {subprocess.py:86} INFO - Output:
[2023-08-30T20:50:42.789+0000] {subprocess.py:93} INFO - Traceback (most recent call last):
[2023-08-30T20:50:42.791+0000] {subprocess.py:93} INFO -   File "/home/***/.local/lib/python3.8/site-packages/sqlalchemy/engine/base.py", line 1890, in _execute_context
[2023-08-30T20:50:42.793+0000] {subprocess.py:93} INFO -     self.dialect.do_executemany(
[2023-08-30T20:50:42.794+0000] {subprocess.py:93} INFO -   File "/home/***/.local/lib/python3.8/site-packages/sqlalchemy/dialects/postgresql/psycopg2.py", line 982, in do_executemany
[2023-08-30T20:50:42.795+0000] {subprocess.py:93} INFO -     context._psycopg2_fetched_rows = xtras.execute_values(
[2023-08-30T20:50:42.797+0000] {subprocess.py:93} INFO -   File "/home/***/.local/lib/python3.8/site-packages/psycopg2/extras.py", line 1299, in execute_values
[2023-08-30T20:50:42.799+0000] {subprocess.py:93} INFO -     cur.execute(b''.join(parts))
[2023-08-30T20:50:42.806+0000] {subprocess.py:93} INFO - psycopg2.errors.NumericValueOutOfRange: value "1692921696000000000" is out of range for type integer
[2023-08-30T20:50:42.810+0000] {subprocess.py:93} INFO - LINE 1: ... longitude, address, weekday, date, time) VALUES ('169292169...
[2023-08-30T20:50:42.814+0000] {subprocess.py:93} INFO -                                                              ^
[2023-08-30T20:50:42.816+0000] {subprocess.py:93} INFO - 
[2023-08-30T20:50:42.818+0000] {subprocess.py:93} INFO - 
[2023-08-30T20:50:42.819+0000] {subprocess.py:93} INFO - The above exception was the direct cause of the following exception:
[2023-08-30T20:50:42.820+0000] {subprocess.py:93} INFO - 
[2023-08-30T20:50:42.821+0000] {subprocess.py:93} INFO - Traceback (most recent call last):
[2023-08-30T20:50:42.822+0000] {subprocess.py:93} INFO -   File "/opt/***/dags/data_to_db.py", line 49, in <module>
[2023-08-30T20:50:42.824+0000] {subprocess.py:93} INFO -     main(args.date, args.connection)
[2023-08-30T20:50:42.826+0000] {subprocess.py:93} INFO -   File "/opt/***/dags/data_to_db.py", line 40, in main
[2023-08-30T20:50:42.827+0000] {subprocess.py:93} INFO -     session.bulk_save_objects(data_insert)
[2023-08-30T20:50:42.828+0000] {subprocess.py:93} INFO -   File "/home/***/.local/lib/python3.8/site-packages/sqlalchemy/orm/session.py", line 3705, in bulk_save_objects
[2023-08-30T20:50:42.833+0000] {subprocess.py:93} INFO -     self._bulk_save_mappings(
[2023-08-30T20:50:42.840+0000] {subprocess.py:93} INFO -   File "/home/***/.local/lib/python3.8/site-packages/sqlalchemy/orm/session.py", line 3913, in _bulk_save_mappings
[2023-08-30T20:50:42.844+0000] {subprocess.py:93} INFO -     transaction.rollback(_capture_exception=True)
[2023-08-30T20:50:42.849+0000] {subprocess.py:93} INFO -   File "/home/***/.local/lib/python3.8/site-packages/sqlalchemy/util/langhelpers.py", line 70, in __exit__
[2023-08-30T20:50:42.851+0000] {subprocess.py:93} INFO -     compat.raise_(
[2023-08-30T20:50:42.853+0000] {subprocess.py:93} INFO -   File "/home/***/.local/lib/python3.8/site-packages/sqlalchemy/util/compat.py", line 211, in raise_
[2023-08-30T20:50:42.856+0000] {subprocess.py:93} INFO -     raise exception
[2023-08-30T20:50:42.859+0000] {subprocess.py:93} INFO -   File "/home/***/.local/lib/python3.8/site-packages/sqlalchemy/orm/session.py", line 3901, in _bulk_save_mappings
[2023-08-30T20:50:42.861+0000] {subprocess.py:93} INFO -     persistence._bulk_insert(
[2023-08-30T20:50:42.863+0000] {subprocess.py:93} INFO -   File "/home/***/.local/lib/python3.8/site-packages/sqlalchemy/orm/persistence.py", line 107, in _bulk_insert
[2023-08-30T20:50:42.864+0000] {subprocess.py:93} INFO -     _emit_insert_statements(
[2023-08-30T20:50:42.865+0000] {subprocess.py:93} INFO -   File "/home/***/.local/lib/python3.8/site-packages/sqlalchemy/orm/persistence.py", line 1097, in _emit_insert_statements
[2023-08-30T20:50:42.868+0000] {subprocess.py:93} INFO -     c = connection._execute_20(
[2023-08-30T20:50:42.871+0000] {subprocess.py:93} INFO -   File "/home/***/.local/lib/python3.8/site-packages/sqlalchemy/engine/base.py", line 1710, in _execute_20
[2023-08-30T20:50:42.874+0000] {subprocess.py:93} INFO -     return meth(self, args_10style, kwargs_10style, execution_options)
[2023-08-30T20:50:42.875+0000] {subprocess.py:93} INFO -   File "/home/***/.local/lib/python3.8/site-packages/sqlalchemy/sql/elements.py", line 334, in _execute_on_connection
[2023-08-30T20:50:42.876+0000] {subprocess.py:93} INFO -     return connection._execute_clauseelement(
[2023-08-30T20:50:42.877+0000] {subprocess.py:93} INFO -   File "/home/***/.local/lib/python3.8/site-packages/sqlalchemy/engine/base.py", line 1577, in _execute_clauseelement
[2023-08-30T20:50:42.879+0000] {subprocess.py:93} INFO -     ret = self._execute_context(
[2023-08-30T20:50:42.882+0000] {subprocess.py:93} INFO -   File "/home/***/.local/lib/python3.8/site-packages/sqlalchemy/engine/base.py", line 1953, in _execute_context
[2023-08-30T20:50:42.883+0000] {subprocess.py:93} INFO -     self._handle_dbapi_exception(
[2023-08-30T20:50:42.886+0000] {subprocess.py:93} INFO -   File "/home/***/.local/lib/python3.8/site-packages/sqlalchemy/engine/base.py", line 2134, in _handle_dbapi_exception
[2023-08-30T20:50:42.888+0000] {subprocess.py:93} INFO -     util.raise_(
[2023-08-30T20:50:42.889+0000] {subprocess.py:93} INFO -   File "/home/***/.local/lib/python3.8/site-packages/sqlalchemy/util/compat.py", line 211, in raise_
[2023-08-30T20:50:42.892+0000] {subprocess.py:93} INFO -     raise exception
[2023-08-30T20:50:42.894+0000] {subprocess.py:93} INFO -   File "/home/***/.local/lib/python3.8/site-packages/sqlalchemy/engine/base.py", line 1890, in _execute_context
[2023-08-30T20:50:42.898+0000] {subprocess.py:93} INFO -     self.dialect.do_executemany(
[2023-08-30T20:50:42.899+0000] {subprocess.py:93} INFO -   File "/home/***/.local/lib/python3.8/site-packages/sqlalchemy/dialects/postgresql/psycopg2.py", line 982, in do_executemany
[2023-08-30T20:50:42.900+0000] {subprocess.py:93} INFO -     context._psycopg2_fetched_rows = xtras.execute_values(
[2023-08-30T20:50:42.903+0000] {subprocess.py:93} INFO -   File "/home/***/.local/lib/python3.8/site-packages/psycopg2/extras.py", line 1299, in execute_values
[2023-08-30T20:50:42.905+0000] {subprocess.py:93} INFO -     cur.execute(b''.join(parts))
[2023-08-30T20:50:42.907+0000] {subprocess.py:93} INFO - sqlalchemy.exc.DataError: (psycopg2.errors.NumericValueOutOfRange) value "1692921696000000000" is out of range for type integer
[2023-08-30T20:50:42.908+0000] {subprocess.py:93} INFO - LINE 1: ... longitude, address, weekday, date, time) VALUES ('169292169...
[2023-08-30T20:50:42.909+0000] {subprocess.py:93} INFO -                                                              ^
[2023-08-30T20:50:42.911+0000] {subprocess.py:93} INFO - 
[2023-08-30T20:50:42.912+0000] {subprocess.py:93} INFO - [SQL: INSERT INTO traffic_report (timestamp, traffic_report_id, date_time, issue_reported, latitude, longitude, address, weekday, date, time) VALUES (%(timestamp)s, %(traffic_report_id)s, %(date_time)s, %(issue_reported)s, %(latitude)s, %(longitude)s, %(address)s, %(weekday)s, %(date)s, %(time)s)]
[2023-08-30T20:50:42.913+0000] {subprocess.py:93} INFO - [parameters: ({'timestamp': '1692921696000000000', 'traffic_report_id': 'B74E9CAD775D997FC742B45E1BA7BD5295D63D13_1692921696', 'date_time': '2023-08-25 00:01:36+00:00', 'issue_reported': 'crash urgent', 'latitude': '30.24078', 'longitude': '-97.688698', 'address': '247-317 bastrop hwy nb', 'weekday': 'Friday', 'date': '2023-08-25', 'time': '00:01:36'}, {'timestamp': '1692922515000000000', 'traffic_report_id': '59E221A4758B17362BDEAE901C5A8F58057468B2_1692922515', 'date_time': '2023-08-25 00:15:15+00:00', 'issue_reported': 'crash service', 'latitude': '30.265881', 'longitude': '-97.735003', 'address': 'e 6th st / n ih 35 svrd sb', 'weekday': 'Friday', 'date': '2023-08-25', 'time': '00:15:15'}, {'timestamp': '1692922987000000000', 'traffic_report_id': '757578FBF23FFA4D748E0800DD7C424A46FEB0CC_1692922987', 'date_time': '2023-08-25 00:23:07+00:00', 'issue_reported': 'crash service', 'latitude': '30.396327', 'longitude': '-97.848308', 'address': '11004 fm 2222 rd', 'weekday': 'Friday', 'date': '2023-08-25', 'time': '00:23:07'}, {'timestamp': '1692923103000000000', 'traffic_report_id': 'C60D81F35D8BE966FA0437E43F1FEFF777C6E121_1692923103', 'date_time': '2023-08-25 00:25:03+00:00', 'issue_reported': 'stalled vehicle', 'latitude': '30.307093', 'longitude': '-97.758168', 'address': 'w 35th to mopac sb ramp', 'weekday': 'Friday', 'date': '2023-08-25', 'time': '00:25:03'}, {'timestamp': '1692923525000000000', 'traffic_report_id': '89CA91E6C9B28BDCFB629B12758F955D21072594_1692923525', 'date_time': '2023-08-25 00:32:05+00:00', 'issue_reported': 'traffic hazard', 'latitude': '30.330871', 'longitude': '-97.731593', 'address': 'w koenig ln / woodrow ave', 'weekday': 'Friday', 'date': '2023-08-25', 'time': '00:32:05'}, {'timestamp': '1692923984000000000', 'traffic_report_id': '3B987A82043F7DF95B5784095B5CE3BB870DC709_1692923984', 'date_time': '2023-08-25 00:39:44+00:00', 'issue_reported': 'collision', 'latitude': '30.107487', 'longitude': '-97.694708', 'address': '9800-blk s us 183 hwy', 'weekday': 'Friday', 'date': '2023-08-25', 'time': '00:39:44'}, {'timestamp': '1692924072000000000', 'traffic_report_id': 'E6602176F26DD0C5FB721FDED265EC8570F686E7_1692924072', 'date_time': '2023-08-25 00:41:12+00:00', 'issue_reported': 'traffic hazard', 'latitude': '30.26303', 'longitude': '-97.743207', 'address': 'brazos st / e cesar chavez st', 'weekday': 'Friday', 'date': '2023-08-25', 'time': '00:41:12'}, {'timestamp': '1692924987000000000', 'traffic_report_id': '6DF29A0769E84AF53CC4F71A6017FCF41AD0148D_1692924987', 'date_time': '2023-08-25 00:56:27+00:00', 'issue_reported': 'crash service', 'latitude': '30.420458', 'longitude': '-97.748872', 'address': '11750 research blvd svrd sb', 'weekday': 'Friday', 'date': '2023-08-25', 'time': '00:56:27'}  ... displaying 10 of 149 total bound parameter sets ...  {'timestamp': '1693007033000000000', 'traffic_report_id': '3E9459D66B2BF63A0F4CFDDC2B117A444BCD6A95_1693007033', 'date_time': '2023-08-25 23:43:53+00:00', 'issue_reported': 'crash service', 'latitude': '30.206611', 'longitude': '-97.638781', 'address': '2900-3148 s fm 973 rd', 'weekday': 'Friday', 'date': '2023-08-25', 'time': '23:43:53'}, {'timestamp': '1693007481000000000', 'traffic_report_id': '7CA48B0569F515A124807357262BB8714E81FCA3_1693007481', 'date_time': '2023-08-25 23:51:21+00:00', 'issue_reported': 'collision', 'latitude': '30.257618', 'longitude': '-97.60157', 'address': '5000-7475 n sh 130 nb', 'weekday': 'Friday', 'date': '2023-08-25', 'time': '23:51:21'})]
[2023-08-30T20:50:42.915+0000] {subprocess.py:93} INFO - (Background on this error at: https://sqlalche.me/e/14/9h9h)
[2023-08-30T20:50:42.917+0000] {subprocess.py:97} INFO - Command exited with return code 1
[2023-08-30T20:50:42.935+0000] {taskinstance.py:1943} ERROR - Task failed with exception
Traceback (most recent call last):
  File "/home/airflow/.local/lib/python3.8/site-packages/airflow/operators/bash.py", line 210, in execute
    raise AirflowException(
airflow.exceptions.AirflowException: Bash command failed. The command returned a non-zero exit code 1.
[2023-08-30T20:50:42.940+0000] {taskinstance.py:1400} INFO - Marking task as FAILED. dag_id=traffic_report, task_id=export_data_to_db, execution_date=20230826T000000, start_date=20230830T205035, end_date=20230830T205042
[2023-08-30T20:50:42.956+0000] {standard_task_runner.py:104} ERROR - Failed to execute job 25 for task export_data_to_db (Bash command failed. The command returned a non-zero exit code 1.; 480)
[2023-08-30T20:50:43.001+0000] {local_task_job_runner.py:228} INFO - Task exited with return code 1
[2023-08-30T20:50:43.021+0000] {taskinstance.py:2784} INFO - 0 downstream tasks scheduled from follow-on schedule check
[2023-08-30T21:10:00.850+0000] {logging_mixin.py:151} WARNING - /home/***/.local/lib/python3.8/site-packages/***/utils/sqlalchemy.py:124 DeprecationWarning: The sql_alchemy_conn option in [core] has been moved to the sql_alchemy_conn option in [database] - the old setting has been used, but please update your config.
[2023-08-30T21:10:01.365+0000] {taskinstance.py:1159} INFO - Dependencies all met for dep_context=non-requeueable deps ti=<TaskInstance: traffic_report.export_data_to_db scheduled__2023-08-26T00:00:00+00:00 [queued]>
[2023-08-30T21:10:01.429+0000] {taskinstance.py:1159} INFO - Dependencies all met for dep_context=requeueable deps ti=<TaskInstance: traffic_report.export_data_to_db scheduled__2023-08-26T00:00:00+00:00 [queued]>
[2023-08-30T21:10:01.432+0000] {taskinstance.py:1361} INFO - Starting attempt 2 of 2
[2023-08-30T21:10:05.092+0000] {taskinstance.py:1382} INFO - Executing <Task(BashOperator): export_data_to_db> on 2023-08-26 00:00:00+00:00
[2023-08-30T21:10:05.122+0000] {standard_task_runner.py:57} INFO - Started process 454 to run task
[2023-08-30T21:10:05.164+0000] {standard_task_runner.py:84} INFO - Running: ['***', 'tasks', 'run', 'traffic_report', 'export_data_to_db', 'scheduled__2023-08-26T00:00:00+00:00', '--job-id', '27', '--raw', '--subdir', 'DAGS_FOLDER/traffic_dag.py', '--cfg-path', '/tmp/tmpvbegbu2e']
[2023-08-30T21:10:05.171+0000] {standard_task_runner.py:85} INFO - Job 27: Subtask export_data_to_db
[2023-08-30T21:10:05.261+0000] {logging_mixin.py:151} WARNING - /home/***/.local/lib/python3.8/site-packages/***/settings.py:195 DeprecationWarning: The sql_alchemy_conn option in [core] has been moved to the sql_alchemy_conn option in [database] - the old setting has been used, but please update your config.
[2023-08-30T21:10:05.437+0000] {task_command.py:415} INFO - Running <TaskInstance: traffic_report.export_data_to_db scheduled__2023-08-26T00:00:00+00:00 [running]> on host cbc745b7550b
[2023-08-30T21:10:05.464+0000] {logging_mixin.py:151} WARNING - /home/***/.local/lib/python3.8/site-packages/***/utils/sqlalchemy.py:124 DeprecationWarning: The sql_alchemy_conn option in [core] has been moved to the sql_alchemy_conn option in [database] - the old setting has been used, but please update your config.
[2023-08-30T21:10:05.559+0000] {taskinstance.py:1660} INFO - Exporting env vars: AIRFLOW_CTX_DAG_OWNER='***' AIRFLOW_CTX_DAG_ID='traffic_report' AIRFLOW_CTX_TASK_ID='export_data_to_db' AIRFLOW_CTX_EXECUTION_DATE='2023-08-26T00:00:00+00:00' AIRFLOW_CTX_TRY_NUMBER='2' AIRFLOW_CTX_DAG_RUN_ID='scheduled__2023-08-26T00:00:00+00:00'
[2023-08-30T21:10:05.562+0000] {subprocess.py:63} INFO - Tmp dir root location: /tmp
[2023-08-30T21:10:05.564+0000] {subprocess.py:75} INFO - Running command: ['/bin/bash', '-c', 'python /opt/***/dags/data_to_db.py --date 2023-08-26 --connection postgresql+psycopg2://***:***@postgres/***']
[2023-08-30T21:10:05.578+0000] {subprocess.py:86} INFO - Output:
[2023-08-30T21:10:30.445+0000] {subprocess.py:93} INFO - Traceback (most recent call last):
[2023-08-30T21:10:30.448+0000] {subprocess.py:93} INFO -   File "/home/***/.local/lib/python3.8/site-packages/sqlalchemy/engine/base.py", line 1890, in _execute_context
[2023-08-30T21:10:30.450+0000] {subprocess.py:93} INFO -     self.dialect.do_executemany(
[2023-08-30T21:10:30.451+0000] {subprocess.py:93} INFO -   File "/home/***/.local/lib/python3.8/site-packages/sqlalchemy/dialects/postgresql/psycopg2.py", line 982, in do_executemany
[2023-08-30T21:10:30.453+0000] {subprocess.py:93} INFO -     context._psycopg2_fetched_rows = xtras.execute_values(
[2023-08-30T21:10:30.455+0000] {subprocess.py:93} INFO -   File "/home/***/.local/lib/python3.8/site-packages/psycopg2/extras.py", line 1299, in execute_values
[2023-08-30T21:10:30.457+0000] {subprocess.py:93} INFO -     cur.execute(b''.join(parts))
[2023-08-30T21:10:30.458+0000] {subprocess.py:93} INFO - psycopg2.errors.StringDataRightTruncation: value too long for type character varying(20)
[2023-08-30T21:10:30.459+0000] {subprocess.py:93} INFO - 
[2023-08-30T21:10:30.462+0000] {subprocess.py:93} INFO - 
[2023-08-30T21:10:30.464+0000] {subprocess.py:93} INFO - The above exception was the direct cause of the following exception:
[2023-08-30T21:10:30.465+0000] {subprocess.py:93} INFO - 
[2023-08-30T21:10:30.466+0000] {subprocess.py:93} INFO - Traceback (most recent call last):
[2023-08-30T21:10:30.468+0000] {subprocess.py:93} INFO -   File "/opt/***/dags/data_to_db.py", line 49, in <module>
[2023-08-30T21:10:30.470+0000] {subprocess.py:93} INFO -     main(args.date, args.connection)
[2023-08-30T21:10:30.472+0000] {subprocess.py:93} INFO -   File "/opt/***/dags/data_to_db.py", line 40, in main
[2023-08-30T21:10:30.474+0000] {subprocess.py:93} INFO -     session.bulk_save_objects(data_insert)
[2023-08-30T21:10:30.476+0000] {subprocess.py:93} INFO -   File "/home/***/.local/lib/python3.8/site-packages/sqlalchemy/orm/session.py", line 3705, in bulk_save_objects
[2023-08-30T21:10:30.477+0000] {subprocess.py:93} INFO -     self._bulk_save_mappings(
[2023-08-30T21:10:30.479+0000] {subprocess.py:93} INFO -   File "/home/***/.local/lib/python3.8/site-packages/sqlalchemy/orm/session.py", line 3913, in _bulk_save_mappings
[2023-08-30T21:10:30.485+0000] {subprocess.py:93} INFO -     transaction.rollback(_capture_exception=True)
[2023-08-30T21:10:30.488+0000] {subprocess.py:93} INFO -   File "/home/***/.local/lib/python3.8/site-packages/sqlalchemy/util/langhelpers.py", line 70, in __exit__
[2023-08-30T21:10:30.490+0000] {subprocess.py:93} INFO -     compat.raise_(
[2023-08-30T21:10:30.491+0000] {subprocess.py:93} INFO -   File "/home/***/.local/lib/python3.8/site-packages/sqlalchemy/util/compat.py", line 211, in raise_
[2023-08-30T21:10:30.492+0000] {subprocess.py:93} INFO -     raise exception
[2023-08-30T21:10:30.493+0000] {subprocess.py:93} INFO -   File "/home/***/.local/lib/python3.8/site-packages/sqlalchemy/orm/session.py", line 3901, in _bulk_save_mappings
[2023-08-30T21:10:30.495+0000] {subprocess.py:93} INFO -     persistence._bulk_insert(
[2023-08-30T21:10:30.496+0000] {subprocess.py:93} INFO -   File "/home/***/.local/lib/python3.8/site-packages/sqlalchemy/orm/persistence.py", line 107, in _bulk_insert
[2023-08-30T21:10:30.498+0000] {subprocess.py:93} INFO -     _emit_insert_statements(
[2023-08-30T21:10:30.502+0000] {subprocess.py:93} INFO -   File "/home/***/.local/lib/python3.8/site-packages/sqlalchemy/orm/persistence.py", line 1097, in _emit_insert_statements
[2023-08-30T21:10:30.503+0000] {subprocess.py:93} INFO -     c = connection._execute_20(
[2023-08-30T21:10:30.504+0000] {subprocess.py:93} INFO -   File "/home/***/.local/lib/python3.8/site-packages/sqlalchemy/engine/base.py", line 1710, in _execute_20
[2023-08-30T21:10:30.506+0000] {subprocess.py:93} INFO -     return meth(self, args_10style, kwargs_10style, execution_options)
[2023-08-30T21:10:30.507+0000] {subprocess.py:93} INFO -   File "/home/***/.local/lib/python3.8/site-packages/sqlalchemy/sql/elements.py", line 334, in _execute_on_connection
[2023-08-30T21:10:30.508+0000] {subprocess.py:93} INFO -     return connection._execute_clauseelement(
[2023-08-30T21:10:30.510+0000] {subprocess.py:93} INFO -   File "/home/***/.local/lib/python3.8/site-packages/sqlalchemy/engine/base.py", line 1577, in _execute_clauseelement
[2023-08-30T21:10:30.512+0000] {subprocess.py:93} INFO -     ret = self._execute_context(
[2023-08-30T21:10:30.516+0000] {subprocess.py:93} INFO -   File "/home/***/.local/lib/python3.8/site-packages/sqlalchemy/engine/base.py", line 1953, in _execute_context
[2023-08-30T21:10:30.517+0000] {subprocess.py:93} INFO -     self._handle_dbapi_exception(
[2023-08-30T21:10:30.518+0000] {subprocess.py:93} INFO -   File "/home/***/.local/lib/python3.8/site-packages/sqlalchemy/engine/base.py", line 2134, in _handle_dbapi_exception
[2023-08-30T21:10:30.521+0000] {subprocess.py:93} INFO -     util.raise_(
[2023-08-30T21:10:30.525+0000] {subprocess.py:93} INFO -   File "/home/***/.local/lib/python3.8/site-packages/sqlalchemy/util/compat.py", line 211, in raise_
[2023-08-30T21:10:30.529+0000] {subprocess.py:93} INFO -     raise exception
[2023-08-30T21:10:30.531+0000] {subprocess.py:93} INFO -   File "/home/***/.local/lib/python3.8/site-packages/sqlalchemy/engine/base.py", line 1890, in _execute_context
[2023-08-30T21:10:30.534+0000] {subprocess.py:93} INFO -     self.dialect.do_executemany(
[2023-08-30T21:10:30.537+0000] {subprocess.py:93} INFO -   File "/home/***/.local/lib/python3.8/site-packages/sqlalchemy/dialects/postgresql/psycopg2.py", line 982, in do_executemany
[2023-08-30T21:10:30.539+0000] {subprocess.py:93} INFO -     context._psycopg2_fetched_rows = xtras.execute_values(
[2023-08-30T21:10:30.541+0000] {subprocess.py:93} INFO -   File "/home/***/.local/lib/python3.8/site-packages/psycopg2/extras.py", line 1299, in execute_values
[2023-08-30T21:10:30.542+0000] {subprocess.py:93} INFO -     cur.execute(b''.join(parts))
[2023-08-30T21:10:30.544+0000] {subprocess.py:93} INFO - sqlalchemy.exc.DataError: (psycopg2.errors.StringDataRightTruncation) value too long for type character varying(20)
[2023-08-30T21:10:30.546+0000] {subprocess.py:93} INFO - 
[2023-08-30T21:10:30.547+0000] {subprocess.py:93} INFO - [SQL: INSERT INTO traffic_report (timestamp, traffic_report_id, date_time, issue_reported, latitude, longitude, address, weekday, date, time) VALUES (%(timestamp)s, %(traffic_report_id)s, %(date_time)s, %(issue_reported)s, %(latitude)s, %(longitude)s, %(address)s, %(weekday)s, %(date)s, %(time)s)]
[2023-08-30T21:10:30.550+0000] {subprocess.py:93} INFO - [parameters: ({'timestamp': '1692921696000000000', 'traffic_report_id': 'B74E9CAD775D997FC742B45E1BA7BD5295D63D13_1692921696', 'date_time': '2023-08-25 00:01:36+00:00', 'issue_reported': 'crash urgent', 'latitude': '30.24078', 'longitude': '-97.688698', 'address': '247-317 bastrop hwy nb', 'weekday': 'Friday', 'date': '2023-08-25', 'time': '00:01:36'}, {'timestamp': '1692922515000000000', 'traffic_report_id': '59E221A4758B17362BDEAE901C5A8F58057468B2_1692922515', 'date_time': '2023-08-25 00:15:15+00:00', 'issue_reported': 'crash service', 'latitude': '30.265881', 'longitude': '-97.735003', 'address': 'e 6th st / n ih 35 svrd sb', 'weekday': 'Friday', 'date': '2023-08-25', 'time': '00:15:15'}, {'timestamp': '1692922987000000000', 'traffic_report_id': '757578FBF23FFA4D748E0800DD7C424A46FEB0CC_1692922987', 'date_time': '2023-08-25 00:23:07+00:00', 'issue_reported': 'crash service', 'latitude': '30.396327', 'longitude': '-97.848308', 'address': '11004 fm 2222 rd', 'weekday': 'Friday', 'date': '2023-08-25', 'time': '00:23:07'}, {'timestamp': '1692923103000000000', 'traffic_report_id': 'C60D81F35D8BE966FA0437E43F1FEFF777C6E121_1692923103', 'date_time': '2023-08-25 00:25:03+00:00', 'issue_reported': 'stalled vehicle', 'latitude': '30.307093', 'longitude': '-97.758168', 'address': 'w 35th to mopac sb ramp', 'weekday': 'Friday', 'date': '2023-08-25', 'time': '00:25:03'}, {'timestamp': '1692923525000000000', 'traffic_report_id': '89CA91E6C9B28BDCFB629B12758F955D21072594_1692923525', 'date_time': '2023-08-25 00:32:05+00:00', 'issue_reported': 'traffic hazard', 'latitude': '30.330871', 'longitude': '-97.731593', 'address': 'w koenig ln / woodrow ave', 'weekday': 'Friday', 'date': '2023-08-25', 'time': '00:32:05'}, {'timestamp': '1692923984000000000', 'traffic_report_id': '3B987A82043F7DF95B5784095B5CE3BB870DC709_1692923984', 'date_time': '2023-08-25 00:39:44+00:00', 'issue_reported': 'collision', 'latitude': '30.107487', 'longitude': '-97.694708', 'address': '9800-blk s us 183 hwy', 'weekday': 'Friday', 'date': '2023-08-25', 'time': '00:39:44'}, {'timestamp': '1692924072000000000', 'traffic_report_id': 'E6602176F26DD0C5FB721FDED265EC8570F686E7_1692924072', 'date_time': '2023-08-25 00:41:12+00:00', 'issue_reported': 'traffic hazard', 'latitude': '30.26303', 'longitude': '-97.743207', 'address': 'brazos st / e cesar chavez st', 'weekday': 'Friday', 'date': '2023-08-25', 'time': '00:41:12'}, {'timestamp': '1692924987000000000', 'traffic_report_id': '6DF29A0769E84AF53CC4F71A6017FCF41AD0148D_1692924987', 'date_time': '2023-08-25 00:56:27+00:00', 'issue_reported': 'crash service', 'latitude': '30.420458', 'longitude': '-97.748872', 'address': '11750 research blvd svrd sb', 'weekday': 'Friday', 'date': '2023-08-25', 'time': '00:56:27'}  ... displaying 10 of 149 total bound parameter sets ...  {'timestamp': '1693007033000000000', 'traffic_report_id': '3E9459D66B2BF63A0F4CFDDC2B117A444BCD6A95_1693007033', 'date_time': '2023-08-25 23:43:53+00:00', 'issue_reported': 'crash service', 'latitude': '30.206611', 'longitude': '-97.638781', 'address': '2900-3148 s fm 973 rd', 'weekday': 'Friday', 'date': '2023-08-25', 'time': '23:43:53'}, {'timestamp': '1693007481000000000', 'traffic_report_id': '7CA48B0569F515A124807357262BB8714E81FCA3_1693007481', 'date_time': '2023-08-25 23:51:21+00:00', 'issue_reported': 'collision', 'latitude': '30.257618', 'longitude': '-97.60157', 'address': '5000-7475 n sh 130 nb', 'weekday': 'Friday', 'date': '2023-08-25', 'time': '23:51:21'})]
[2023-08-30T21:10:30.551+0000] {subprocess.py:93} INFO - (Background on this error at: https://sqlalche.me/e/14/9h9h)
[2023-08-30T21:10:30.553+0000] {subprocess.py:97} INFO - Command exited with return code 1
[2023-08-30T21:10:30.599+0000] {taskinstance.py:1943} ERROR - Task failed with exception
Traceback (most recent call last):
  File "/home/airflow/.local/lib/python3.8/site-packages/airflow/operators/bash.py", line 210, in execute
    raise AirflowException(
airflow.exceptions.AirflowException: Bash command failed. The command returned a non-zero exit code 1.
[2023-08-30T21:10:30.606+0000] {taskinstance.py:1400} INFO - Marking task as FAILED. dag_id=traffic_report, task_id=export_data_to_db, execution_date=20230826T000000, start_date=20230830T211001, end_date=20230830T211030
[2023-08-30T21:10:30.635+0000] {standard_task_runner.py:104} ERROR - Failed to execute job 27 for task export_data_to_db (Bash command failed. The command returned a non-zero exit code 1.; 454)
[2023-08-30T21:10:30.661+0000] {local_task_job_runner.py:228} INFO - Task exited with return code 1
[2023-08-30T21:10:30.688+0000] {taskinstance.py:2784} INFO - 0 downstream tasks scheduled from follow-on schedule check
