[2023-08-30T19:31:43.105+0000] {logging_mixin.py:151} WARNING - /home/***/.local/lib/python3.8/site-packages/***/utils/sqlalchemy.py:124 DeprecationWarning: The sql_alchemy_conn option in [core] has been moved to the sql_alchemy_conn option in [database] - the old setting has been used, but please update your config.
[2023-08-30T19:31:43.117+0000] {taskinstance.py:1159} INFO - Dependencies all met for dep_context=non-requeueable deps ti=<TaskInstance: traffic_report.export_data_to_db scheduled__2023-08-26T00:00:00+00:00 [queued]>
[2023-08-30T19:31:43.128+0000] {taskinstance.py:1159} INFO - Dependencies all met for dep_context=requeueable deps ti=<TaskInstance: traffic_report.export_data_to_db scheduled__2023-08-26T00:00:00+00:00 [queued]>
[2023-08-30T19:31:43.131+0000] {taskinstance.py:1361} INFO - Starting attempt 1 of 2
[2023-08-30T19:31:43.143+0000] {taskinstance.py:1382} INFO - Executing <Task(BashOperator): export_data_to_db> on 2023-08-26 00:00:00+00:00
[2023-08-30T19:31:43.149+0000] {standard_task_runner.py:57} INFO - Started process 317 to run task
[2023-08-30T19:31:43.158+0000] {standard_task_runner.py:84} INFO - Running: ['***', 'tasks', 'run', 'traffic_report', 'export_data_to_db', 'scheduled__2023-08-26T00:00:00+00:00', '--job-id', '17', '--raw', '--subdir', 'DAGS_FOLDER/traffic_dag.py', '--cfg-path', '/tmp/tmpa7atqsr4']
[2023-08-30T19:31:43.161+0000] {standard_task_runner.py:85} INFO - Job 17: Subtask export_data_to_db
[2023-08-30T19:31:43.183+0000] {logging_mixin.py:151} WARNING - /home/***/.local/lib/python3.8/site-packages/***/settings.py:195 DeprecationWarning: The sql_alchemy_conn option in [core] has been moved to the sql_alchemy_conn option in [database] - the old setting has been used, but please update your config.
[2023-08-30T19:31:43.244+0000] {task_command.py:415} INFO - Running <TaskInstance: traffic_report.export_data_to_db scheduled__2023-08-26T00:00:00+00:00 [running]> on host f6bcf103ff79
[2023-08-30T19:31:43.261+0000] {logging_mixin.py:151} WARNING - /home/***/.local/lib/python3.8/site-packages/***/utils/sqlalchemy.py:124 DeprecationWarning: The sql_alchemy_conn option in [core] has been moved to the sql_alchemy_conn option in [database] - the old setting has been used, but please update your config.
[2023-08-30T19:31:43.320+0000] {taskinstance.py:1660} INFO - Exporting env vars: AIRFLOW_CTX_DAG_OWNER='***' AIRFLOW_CTX_DAG_ID='traffic_report' AIRFLOW_CTX_TASK_ID='export_data_to_db' AIRFLOW_CTX_EXECUTION_DATE='2023-08-26T00:00:00+00:00' AIRFLOW_CTX_TRY_NUMBER='1' AIRFLOW_CTX_DAG_RUN_ID='scheduled__2023-08-26T00:00:00+00:00'
[2023-08-30T19:31:43.323+0000] {subprocess.py:63} INFO - Tmp dir root location: /tmp
[2023-08-30T19:31:43.325+0000] {subprocess.py:75} INFO - Running command: ['/bin/bash', '-c', 'python /opt/***/dags/data_to_db.py --date 2023-08-26 --connection postgresql+psycopg2://***:***@postgres/***']
[2023-08-30T19:31:43.337+0000] {subprocess.py:86} INFO - Output:
[2023-08-30T19:31:43.740+0000] {subprocess.py:93} INFO - Traceback (most recent call last):
[2023-08-30T19:31:43.741+0000] {subprocess.py:93} INFO -   File "/opt/***/dags/data_to_db.py", line 6, in <module>
[2023-08-30T19:31:43.743+0000] {subprocess.py:93} INFO -     from model import Connection, Traffic
[2023-08-30T19:31:43.744+0000] {subprocess.py:93} INFO -   File "/opt/***/dags/model.py", line 5, in <module>
[2023-08-30T19:31:43.746+0000] {subprocess.py:93} INFO -     from geoalchemy2 import Geometry
[2023-08-30T19:31:43.747+0000] {subprocess.py:93} INFO - ModuleNotFoundError: No module named 'geoalchemy2'
[2023-08-30T19:31:43.783+0000] {subprocess.py:97} INFO - Command exited with return code 1
[2023-08-30T19:31:43.806+0000] {taskinstance.py:1943} ERROR - Task failed with exception
Traceback (most recent call last):
  File "/home/airflow/.local/lib/python3.8/site-packages/airflow/operators/bash.py", line 210, in execute
    raise AirflowException(
airflow.exceptions.AirflowException: Bash command failed. The command returned a non-zero exit code 1.
[2023-08-30T19:31:43.811+0000] {taskinstance.py:1400} INFO - Marking task as UP_FOR_RETRY. dag_id=traffic_report, task_id=export_data_to_db, execution_date=20230826T000000, start_date=20230830T193143, end_date=20230830T193143
[2023-08-30T19:31:43.831+0000] {standard_task_runner.py:104} ERROR - Failed to execute job 17 for task export_data_to_db (Bash command failed. The command returned a non-zero exit code 1.; 317)
[2023-08-30T19:31:43.864+0000] {local_task_job_runner.py:228} INFO - Task exited with return code 1
[2023-08-30T19:31:43.883+0000] {taskinstance.py:2784} INFO - 0 downstream tasks scheduled from follow-on schedule check
[2023-08-30T19:42:02.049+0000] {logging_mixin.py:151} WARNING - /home/***/.local/lib/python3.8/site-packages/***/utils/sqlalchemy.py:124 DeprecationWarning: The sql_alchemy_conn option in [core] has been moved to the sql_alchemy_conn option in [database] - the old setting has been used, but please update your config.
[2023-08-30T19:42:02.063+0000] {taskinstance.py:1159} INFO - Dependencies all met for dep_context=non-requeueable deps ti=<TaskInstance: traffic_report.export_data_to_db scheduled__2023-08-26T00:00:00+00:00 [queued]>
[2023-08-30T19:42:02.071+0000] {taskinstance.py:1159} INFO - Dependencies all met for dep_context=requeueable deps ti=<TaskInstance: traffic_report.export_data_to_db scheduled__2023-08-26T00:00:00+00:00 [queued]>
[2023-08-30T19:42:02.073+0000] {taskinstance.py:1361} INFO - Starting attempt 1 of 2
[2023-08-30T19:42:02.090+0000] {taskinstance.py:1382} INFO - Executing <Task(BashOperator): export_data_to_db> on 2023-08-26 00:00:00+00:00
[2023-08-30T19:42:02.097+0000] {standard_task_runner.py:57} INFO - Started process 381 to run task
[2023-08-30T19:42:02.110+0000] {standard_task_runner.py:84} INFO - Running: ['***', 'tasks', 'run', 'traffic_report', 'export_data_to_db', 'scheduled__2023-08-26T00:00:00+00:00', '--job-id', '16', '--raw', '--subdir', 'DAGS_FOLDER/traffic_dag.py', '--cfg-path', '/tmp/tmpqquwf1w5']
[2023-08-30T19:42:02.113+0000] {standard_task_runner.py:85} INFO - Job 16: Subtask export_data_to_db
[2023-08-30T19:42:02.142+0000] {logging_mixin.py:151} WARNING - /home/***/.local/lib/python3.8/site-packages/***/settings.py:195 DeprecationWarning: The sql_alchemy_conn option in [core] has been moved to the sql_alchemy_conn option in [database] - the old setting has been used, but please update your config.
[2023-08-30T19:42:02.214+0000] {task_command.py:415} INFO - Running <TaskInstance: traffic_report.export_data_to_db scheduled__2023-08-26T00:00:00+00:00 [running]> on host 81eeb4b7c8a9
[2023-08-30T19:42:02.231+0000] {logging_mixin.py:151} WARNING - /home/***/.local/lib/python3.8/site-packages/***/utils/sqlalchemy.py:124 DeprecationWarning: The sql_alchemy_conn option in [core] has been moved to the sql_alchemy_conn option in [database] - the old setting has been used, but please update your config.
[2023-08-30T19:42:02.308+0000] {taskinstance.py:1660} INFO - Exporting env vars: AIRFLOW_CTX_DAG_OWNER='***' AIRFLOW_CTX_DAG_ID='traffic_report' AIRFLOW_CTX_TASK_ID='export_data_to_db' AIRFLOW_CTX_EXECUTION_DATE='2023-08-26T00:00:00+00:00' AIRFLOW_CTX_TRY_NUMBER='1' AIRFLOW_CTX_DAG_RUN_ID='scheduled__2023-08-26T00:00:00+00:00'
[2023-08-30T19:42:02.314+0000] {subprocess.py:63} INFO - Tmp dir root location: /tmp
[2023-08-30T19:42:02.318+0000] {subprocess.py:75} INFO - Running command: ['/bin/bash', '-c', 'python /opt/***/dags/data_to_db.py --date 2023-08-26 --connection postgresql+psycopg2://***:***@postgres/***']
[2023-08-30T19:42:02.342+0000] {subprocess.py:86} INFO - Output:
[2023-08-30T19:42:02.875+0000] {subprocess.py:93} INFO - Traceback (most recent call last):
[2023-08-30T19:42:02.878+0000] {subprocess.py:93} INFO -   File "/opt/***/dags/data_to_db.py", line 6, in <module>
[2023-08-30T19:42:02.880+0000] {subprocess.py:93} INFO -     from model import Connection, Traffic
[2023-08-30T19:42:02.881+0000] {subprocess.py:93} INFO -   File "/opt/***/dags/model.py", line 5, in <module>
[2023-08-30T19:42:02.882+0000] {subprocess.py:93} INFO -     from geoalchemy2 import Geometry
[2023-08-30T19:42:02.883+0000] {subprocess.py:93} INFO - ModuleNotFoundError: No module named 'geoalchemy2'
[2023-08-30T19:42:02.924+0000] {subprocess.py:97} INFO - Command exited with return code 1
[2023-08-30T19:42:02.944+0000] {taskinstance.py:1943} ERROR - Task failed with exception
Traceback (most recent call last):
  File "/home/airflow/.local/lib/python3.8/site-packages/airflow/operators/bash.py", line 210, in execute
    raise AirflowException(
airflow.exceptions.AirflowException: Bash command failed. The command returned a non-zero exit code 1.
[2023-08-30T19:42:02.953+0000] {taskinstance.py:1400} INFO - Marking task as UP_FOR_RETRY. dag_id=traffic_report, task_id=export_data_to_db, execution_date=20230826T000000, start_date=20230830T194202, end_date=20230830T194202
[2023-08-30T19:42:02.973+0000] {standard_task_runner.py:104} ERROR - Failed to execute job 16 for task export_data_to_db (Bash command failed. The command returned a non-zero exit code 1.; 381)
[2023-08-30T19:42:03.021+0000] {local_task_job_runner.py:228} INFO - Task exited with return code 1
[2023-08-30T19:42:03.042+0000] {taskinstance.py:2784} INFO - 0 downstream tasks scheduled from follow-on schedule check
[2023-08-30T19:51:05.593+0000] {logging_mixin.py:151} WARNING - /home/***/.local/lib/python3.8/site-packages/***/utils/sqlalchemy.py:124 DeprecationWarning: The sql_alchemy_conn option in [core] has been moved to the sql_alchemy_conn option in [database] - the old setting has been used, but please update your config.
[2023-08-30T19:51:05.612+0000] {taskinstance.py:1159} INFO - Dependencies all met for dep_context=non-requeueable deps ti=<TaskInstance: traffic_report.export_data_to_db scheduled__2023-08-26T00:00:00+00:00 [queued]>
[2023-08-30T19:51:05.627+0000] {taskinstance.py:1159} INFO - Dependencies all met for dep_context=requeueable deps ti=<TaskInstance: traffic_report.export_data_to_db scheduled__2023-08-26T00:00:00+00:00 [queued]>
[2023-08-30T19:51:05.629+0000] {taskinstance.py:1361} INFO - Starting attempt 1 of 2
[2023-08-30T19:51:05.642+0000] {taskinstance.py:1382} INFO - Executing <Task(BashOperator): export_data_to_db> on 2023-08-26 00:00:00+00:00
[2023-08-30T19:51:05.653+0000] {standard_task_runner.py:57} INFO - Started process 359 to run task
[2023-08-30T19:51:05.657+0000] {standard_task_runner.py:84} INFO - Running: ['***', 'tasks', 'run', 'traffic_report', 'export_data_to_db', 'scheduled__2023-08-26T00:00:00+00:00', '--job-id', '19', '--raw', '--subdir', 'DAGS_FOLDER/traffic_dag.py', '--cfg-path', '/tmp/tmp158jla7z']
[2023-08-30T19:51:05.677+0000] {standard_task_runner.py:85} INFO - Job 19: Subtask export_data_to_db
[2023-08-30T19:51:06.850+0000] {logging_mixin.py:151} WARNING - /home/***/.local/lib/python3.8/site-packages/***/settings.py:195 DeprecationWarning: The sql_alchemy_conn option in [core] has been moved to the sql_alchemy_conn option in [database] - the old setting has been used, but please update your config.
[2023-08-30T19:51:07.702+0000] {task_command.py:415} INFO - Running <TaskInstance: traffic_report.export_data_to_db scheduled__2023-08-26T00:00:00+00:00 [running]> on host 206ecb1dc8df
[2023-08-30T19:51:08.364+0000] {logging_mixin.py:151} WARNING - /home/***/.local/lib/python3.8/site-packages/***/utils/sqlalchemy.py:124 DeprecationWarning: The sql_alchemy_conn option in [core] has been moved to the sql_alchemy_conn option in [database] - the old setting has been used, but please update your config.
[2023-08-30T19:51:14.513+0000] {taskinstance.py:1660} INFO - Exporting env vars: AIRFLOW_CTX_DAG_OWNER='***' AIRFLOW_CTX_DAG_ID='traffic_report' AIRFLOW_CTX_TASK_ID='export_data_to_db' AIRFLOW_CTX_EXECUTION_DATE='2023-08-26T00:00:00+00:00' AIRFLOW_CTX_TRY_NUMBER='1' AIRFLOW_CTX_DAG_RUN_ID='scheduled__2023-08-26T00:00:00+00:00'
[2023-08-30T19:51:14.928+0000] {subprocess.py:63} INFO - Tmp dir root location: /tmp
[2023-08-30T19:51:15.012+0000] {subprocess.py:75} INFO - Running command: ['/bin/bash', '-c', 'python /opt/***/dags/data_to_db.py --date 2023-08-26 --connection postgresql+psycopg2://***:***@postgres/***']
[2023-08-30T19:51:15.170+0000] {subprocess.py:86} INFO - Output:
[2023-08-30T19:51:33.985+0000] {subprocess.py:93} INFO - Traceback (most recent call last):
[2023-08-30T19:51:33.989+0000] {subprocess.py:93} INFO -   File "/opt/***/dags/data_to_db.py", line 50, in <module>
[2023-08-30T19:51:33.992+0000] {subprocess.py:93} INFO -     main(args.date, args.connection)
[2023-08-30T19:51:33.994+0000] {subprocess.py:93} INFO -   File "/opt/***/dags/data_to_db.py", line 22, in main
[2023-08-30T19:51:33.995+0000] {subprocess.py:93} INFO -     with open(filename, encoding='utf-8') as csvf:
[2023-08-30T19:51:33.998+0000] {subprocess.py:93} INFO - FileNotFoundError: [Errno 2] No such file or directory: '/opt/***/dags/data/traffic_2023-08-25.csv'
[2023-08-30T19:51:34.116+0000] {subprocess.py:97} INFO - Command exited with return code 1
[2023-08-30T19:51:34.150+0000] {taskinstance.py:1943} ERROR - Task failed with exception
Traceback (most recent call last):
  File "/home/airflow/.local/lib/python3.8/site-packages/airflow/operators/bash.py", line 210, in execute
    raise AirflowException(
airflow.exceptions.AirflowException: Bash command failed. The command returned a non-zero exit code 1.
[2023-08-30T19:51:34.163+0000] {taskinstance.py:1400} INFO - Marking task as UP_FOR_RETRY. dag_id=traffic_report, task_id=export_data_to_db, execution_date=20230826T000000, start_date=20230830T195105, end_date=20230830T195134
[2023-08-30T19:51:34.192+0000] {standard_task_runner.py:104} ERROR - Failed to execute job 19 for task export_data_to_db (Bash command failed. The command returned a non-zero exit code 1.; 359)
[2023-08-30T19:51:34.224+0000] {local_task_job_runner.py:228} INFO - Task exited with return code 1
[2023-08-30T19:51:34.245+0000] {taskinstance.py:2784} INFO - 0 downstream tasks scheduled from follow-on schedule check
[2023-08-30T19:54:33.290+0000] {logging_mixin.py:151} WARNING - /home/***/.local/lib/python3.8/site-packages/***/utils/sqlalchemy.py:124 DeprecationWarning: The sql_alchemy_conn option in [core] has been moved to the sql_alchemy_conn option in [database] - the old setting has been used, but please update your config.
[2023-08-30T19:54:33.309+0000] {taskinstance.py:1159} INFO - Dependencies all met for dep_context=non-requeueable deps ti=<TaskInstance: traffic_report.export_data_to_db scheduled__2023-08-26T00:00:00+00:00 [queued]>
[2023-08-30T19:54:33.325+0000] {taskinstance.py:1159} INFO - Dependencies all met for dep_context=requeueable deps ti=<TaskInstance: traffic_report.export_data_to_db scheduled__2023-08-26T00:00:00+00:00 [queued]>
[2023-08-30T19:54:33.327+0000] {taskinstance.py:1361} INFO - Starting attempt 1 of 2
[2023-08-30T19:54:33.349+0000] {taskinstance.py:1382} INFO - Executing <Task(BashOperator): export_data_to_db> on 2023-08-26 00:00:00+00:00
[2023-08-30T19:54:33.363+0000] {standard_task_runner.py:57} INFO - Started process 314 to run task
[2023-08-30T19:54:33.371+0000] {standard_task_runner.py:84} INFO - Running: ['***', 'tasks', 'run', 'traffic_report', 'export_data_to_db', 'scheduled__2023-08-26T00:00:00+00:00', '--job-id', '18', '--raw', '--subdir', 'DAGS_FOLDER/traffic_dag.py', '--cfg-path', '/tmp/tmpbm16nsnm']
[2023-08-30T19:54:33.375+0000] {standard_task_runner.py:85} INFO - Job 18: Subtask export_data_to_db
[2023-08-30T19:54:33.395+0000] {logging_mixin.py:151} WARNING - /home/***/.local/lib/python3.8/site-packages/***/settings.py:195 DeprecationWarning: The sql_alchemy_conn option in [core] has been moved to the sql_alchemy_conn option in [database] - the old setting has been used, but please update your config.
[2023-08-30T19:54:33.437+0000] {task_command.py:415} INFO - Running <TaskInstance: traffic_report.export_data_to_db scheduled__2023-08-26T00:00:00+00:00 [running]> on host 86f9e97d6c70
[2023-08-30T19:54:33.457+0000] {logging_mixin.py:151} WARNING - /home/***/.local/lib/python3.8/site-packages/***/utils/sqlalchemy.py:124 DeprecationWarning: The sql_alchemy_conn option in [core] has been moved to the sql_alchemy_conn option in [database] - the old setting has been used, but please update your config.
[2023-08-30T19:54:33.545+0000] {taskinstance.py:1660} INFO - Exporting env vars: AIRFLOW_CTX_DAG_OWNER='***' AIRFLOW_CTX_DAG_ID='traffic_report' AIRFLOW_CTX_TASK_ID='export_data_to_db' AIRFLOW_CTX_EXECUTION_DATE='2023-08-26T00:00:00+00:00' AIRFLOW_CTX_TRY_NUMBER='1' AIRFLOW_CTX_DAG_RUN_ID='scheduled__2023-08-26T00:00:00+00:00'
[2023-08-30T19:54:33.564+0000] {subprocess.py:63} INFO - Tmp dir root location: /tmp
[2023-08-30T19:54:33.566+0000] {subprocess.py:75} INFO - Running command: ['/bin/bash', '-c', 'python /opt/***/dags/data_to_db.py --date 2023-08-26 --connection postgresql+psycopg2://***:***@postgres/***']
[2023-08-30T19:54:33.589+0000] {subprocess.py:86} INFO - Output:
[2023-08-30T19:54:34.577+0000] {subprocess.py:93} INFO - Traceback (most recent call last):
[2023-08-30T19:54:34.581+0000] {subprocess.py:93} INFO -   File "/home/***/.local/lib/python3.8/site-packages/sqlalchemy/engine/base.py", line 1910, in _execute_context
[2023-08-30T19:54:34.587+0000] {subprocess.py:93} INFO -     self.dialect.do_execute(
[2023-08-30T19:54:34.589+0000] {subprocess.py:93} INFO -   File "/home/***/.local/lib/python3.8/site-packages/sqlalchemy/engine/default.py", line 736, in do_execute
[2023-08-30T19:54:34.592+0000] {subprocess.py:93} INFO -     cursor.execute(statement, parameters)
[2023-08-30T19:54:34.594+0000] {subprocess.py:93} INFO - psycopg2.errors.UndefinedTable: relation "traffic_report" does not exist
[2023-08-30T19:54:34.596+0000] {subprocess.py:93} INFO - LINE 1: DELETE FROM traffic_report where date_time >= timestamp '202...
[2023-08-30T19:54:34.598+0000] {subprocess.py:93} INFO -                     ^
[2023-08-30T19:54:34.603+0000] {subprocess.py:93} INFO - 
[2023-08-30T19:54:34.614+0000] {subprocess.py:93} INFO - 
[2023-08-30T19:54:34.630+0000] {subprocess.py:93} INFO - The above exception was the direct cause of the following exception:
[2023-08-30T19:54:34.634+0000] {subprocess.py:93} INFO - 
[2023-08-30T19:54:34.641+0000] {subprocess.py:93} INFO - Traceback (most recent call last):
[2023-08-30T19:54:34.648+0000] {subprocess.py:93} INFO -   File "/opt/***/dags/data_to_db.py", line 50, in <module>
[2023-08-30T19:54:34.650+0000] {subprocess.py:93} INFO -     main(args.date, args.connection)
[2023-08-30T19:54:34.651+0000] {subprocess.py:93} INFO -   File "/opt/***/dags/data_to_db.py", line 40, in main
[2023-08-30T19:54:34.657+0000] {subprocess.py:93} INFO -     session.execute("DELETE FROM traffic_report where date_time >= timestamp '{} 00:00:00' and date_time < timestamp'{} 00:00:00'".format(yesterday, fetch_date))
[2023-08-30T19:54:34.660+0000] {subprocess.py:93} INFO -   File "/home/***/.local/lib/python3.8/site-packages/sqlalchemy/orm/session.py", line 1717, in execute
[2023-08-30T19:54:34.661+0000] {subprocess.py:93} INFO -     result = conn._execute_20(statement, params or {}, execution_options)
[2023-08-30T19:54:34.662+0000] {subprocess.py:93} INFO -   File "/home/***/.local/lib/python3.8/site-packages/sqlalchemy/engine/base.py", line 1710, in _execute_20
[2023-08-30T19:54:34.664+0000] {subprocess.py:93} INFO -     return meth(self, args_10style, kwargs_10style, execution_options)
[2023-08-30T19:54:34.666+0000] {subprocess.py:93} INFO -   File "/home/***/.local/lib/python3.8/site-packages/sqlalchemy/sql/elements.py", line 334, in _execute_on_connection
[2023-08-30T19:54:34.667+0000] {subprocess.py:93} INFO -     return connection._execute_clauseelement(
[2023-08-30T19:54:34.668+0000] {subprocess.py:93} INFO -   File "/home/***/.local/lib/python3.8/site-packages/sqlalchemy/engine/base.py", line 1577, in _execute_clauseelement
[2023-08-30T19:54:34.669+0000] {subprocess.py:93} INFO -     ret = self._execute_context(
[2023-08-30T19:54:34.670+0000] {subprocess.py:93} INFO -   File "/home/***/.local/lib/python3.8/site-packages/sqlalchemy/engine/base.py", line 1953, in _execute_context
[2023-08-30T19:54:34.672+0000] {subprocess.py:93} INFO -     self._handle_dbapi_exception(
[2023-08-30T19:54:34.673+0000] {subprocess.py:93} INFO -   File "/home/***/.local/lib/python3.8/site-packages/sqlalchemy/engine/base.py", line 2134, in _handle_dbapi_exception
[2023-08-30T19:54:34.674+0000] {subprocess.py:93} INFO -     util.raise_(
[2023-08-30T19:54:34.676+0000] {subprocess.py:93} INFO -   File "/home/***/.local/lib/python3.8/site-packages/sqlalchemy/util/compat.py", line 211, in raise_
[2023-08-30T19:54:34.677+0000] {subprocess.py:93} INFO -     raise exception
[2023-08-30T19:54:34.678+0000] {subprocess.py:93} INFO -   File "/home/***/.local/lib/python3.8/site-packages/sqlalchemy/engine/base.py", line 1910, in _execute_context
[2023-08-30T19:54:34.678+0000] {subprocess.py:93} INFO -     self.dialect.do_execute(
[2023-08-30T19:54:34.679+0000] {subprocess.py:93} INFO -   File "/home/***/.local/lib/python3.8/site-packages/sqlalchemy/engine/default.py", line 736, in do_execute
[2023-08-30T19:54:34.680+0000] {subprocess.py:93} INFO -     cursor.execute(statement, parameters)
[2023-08-30T19:54:34.681+0000] {subprocess.py:93} INFO - sqlalchemy.exc.ProgrammingError: (psycopg2.errors.UndefinedTable) relation "traffic_report" does not exist
[2023-08-30T19:54:34.682+0000] {subprocess.py:93} INFO - LINE 1: DELETE FROM traffic_report where date_time >= timestamp '202...
[2023-08-30T19:54:34.683+0000] {subprocess.py:93} INFO -                     ^
[2023-08-30T19:54:34.683+0000] {subprocess.py:93} INFO - 
[2023-08-30T19:54:34.685+0000] {subprocess.py:93} INFO - [SQL: DELETE FROM traffic_report where date_time >= timestamp '2023-08-25 00:00:00' and date_time < timestamp'2023-08-26 00:00:00']
[2023-08-30T19:54:34.686+0000] {subprocess.py:93} INFO - (Background on this error at: https://sqlalche.me/e/14/f405)
[2023-08-30T19:54:34.731+0000] {subprocess.py:97} INFO - Command exited with return code 1
[2023-08-30T19:54:34.751+0000] {taskinstance.py:1943} ERROR - Task failed with exception
Traceback (most recent call last):
  File "/home/airflow/.local/lib/python3.8/site-packages/airflow/operators/bash.py", line 210, in execute
    raise AirflowException(
airflow.exceptions.AirflowException: Bash command failed. The command returned a non-zero exit code 1.
[2023-08-30T19:54:34.760+0000] {taskinstance.py:1400} INFO - Marking task as UP_FOR_RETRY. dag_id=traffic_report, task_id=export_data_to_db, execution_date=20230826T000000, start_date=20230830T195433, end_date=20230830T195434
[2023-08-30T19:54:34.783+0000] {standard_task_runner.py:104} ERROR - Failed to execute job 18 for task export_data_to_db (Bash command failed. The command returned a non-zero exit code 1.; 314)
[2023-08-30T19:54:34.834+0000] {local_task_job_runner.py:228} INFO - Task exited with return code 1
[2023-08-30T19:54:34.859+0000] {taskinstance.py:2784} INFO - 0 downstream tasks scheduled from follow-on schedule check
[2023-08-30T20:05:57.068+0000] {logging_mixin.py:151} WARNING - /home/***/.local/lib/python3.8/site-packages/***/utils/sqlalchemy.py:124 DeprecationWarning: The sql_alchemy_conn option in [core] has been moved to the sql_alchemy_conn option in [database] - the old setting has been used, but please update your config.
[2023-08-30T20:05:57.079+0000] {taskinstance.py:1159} INFO - Dependencies all met for dep_context=non-requeueable deps ti=<TaskInstance: traffic_report.export_data_to_db scheduled__2023-08-26T00:00:00+00:00 [queued]>
[2023-08-30T20:05:57.091+0000] {taskinstance.py:1159} INFO - Dependencies all met for dep_context=requeueable deps ti=<TaskInstance: traffic_report.export_data_to_db scheduled__2023-08-26T00:00:00+00:00 [queued]>
[2023-08-30T20:05:57.093+0000] {taskinstance.py:1361} INFO - Starting attempt 1 of 2
[2023-08-30T20:05:57.107+0000] {taskinstance.py:1382} INFO - Executing <Task(BashOperator): export_data_to_db> on 2023-08-26 00:00:00+00:00
[2023-08-30T20:05:57.113+0000] {standard_task_runner.py:57} INFO - Started process 515 to run task
[2023-08-30T20:05:57.120+0000] {standard_task_runner.py:84} INFO - Running: ['***', 'tasks', 'run', 'traffic_report', 'export_data_to_db', 'scheduled__2023-08-26T00:00:00+00:00', '--job-id', '20', '--raw', '--subdir', 'DAGS_FOLDER/traffic_dag.py', '--cfg-path', '/tmp/tmprwz96_4z']
[2023-08-30T20:05:57.124+0000] {standard_task_runner.py:85} INFO - Job 20: Subtask export_data_to_db
[2023-08-30T20:05:57.144+0000] {logging_mixin.py:151} WARNING - /home/***/.local/lib/python3.8/site-packages/***/settings.py:195 DeprecationWarning: The sql_alchemy_conn option in [core] has been moved to the sql_alchemy_conn option in [database] - the old setting has been used, but please update your config.
[2023-08-30T20:05:57.187+0000] {task_command.py:415} INFO - Running <TaskInstance: traffic_report.export_data_to_db scheduled__2023-08-26T00:00:00+00:00 [running]> on host 3938d7abd9ff
[2023-08-30T20:05:57.201+0000] {logging_mixin.py:151} WARNING - /home/***/.local/lib/python3.8/site-packages/***/utils/sqlalchemy.py:124 DeprecationWarning: The sql_alchemy_conn option in [core] has been moved to the sql_alchemy_conn option in [database] - the old setting has been used, but please update your config.
[2023-08-30T20:05:57.259+0000] {taskinstance.py:1660} INFO - Exporting env vars: AIRFLOW_CTX_DAG_OWNER='***' AIRFLOW_CTX_DAG_ID='traffic_report' AIRFLOW_CTX_TASK_ID='export_data_to_db' AIRFLOW_CTX_EXECUTION_DATE='2023-08-26T00:00:00+00:00' AIRFLOW_CTX_TRY_NUMBER='1' AIRFLOW_CTX_DAG_RUN_ID='scheduled__2023-08-26T00:00:00+00:00'
[2023-08-30T20:05:57.271+0000] {subprocess.py:63} INFO - Tmp dir root location: /tmp
[2023-08-30T20:05:57.273+0000] {subprocess.py:75} INFO - Running command: ['/bin/bash', '-c', 'python /opt/***/dags/data_to_db.py --date 2023-08-26 --connection postgresql+psycopg2://***:***@postgres/***']
[2023-08-30T20:05:57.286+0000] {subprocess.py:86} INFO - Output:
[2023-08-30T20:05:58.190+0000] {subprocess.py:93} INFO - Traceback (most recent call last):
[2023-08-30T20:05:58.193+0000] {subprocess.py:93} INFO -   File "/home/***/.local/lib/python3.8/site-packages/sqlalchemy/engine/base.py", line 1890, in _execute_context
[2023-08-30T20:05:58.194+0000] {subprocess.py:93} INFO -     self.dialect.do_executemany(
[2023-08-30T20:05:58.197+0000] {subprocess.py:93} INFO -   File "/home/***/.local/lib/python3.8/site-packages/sqlalchemy/dialects/postgresql/psycopg2.py", line 982, in do_executemany
[2023-08-30T20:05:58.199+0000] {subprocess.py:93} INFO -     context._psycopg2_fetched_rows = xtras.execute_values(
[2023-08-30T20:05:58.201+0000] {subprocess.py:93} INFO -   File "/home/***/.local/lib/python3.8/site-packages/psycopg2/extras.py", line 1299, in execute_values
[2023-08-30T20:05:58.202+0000] {subprocess.py:93} INFO -     cur.execute(b''.join(parts))
[2023-08-30T20:05:58.203+0000] {subprocess.py:93} INFO - psycopg2.errors.UndefinedFunction: function st_geomfromewkt(unknown) does not exist
[2023-08-30T20:05:58.205+0000] {subprocess.py:93} INFO - LINE 1: ...96', '2023-08-25 00:01:36+00:00', 'crash urgent', ST_GeomFro...
[2023-08-30T20:05:58.207+0000] {subprocess.py:93} INFO -                                                              ^
[2023-08-30T20:05:58.213+0000] {subprocess.py:93} INFO - HINT:  No function matches the given name and argument types. You might need to add explicit type casts.
[2023-08-30T20:05:58.215+0000] {subprocess.py:93} INFO - 
[2023-08-30T20:05:58.216+0000] {subprocess.py:93} INFO - 
[2023-08-30T20:05:58.217+0000] {subprocess.py:93} INFO - The above exception was the direct cause of the following exception:
[2023-08-30T20:05:58.219+0000] {subprocess.py:93} INFO - 
[2023-08-30T20:05:58.222+0000] {subprocess.py:93} INFO - Traceback (most recent call last):
[2023-08-30T20:05:58.224+0000] {subprocess.py:93} INFO -   File "/opt/***/dags/data_to_db.py", line 50, in <module>
[2023-08-30T20:05:58.224+0000] {subprocess.py:93} INFO -     main(args.date, args.connection)
[2023-08-30T20:05:58.225+0000] {subprocess.py:93} INFO -   File "/opt/***/dags/data_to_db.py", line 41, in main
[2023-08-30T20:05:58.226+0000] {subprocess.py:93} INFO -     session.bulk_save_objects(data_insert)
[2023-08-30T20:05:58.227+0000] {subprocess.py:93} INFO -   File "/home/***/.local/lib/python3.8/site-packages/sqlalchemy/orm/session.py", line 3705, in bulk_save_objects
[2023-08-30T20:05:58.228+0000] {subprocess.py:93} INFO -     self._bulk_save_mappings(
[2023-08-30T20:05:58.229+0000] {subprocess.py:93} INFO -   File "/home/***/.local/lib/python3.8/site-packages/sqlalchemy/orm/session.py", line 3913, in _bulk_save_mappings
[2023-08-30T20:05:58.232+0000] {subprocess.py:93} INFO -     transaction.rollback(_capture_exception=True)
[2023-08-30T20:05:58.233+0000] {subprocess.py:93} INFO -   File "/home/***/.local/lib/python3.8/site-packages/sqlalchemy/util/langhelpers.py", line 70, in __exit__
[2023-08-30T20:05:58.235+0000] {subprocess.py:93} INFO -     compat.raise_(
[2023-08-30T20:05:58.236+0000] {subprocess.py:93} INFO -   File "/home/***/.local/lib/python3.8/site-packages/sqlalchemy/util/compat.py", line 211, in raise_
[2023-08-30T20:05:58.239+0000] {subprocess.py:93} INFO -     raise exception
[2023-08-30T20:05:58.241+0000] {subprocess.py:93} INFO -   File "/home/***/.local/lib/python3.8/site-packages/sqlalchemy/orm/session.py", line 3901, in _bulk_save_mappings
[2023-08-30T20:05:58.243+0000] {subprocess.py:93} INFO -     persistence._bulk_insert(
[2023-08-30T20:05:58.244+0000] {subprocess.py:93} INFO -   File "/home/***/.local/lib/python3.8/site-packages/sqlalchemy/orm/persistence.py", line 107, in _bulk_insert
[2023-08-30T20:05:58.246+0000] {subprocess.py:93} INFO -     _emit_insert_statements(
[2023-08-30T20:05:58.248+0000] {subprocess.py:93} INFO -   File "/home/***/.local/lib/python3.8/site-packages/sqlalchemy/orm/persistence.py", line 1097, in _emit_insert_statements
[2023-08-30T20:05:58.250+0000] {subprocess.py:93} INFO -     c = connection._execute_20(
[2023-08-30T20:05:58.253+0000] {subprocess.py:93} INFO -   File "/home/***/.local/lib/python3.8/site-packages/sqlalchemy/engine/base.py", line 1710, in _execute_20
[2023-08-30T20:05:58.262+0000] {subprocess.py:93} INFO -     return meth(self, args_10style, kwargs_10style, execution_options)
[2023-08-30T20:05:58.277+0000] {subprocess.py:93} INFO -   File "/home/***/.local/lib/python3.8/site-packages/sqlalchemy/sql/elements.py", line 334, in _execute_on_connection
[2023-08-30T20:05:58.283+0000] {subprocess.py:93} INFO -     return connection._execute_clauseelement(
[2023-08-30T20:05:58.287+0000] {subprocess.py:93} INFO -   File "/home/***/.local/lib/python3.8/site-packages/sqlalchemy/engine/base.py", line 1577, in _execute_clauseelement
[2023-08-30T20:05:58.289+0000] {subprocess.py:93} INFO -     ret = self._execute_context(
[2023-08-30T20:05:58.291+0000] {subprocess.py:93} INFO -   File "/home/***/.local/lib/python3.8/site-packages/sqlalchemy/engine/base.py", line 1953, in _execute_context
[2023-08-30T20:05:58.292+0000] {subprocess.py:93} INFO -     self._handle_dbapi_exception(
[2023-08-30T20:05:58.294+0000] {subprocess.py:93} INFO -   File "/home/***/.local/lib/python3.8/site-packages/sqlalchemy/engine/base.py", line 2134, in _handle_dbapi_exception
[2023-08-30T20:05:58.296+0000] {subprocess.py:93} INFO -     util.raise_(
[2023-08-30T20:05:58.297+0000] {subprocess.py:93} INFO -   File "/home/***/.local/lib/python3.8/site-packages/sqlalchemy/util/compat.py", line 211, in raise_
[2023-08-30T20:05:58.298+0000] {subprocess.py:93} INFO -     raise exception
[2023-08-30T20:05:58.299+0000] {subprocess.py:93} INFO -   File "/home/***/.local/lib/python3.8/site-packages/sqlalchemy/engine/base.py", line 1890, in _execute_context
[2023-08-30T20:05:58.300+0000] {subprocess.py:93} INFO -     self.dialect.do_executemany(
[2023-08-30T20:05:58.301+0000] {subprocess.py:93} INFO -   File "/home/***/.local/lib/python3.8/site-packages/sqlalchemy/dialects/postgresql/psycopg2.py", line 982, in do_executemany
[2023-08-30T20:05:58.302+0000] {subprocess.py:93} INFO -     context._psycopg2_fetched_rows = xtras.execute_values(
[2023-08-30T20:05:58.304+0000] {subprocess.py:93} INFO -   File "/home/***/.local/lib/python3.8/site-packages/psycopg2/extras.py", line 1299, in execute_values
[2023-08-30T20:05:58.305+0000] {subprocess.py:93} INFO -     cur.execute(b''.join(parts))
[2023-08-30T20:05:58.306+0000] {subprocess.py:93} INFO - sqlalchemy.exc.ProgrammingError: (psycopg2.errors.UndefinedFunction) function st_geomfromewkt(unknown) does not exist
[2023-08-30T20:05:58.307+0000] {subprocess.py:93} INFO - LINE 1: ...96', '2023-08-25 00:01:36+00:00', 'crash urgent', ST_GeomFro...
[2023-08-30T20:05:58.309+0000] {subprocess.py:93} INFO -                                                              ^
[2023-08-30T20:05:58.310+0000] {subprocess.py:93} INFO - HINT:  No function matches the given name and argument types. You might need to add explicit type casts.
[2023-08-30T20:05:58.310+0000] {subprocess.py:93} INFO - 
[2023-08-30T20:05:58.311+0000] {subprocess.py:93} INFO - [SQL: INSERT INTO traffic_report (timestamp, traffic_report_id, date_time, issue_reported, location, latitude, longitude, address, weekday, date, time) VALUES (%(timestamp)s, %(traffic_report_id)s, %(date_time)s, %(issue_reported)s, ST_GeomFromEWKT(%(location)s), %(latitude)s, %(longitude)s, %(address)s, %(weekday)s, %(date)s, %(time)s)]
[2023-08-30T20:05:58.312+0000] {subprocess.py:93} INFO - [parameters: ({'timestamp': '1692921696000000000', 'traffic_report_id': 'B74E9CAD775D997FC742B45E1BA7BD5295D63D13_1692921696', 'date_time': '2023-08-25 00:01:36+00:00', 'issue_reported': 'crash urgent', 'location': 'POINT(-97.688698 30.24078)', 'latitude': '30.24078', 'longitude': '-97.688698', 'address': '247-317 bastrop hwy nb', 'weekday': 'Friday', 'date': '2023-08-25', 'time': '00:01:36'}, {'timestamp': '1692922515000000000', 'traffic_report_id': '59E221A4758B17362BDEAE901C5A8F58057468B2_1692922515', 'date_time': '2023-08-25 00:15:15+00:00', 'issue_reported': 'crash service', 'location': 'POINT(-97.735003 30.265881)', 'latitude': '30.265881', 'longitude': '-97.735003', 'address': 'e 6th st / n ih 35 svrd sb', 'weekday': 'Friday', 'date': '2023-08-25', 'time': '00:15:15'}, {'timestamp': '1692922987000000000', 'traffic_report_id': '757578FBF23FFA4D748E0800DD7C424A46FEB0CC_1692922987', 'date_time': '2023-08-25 00:23:07+00:00', 'issue_reported': 'crash service', 'location': 'POINT(-97.848308 30.396327)', 'latitude': '30.396327', 'longitude': '-97.848308', 'address': '11004 fm 2222 rd', 'weekday': 'Friday', 'date': '2023-08-25', 'time': '00:23:07'}, {'timestamp': '1692923103000000000', 'traffic_report_id': 'C60D81F35D8BE966FA0437E43F1FEFF777C6E121_1692923103', 'date_time': '2023-08-25 00:25:03+00:00', 'issue_reported': 'stalled vehicle', 'location': 'POINT(-97.758168 30.307093)', 'latitude': '30.307093', 'longitude': '-97.758168', 'address': 'w 35th to mopac sb ramp', 'weekday': 'Friday', 'date': '2023-08-25', 'time': '00:25:03'}, {'timestamp': '1692923525000000000', 'traffic_report_id': '89CA91E6C9B28BDCFB629B12758F955D21072594_1692923525', 'date_time': '2023-08-25 00:32:05+00:00', 'issue_reported': 'traffic hazard', 'location': 'POINT(-97.731593 30.330871)', 'latitude': '30.330871', 'longitude': '-97.731593', 'address': 'w koenig ln / woodrow ave', 'weekday': 'Friday', 'date': '2023-08-25', 'time': '00:32:05'}, {'timestamp': '1692923984000000000', 'traffic_report_id': '3B987A82043F7DF95B5784095B5CE3BB870DC709_1692923984', 'date_time': '2023-08-25 00:39:44+00:00', 'issue_reported': 'collision', 'location': 'POINT(-97.694708 30.107487)', 'latitude': '30.107487', 'longitude': '-97.694708', 'address': '9800-blk s us 183 hwy', 'weekday': 'Friday', 'date': '2023-08-25', 'time': '00:39:44'}, {'timestamp': '1692924072000000000', 'traffic_report_id': 'E6602176F26DD0C5FB721FDED265EC8570F686E7_1692924072', 'date_time': '2023-08-25 00:41:12+00:00', 'issue_reported': 'traffic hazard', 'location': 'POINT(-97.743207 30.26303)', 'latitude': '30.26303', 'longitude': '-97.743207', 'address': 'brazos st / e cesar chavez st', 'weekday': 'Friday', 'date': '2023-08-25', 'time': '00:41:12'}, {'timestamp': '1692924987000000000', 'traffic_report_id': '6DF29A0769E84AF53CC4F71A6017FCF41AD0148D_1692924987', 'date_time': '2023-08-25 00:56:27+00:00', 'issue_reported': 'crash service', 'location': 'POINT(-97.748872 30.420458)', 'latitude': '30.420458', 'longitude': '-97.748872', 'address': '11750 research blvd svrd sb', 'weekday': 'Friday', 'date': '2023-08-25', 'time': '00:56:27'}  ... displaying 10 of 149 total bound parameter sets ...  {'timestamp': '1693007033000000000', 'traffic_report_id': '3E9459D66B2BF63A0F4CFDDC2B117A444BCD6A95_1693007033', 'date_time': '2023-08-25 23:43:53+00:00', 'issue_reported': 'crash service', 'location': 'POINT(-97.638781 30.206611)', 'latitude': '30.206611', 'longitude': '-97.638781', 'address': '2900-3148 s fm 973 rd', 'weekday': 'Friday', 'date': '2023-08-25', 'time': '23:43:53'}, {'timestamp': '1693007481000000000', 'traffic_report_id': '7CA48B0569F515A124807357262BB8714E81FCA3_1693007481', 'date_time': '2023-08-25 23:51:21+00:00', 'issue_reported': 'collision', 'location': 'POINT(-97.60157 30.257618)', 'latitude': '30.257618', 'longitude': '-97.60157', 'address': '5000-7475 n sh 130 nb', 'weekday': 'Friday', 'date': '2023-08-25', 'time': '23:51:21'})]
[2023-08-30T20:05:58.314+0000] {subprocess.py:93} INFO - (Background on this error at: https://sqlalche.me/e/14/f405)
[2023-08-30T20:05:58.315+0000] {subprocess.py:97} INFO - Command exited with return code 1
[2023-08-30T20:05:58.340+0000] {taskinstance.py:1943} ERROR - Task failed with exception
Traceback (most recent call last):
  File "/home/airflow/.local/lib/python3.8/site-packages/airflow/operators/bash.py", line 210, in execute
    raise AirflowException(
airflow.exceptions.AirflowException: Bash command failed. The command returned a non-zero exit code 1.
[2023-08-30T20:05:58.343+0000] {taskinstance.py:1400} INFO - Marking task as UP_FOR_RETRY. dag_id=traffic_report, task_id=export_data_to_db, execution_date=20230826T000000, start_date=20230830T200557, end_date=20230830T200558
[2023-08-30T20:05:58.360+0000] {standard_task_runner.py:104} ERROR - Failed to execute job 20 for task export_data_to_db (Bash command failed. The command returned a non-zero exit code 1.; 515)
[2023-08-30T20:05:58.380+0000] {local_task_job_runner.py:228} INFO - Task exited with return code 1
[2023-08-30T20:05:58.397+0000] {taskinstance.py:2784} INFO - 0 downstream tasks scheduled from follow-on schedule check
[2023-08-30T20:33:59.746+0000] {logging_mixin.py:151} WARNING - /home/***/.local/lib/python3.8/site-packages/***/utils/sqlalchemy.py:124 DeprecationWarning: The sql_alchemy_conn option in [core] has been moved to the sql_alchemy_conn option in [database] - the old setting has been used, but please update your config.
[2023-08-30T20:33:59.760+0000] {taskinstance.py:1159} INFO - Dependencies all met for dep_context=non-requeueable deps ti=<TaskInstance: traffic_report.export_data_to_db scheduled__2023-08-26T00:00:00+00:00 [queued]>
[2023-08-30T20:33:59.775+0000] {taskinstance.py:1159} INFO - Dependencies all met for dep_context=requeueable deps ti=<TaskInstance: traffic_report.export_data_to_db scheduled__2023-08-26T00:00:00+00:00 [queued]>
[2023-08-30T20:33:59.776+0000] {taskinstance.py:1361} INFO - Starting attempt 1 of 2
[2023-08-30T20:33:59.793+0000] {taskinstance.py:1382} INFO - Executing <Task(BashOperator): export_data_to_db> on 2023-08-26 00:00:00+00:00
[2023-08-30T20:33:59.801+0000] {standard_task_runner.py:57} INFO - Started process 338 to run task
[2023-08-30T20:33:59.807+0000] {standard_task_runner.py:84} INFO - Running: ['***', 'tasks', 'run', 'traffic_report', 'export_data_to_db', 'scheduled__2023-08-26T00:00:00+00:00', '--job-id', '16', '--raw', '--subdir', 'DAGS_FOLDER/traffic_dag.py', '--cfg-path', '/tmp/tmpyxdph_pd']
[2023-08-30T20:33:59.812+0000] {standard_task_runner.py:85} INFO - Job 16: Subtask export_data_to_db
[2023-08-30T20:33:59.845+0000] {logging_mixin.py:151} WARNING - /home/***/.local/lib/python3.8/site-packages/***/settings.py:195 DeprecationWarning: The sql_alchemy_conn option in [core] has been moved to the sql_alchemy_conn option in [database] - the old setting has been used, but please update your config.
[2023-08-30T20:33:59.902+0000] {task_command.py:415} INFO - Running <TaskInstance: traffic_report.export_data_to_db scheduled__2023-08-26T00:00:00+00:00 [running]> on host 961f38e8363e
[2023-08-30T20:33:59.920+0000] {logging_mixin.py:151} WARNING - /home/***/.local/lib/python3.8/site-packages/***/utils/sqlalchemy.py:124 DeprecationWarning: The sql_alchemy_conn option in [core] has been moved to the sql_alchemy_conn option in [database] - the old setting has been used, but please update your config.
[2023-08-30T20:34:00.027+0000] {taskinstance.py:1660} INFO - Exporting env vars: AIRFLOW_CTX_DAG_OWNER='***' AIRFLOW_CTX_DAG_ID='traffic_report' AIRFLOW_CTX_TASK_ID='export_data_to_db' AIRFLOW_CTX_EXECUTION_DATE='2023-08-26T00:00:00+00:00' AIRFLOW_CTX_TRY_NUMBER='1' AIRFLOW_CTX_DAG_RUN_ID='scheduled__2023-08-26T00:00:00+00:00'
[2023-08-30T20:34:00.034+0000] {subprocess.py:63} INFO - Tmp dir root location: /tmp
[2023-08-30T20:34:00.036+0000] {subprocess.py:75} INFO - Running command: ['/bin/bash', '-c', 'python /opt/***/dags/data_to_db.py --date 2023-08-26 --connection postgresql+psycopg2://***:***@postgres/***']
[2023-08-30T20:34:00.052+0000] {subprocess.py:86} INFO - Output:
[2023-08-30T20:34:01.058+0000] {subprocess.py:93} INFO - Traceback (most recent call last):
[2023-08-30T20:34:01.061+0000] {subprocess.py:93} INFO -   File "/home/***/.local/lib/python3.8/site-packages/sqlalchemy/engine/base.py", line 1890, in _execute_context
[2023-08-30T20:34:01.062+0000] {subprocess.py:93} INFO -     self.dialect.do_executemany(
[2023-08-30T20:34:01.064+0000] {subprocess.py:93} INFO -   File "/home/***/.local/lib/python3.8/site-packages/sqlalchemy/dialects/postgresql/psycopg2.py", line 982, in do_executemany
[2023-08-30T20:34:01.065+0000] {subprocess.py:93} INFO -     context._psycopg2_fetched_rows = xtras.execute_values(
[2023-08-30T20:34:01.073+0000] {subprocess.py:93} INFO -   File "/home/***/.local/lib/python3.8/site-packages/psycopg2/extras.py", line 1299, in execute_values
[2023-08-30T20:34:01.076+0000] {subprocess.py:93} INFO -     cur.execute(b''.join(parts))
[2023-08-30T20:34:01.078+0000] {subprocess.py:93} INFO - psycopg2.errors.UndefinedFunction: function st_geomfromewkt(unknown) does not exist
[2023-08-30T20:34:01.079+0000] {subprocess.py:93} INFO - LINE 1: ...96', '2023-08-25 00:01:36+00:00', 'crash urgent', ST_GeomFro...
[2023-08-30T20:34:01.081+0000] {subprocess.py:93} INFO -                                                              ^
[2023-08-30T20:34:01.085+0000] {subprocess.py:93} INFO - HINT:  No function matches the given name and argument types. You might need to add explicit type casts.
[2023-08-30T20:34:01.087+0000] {subprocess.py:93} INFO - 
[2023-08-30T20:34:01.088+0000] {subprocess.py:93} INFO - 
[2023-08-30T20:34:01.089+0000] {subprocess.py:93} INFO - The above exception was the direct cause of the following exception:
[2023-08-30T20:34:01.091+0000] {subprocess.py:93} INFO - 
[2023-08-30T20:34:01.092+0000] {subprocess.py:93} INFO - Traceback (most recent call last):
[2023-08-30T20:34:01.094+0000] {subprocess.py:93} INFO -   File "/opt/***/dags/data_to_db.py", line 50, in <module>
[2023-08-30T20:34:01.095+0000] {subprocess.py:93} INFO -     main(args.date, args.connection)
[2023-08-30T20:34:01.097+0000] {subprocess.py:93} INFO -   File "/opt/***/dags/data_to_db.py", line 41, in main
[2023-08-30T20:34:01.098+0000] {subprocess.py:93} INFO -     session.bulk_save_objects(data_insert)
[2023-08-30T20:34:01.101+0000] {subprocess.py:93} INFO -   File "/home/***/.local/lib/python3.8/site-packages/sqlalchemy/orm/session.py", line 3705, in bulk_save_objects
[2023-08-30T20:34:01.103+0000] {subprocess.py:93} INFO -     self._bulk_save_mappings(
[2023-08-30T20:34:01.104+0000] {subprocess.py:93} INFO -   File "/home/***/.local/lib/python3.8/site-packages/sqlalchemy/orm/session.py", line 3913, in _bulk_save_mappings
[2023-08-30T20:34:01.105+0000] {subprocess.py:93} INFO -     transaction.rollback(_capture_exception=True)
[2023-08-30T20:34:01.107+0000] {subprocess.py:93} INFO -   File "/home/***/.local/lib/python3.8/site-packages/sqlalchemy/util/langhelpers.py", line 70, in __exit__
[2023-08-30T20:34:01.108+0000] {subprocess.py:93} INFO -     compat.raise_(
[2023-08-30T20:34:01.110+0000] {subprocess.py:93} INFO -   File "/home/***/.local/lib/python3.8/site-packages/sqlalchemy/util/compat.py", line 211, in raise_
[2023-08-30T20:34:01.112+0000] {subprocess.py:93} INFO -     raise exception
[2023-08-30T20:34:01.113+0000] {subprocess.py:93} INFO -   File "/home/***/.local/lib/python3.8/site-packages/sqlalchemy/orm/session.py", line 3901, in _bulk_save_mappings
[2023-08-30T20:34:01.115+0000] {subprocess.py:93} INFO -     persistence._bulk_insert(
[2023-08-30T20:34:01.118+0000] {subprocess.py:93} INFO -   File "/home/***/.local/lib/python3.8/site-packages/sqlalchemy/orm/persistence.py", line 107, in _bulk_insert
[2023-08-30T20:34:01.120+0000] {subprocess.py:93} INFO -     _emit_insert_statements(
[2023-08-30T20:34:01.121+0000] {subprocess.py:93} INFO -   File "/home/***/.local/lib/python3.8/site-packages/sqlalchemy/orm/persistence.py", line 1097, in _emit_insert_statements
[2023-08-30T20:34:01.122+0000] {subprocess.py:93} INFO -     c = connection._execute_20(
[2023-08-30T20:34:01.124+0000] {subprocess.py:93} INFO -   File "/home/***/.local/lib/python3.8/site-packages/sqlalchemy/engine/base.py", line 1710, in _execute_20
[2023-08-30T20:34:01.126+0000] {subprocess.py:93} INFO -     return meth(self, args_10style, kwargs_10style, execution_options)
[2023-08-30T20:34:01.128+0000] {subprocess.py:93} INFO -   File "/home/***/.local/lib/python3.8/site-packages/sqlalchemy/sql/elements.py", line 334, in _execute_on_connection
[2023-08-30T20:34:01.129+0000] {subprocess.py:93} INFO -     return connection._execute_clauseelement(
[2023-08-30T20:34:01.131+0000] {subprocess.py:93} INFO -   File "/home/***/.local/lib/python3.8/site-packages/sqlalchemy/engine/base.py", line 1577, in _execute_clauseelement
[2023-08-30T20:34:01.132+0000] {subprocess.py:93} INFO -     ret = self._execute_context(
[2023-08-30T20:34:01.133+0000] {subprocess.py:93} INFO -   File "/home/***/.local/lib/python3.8/site-packages/sqlalchemy/engine/base.py", line 1953, in _execute_context
[2023-08-30T20:34:01.136+0000] {subprocess.py:93} INFO -     self._handle_dbapi_exception(
[2023-08-30T20:34:01.138+0000] {subprocess.py:93} INFO -   File "/home/***/.local/lib/python3.8/site-packages/sqlalchemy/engine/base.py", line 2134, in _handle_dbapi_exception
[2023-08-30T20:34:01.140+0000] {subprocess.py:93} INFO -     util.raise_(
[2023-08-30T20:34:01.143+0000] {subprocess.py:93} INFO -   File "/home/***/.local/lib/python3.8/site-packages/sqlalchemy/util/compat.py", line 211, in raise_
[2023-08-30T20:34:01.145+0000] {subprocess.py:93} INFO -     raise exception
[2023-08-30T20:34:01.146+0000] {subprocess.py:93} INFO -   File "/home/***/.local/lib/python3.8/site-packages/sqlalchemy/engine/base.py", line 1890, in _execute_context
[2023-08-30T20:34:01.148+0000] {subprocess.py:93} INFO -     self.dialect.do_executemany(
[2023-08-30T20:34:01.149+0000] {subprocess.py:93} INFO -   File "/home/***/.local/lib/python3.8/site-packages/sqlalchemy/dialects/postgresql/psycopg2.py", line 982, in do_executemany
[2023-08-30T20:34:01.152+0000] {subprocess.py:93} INFO -     context._psycopg2_fetched_rows = xtras.execute_values(
[2023-08-30T20:34:01.156+0000] {subprocess.py:93} INFO -   File "/home/***/.local/lib/python3.8/site-packages/psycopg2/extras.py", line 1299, in execute_values
[2023-08-30T20:34:01.158+0000] {subprocess.py:93} INFO -     cur.execute(b''.join(parts))
[2023-08-30T20:34:01.160+0000] {subprocess.py:93} INFO - sqlalchemy.exc.ProgrammingError: (psycopg2.errors.UndefinedFunction) function st_geomfromewkt(unknown) does not exist
[2023-08-30T20:34:01.161+0000] {subprocess.py:93} INFO - LINE 1: ...96', '2023-08-25 00:01:36+00:00', 'crash urgent', ST_GeomFro...
[2023-08-30T20:34:01.162+0000] {subprocess.py:93} INFO -                                                              ^
[2023-08-30T20:34:01.164+0000] {subprocess.py:93} INFO - HINT:  No function matches the given name and argument types. You might need to add explicit type casts.
[2023-08-30T20:34:01.165+0000] {subprocess.py:93} INFO - 
[2023-08-30T20:34:01.166+0000] {subprocess.py:93} INFO - [SQL: INSERT INTO traffic_report (timestamp, traffic_report_id, date_time, issue_reported, location, latitude, longitude, address, weekday, date, time) VALUES (%(timestamp)s, %(traffic_report_id)s, %(date_time)s, %(issue_reported)s, ST_GeomFromEWKT(%(location)s), %(latitude)s, %(longitude)s, %(address)s, %(weekday)s, %(date)s, %(time)s)]
[2023-08-30T20:34:01.171+0000] {subprocess.py:93} INFO - [parameters: ({'timestamp': '1692921696000000000', 'traffic_report_id': 'B74E9CAD775D997FC742B45E1BA7BD5295D63D13_1692921696', 'date_time': '2023-08-25 00:01:36+00:00', 'issue_reported': 'crash urgent', 'location': 'POINT(-97.688698 30.24078)', 'latitude': '30.24078', 'longitude': '-97.688698', 'address': '247-317 bastrop hwy nb', 'weekday': 'Friday', 'date': '2023-08-25', 'time': '00:01:36'}, {'timestamp': '1692922515000000000', 'traffic_report_id': '59E221A4758B17362BDEAE901C5A8F58057468B2_1692922515', 'date_time': '2023-08-25 00:15:15+00:00', 'issue_reported': 'crash service', 'location': 'POINT(-97.735003 30.265881)', 'latitude': '30.265881', 'longitude': '-97.735003', 'address': 'e 6th st / n ih 35 svrd sb', 'weekday': 'Friday', 'date': '2023-08-25', 'time': '00:15:15'}, {'timestamp': '1692922987000000000', 'traffic_report_id': '757578FBF23FFA4D748E0800DD7C424A46FEB0CC_1692922987', 'date_time': '2023-08-25 00:23:07+00:00', 'issue_reported': 'crash service', 'location': 'POINT(-97.848308 30.396327)', 'latitude': '30.396327', 'longitude': '-97.848308', 'address': '11004 fm 2222 rd', 'weekday': 'Friday', 'date': '2023-08-25', 'time': '00:23:07'}, {'timestamp': '1692923103000000000', 'traffic_report_id': 'C60D81F35D8BE966FA0437E43F1FEFF777C6E121_1692923103', 'date_time': '2023-08-25 00:25:03+00:00', 'issue_reported': 'stalled vehicle', 'location': 'POINT(-97.758168 30.307093)', 'latitude': '30.307093', 'longitude': '-97.758168', 'address': 'w 35th to mopac sb ramp', 'weekday': 'Friday', 'date': '2023-08-25', 'time': '00:25:03'}, {'timestamp': '1692923525000000000', 'traffic_report_id': '89CA91E6C9B28BDCFB629B12758F955D21072594_1692923525', 'date_time': '2023-08-25 00:32:05+00:00', 'issue_reported': 'traffic hazard', 'location': 'POINT(-97.731593 30.330871)', 'latitude': '30.330871', 'longitude': '-97.731593', 'address': 'w koenig ln / woodrow ave', 'weekday': 'Friday', 'date': '2023-08-25', 'time': '00:32:05'}, {'timestamp': '1692923984000000000', 'traffic_report_id': '3B987A82043F7DF95B5784095B5CE3BB870DC709_1692923984', 'date_time': '2023-08-25 00:39:44+00:00', 'issue_reported': 'collision', 'location': 'POINT(-97.694708 30.107487)', 'latitude': '30.107487', 'longitude': '-97.694708', 'address': '9800-blk s us 183 hwy', 'weekday': 'Friday', 'date': '2023-08-25', 'time': '00:39:44'}, {'timestamp': '1692924072000000000', 'traffic_report_id': 'E6602176F26DD0C5FB721FDED265EC8570F686E7_1692924072', 'date_time': '2023-08-25 00:41:12+00:00', 'issue_reported': 'traffic hazard', 'location': 'POINT(-97.743207 30.26303)', 'latitude': '30.26303', 'longitude': '-97.743207', 'address': 'brazos st / e cesar chavez st', 'weekday': 'Friday', 'date': '2023-08-25', 'time': '00:41:12'}, {'timestamp': '1692924987000000000', 'traffic_report_id': '6DF29A0769E84AF53CC4F71A6017FCF41AD0148D_1692924987', 'date_time': '2023-08-25 00:56:27+00:00', 'issue_reported': 'crash service', 'location': 'POINT(-97.748872 30.420458)', 'latitude': '30.420458', 'longitude': '-97.748872', 'address': '11750 research blvd svrd sb', 'weekday': 'Friday', 'date': '2023-08-25', 'time': '00:56:27'}  ... displaying 10 of 149 total bound parameter sets ...  {'timestamp': '1693007033000000000', 'traffic_report_id': '3E9459D66B2BF63A0F4CFDDC2B117A444BCD6A95_1693007033', 'date_time': '2023-08-25 23:43:53+00:00', 'issue_reported': 'crash service', 'location': 'POINT(-97.638781 30.206611)', 'latitude': '30.206611', 'longitude': '-97.638781', 'address': '2900-3148 s fm 973 rd', 'weekday': 'Friday', 'date': '2023-08-25', 'time': '23:43:53'}, {'timestamp': '1693007481000000000', 'traffic_report_id': '7CA48B0569F515A124807357262BB8714E81FCA3_1693007481', 'date_time': '2023-08-25 23:51:21+00:00', 'issue_reported': 'collision', 'location': 'POINT(-97.60157 30.257618)', 'latitude': '30.257618', 'longitude': '-97.60157', 'address': '5000-7475 n sh 130 nb', 'weekday': 'Friday', 'date': '2023-08-25', 'time': '23:51:21'})]
[2023-08-30T20:34:01.173+0000] {subprocess.py:93} INFO - (Background on this error at: https://sqlalche.me/e/14/f405)
[2023-08-30T20:34:01.337+0000] {subprocess.py:97} INFO - Command exited with return code 1
[2023-08-30T20:34:01.361+0000] {taskinstance.py:1943} ERROR - Task failed with exception
Traceback (most recent call last):
  File "/home/airflow/.local/lib/python3.8/site-packages/airflow/operators/bash.py", line 210, in execute
    raise AirflowException(
airflow.exceptions.AirflowException: Bash command failed. The command returned a non-zero exit code 1.
[2023-08-30T20:34:01.369+0000] {taskinstance.py:1400} INFO - Marking task as UP_FOR_RETRY. dag_id=traffic_report, task_id=export_data_to_db, execution_date=20230826T000000, start_date=20230830T203359, end_date=20230830T203401
[2023-08-30T20:34:01.424+0000] {standard_task_runner.py:104} ERROR - Failed to execute job 16 for task export_data_to_db (Bash command failed. The command returned a non-zero exit code 1.; 338)
[2023-08-30T20:34:01.477+0000] {local_task_job_runner.py:228} INFO - Task exited with return code 1
[2023-08-30T20:34:01.498+0000] {taskinstance.py:2784} INFO - 0 downstream tasks scheduled from follow-on schedule check
[2023-08-30T20:48:32.602+0000] {logging_mixin.py:151} WARNING - /home/***/.local/lib/python3.8/site-packages/***/utils/sqlalchemy.py:124 DeprecationWarning: The sql_alchemy_conn option in [core] has been moved to the sql_alchemy_conn option in [database] - the old setting has been used, but please update your config.
[2023-08-30T20:48:32.619+0000] {taskinstance.py:1159} INFO - Dependencies all met for dep_context=non-requeueable deps ti=<TaskInstance: traffic_report.export_data_to_db scheduled__2023-08-26T00:00:00+00:00 [queued]>
[2023-08-30T20:48:32.634+0000] {taskinstance.py:1159} INFO - Dependencies all met for dep_context=requeueable deps ti=<TaskInstance: traffic_report.export_data_to_db scheduled__2023-08-26T00:00:00+00:00 [queued]>
[2023-08-30T20:48:32.635+0000] {taskinstance.py:1361} INFO - Starting attempt 1 of 2
[2023-08-30T20:48:32.652+0000] {taskinstance.py:1382} INFO - Executing <Task(BashOperator): export_data_to_db> on 2023-08-26 00:00:00+00:00
[2023-08-30T20:48:32.659+0000] {standard_task_runner.py:57} INFO - Started process 395 to run task
[2023-08-30T20:48:32.664+0000] {standard_task_runner.py:84} INFO - Running: ['***', 'tasks', 'run', 'traffic_report', 'export_data_to_db', 'scheduled__2023-08-26T00:00:00+00:00', '--job-id', '19', '--raw', '--subdir', 'DAGS_FOLDER/traffic_dag.py', '--cfg-path', '/tmp/tmpze5j8cpd']
[2023-08-30T20:48:32.669+0000] {standard_task_runner.py:85} INFO - Job 19: Subtask export_data_to_db
[2023-08-30T20:48:32.690+0000] {logging_mixin.py:151} WARNING - /home/***/.local/lib/python3.8/site-packages/***/settings.py:195 DeprecationWarning: The sql_alchemy_conn option in [core] has been moved to the sql_alchemy_conn option in [database] - the old setting has been used, but please update your config.
[2023-08-30T20:48:32.736+0000] {task_command.py:415} INFO - Running <TaskInstance: traffic_report.export_data_to_db scheduled__2023-08-26T00:00:00+00:00 [running]> on host 8f66711a2898
[2023-08-30T20:48:32.765+0000] {logging_mixin.py:151} WARNING - /home/***/.local/lib/python3.8/site-packages/***/utils/sqlalchemy.py:124 DeprecationWarning: The sql_alchemy_conn option in [core] has been moved to the sql_alchemy_conn option in [database] - the old setting has been used, but please update your config.
[2023-08-30T20:48:32.841+0000] {taskinstance.py:1660} INFO - Exporting env vars: AIRFLOW_CTX_DAG_OWNER='***' AIRFLOW_CTX_DAG_ID='traffic_report' AIRFLOW_CTX_TASK_ID='export_data_to_db' AIRFLOW_CTX_EXECUTION_DATE='2023-08-26T00:00:00+00:00' AIRFLOW_CTX_TRY_NUMBER='1' AIRFLOW_CTX_DAG_RUN_ID='scheduled__2023-08-26T00:00:00+00:00'
[2023-08-30T20:48:32.844+0000] {subprocess.py:63} INFO - Tmp dir root location: /tmp
[2023-08-30T20:48:32.847+0000] {subprocess.py:75} INFO - Running command: ['/bin/bash', '-c', 'python /opt/***/dags/data_to_db.py --date 2023-08-26 --connection postgresql+psycopg2://***:***@postgres/***']
[2023-08-30T20:48:32.866+0000] {subprocess.py:86} INFO - Output:
[2023-08-30T20:48:33.515+0000] {subprocess.py:93} INFO - Traceback (most recent call last):
[2023-08-30T20:48:33.516+0000] {subprocess.py:93} INFO -   File "/home/***/.local/lib/python3.8/site-packages/sqlalchemy/engine/base.py", line 1890, in _execute_context
[2023-08-30T20:48:33.519+0000] {subprocess.py:93} INFO -     self.dialect.do_executemany(
[2023-08-30T20:48:33.522+0000] {subprocess.py:93} INFO -   File "/home/***/.local/lib/python3.8/site-packages/sqlalchemy/dialects/postgresql/psycopg2.py", line 982, in do_executemany
[2023-08-30T20:48:33.525+0000] {subprocess.py:93} INFO -     context._psycopg2_fetched_rows = xtras.execute_values(
[2023-08-30T20:48:33.532+0000] {subprocess.py:93} INFO -   File "/home/***/.local/lib/python3.8/site-packages/psycopg2/extras.py", line 1299, in execute_values
[2023-08-30T20:48:33.537+0000] {subprocess.py:93} INFO -     cur.execute(b''.join(parts))
[2023-08-30T20:48:33.543+0000] {subprocess.py:93} INFO - psycopg2.errors.NumericValueOutOfRange: value "1692921696000000000" is out of range for type integer
[2023-08-30T20:48:33.545+0000] {subprocess.py:93} INFO - LINE 1: ... longitude, address, weekday, date, time) VALUES ('169292169...
[2023-08-30T20:48:33.547+0000] {subprocess.py:93} INFO -                                                              ^
[2023-08-30T20:48:33.548+0000] {subprocess.py:93} INFO - 
[2023-08-30T20:48:33.552+0000] {subprocess.py:93} INFO - 
[2023-08-30T20:48:33.559+0000] {subprocess.py:93} INFO - The above exception was the direct cause of the following exception:
[2023-08-30T20:48:33.560+0000] {subprocess.py:93} INFO - 
[2023-08-30T20:48:33.562+0000] {subprocess.py:93} INFO - Traceback (most recent call last):
[2023-08-30T20:48:33.566+0000] {subprocess.py:93} INFO -   File "/opt/***/dags/data_to_db.py", line 49, in <module>
[2023-08-30T20:48:33.568+0000] {subprocess.py:93} INFO -     main(args.date, args.connection)
[2023-08-30T20:48:33.570+0000] {subprocess.py:93} INFO -   File "/opt/***/dags/data_to_db.py", line 40, in main
[2023-08-30T20:48:33.574+0000] {subprocess.py:93} INFO -     session.bulk_save_objects(data_insert)
[2023-08-30T20:48:33.576+0000] {subprocess.py:93} INFO -   File "/home/***/.local/lib/python3.8/site-packages/sqlalchemy/orm/session.py", line 3705, in bulk_save_objects
[2023-08-30T20:48:33.578+0000] {subprocess.py:93} INFO -     self._bulk_save_mappings(
[2023-08-30T20:48:33.585+0000] {subprocess.py:93} INFO -   File "/home/***/.local/lib/python3.8/site-packages/sqlalchemy/orm/session.py", line 3913, in _bulk_save_mappings
[2023-08-30T20:48:33.588+0000] {subprocess.py:93} INFO -     transaction.rollback(_capture_exception=True)
[2023-08-30T20:48:33.589+0000] {subprocess.py:93} INFO -   File "/home/***/.local/lib/python3.8/site-packages/sqlalchemy/util/langhelpers.py", line 70, in __exit__
[2023-08-30T20:48:33.594+0000] {subprocess.py:93} INFO -     compat.raise_(
[2023-08-30T20:48:33.599+0000] {subprocess.py:93} INFO -   File "/home/***/.local/lib/python3.8/site-packages/sqlalchemy/util/compat.py", line 211, in raise_
[2023-08-30T20:48:33.604+0000] {subprocess.py:93} INFO -     raise exception
[2023-08-30T20:48:33.609+0000] {subprocess.py:93} INFO -   File "/home/***/.local/lib/python3.8/site-packages/sqlalchemy/orm/session.py", line 3901, in _bulk_save_mappings
[2023-08-30T20:48:33.610+0000] {subprocess.py:93} INFO -     persistence._bulk_insert(
[2023-08-30T20:48:33.611+0000] {subprocess.py:93} INFO -   File "/home/***/.local/lib/python3.8/site-packages/sqlalchemy/orm/persistence.py", line 107, in _bulk_insert
[2023-08-30T20:48:33.613+0000] {subprocess.py:93} INFO -     _emit_insert_statements(
[2023-08-30T20:48:33.615+0000] {subprocess.py:93} INFO -   File "/home/***/.local/lib/python3.8/site-packages/sqlalchemy/orm/persistence.py", line 1097, in _emit_insert_statements
[2023-08-30T20:48:33.617+0000] {subprocess.py:93} INFO -     c = connection._execute_20(
[2023-08-30T20:48:33.618+0000] {subprocess.py:93} INFO -   File "/home/***/.local/lib/python3.8/site-packages/sqlalchemy/engine/base.py", line 1710, in _execute_20
[2023-08-30T20:48:33.621+0000] {subprocess.py:93} INFO -     return meth(self, args_10style, kwargs_10style, execution_options)
[2023-08-30T20:48:33.625+0000] {subprocess.py:93} INFO -   File "/home/***/.local/lib/python3.8/site-packages/sqlalchemy/sql/elements.py", line 334, in _execute_on_connection
[2023-08-30T20:48:33.628+0000] {subprocess.py:93} INFO -     return connection._execute_clauseelement(
[2023-08-30T20:48:33.630+0000] {subprocess.py:93} INFO -   File "/home/***/.local/lib/python3.8/site-packages/sqlalchemy/engine/base.py", line 1577, in _execute_clauseelement
[2023-08-30T20:48:33.632+0000] {subprocess.py:93} INFO -     ret = self._execute_context(
[2023-08-30T20:48:33.634+0000] {subprocess.py:93} INFO -   File "/home/***/.local/lib/python3.8/site-packages/sqlalchemy/engine/base.py", line 1953, in _execute_context
[2023-08-30T20:48:33.636+0000] {subprocess.py:93} INFO -     self._handle_dbapi_exception(
[2023-08-30T20:48:33.637+0000] {subprocess.py:93} INFO -   File "/home/***/.local/lib/python3.8/site-packages/sqlalchemy/engine/base.py", line 2134, in _handle_dbapi_exception
[2023-08-30T20:48:33.638+0000] {subprocess.py:93} INFO -     util.raise_(
[2023-08-30T20:48:33.640+0000] {subprocess.py:93} INFO -   File "/home/***/.local/lib/python3.8/site-packages/sqlalchemy/util/compat.py", line 211, in raise_
[2023-08-30T20:48:33.641+0000] {subprocess.py:93} INFO -     raise exception
[2023-08-30T20:48:33.642+0000] {subprocess.py:93} INFO -   File "/home/***/.local/lib/python3.8/site-packages/sqlalchemy/engine/base.py", line 1890, in _execute_context
[2023-08-30T20:48:33.643+0000] {subprocess.py:93} INFO -     self.dialect.do_executemany(
[2023-08-30T20:48:33.644+0000] {subprocess.py:93} INFO -   File "/home/***/.local/lib/python3.8/site-packages/sqlalchemy/dialects/postgresql/psycopg2.py", line 982, in do_executemany
[2023-08-30T20:48:33.646+0000] {subprocess.py:93} INFO -     context._psycopg2_fetched_rows = xtras.execute_values(
[2023-08-30T20:48:33.647+0000] {subprocess.py:93} INFO -   File "/home/***/.local/lib/python3.8/site-packages/psycopg2/extras.py", line 1299, in execute_values
[2023-08-30T20:48:33.648+0000] {subprocess.py:93} INFO -     cur.execute(b''.join(parts))
[2023-08-30T20:48:33.649+0000] {subprocess.py:93} INFO - sqlalchemy.exc.DataError: (psycopg2.errors.NumericValueOutOfRange) value "1692921696000000000" is out of range for type integer
[2023-08-30T20:48:33.651+0000] {subprocess.py:93} INFO - LINE 1: ... longitude, address, weekday, date, time) VALUES ('169292169...
[2023-08-30T20:48:33.653+0000] {subprocess.py:93} INFO -                                                              ^
[2023-08-30T20:48:33.654+0000] {subprocess.py:93} INFO - 
[2023-08-30T20:48:33.656+0000] {subprocess.py:93} INFO - [SQL: INSERT INTO traffic_report (timestamp, traffic_report_id, date_time, issue_reported, latitude, longitude, address, weekday, date, time) VALUES (%(timestamp)s, %(traffic_report_id)s, %(date_time)s, %(issue_reported)s, %(latitude)s, %(longitude)s, %(address)s, %(weekday)s, %(date)s, %(time)s)]
[2023-08-30T20:48:33.657+0000] {subprocess.py:93} INFO - [parameters: ({'timestamp': '1692921696000000000', 'traffic_report_id': 'B74E9CAD775D997FC742B45E1BA7BD5295D63D13_1692921696', 'date_time': '2023-08-25 00:01:36+00:00', 'issue_reported': 'crash urgent', 'latitude': '30.24078', 'longitude': '-97.688698', 'address': '247-317 bastrop hwy nb', 'weekday': 'Friday', 'date': '2023-08-25', 'time': '00:01:36'}, {'timestamp': '1692922515000000000', 'traffic_report_id': '59E221A4758B17362BDEAE901C5A8F58057468B2_1692922515', 'date_time': '2023-08-25 00:15:15+00:00', 'issue_reported': 'crash service', 'latitude': '30.265881', 'longitude': '-97.735003', 'address': 'e 6th st / n ih 35 svrd sb', 'weekday': 'Friday', 'date': '2023-08-25', 'time': '00:15:15'}, {'timestamp': '1692922987000000000', 'traffic_report_id': '757578FBF23FFA4D748E0800DD7C424A46FEB0CC_1692922987', 'date_time': '2023-08-25 00:23:07+00:00', 'issue_reported': 'crash service', 'latitude': '30.396327', 'longitude': '-97.848308', 'address': '11004 fm 2222 rd', 'weekday': 'Friday', 'date': '2023-08-25', 'time': '00:23:07'}, {'timestamp': '1692923103000000000', 'traffic_report_id': 'C60D81F35D8BE966FA0437E43F1FEFF777C6E121_1692923103', 'date_time': '2023-08-25 00:25:03+00:00', 'issue_reported': 'stalled vehicle', 'latitude': '30.307093', 'longitude': '-97.758168', 'address': 'w 35th to mopac sb ramp', 'weekday': 'Friday', 'date': '2023-08-25', 'time': '00:25:03'}, {'timestamp': '1692923525000000000', 'traffic_report_id': '89CA91E6C9B28BDCFB629B12758F955D21072594_1692923525', 'date_time': '2023-08-25 00:32:05+00:00', 'issue_reported': 'traffic hazard', 'latitude': '30.330871', 'longitude': '-97.731593', 'address': 'w koenig ln / woodrow ave', 'weekday': 'Friday', 'date': '2023-08-25', 'time': '00:32:05'}, {'timestamp': '1692923984000000000', 'traffic_report_id': '3B987A82043F7DF95B5784095B5CE3BB870DC709_1692923984', 'date_time': '2023-08-25 00:39:44+00:00', 'issue_reported': 'collision', 'latitude': '30.107487', 'longitude': '-97.694708', 'address': '9800-blk s us 183 hwy', 'weekday': 'Friday', 'date': '2023-08-25', 'time': '00:39:44'}, {'timestamp': '1692924072000000000', 'traffic_report_id': 'E6602176F26DD0C5FB721FDED265EC8570F686E7_1692924072', 'date_time': '2023-08-25 00:41:12+00:00', 'issue_reported': 'traffic hazard', 'latitude': '30.26303', 'longitude': '-97.743207', 'address': 'brazos st / e cesar chavez st', 'weekday': 'Friday', 'date': '2023-08-25', 'time': '00:41:12'}, {'timestamp': '1692924987000000000', 'traffic_report_id': '6DF29A0769E84AF53CC4F71A6017FCF41AD0148D_1692924987', 'date_time': '2023-08-25 00:56:27+00:00', 'issue_reported': 'crash service', 'latitude': '30.420458', 'longitude': '-97.748872', 'address': '11750 research blvd svrd sb', 'weekday': 'Friday', 'date': '2023-08-25', 'time': '00:56:27'}  ... displaying 10 of 149 total bound parameter sets ...  {'timestamp': '1693007033000000000', 'traffic_report_id': '3E9459D66B2BF63A0F4CFDDC2B117A444BCD6A95_1693007033', 'date_time': '2023-08-25 23:43:53+00:00', 'issue_reported': 'crash service', 'latitude': '30.206611', 'longitude': '-97.638781', 'address': '2900-3148 s fm 973 rd', 'weekday': 'Friday', 'date': '2023-08-25', 'time': '23:43:53'}, {'timestamp': '1693007481000000000', 'traffic_report_id': '7CA48B0569F515A124807357262BB8714E81FCA3_1693007481', 'date_time': '2023-08-25 23:51:21+00:00', 'issue_reported': 'collision', 'latitude': '30.257618', 'longitude': '-97.60157', 'address': '5000-7475 n sh 130 nb', 'weekday': 'Friday', 'date': '2023-08-25', 'time': '23:51:21'})]
[2023-08-30T20:48:33.661+0000] {subprocess.py:93} INFO - (Background on this error at: https://sqlalche.me/e/14/9h9h)
[2023-08-30T20:48:33.668+0000] {subprocess.py:97} INFO - Command exited with return code 1
[2023-08-30T20:48:33.688+0000] {taskinstance.py:1943} ERROR - Task failed with exception
Traceback (most recent call last):
  File "/home/airflow/.local/lib/python3.8/site-packages/airflow/operators/bash.py", line 210, in execute
    raise AirflowException(
airflow.exceptions.AirflowException: Bash command failed. The command returned a non-zero exit code 1.
[2023-08-30T20:48:33.696+0000] {taskinstance.py:1400} INFO - Marking task as UP_FOR_RETRY. dag_id=traffic_report, task_id=export_data_to_db, execution_date=20230826T000000, start_date=20230830T204832, end_date=20230830T204833
[2023-08-30T20:48:33.718+0000] {standard_task_runner.py:104} ERROR - Failed to execute job 19 for task export_data_to_db (Bash command failed. The command returned a non-zero exit code 1.; 395)
[2023-08-30T20:48:33.766+0000] {local_task_job_runner.py:228} INFO - Task exited with return code 1
[2023-08-30T20:48:33.787+0000] {taskinstance.py:2784} INFO - 0 downstream tasks scheduled from follow-on schedule check
[2023-08-30T21:07:56.277+0000] {logging_mixin.py:151} WARNING - /home/***/.local/lib/python3.8/site-packages/***/utils/sqlalchemy.py:124 DeprecationWarning: The sql_alchemy_conn option in [core] has been moved to the sql_alchemy_conn option in [database] - the old setting has been used, but please update your config.
[2023-08-30T21:07:56.294+0000] {taskinstance.py:1159} INFO - Dependencies all met for dep_context=non-requeueable deps ti=<TaskInstance: traffic_report.export_data_to_db scheduled__2023-08-26T00:00:00+00:00 [queued]>
[2023-08-30T21:07:56.304+0000] {taskinstance.py:1159} INFO - Dependencies all met for dep_context=requeueable deps ti=<TaskInstance: traffic_report.export_data_to_db scheduled__2023-08-26T00:00:00+00:00 [queued]>
[2023-08-30T21:07:56.306+0000] {taskinstance.py:1361} INFO - Starting attempt 1 of 2
[2023-08-30T21:07:56.325+0000] {taskinstance.py:1382} INFO - Executing <Task(BashOperator): export_data_to_db> on 2023-08-26 00:00:00+00:00
[2023-08-30T21:07:56.331+0000] {standard_task_runner.py:57} INFO - Started process 367 to run task
[2023-08-30T21:07:56.335+0000] {standard_task_runner.py:84} INFO - Running: ['***', 'tasks', 'run', 'traffic_report', 'export_data_to_db', 'scheduled__2023-08-26T00:00:00+00:00', '--job-id', '16', '--raw', '--subdir', 'DAGS_FOLDER/traffic_dag.py', '--cfg-path', '/tmp/tmp65h6m9kh']
[2023-08-30T21:07:56.340+0000] {standard_task_runner.py:85} INFO - Job 16: Subtask export_data_to_db
[2023-08-30T21:07:56.367+0000] {logging_mixin.py:151} WARNING - /home/***/.local/lib/python3.8/site-packages/***/settings.py:195 DeprecationWarning: The sql_alchemy_conn option in [core] has been moved to the sql_alchemy_conn option in [database] - the old setting has been used, but please update your config.
[2023-08-30T21:07:56.427+0000] {task_command.py:415} INFO - Running <TaskInstance: traffic_report.export_data_to_db scheduled__2023-08-26T00:00:00+00:00 [running]> on host cbc745b7550b
[2023-08-30T21:07:56.456+0000] {logging_mixin.py:151} WARNING - /home/***/.local/lib/python3.8/site-packages/***/utils/sqlalchemy.py:124 DeprecationWarning: The sql_alchemy_conn option in [core] has been moved to the sql_alchemy_conn option in [database] - the old setting has been used, but please update your config.
[2023-08-30T21:07:56.530+0000] {taskinstance.py:1660} INFO - Exporting env vars: AIRFLOW_CTX_DAG_OWNER='***' AIRFLOW_CTX_DAG_ID='traffic_report' AIRFLOW_CTX_TASK_ID='export_data_to_db' AIRFLOW_CTX_EXECUTION_DATE='2023-08-26T00:00:00+00:00' AIRFLOW_CTX_TRY_NUMBER='1' AIRFLOW_CTX_DAG_RUN_ID='scheduled__2023-08-26T00:00:00+00:00'
[2023-08-30T21:07:56.532+0000] {subprocess.py:63} INFO - Tmp dir root location: /tmp
[2023-08-30T21:07:56.534+0000] {subprocess.py:75} INFO - Running command: ['/bin/bash', '-c', 'python /opt/***/dags/data_to_db.py --date 2023-08-26 --connection postgresql+psycopg2://***:***@postgres/***']
[2023-08-30T21:07:56.548+0000] {subprocess.py:86} INFO - Output:
[2023-08-30T21:07:57.226+0000] {subprocess.py:93} INFO - Traceback (most recent call last):
[2023-08-30T21:07:57.228+0000] {subprocess.py:93} INFO -   File "/home/***/.local/lib/python3.8/site-packages/sqlalchemy/engine/base.py", line 1890, in _execute_context
[2023-08-30T21:07:57.229+0000] {subprocess.py:93} INFO -     self.dialect.do_executemany(
[2023-08-30T21:07:57.231+0000] {subprocess.py:93} INFO -   File "/home/***/.local/lib/python3.8/site-packages/sqlalchemy/dialects/postgresql/psycopg2.py", line 982, in do_executemany
[2023-08-30T21:07:57.234+0000] {subprocess.py:93} INFO -     context._psycopg2_fetched_rows = xtras.execute_values(
[2023-08-30T21:07:57.239+0000] {subprocess.py:93} INFO -   File "/home/***/.local/lib/python3.8/site-packages/psycopg2/extras.py", line 1299, in execute_values
[2023-08-30T21:07:57.242+0000] {subprocess.py:93} INFO -     cur.execute(b''.join(parts))
[2023-08-30T21:07:57.244+0000] {subprocess.py:93} INFO - psycopg2.errors.StringDataRightTruncation: value too long for type character varying(20)
[2023-08-30T21:07:57.245+0000] {subprocess.py:93} INFO - 
[2023-08-30T21:07:57.246+0000] {subprocess.py:93} INFO - 
[2023-08-30T21:07:57.248+0000] {subprocess.py:93} INFO - The above exception was the direct cause of the following exception:
[2023-08-30T21:07:57.249+0000] {subprocess.py:93} INFO - 
[2023-08-30T21:07:57.251+0000] {subprocess.py:93} INFO - Traceback (most recent call last):
[2023-08-30T21:07:57.252+0000] {subprocess.py:93} INFO -   File "/opt/***/dags/data_to_db.py", line 49, in <module>
[2023-08-30T21:07:57.276+0000] {subprocess.py:93} INFO -     main(args.date, args.connection)
[2023-08-30T21:07:57.279+0000] {subprocess.py:93} INFO -   File "/opt/***/dags/data_to_db.py", line 40, in main
[2023-08-30T21:07:57.280+0000] {subprocess.py:93} INFO -     session.bulk_save_objects(data_insert)
[2023-08-30T21:07:57.287+0000] {subprocess.py:93} INFO -   File "/home/***/.local/lib/python3.8/site-packages/sqlalchemy/orm/session.py", line 3705, in bulk_save_objects
[2023-08-30T21:07:57.288+0000] {subprocess.py:93} INFO -     self._bulk_save_mappings(
[2023-08-30T21:07:57.296+0000] {subprocess.py:93} INFO -   File "/home/***/.local/lib/python3.8/site-packages/sqlalchemy/orm/session.py", line 3913, in _bulk_save_mappings
[2023-08-30T21:07:57.299+0000] {subprocess.py:93} INFO -     transaction.rollback(_capture_exception=True)
[2023-08-30T21:07:57.301+0000] {subprocess.py:93} INFO -   File "/home/***/.local/lib/python3.8/site-packages/sqlalchemy/util/langhelpers.py", line 70, in __exit__
[2023-08-30T21:07:57.303+0000] {subprocess.py:93} INFO -     compat.raise_(
[2023-08-30T21:07:57.305+0000] {subprocess.py:93} INFO -   File "/home/***/.local/lib/python3.8/site-packages/sqlalchemy/util/compat.py", line 211, in raise_
[2023-08-30T21:07:57.309+0000] {subprocess.py:93} INFO -     raise exception
[2023-08-30T21:07:57.320+0000] {subprocess.py:93} INFO -   File "/home/***/.local/lib/python3.8/site-packages/sqlalchemy/orm/session.py", line 3901, in _bulk_save_mappings
[2023-08-30T21:07:57.322+0000] {subprocess.py:93} INFO -     persistence._bulk_insert(
[2023-08-30T21:07:57.325+0000] {subprocess.py:93} INFO -   File "/home/***/.local/lib/python3.8/site-packages/sqlalchemy/orm/persistence.py", line 107, in _bulk_insert
[2023-08-30T21:07:57.327+0000] {subprocess.py:93} INFO -     _emit_insert_statements(
[2023-08-30T21:07:57.328+0000] {subprocess.py:93} INFO -   File "/home/***/.local/lib/python3.8/site-packages/sqlalchemy/orm/persistence.py", line 1097, in _emit_insert_statements
[2023-08-30T21:07:57.330+0000] {subprocess.py:93} INFO -     c = connection._execute_20(
[2023-08-30T21:07:57.331+0000] {subprocess.py:93} INFO -   File "/home/***/.local/lib/python3.8/site-packages/sqlalchemy/engine/base.py", line 1710, in _execute_20
[2023-08-30T21:07:57.336+0000] {subprocess.py:93} INFO -     return meth(self, args_10style, kwargs_10style, execution_options)
[2023-08-30T21:07:57.344+0000] {subprocess.py:93} INFO -   File "/home/***/.local/lib/python3.8/site-packages/sqlalchemy/sql/elements.py", line 334, in _execute_on_connection
[2023-08-30T21:07:57.347+0000] {subprocess.py:93} INFO -     return connection._execute_clauseelement(
[2023-08-30T21:07:57.350+0000] {subprocess.py:93} INFO -   File "/home/***/.local/lib/python3.8/site-packages/sqlalchemy/engine/base.py", line 1577, in _execute_clauseelement
[2023-08-30T21:07:57.353+0000] {subprocess.py:93} INFO -     ret = self._execute_context(
[2023-08-30T21:07:57.357+0000] {subprocess.py:93} INFO -   File "/home/***/.local/lib/python3.8/site-packages/sqlalchemy/engine/base.py", line 1953, in _execute_context
[2023-08-30T21:07:57.358+0000] {subprocess.py:93} INFO -     self._handle_dbapi_exception(
[2023-08-30T21:07:57.361+0000] {subprocess.py:93} INFO -   File "/home/***/.local/lib/python3.8/site-packages/sqlalchemy/engine/base.py", line 2134, in _handle_dbapi_exception
[2023-08-30T21:07:57.365+0000] {subprocess.py:93} INFO -     util.raise_(
[2023-08-30T21:07:57.372+0000] {subprocess.py:93} INFO -   File "/home/***/.local/lib/python3.8/site-packages/sqlalchemy/util/compat.py", line 211, in raise_
[2023-08-30T21:07:57.377+0000] {subprocess.py:93} INFO -     raise exception
[2023-08-30T21:07:57.384+0000] {subprocess.py:93} INFO -   File "/home/***/.local/lib/python3.8/site-packages/sqlalchemy/engine/base.py", line 1890, in _execute_context
[2023-08-30T21:07:57.389+0000] {subprocess.py:93} INFO -     self.dialect.do_executemany(
[2023-08-30T21:07:57.394+0000] {subprocess.py:93} INFO -   File "/home/***/.local/lib/python3.8/site-packages/sqlalchemy/dialects/postgresql/psycopg2.py", line 982, in do_executemany
[2023-08-30T21:07:57.399+0000] {subprocess.py:93} INFO -     context._psycopg2_fetched_rows = xtras.execute_values(
[2023-08-30T21:07:57.401+0000] {subprocess.py:93} INFO -   File "/home/***/.local/lib/python3.8/site-packages/psycopg2/extras.py", line 1299, in execute_values
[2023-08-30T21:07:57.403+0000] {subprocess.py:93} INFO -     cur.execute(b''.join(parts))
[2023-08-30T21:07:57.406+0000] {subprocess.py:93} INFO - sqlalchemy.exc.DataError: (psycopg2.errors.StringDataRightTruncation) value too long for type character varying(20)
[2023-08-30T21:07:57.408+0000] {subprocess.py:93} INFO - 
[2023-08-30T21:07:57.410+0000] {subprocess.py:93} INFO - [SQL: INSERT INTO traffic_report (timestamp, traffic_report_id, date_time, issue_reported, latitude, longitude, address, weekday, date, time) VALUES (%(timestamp)s, %(traffic_report_id)s, %(date_time)s, %(issue_reported)s, %(latitude)s, %(longitude)s, %(address)s, %(weekday)s, %(date)s, %(time)s)]
[2023-08-30T21:07:57.412+0000] {subprocess.py:93} INFO - [parameters: ({'timestamp': '1692921696000000000', 'traffic_report_id': 'B74E9CAD775D997FC742B45E1BA7BD5295D63D13_1692921696', 'date_time': '2023-08-25 00:01:36+00:00', 'issue_reported': 'crash urgent', 'latitude': '30.24078', 'longitude': '-97.688698', 'address': '247-317 bastrop hwy nb', 'weekday': 'Friday', 'date': '2023-08-25', 'time': '00:01:36'}, {'timestamp': '1692922515000000000', 'traffic_report_id': '59E221A4758B17362BDEAE901C5A8F58057468B2_1692922515', 'date_time': '2023-08-25 00:15:15+00:00', 'issue_reported': 'crash service', 'latitude': '30.265881', 'longitude': '-97.735003', 'address': 'e 6th st / n ih 35 svrd sb', 'weekday': 'Friday', 'date': '2023-08-25', 'time': '00:15:15'}, {'timestamp': '1692922987000000000', 'traffic_report_id': '757578FBF23FFA4D748E0800DD7C424A46FEB0CC_1692922987', 'date_time': '2023-08-25 00:23:07+00:00', 'issue_reported': 'crash service', 'latitude': '30.396327', 'longitude': '-97.848308', 'address': '11004 fm 2222 rd', 'weekday': 'Friday', 'date': '2023-08-25', 'time': '00:23:07'}, {'timestamp': '1692923103000000000', 'traffic_report_id': 'C60D81F35D8BE966FA0437E43F1FEFF777C6E121_1692923103', 'date_time': '2023-08-25 00:25:03+00:00', 'issue_reported': 'stalled vehicle', 'latitude': '30.307093', 'longitude': '-97.758168', 'address': 'w 35th to mopac sb ramp', 'weekday': 'Friday', 'date': '2023-08-25', 'time': '00:25:03'}, {'timestamp': '1692923525000000000', 'traffic_report_id': '89CA91E6C9B28BDCFB629B12758F955D21072594_1692923525', 'date_time': '2023-08-25 00:32:05+00:00', 'issue_reported': 'traffic hazard', 'latitude': '30.330871', 'longitude': '-97.731593', 'address': 'w koenig ln / woodrow ave', 'weekday': 'Friday', 'date': '2023-08-25', 'time': '00:32:05'}, {'timestamp': '1692923984000000000', 'traffic_report_id': '3B987A82043F7DF95B5784095B5CE3BB870DC709_1692923984', 'date_time': '2023-08-25 00:39:44+00:00', 'issue_reported': 'collision', 'latitude': '30.107487', 'longitude': '-97.694708', 'address': '9800-blk s us 183 hwy', 'weekday': 'Friday', 'date': '2023-08-25', 'time': '00:39:44'}, {'timestamp': '1692924072000000000', 'traffic_report_id': 'E6602176F26DD0C5FB721FDED265EC8570F686E7_1692924072', 'date_time': '2023-08-25 00:41:12+00:00', 'issue_reported': 'traffic hazard', 'latitude': '30.26303', 'longitude': '-97.743207', 'address': 'brazos st / e cesar chavez st', 'weekday': 'Friday', 'date': '2023-08-25', 'time': '00:41:12'}, {'timestamp': '1692924987000000000', 'traffic_report_id': '6DF29A0769E84AF53CC4F71A6017FCF41AD0148D_1692924987', 'date_time': '2023-08-25 00:56:27+00:00', 'issue_reported': 'crash service', 'latitude': '30.420458', 'longitude': '-97.748872', 'address': '11750 research blvd svrd sb', 'weekday': 'Friday', 'date': '2023-08-25', 'time': '00:56:27'}  ... displaying 10 of 149 total bound parameter sets ...  {'timestamp': '1693007033000000000', 'traffic_report_id': '3E9459D66B2BF63A0F4CFDDC2B117A444BCD6A95_1693007033', 'date_time': '2023-08-25 23:43:53+00:00', 'issue_reported': 'crash service', 'latitude': '30.206611', 'longitude': '-97.638781', 'address': '2900-3148 s fm 973 rd', 'weekday': 'Friday', 'date': '2023-08-25', 'time': '23:43:53'}, {'timestamp': '1693007481000000000', 'traffic_report_id': '7CA48B0569F515A124807357262BB8714E81FCA3_1693007481', 'date_time': '2023-08-25 23:51:21+00:00', 'issue_reported': 'collision', 'latitude': '30.257618', 'longitude': '-97.60157', 'address': '5000-7475 n sh 130 nb', 'weekday': 'Friday', 'date': '2023-08-25', 'time': '23:51:21'})]
[2023-08-30T21:07:57.414+0000] {subprocess.py:93} INFO - (Background on this error at: https://sqlalche.me/e/14/9h9h)
[2023-08-30T21:07:57.416+0000] {subprocess.py:97} INFO - Command exited with return code 1
[2023-08-30T21:07:57.441+0000] {taskinstance.py:1943} ERROR - Task failed with exception
Traceback (most recent call last):
  File "/home/airflow/.local/lib/python3.8/site-packages/airflow/operators/bash.py", line 210, in execute
    raise AirflowException(
airflow.exceptions.AirflowException: Bash command failed. The command returned a non-zero exit code 1.
[2023-08-30T21:07:57.450+0000] {taskinstance.py:1400} INFO - Marking task as UP_FOR_RETRY. dag_id=traffic_report, task_id=export_data_to_db, execution_date=20230826T000000, start_date=20230830T210756, end_date=20230830T210757
[2023-08-30T21:07:57.478+0000] {standard_task_runner.py:104} ERROR - Failed to execute job 16 for task export_data_to_db (Bash command failed. The command returned a non-zero exit code 1.; 367)
[2023-08-30T21:07:57.520+0000] {local_task_job_runner.py:228} INFO - Task exited with return code 1
[2023-08-30T21:07:57.541+0000] {taskinstance.py:2784} INFO - 0 downstream tasks scheduled from follow-on schedule check
[2023-08-30T21:17:15.113+0000] {logging_mixin.py:151} WARNING - /home/***/.local/lib/python3.8/site-packages/***/utils/sqlalchemy.py:124 DeprecationWarning: The sql_alchemy_conn option in [core] has been moved to the sql_alchemy_conn option in [database] - the old setting has been used, but please update your config.
[2023-08-30T21:17:15.125+0000] {taskinstance.py:1159} INFO - Dependencies all met for dep_context=non-requeueable deps ti=<TaskInstance: traffic_report.export_data_to_db scheduled__2023-08-26T00:00:00+00:00 [queued]>
[2023-08-30T21:17:15.134+0000] {taskinstance.py:1159} INFO - Dependencies all met for dep_context=requeueable deps ti=<TaskInstance: traffic_report.export_data_to_db scheduled__2023-08-26T00:00:00+00:00 [queued]>
[2023-08-30T21:17:15.135+0000] {taskinstance.py:1361} INFO - Starting attempt 1 of 2
[2023-08-30T21:17:15.150+0000] {taskinstance.py:1382} INFO - Executing <Task(BashOperator): export_data_to_db> on 2023-08-26 00:00:00+00:00
[2023-08-30T21:17:15.155+0000] {standard_task_runner.py:57} INFO - Started process 405 to run task
[2023-08-30T21:17:15.166+0000] {standard_task_runner.py:84} INFO - Running: ['***', 'tasks', 'run', 'traffic_report', 'export_data_to_db', 'scheduled__2023-08-26T00:00:00+00:00', '--job-id', '19', '--raw', '--subdir', 'DAGS_FOLDER/traffic_dag.py', '--cfg-path', '/tmp/tmpnficohze']
[2023-08-30T21:17:15.170+0000] {standard_task_runner.py:85} INFO - Job 19: Subtask export_data_to_db
[2023-08-30T21:17:15.195+0000] {logging_mixin.py:151} WARNING - /home/***/.local/lib/python3.8/site-packages/***/settings.py:195 DeprecationWarning: The sql_alchemy_conn option in [core] has been moved to the sql_alchemy_conn option in [database] - the old setting has been used, but please update your config.
[2023-08-30T21:17:15.247+0000] {task_command.py:415} INFO - Running <TaskInstance: traffic_report.export_data_to_db scheduled__2023-08-26T00:00:00+00:00 [running]> on host 5b9f14bf20e0
[2023-08-30T21:17:15.269+0000] {logging_mixin.py:151} WARNING - /home/***/.local/lib/python3.8/site-packages/***/utils/sqlalchemy.py:124 DeprecationWarning: The sql_alchemy_conn option in [core] has been moved to the sql_alchemy_conn option in [database] - the old setting has been used, but please update your config.
[2023-08-30T21:17:15.351+0000] {taskinstance.py:1660} INFO - Exporting env vars: AIRFLOW_CTX_DAG_OWNER='***' AIRFLOW_CTX_DAG_ID='traffic_report' AIRFLOW_CTX_TASK_ID='export_data_to_db' AIRFLOW_CTX_EXECUTION_DATE='2023-08-26T00:00:00+00:00' AIRFLOW_CTX_TRY_NUMBER='1' AIRFLOW_CTX_DAG_RUN_ID='scheduled__2023-08-26T00:00:00+00:00'
[2023-08-30T21:17:15.354+0000] {subprocess.py:63} INFO - Tmp dir root location: /tmp
[2023-08-30T21:17:15.355+0000] {subprocess.py:75} INFO - Running command: ['/bin/bash', '-c', 'python /opt/***/dags/data_to_db.py --date 2023-08-26 --connection postgresql+psycopg2://***:***@postgres/***']
[2023-08-30T21:17:15.369+0000] {subprocess.py:86} INFO - Output:
[2023-08-30T21:17:16.149+0000] {subprocess.py:97} INFO - Command exited with return code 0
[2023-08-30T21:17:16.177+0000] {taskinstance.py:1400} INFO - Marking task as SUCCESS. dag_id=traffic_report, task_id=export_data_to_db, execution_date=20230826T000000, start_date=20230830T211715, end_date=20230830T211716
[2023-08-30T21:17:16.221+0000] {local_task_job_runner.py:228} INFO - Task exited with return code 0
[2023-08-30T21:17:16.237+0000] {taskinstance.py:2784} INFO - 0 downstream tasks scheduled from follow-on schedule check
