[2023-08-29T19:48:58.822+0000] {logging_mixin.py:151} WARNING - /home/***/.local/lib/python3.8/site-packages/***/utils/sqlalchemy.py:124 DeprecationWarning: The sql_alchemy_conn option in [core] has been moved to the sql_alchemy_conn option in [database] - the old setting has been used, but please update your config.
[2023-08-29T19:48:58.838+0000] {taskinstance.py:1159} INFO - Dependencies all met for dep_context=non-requeueable deps ti=<TaskInstance: traffic_report.import_data_to_csv scheduled__2023-08-25T00:00:00+00:00 [queued]>
[2023-08-29T19:48:58.853+0000] {taskinstance.py:1159} INFO - Dependencies all met for dep_context=requeueable deps ti=<TaskInstance: traffic_report.import_data_to_csv scheduled__2023-08-25T00:00:00+00:00 [queued]>
[2023-08-29T19:48:58.854+0000] {taskinstance.py:1361} INFO - Starting attempt 2 of 2
[2023-08-29T19:48:58.887+0000] {taskinstance.py:1382} INFO - Executing <Task(BashOperator): import_data_to_csv> on 2023-08-25 00:00:00+00:00
[2023-08-29T19:48:58.934+0000] {standard_task_runner.py:57} INFO - Started process 614 to run task
[2023-08-29T19:48:58.968+0000] {standard_task_runner.py:84} INFO - Running: ['***', 'tasks', 'run', 'traffic_report', 'import_data_to_csv', 'scheduled__2023-08-25T00:00:00+00:00', '--job-id', '29', '--raw', '--subdir', 'DAGS_FOLDER/traffic_dag.py', '--cfg-path', '/tmp/tmp7q9wz6sx']
[2023-08-29T19:48:58.986+0000] {standard_task_runner.py:85} INFO - Job 29: Subtask import_data_to_csv
[2023-08-29T19:48:59.061+0000] {logging_mixin.py:151} WARNING - /home/***/.local/lib/python3.8/site-packages/***/settings.py:195 DeprecationWarning: The sql_alchemy_conn option in [core] has been moved to the sql_alchemy_conn option in [database] - the old setting has been used, but please update your config.
[2023-08-29T19:49:00.688+0000] {task_command.py:415} INFO - Running <TaskInstance: traffic_report.import_data_to_csv scheduled__2023-08-25T00:00:00+00:00 [running]> on host e69093e17de8
[2023-08-29T19:49:00.708+0000] {logging_mixin.py:151} WARNING - /home/***/.local/lib/python3.8/site-packages/***/utils/sqlalchemy.py:124 DeprecationWarning: The sql_alchemy_conn option in [core] has been moved to the sql_alchemy_conn option in [database] - the old setting has been used, but please update your config.
[2023-08-29T19:49:00.869+0000] {taskinstance.py:1660} INFO - Exporting env vars: AIRFLOW_CTX_DAG_OWNER='***' AIRFLOW_CTX_DAG_ID='traffic_report' AIRFLOW_CTX_TASK_ID='import_data_to_csv' AIRFLOW_CTX_EXECUTION_DATE='2023-08-25T00:00:00+00:00' AIRFLOW_CTX_TRY_NUMBER='2' AIRFLOW_CTX_DAG_RUN_ID='scheduled__2023-08-25T00:00:00+00:00'
[2023-08-29T19:49:00.897+0000] {subprocess.py:63} INFO - Tmp dir root location: /tmp
[2023-08-29T19:49:00.911+0000] {subprocess.py:75} INFO - Running command: ['/bin/bash', '-c', 'python /Users/jinee.hira/Dropbox/virtual_envs/austin-flow/***/dags/data_ingestion.py --date 2023-08-25']
[2023-08-29T19:49:00.929+0000] {subprocess.py:86} INFO - Output:
[2023-08-29T19:49:01.705+0000] {subprocess.py:93} INFO - python: can't open file '/Users/jinee.hira/Dropbox/virtual_envs/austin-flow/***/dags/data_ingestion.py': [Errno 2] No such file or directory
[2023-08-29T19:49:01.715+0000] {subprocess.py:97} INFO - Command exited with return code 2
[2023-08-29T19:49:01.732+0000] {taskinstance.py:1943} ERROR - Task failed with exception
Traceback (most recent call last):
  File "/home/airflow/.local/lib/python3.8/site-packages/airflow/operators/bash.py", line 210, in execute
    raise AirflowException(
airflow.exceptions.AirflowException: Bash command failed. The command returned a non-zero exit code 2.
[2023-08-29T19:49:01.741+0000] {taskinstance.py:1400} INFO - Marking task as FAILED. dag_id=traffic_report, task_id=import_data_to_csv, execution_date=20230825T000000, start_date=20230829T194858, end_date=20230829T194901
[2023-08-29T19:49:01.775+0000] {standard_task_runner.py:104} ERROR - Failed to execute job 29 for task import_data_to_csv (Bash command failed. The command returned a non-zero exit code 2.; 614)
[2023-08-29T19:49:01.828+0000] {local_task_job_runner.py:228} INFO - Task exited with return code 1
[2023-08-29T19:49:01.900+0000] {taskinstance.py:2784} INFO - 0 downstream tasks scheduled from follow-on schedule check
[2023-08-30T19:01:48.659+0000] {logging_mixin.py:151} WARNING - /home/***/.local/lib/python3.8/site-packages/***/utils/sqlalchemy.py:124 DeprecationWarning: The sql_alchemy_conn option in [core] has been moved to the sql_alchemy_conn option in [database] - the old setting has been used, but please update your config.
[2023-08-30T19:01:48.673+0000] {taskinstance.py:1159} INFO - Dependencies all met for dep_context=non-requeueable deps ti=<TaskInstance: traffic_report.import_data_to_csv scheduled__2023-08-25T00:00:00+00:00 [queued]>
[2023-08-30T19:01:48.686+0000] {taskinstance.py:1159} INFO - Dependencies all met for dep_context=requeueable deps ti=<TaskInstance: traffic_report.import_data_to_csv scheduled__2023-08-25T00:00:00+00:00 [queued]>
[2023-08-30T19:01:48.688+0000] {taskinstance.py:1361} INFO - Starting attempt 2 of 2
[2023-08-30T19:01:48.711+0000] {taskinstance.py:1382} INFO - Executing <Task(BashOperator): import_data_to_csv> on 2023-08-25 00:00:00+00:00
[2023-08-30T19:01:48.724+0000] {standard_task_runner.py:57} INFO - Started process 717 to run task
[2023-08-30T19:01:48.746+0000] {standard_task_runner.py:84} INFO - Running: ['***', 'tasks', 'run', 'traffic_report', 'import_data_to_csv', 'scheduled__2023-08-25T00:00:00+00:00', '--job-id', '15', '--raw', '--subdir', 'DAGS_FOLDER/traffic_dag.py', '--cfg-path', '/tmp/tmpi_kfyspc']
[2023-08-30T19:01:48.768+0000] {standard_task_runner.py:85} INFO - Job 15: Subtask import_data_to_csv
[2023-08-30T19:01:49.274+0000] {logging_mixin.py:151} WARNING - /home/***/.local/lib/python3.8/site-packages/***/settings.py:195 DeprecationWarning: The sql_alchemy_conn option in [core] has been moved to the sql_alchemy_conn option in [database] - the old setting has been used, but please update your config.
[2023-08-30T19:01:54.638+0000] {task_command.py:415} INFO - Running <TaskInstance: traffic_report.import_data_to_csv scheduled__2023-08-25T00:00:00+00:00 [running]> on host 5e7fbf8b7901
[2023-08-30T19:01:54.854+0000] {logging_mixin.py:151} WARNING - /home/***/.local/lib/python3.8/site-packages/***/utils/sqlalchemy.py:124 DeprecationWarning: The sql_alchemy_conn option in [core] has been moved to the sql_alchemy_conn option in [database] - the old setting has been used, but please update your config.
[2023-08-30T19:01:55.097+0000] {taskinstance.py:1660} INFO - Exporting env vars: AIRFLOW_CTX_DAG_OWNER='***' AIRFLOW_CTX_DAG_ID='traffic_report' AIRFLOW_CTX_TASK_ID='import_data_to_csv' AIRFLOW_CTX_EXECUTION_DATE='2023-08-25T00:00:00+00:00' AIRFLOW_CTX_TRY_NUMBER='2' AIRFLOW_CTX_DAG_RUN_ID='scheduled__2023-08-25T00:00:00+00:00'
[2023-08-30T19:01:55.179+0000] {subprocess.py:63} INFO - Tmp dir root location: /tmp
[2023-08-30T19:01:55.189+0000] {subprocess.py:75} INFO - Running command: ['/bin/bash', '-c', 'python /Users/jinee.hira/Dropbox/virtual_envs/austin-flow/***/dags/data_ingestion.py --date 2023-08-25']
[2023-08-30T19:01:55.217+0000] {subprocess.py:86} INFO - Output:
[2023-08-30T19:02:06.220+0000] {subprocess.py:93} INFO - python: can't open file '/Users/jinee.hira/Dropbox/virtual_envs/austin-flow/***/dags/data_ingestion.py': [Errno 2] No such file or directory
[2023-08-30T19:02:06.231+0000] {subprocess.py:97} INFO - Command exited with return code 2
[2023-08-30T19:02:06.261+0000] {taskinstance.py:1943} ERROR - Task failed with exception
Traceback (most recent call last):
  File "/home/airflow/.local/lib/python3.8/site-packages/airflow/operators/bash.py", line 210, in execute
    raise AirflowException(
airflow.exceptions.AirflowException: Bash command failed. The command returned a non-zero exit code 2.
[2023-08-30T19:02:06.270+0000] {taskinstance.py:1400} INFO - Marking task as FAILED. dag_id=traffic_report, task_id=import_data_to_csv, execution_date=20230825T000000, start_date=20230830T190148, end_date=20230830T190206
[2023-08-30T19:02:06.300+0000] {standard_task_runner.py:104} ERROR - Failed to execute job 15 for task import_data_to_csv (Bash command failed. The command returned a non-zero exit code 2.; 717)
[2023-08-30T19:02:06.319+0000] {local_task_job_runner.py:228} INFO - Task exited with return code 1
[2023-08-30T19:02:06.343+0000] {taskinstance.py:2784} INFO - 0 downstream tasks scheduled from follow-on schedule check
[2023-08-30T19:22:01.962+0000] {logging_mixin.py:151} WARNING - /home/***/.local/lib/python3.8/site-packages/***/utils/sqlalchemy.py:124 DeprecationWarning: The sql_alchemy_conn option in [core] has been moved to the sql_alchemy_conn option in [database] - the old setting has been used, but please update your config.
[2023-08-30T19:22:01.972+0000] {taskinstance.py:1159} INFO - Dependencies all met for dep_context=non-requeueable deps ti=<TaskInstance: traffic_report.import_data_to_csv scheduled__2023-08-25T00:00:00+00:00 [queued]>
[2023-08-30T19:22:01.989+0000] {taskinstance.py:1159} INFO - Dependencies all met for dep_context=requeueable deps ti=<TaskInstance: traffic_report.import_data_to_csv scheduled__2023-08-25T00:00:00+00:00 [queued]>
[2023-08-30T19:22:01.990+0000] {taskinstance.py:1361} INFO - Starting attempt 2 of 2
[2023-08-30T19:22:02.013+0000] {taskinstance.py:1382} INFO - Executing <Task(BashOperator): import_data_to_csv> on 2023-08-25 00:00:00+00:00
[2023-08-30T19:22:02.027+0000] {standard_task_runner.py:57} INFO - Started process 346 to run task
[2023-08-30T19:22:02.035+0000] {standard_task_runner.py:84} INFO - Running: ['***', 'tasks', 'run', 'traffic_report', 'import_data_to_csv', 'scheduled__2023-08-25T00:00:00+00:00', '--job-id', '16', '--raw', '--subdir', 'DAGS_FOLDER/traffic_dag.py', '--cfg-path', '/tmp/tmp34l5b6m7']
[2023-08-30T19:22:02.050+0000] {standard_task_runner.py:85} INFO - Job 16: Subtask import_data_to_csv
[2023-08-30T19:22:02.106+0000] {logging_mixin.py:151} WARNING - /home/***/.local/lib/python3.8/site-packages/***/settings.py:195 DeprecationWarning: The sql_alchemy_conn option in [core] has been moved to the sql_alchemy_conn option in [database] - the old setting has been used, but please update your config.
[2023-08-30T19:22:02.225+0000] {task_command.py:415} INFO - Running <TaskInstance: traffic_report.import_data_to_csv scheduled__2023-08-25T00:00:00+00:00 [running]> on host 884d86529f65
[2023-08-30T19:22:02.245+0000] {logging_mixin.py:151} WARNING - /home/***/.local/lib/python3.8/site-packages/***/utils/sqlalchemy.py:124 DeprecationWarning: The sql_alchemy_conn option in [core] has been moved to the sql_alchemy_conn option in [database] - the old setting has been used, but please update your config.
[2023-08-30T19:22:02.344+0000] {taskinstance.py:1660} INFO - Exporting env vars: AIRFLOW_CTX_DAG_OWNER='***' AIRFLOW_CTX_DAG_ID='traffic_report' AIRFLOW_CTX_TASK_ID='import_data_to_csv' AIRFLOW_CTX_EXECUTION_DATE='2023-08-25T00:00:00+00:00' AIRFLOW_CTX_TRY_NUMBER='2' AIRFLOW_CTX_DAG_RUN_ID='scheduled__2023-08-25T00:00:00+00:00'
[2023-08-30T19:22:02.369+0000] {subprocess.py:63} INFO - Tmp dir root location: /tmp
[2023-08-30T19:22:02.373+0000] {subprocess.py:75} INFO - Running command: ['/bin/bash', '-c', 'python ./dags/data_ingestion.py --date 2023-08-25']
[2023-08-30T19:22:02.398+0000] {subprocess.py:86} INFO - Output:
[2023-08-30T19:22:04.260+0000] {subprocess.py:93} INFO - python: can't open file './dags/data_ingestion.py': [Errno 2] No such file or directory
[2023-08-30T19:22:04.266+0000] {subprocess.py:97} INFO - Command exited with return code 2
[2023-08-30T19:22:04.358+0000] {taskinstance.py:1943} ERROR - Task failed with exception
Traceback (most recent call last):
  File "/home/airflow/.local/lib/python3.8/site-packages/airflow/operators/bash.py", line 210, in execute
    raise AirflowException(
airflow.exceptions.AirflowException: Bash command failed. The command returned a non-zero exit code 2.
[2023-08-30T19:22:04.391+0000] {taskinstance.py:1400} INFO - Marking task as FAILED. dag_id=traffic_report, task_id=import_data_to_csv, execution_date=20230825T000000, start_date=20230830T192201, end_date=20230830T192204
[2023-08-30T19:22:04.535+0000] {standard_task_runner.py:104} ERROR - Failed to execute job 16 for task import_data_to_csv (Bash command failed. The command returned a non-zero exit code 2.; 346)
[2023-08-30T19:22:04.557+0000] {local_task_job_runner.py:228} INFO - Task exited with return code 1
[2023-08-30T19:22:04.618+0000] {taskinstance.py:2784} INFO - 0 downstream tasks scheduled from follow-on schedule check
