[2023-08-29T19:48:58.823+0000] {logging_mixin.py:151} WARNING - /home/***/.local/lib/python3.8/site-packages/***/utils/sqlalchemy.py:124 DeprecationWarning: The sql_alchemy_conn option in [core] has been moved to the sql_alchemy_conn option in [database] - the old setting has been used, but please update your config.
[2023-08-29T19:48:58.837+0000] {taskinstance.py:1159} INFO - Dependencies all met for dep_context=non-requeueable deps ti=<TaskInstance: traffic_report.import_data_to_csv scheduled__2023-08-24T00:00:00+00:00 [queued]>
[2023-08-29T19:48:58.860+0000] {taskinstance.py:1159} INFO - Dependencies all met for dep_context=requeueable deps ti=<TaskInstance: traffic_report.import_data_to_csv scheduled__2023-08-24T00:00:00+00:00 [queued]>
[2023-08-29T19:48:58.861+0000] {taskinstance.py:1361} INFO - Starting attempt 2 of 2
[2023-08-29T19:48:58.880+0000] {taskinstance.py:1382} INFO - Executing <Task(BashOperator): import_data_to_csv> on 2023-08-24 00:00:00+00:00
[2023-08-29T19:48:58.902+0000] {standard_task_runner.py:57} INFO - Started process 613 to run task
[2023-08-29T19:48:58.983+0000] {standard_task_runner.py:84} INFO - Running: ['***', 'tasks', 'run', 'traffic_report', 'import_data_to_csv', 'scheduled__2023-08-24T00:00:00+00:00', '--job-id', '26', '--raw', '--subdir', 'DAGS_FOLDER/traffic_dag.py', '--cfg-path', '/tmp/tmpb6l6vjh7']
[2023-08-29T19:48:59.007+0000] {standard_task_runner.py:85} INFO - Job 26: Subtask import_data_to_csv
[2023-08-29T19:48:59.115+0000] {logging_mixin.py:151} WARNING - /home/***/.local/lib/python3.8/site-packages/***/settings.py:195 DeprecationWarning: The sql_alchemy_conn option in [core] has been moved to the sql_alchemy_conn option in [database] - the old setting has been used, but please update your config.
[2023-08-29T19:49:00.728+0000] {task_command.py:415} INFO - Running <TaskInstance: traffic_report.import_data_to_csv scheduled__2023-08-24T00:00:00+00:00 [running]> on host e69093e17de8
[2023-08-29T19:49:00.663+0000] {logging_mixin.py:151} WARNING - /home/***/.local/lib/python3.8/site-packages/***/utils/sqlalchemy.py:124 DeprecationWarning: The sql_alchemy_conn option in [core] has been moved to the sql_alchemy_conn option in [database] - the old setting has been used, but please update your config.
[2023-08-29T19:49:00.772+0000] {taskinstance.py:1660} INFO - Exporting env vars: AIRFLOW_CTX_DAG_OWNER='***' AIRFLOW_CTX_DAG_ID='traffic_report' AIRFLOW_CTX_TASK_ID='import_data_to_csv' AIRFLOW_CTX_EXECUTION_DATE='2023-08-24T00:00:00+00:00' AIRFLOW_CTX_TRY_NUMBER='2' AIRFLOW_CTX_DAG_RUN_ID='scheduled__2023-08-24T00:00:00+00:00'
[2023-08-29T19:49:00.797+0000] {subprocess.py:63} INFO - Tmp dir root location: /tmp
[2023-08-29T19:49:00.799+0000] {subprocess.py:75} INFO - Running command: ['/bin/bash', '-c', 'python /Users/jinee.hira/Dropbox/virtual_envs/austin-flow/***/dags/data_ingestion.py --date 2023-08-24']
[2023-08-29T19:49:00.843+0000] {subprocess.py:86} INFO - Output:
[2023-08-29T19:49:01.475+0000] {subprocess.py:93} INFO - python: can't open file '/Users/jinee.hira/Dropbox/virtual_envs/austin-flow/***/dags/data_ingestion.py': [Errno 2] No such file or directory
[2023-08-29T19:49:01.493+0000] {subprocess.py:97} INFO - Command exited with return code 2
[2023-08-29T19:49:01.576+0000] {taskinstance.py:1943} ERROR - Task failed with exception
Traceback (most recent call last):
  File "/home/airflow/.local/lib/python3.8/site-packages/airflow/operators/bash.py", line 210, in execute
    raise AirflowException(
airflow.exceptions.AirflowException: Bash command failed. The command returned a non-zero exit code 2.
[2023-08-29T19:49:01.595+0000] {taskinstance.py:1400} INFO - Marking task as FAILED. dag_id=traffic_report, task_id=import_data_to_csv, execution_date=20230824T000000, start_date=20230829T194858, end_date=20230829T194901
[2023-08-29T19:49:01.647+0000] {standard_task_runner.py:104} ERROR - Failed to execute job 26 for task import_data_to_csv (Bash command failed. The command returned a non-zero exit code 2.; 613)
[2023-08-29T19:49:01.668+0000] {local_task_job_runner.py:228} INFO - Task exited with return code 1
[2023-08-29T19:49:01.732+0000] {taskinstance.py:2784} INFO - 0 downstream tasks scheduled from follow-on schedule check
[2023-08-30T19:01:48.664+0000] {logging_mixin.py:151} WARNING - /home/***/.local/lib/python3.8/site-packages/***/utils/sqlalchemy.py:124 DeprecationWarning: The sql_alchemy_conn option in [core] has been moved to the sql_alchemy_conn option in [database] - the old setting has been used, but please update your config.
[2023-08-30T19:01:48.681+0000] {taskinstance.py:1159} INFO - Dependencies all met for dep_context=non-requeueable deps ti=<TaskInstance: traffic_report.import_data_to_csv scheduled__2023-08-24T00:00:00+00:00 [queued]>
[2023-08-30T19:01:48.694+0000] {taskinstance.py:1159} INFO - Dependencies all met for dep_context=requeueable deps ti=<TaskInstance: traffic_report.import_data_to_csv scheduled__2023-08-24T00:00:00+00:00 [queued]>
[2023-08-30T19:01:48.695+0000] {taskinstance.py:1361} INFO - Starting attempt 2 of 2
[2023-08-30T19:01:48.715+0000] {taskinstance.py:1382} INFO - Executing <Task(BashOperator): import_data_to_csv> on 2023-08-24 00:00:00+00:00
[2023-08-30T19:01:48.720+0000] {standard_task_runner.py:57} INFO - Started process 715 to run task
[2023-08-30T19:01:48.729+0000] {standard_task_runner.py:84} INFO - Running: ['***', 'tasks', 'run', 'traffic_report', 'import_data_to_csv', 'scheduled__2023-08-24T00:00:00+00:00', '--job-id', '18', '--raw', '--subdir', 'DAGS_FOLDER/traffic_dag.py', '--cfg-path', '/tmp/tmpx_l8m12o']
[2023-08-30T19:01:48.736+0000] {standard_task_runner.py:85} INFO - Job 18: Subtask import_data_to_csv
[2023-08-30T19:01:51.142+0000] {logging_mixin.py:151} WARNING - /home/***/.local/lib/python3.8/site-packages/***/settings.py:195 DeprecationWarning: The sql_alchemy_conn option in [core] has been moved to the sql_alchemy_conn option in [database] - the old setting has been used, but please update your config.
[2023-08-30T19:01:54.760+0000] {task_command.py:415} INFO - Running <TaskInstance: traffic_report.import_data_to_csv scheduled__2023-08-24T00:00:00+00:00 [running]> on host 5e7fbf8b7901
[2023-08-30T19:01:54.848+0000] {logging_mixin.py:151} WARNING - /home/***/.local/lib/python3.8/site-packages/***/utils/sqlalchemy.py:124 DeprecationWarning: The sql_alchemy_conn option in [core] has been moved to the sql_alchemy_conn option in [database] - the old setting has been used, but please update your config.
[2023-08-30T19:01:55.306+0000] {taskinstance.py:1660} INFO - Exporting env vars: AIRFLOW_CTX_DAG_OWNER='***' AIRFLOW_CTX_DAG_ID='traffic_report' AIRFLOW_CTX_TASK_ID='import_data_to_csv' AIRFLOW_CTX_EXECUTION_DATE='2023-08-24T00:00:00+00:00' AIRFLOW_CTX_TRY_NUMBER='2' AIRFLOW_CTX_DAG_RUN_ID='scheduled__2023-08-24T00:00:00+00:00'
[2023-08-30T19:01:55.364+0000] {subprocess.py:63} INFO - Tmp dir root location: /tmp
[2023-08-30T19:01:55.371+0000] {subprocess.py:75} INFO - Running command: ['/bin/bash', '-c', 'python /Users/jinee.hira/Dropbox/virtual_envs/austin-flow/***/dags/data_ingestion.py --date 2023-08-24']
[2023-08-30T19:01:55.404+0000] {subprocess.py:86} INFO - Output:
[2023-08-30T19:02:06.223+0000] {subprocess.py:93} INFO - python: can't open file '/Users/jinee.hira/Dropbox/virtual_envs/austin-flow/***/dags/data_ingestion.py': [Errno 2] No such file or directory
[2023-08-30T19:02:06.232+0000] {subprocess.py:97} INFO - Command exited with return code 2
[2023-08-30T19:02:06.253+0000] {taskinstance.py:1943} ERROR - Task failed with exception
Traceback (most recent call last):
  File "/home/airflow/.local/lib/python3.8/site-packages/airflow/operators/bash.py", line 210, in execute
    raise AirflowException(
airflow.exceptions.AirflowException: Bash command failed. The command returned a non-zero exit code 2.
[2023-08-30T19:02:06.259+0000] {taskinstance.py:1400} INFO - Marking task as FAILED. dag_id=traffic_report, task_id=import_data_to_csv, execution_date=20230824T000000, start_date=20230830T190148, end_date=20230830T190206
[2023-08-30T19:02:06.281+0000] {standard_task_runner.py:104} ERROR - Failed to execute job 18 for task import_data_to_csv (Bash command failed. The command returned a non-zero exit code 2.; 715)
[2023-08-30T19:02:06.305+0000] {local_task_job_runner.py:228} INFO - Task exited with return code 1
[2023-08-30T19:02:06.326+0000] {taskinstance.py:2784} INFO - 0 downstream tasks scheduled from follow-on schedule check
[2023-08-30T19:22:05.092+0000] {logging_mixin.py:151} WARNING - /home/***/.local/lib/python3.8/site-packages/***/utils/sqlalchemy.py:124 DeprecationWarning: The sql_alchemy_conn option in [core] has been moved to the sql_alchemy_conn option in [database] - the old setting has been used, but please update your config.
[2023-08-30T19:22:05.101+0000] {taskinstance.py:1159} INFO - Dependencies all met for dep_context=non-requeueable deps ti=<TaskInstance: traffic_report.import_data_to_csv scheduled__2023-08-24T00:00:00+00:00 [queued]>
[2023-08-30T19:22:05.109+0000] {taskinstance.py:1159} INFO - Dependencies all met for dep_context=requeueable deps ti=<TaskInstance: traffic_report.import_data_to_csv scheduled__2023-08-24T00:00:00+00:00 [queued]>
[2023-08-30T19:22:05.111+0000] {taskinstance.py:1361} INFO - Starting attempt 2 of 2
[2023-08-30T19:22:05.120+0000] {taskinstance.py:1382} INFO - Executing <Task(BashOperator): import_data_to_csv> on 2023-08-24 00:00:00+00:00
[2023-08-30T19:22:05.126+0000] {standard_task_runner.py:57} INFO - Started process 353 to run task
[2023-08-30T19:22:05.130+0000] {standard_task_runner.py:84} INFO - Running: ['***', 'tasks', 'run', 'traffic_report', 'import_data_to_csv', 'scheduled__2023-08-24T00:00:00+00:00', '--job-id', '19', '--raw', '--subdir', 'DAGS_FOLDER/traffic_dag.py', '--cfg-path', '/tmp/tmp2shwqvjw']
[2023-08-30T19:22:05.134+0000] {standard_task_runner.py:85} INFO - Job 19: Subtask import_data_to_csv
[2023-08-30T19:22:05.150+0000] {logging_mixin.py:151} WARNING - /home/***/.local/lib/python3.8/site-packages/***/settings.py:195 DeprecationWarning: The sql_alchemy_conn option in [core] has been moved to the sql_alchemy_conn option in [database] - the old setting has been used, but please update your config.
[2023-08-30T19:22:05.200+0000] {task_command.py:415} INFO - Running <TaskInstance: traffic_report.import_data_to_csv scheduled__2023-08-24T00:00:00+00:00 [running]> on host 884d86529f65
[2023-08-30T19:22:05.217+0000] {logging_mixin.py:151} WARNING - /home/***/.local/lib/python3.8/site-packages/***/utils/sqlalchemy.py:124 DeprecationWarning: The sql_alchemy_conn option in [core] has been moved to the sql_alchemy_conn option in [database] - the old setting has been used, but please update your config.
[2023-08-30T19:22:05.300+0000] {taskinstance.py:1660} INFO - Exporting env vars: AIRFLOW_CTX_DAG_OWNER='***' AIRFLOW_CTX_DAG_ID='traffic_report' AIRFLOW_CTX_TASK_ID='import_data_to_csv' AIRFLOW_CTX_EXECUTION_DATE='2023-08-24T00:00:00+00:00' AIRFLOW_CTX_TRY_NUMBER='2' AIRFLOW_CTX_DAG_RUN_ID='scheduled__2023-08-24T00:00:00+00:00'
[2023-08-30T19:22:05.316+0000] {subprocess.py:63} INFO - Tmp dir root location: /tmp
[2023-08-30T19:22:05.319+0000] {subprocess.py:75} INFO - Running command: ['/bin/bash', '-c', 'python ./dags/data_ingestion.py --date 2023-08-24']
[2023-08-30T19:22:05.333+0000] {subprocess.py:86} INFO - Output:
[2023-08-30T19:22:05.439+0000] {subprocess.py:93} INFO - python: can't open file './dags/data_ingestion.py': [Errno 2] No such file or directory
[2023-08-30T19:22:05.442+0000] {subprocess.py:97} INFO - Command exited with return code 2
[2023-08-30T19:22:05.456+0000] {taskinstance.py:1943} ERROR - Task failed with exception
Traceback (most recent call last):
  File "/home/airflow/.local/lib/python3.8/site-packages/airflow/operators/bash.py", line 210, in execute
    raise AirflowException(
airflow.exceptions.AirflowException: Bash command failed. The command returned a non-zero exit code 2.
[2023-08-30T19:22:05.461+0000] {taskinstance.py:1400} INFO - Marking task as FAILED. dag_id=traffic_report, task_id=import_data_to_csv, execution_date=20230824T000000, start_date=20230830T192205, end_date=20230830T192205
[2023-08-30T19:22:05.474+0000] {standard_task_runner.py:104} ERROR - Failed to execute job 19 for task import_data_to_csv (Bash command failed. The command returned a non-zero exit code 2.; 353)
[2023-08-30T19:22:05.506+0000] {local_task_job_runner.py:228} INFO - Task exited with return code 1
[2023-08-30T19:22:05.532+0000] {taskinstance.py:2784} INFO - 0 downstream tasks scheduled from follow-on schedule check
