[2023-08-28T15:00:55.381+0000] {processor.py:157} INFO - Started process (PID=165) to work on /opt/airflow/dags/test_data_migration.py
[2023-08-28T15:00:55.383+0000] {processor.py:829} INFO - Processing file /opt/airflow/dags/test_data_migration.py for tasks to queue
[2023-08-28T15:00:55.385+0000] {logging_mixin.py:151} INFO - [2023-08-28T15:00:55.385+0000] {dagbag.py:539} INFO - Filling up the DagBag from /opt/airflow/dags/test_data_migration.py
[2023-08-28T15:00:55.444+0000] {logging_mixin.py:151} INFO - [2023-08-28T15:00:55.439+0000] {dagbag.py:347} ERROR - Failed to import: /opt/airflow/dags/test_data_migration.py
Traceback (most recent call last):
  File "/home/airflow/.local/lib/python3.8/site-packages/airflow/models/dagbag.py", line 343, in parse
    loader.exec_module(new_module)
  File "<frozen importlib._bootstrap_external>", line 843, in exec_module
  File "<frozen importlib._bootstrap>", line 219, in _call_with_frames_removed
  File "/opt/airflow/dags/test_data_migration.py", line 6, in <module>
    from model import Connection
  File "/opt/airflow/dags/model.py", line 5, in <module>
    from geoalchemy2 import Geometry
ModuleNotFoundError: No module named 'geoalchemy2'
[2023-08-28T15:00:55.445+0000] {processor.py:841} WARNING - No viable dags retrieved from /opt/airflow/dags/test_data_migration.py
[2023-08-28T15:00:55.461+0000] {processor.py:179} INFO - Processing /opt/airflow/dags/test_data_migration.py took 0.082 seconds
[2023-08-28T15:01:25.902+0000] {processor.py:157} INFO - Started process (PID=181) to work on /opt/airflow/dags/test_data_migration.py
[2023-08-28T15:01:25.904+0000] {processor.py:829} INFO - Processing file /opt/airflow/dags/test_data_migration.py for tasks to queue
[2023-08-28T15:01:25.907+0000] {logging_mixin.py:151} INFO - [2023-08-28T15:01:25.906+0000] {dagbag.py:539} INFO - Filling up the DagBag from /opt/airflow/dags/test_data_migration.py
[2023-08-28T15:01:25.955+0000] {logging_mixin.py:151} INFO - [2023-08-28T15:01:25.952+0000] {dagbag.py:347} ERROR - Failed to import: /opt/airflow/dags/test_data_migration.py
Traceback (most recent call last):
  File "/home/airflow/.local/lib/python3.8/site-packages/airflow/models/dagbag.py", line 343, in parse
    loader.exec_module(new_module)
  File "<frozen importlib._bootstrap_external>", line 843, in exec_module
  File "<frozen importlib._bootstrap>", line 219, in _call_with_frames_removed
  File "/opt/airflow/dags/test_data_migration.py", line 6, in <module>
    from model import Connection
  File "/opt/airflow/dags/model.py", line 5, in <module>
    from geoalchemy2 import Geometry
ModuleNotFoundError: No module named 'geoalchemy2'
[2023-08-28T15:01:25.957+0000] {processor.py:841} WARNING - No viable dags retrieved from /opt/airflow/dags/test_data_migration.py
[2023-08-28T15:01:25.977+0000] {processor.py:179} INFO - Processing /opt/airflow/dags/test_data_migration.py took 0.078 seconds
[2023-08-28T15:01:56.445+0000] {processor.py:157} INFO - Started process (PID=197) to work on /opt/airflow/dags/test_data_migration.py
[2023-08-28T15:01:56.453+0000] {processor.py:829} INFO - Processing file /opt/airflow/dags/test_data_migration.py for tasks to queue
[2023-08-28T15:01:56.456+0000] {logging_mixin.py:151} INFO - [2023-08-28T15:01:56.456+0000] {dagbag.py:539} INFO - Filling up the DagBag from /opt/airflow/dags/test_data_migration.py
[2023-08-28T15:01:56.516+0000] {logging_mixin.py:151} INFO - [2023-08-28T15:01:56.510+0000] {dagbag.py:347} ERROR - Failed to import: /opt/airflow/dags/test_data_migration.py
Traceback (most recent call last):
  File "/home/airflow/.local/lib/python3.8/site-packages/airflow/models/dagbag.py", line 343, in parse
    loader.exec_module(new_module)
  File "<frozen importlib._bootstrap_external>", line 843, in exec_module
  File "<frozen importlib._bootstrap>", line 219, in _call_with_frames_removed
  File "/opt/airflow/dags/test_data_migration.py", line 6, in <module>
    from model import Connection
  File "/opt/airflow/dags/model.py", line 5, in <module>
    from geoalchemy2 import Geometry
ModuleNotFoundError: No module named 'geoalchemy2'
[2023-08-28T15:01:56.520+0000] {processor.py:841} WARNING - No viable dags retrieved from /opt/airflow/dags/test_data_migration.py
[2023-08-28T15:01:56.551+0000] {processor.py:179} INFO - Processing /opt/airflow/dags/test_data_migration.py took 0.113 seconds
[2023-08-28T15:02:26.989+0000] {processor.py:157} INFO - Started process (PID=213) to work on /opt/airflow/dags/test_data_migration.py
[2023-08-28T15:02:26.992+0000] {processor.py:829} INFO - Processing file /opt/airflow/dags/test_data_migration.py for tasks to queue
[2023-08-28T15:02:26.995+0000] {logging_mixin.py:151} INFO - [2023-08-28T15:02:26.995+0000] {dagbag.py:539} INFO - Filling up the DagBag from /opt/airflow/dags/test_data_migration.py
[2023-08-28T15:02:27.040+0000] {logging_mixin.py:151} INFO - [2023-08-28T15:02:27.035+0000] {dagbag.py:347} ERROR - Failed to import: /opt/airflow/dags/test_data_migration.py
Traceback (most recent call last):
  File "/home/airflow/.local/lib/python3.8/site-packages/airflow/models/dagbag.py", line 343, in parse
    loader.exec_module(new_module)
  File "<frozen importlib._bootstrap_external>", line 843, in exec_module
  File "<frozen importlib._bootstrap>", line 219, in _call_with_frames_removed
  File "/opt/airflow/dags/test_data_migration.py", line 6, in <module>
    from model import Connection
  File "/opt/airflow/dags/model.py", line 5, in <module>
    from geoalchemy2 import Geometry
ModuleNotFoundError: No module named 'geoalchemy2'
[2023-08-28T15:02:27.042+0000] {processor.py:841} WARNING - No viable dags retrieved from /opt/airflow/dags/test_data_migration.py
[2023-08-28T15:02:27.062+0000] {processor.py:179} INFO - Processing /opt/airflow/dags/test_data_migration.py took 0.075 seconds
[2023-08-28T15:02:57.427+0000] {processor.py:157} INFO - Started process (PID=229) to work on /opt/airflow/dags/test_data_migration.py
[2023-08-28T15:02:57.429+0000] {processor.py:829} INFO - Processing file /opt/airflow/dags/test_data_migration.py for tasks to queue
[2023-08-28T15:02:57.431+0000] {logging_mixin.py:151} INFO - [2023-08-28T15:02:57.430+0000] {dagbag.py:539} INFO - Filling up the DagBag from /opt/airflow/dags/test_data_migration.py
[2023-08-28T15:02:57.477+0000] {logging_mixin.py:151} INFO - [2023-08-28T15:02:57.473+0000] {dagbag.py:347} ERROR - Failed to import: /opt/airflow/dags/test_data_migration.py
Traceback (most recent call last):
  File "/home/airflow/.local/lib/python3.8/site-packages/airflow/models/dagbag.py", line 343, in parse
    loader.exec_module(new_module)
  File "<frozen importlib._bootstrap_external>", line 843, in exec_module
  File "<frozen importlib._bootstrap>", line 219, in _call_with_frames_removed
  File "/opt/airflow/dags/test_data_migration.py", line 6, in <module>
    from model import Connection
  File "/opt/airflow/dags/model.py", line 5, in <module>
    from geoalchemy2 import Geometry
ModuleNotFoundError: No module named 'geoalchemy2'
[2023-08-28T15:02:57.479+0000] {processor.py:841} WARNING - No viable dags retrieved from /opt/airflow/dags/test_data_migration.py
[2023-08-28T15:02:57.493+0000] {processor.py:179} INFO - Processing /opt/airflow/dags/test_data_migration.py took 0.069 seconds
[2023-08-28T15:03:27.962+0000] {processor.py:157} INFO - Started process (PID=245) to work on /opt/airflow/dags/test_data_migration.py
[2023-08-28T15:03:27.967+0000] {processor.py:829} INFO - Processing file /opt/airflow/dags/test_data_migration.py for tasks to queue
[2023-08-28T15:03:27.969+0000] {logging_mixin.py:151} INFO - [2023-08-28T15:03:27.969+0000] {dagbag.py:539} INFO - Filling up the DagBag from /opt/airflow/dags/test_data_migration.py
[2023-08-28T15:03:28.038+0000] {logging_mixin.py:151} INFO - [2023-08-28T15:03:28.026+0000] {dagbag.py:347} ERROR - Failed to import: /opt/airflow/dags/test_data_migration.py
Traceback (most recent call last):
  File "/home/airflow/.local/lib/python3.8/site-packages/airflow/models/dagbag.py", line 343, in parse
    loader.exec_module(new_module)
  File "<frozen importlib._bootstrap_external>", line 843, in exec_module
  File "<frozen importlib._bootstrap>", line 219, in _call_with_frames_removed
  File "/opt/airflow/dags/test_data_migration.py", line 6, in <module>
    from model import Connection
  File "/opt/airflow/dags/model.py", line 5, in <module>
    from geoalchemy2 import Geometry
ModuleNotFoundError: No module named 'geoalchemy2'
[2023-08-28T15:03:28.041+0000] {processor.py:841} WARNING - No viable dags retrieved from /opt/airflow/dags/test_data_migration.py
[2023-08-28T15:03:28.065+0000] {processor.py:179} INFO - Processing /opt/airflow/dags/test_data_migration.py took 0.117 seconds
[2023-08-28T15:03:58.506+0000] {processor.py:157} INFO - Started process (PID=261) to work on /opt/airflow/dags/test_data_migration.py
[2023-08-28T15:03:58.508+0000] {processor.py:829} INFO - Processing file /opt/airflow/dags/test_data_migration.py for tasks to queue
[2023-08-28T15:03:58.510+0000] {logging_mixin.py:151} INFO - [2023-08-28T15:03:58.510+0000] {dagbag.py:539} INFO - Filling up the DagBag from /opt/airflow/dags/test_data_migration.py
[2023-08-28T15:03:58.551+0000] {logging_mixin.py:151} INFO - [2023-08-28T15:03:58.548+0000] {dagbag.py:347} ERROR - Failed to import: /opt/airflow/dags/test_data_migration.py
Traceback (most recent call last):
  File "/home/airflow/.local/lib/python3.8/site-packages/airflow/models/dagbag.py", line 343, in parse
    loader.exec_module(new_module)
  File "<frozen importlib._bootstrap_external>", line 843, in exec_module
  File "<frozen importlib._bootstrap>", line 219, in _call_with_frames_removed
  File "/opt/airflow/dags/test_data_migration.py", line 6, in <module>
    from model import Connection
  File "/opt/airflow/dags/model.py", line 5, in <module>
    from geoalchemy2 import Geometry
ModuleNotFoundError: No module named 'geoalchemy2'
[2023-08-28T15:03:58.553+0000] {processor.py:841} WARNING - No viable dags retrieved from /opt/airflow/dags/test_data_migration.py
[2023-08-28T15:03:58.568+0000] {processor.py:179} INFO - Processing /opt/airflow/dags/test_data_migration.py took 0.065 seconds
[2023-08-28T15:04:29.011+0000] {processor.py:157} INFO - Started process (PID=277) to work on /opt/airflow/dags/test_data_migration.py
[2023-08-28T15:04:29.014+0000] {processor.py:829} INFO - Processing file /opt/airflow/dags/test_data_migration.py for tasks to queue
[2023-08-28T15:04:29.018+0000] {logging_mixin.py:151} INFO - [2023-08-28T15:04:29.017+0000] {dagbag.py:539} INFO - Filling up the DagBag from /opt/airflow/dags/test_data_migration.py
[2023-08-28T15:04:29.067+0000] {logging_mixin.py:151} INFO - [2023-08-28T15:04:29.063+0000] {dagbag.py:347} ERROR - Failed to import: /opt/airflow/dags/test_data_migration.py
Traceback (most recent call last):
  File "/home/airflow/.local/lib/python3.8/site-packages/airflow/models/dagbag.py", line 343, in parse
    loader.exec_module(new_module)
  File "<frozen importlib._bootstrap_external>", line 843, in exec_module
  File "<frozen importlib._bootstrap>", line 219, in _call_with_frames_removed
  File "/opt/airflow/dags/test_data_migration.py", line 6, in <module>
    from model import Connection
  File "/opt/airflow/dags/model.py", line 5, in <module>
    from geoalchemy2 import Geometry
ModuleNotFoundError: No module named 'geoalchemy2'
[2023-08-28T15:04:29.069+0000] {processor.py:841} WARNING - No viable dags retrieved from /opt/airflow/dags/test_data_migration.py
[2023-08-28T15:04:29.085+0000] {processor.py:179} INFO - Processing /opt/airflow/dags/test_data_migration.py took 0.077 seconds
[2023-08-28T15:04:59.442+0000] {processor.py:157} INFO - Started process (PID=293) to work on /opt/airflow/dags/test_data_migration.py
[2023-08-28T15:04:59.445+0000] {processor.py:829} INFO - Processing file /opt/airflow/dags/test_data_migration.py for tasks to queue
[2023-08-28T15:04:59.447+0000] {logging_mixin.py:151} INFO - [2023-08-28T15:04:59.447+0000] {dagbag.py:539} INFO - Filling up the DagBag from /opt/airflow/dags/test_data_migration.py
[2023-08-28T15:04:59.489+0000] {logging_mixin.py:151} INFO - [2023-08-28T15:04:59.485+0000] {dagbag.py:347} ERROR - Failed to import: /opt/airflow/dags/test_data_migration.py
Traceback (most recent call last):
  File "/home/airflow/.local/lib/python3.8/site-packages/airflow/models/dagbag.py", line 343, in parse
    loader.exec_module(new_module)
  File "<frozen importlib._bootstrap_external>", line 843, in exec_module
  File "<frozen importlib._bootstrap>", line 219, in _call_with_frames_removed
  File "/opt/airflow/dags/test_data_migration.py", line 6, in <module>
    from model import Connection
  File "/opt/airflow/dags/model.py", line 5, in <module>
    from geoalchemy2 import Geometry
ModuleNotFoundError: No module named 'geoalchemy2'
[2023-08-28T15:04:59.492+0000] {processor.py:841} WARNING - No viable dags retrieved from /opt/airflow/dags/test_data_migration.py
[2023-08-28T15:04:59.507+0000] {processor.py:179} INFO - Processing /opt/airflow/dags/test_data_migration.py took 0.068 seconds
[2023-08-28T15:05:29.946+0000] {processor.py:157} INFO - Started process (PID=309) to work on /opt/airflow/dags/test_data_migration.py
[2023-08-28T15:05:29.949+0000] {processor.py:829} INFO - Processing file /opt/airflow/dags/test_data_migration.py for tasks to queue
[2023-08-28T15:05:29.951+0000] {logging_mixin.py:151} INFO - [2023-08-28T15:05:29.950+0000] {dagbag.py:539} INFO - Filling up the DagBag from /opt/airflow/dags/test_data_migration.py
[2023-08-28T15:05:29.990+0000] {logging_mixin.py:151} INFO - [2023-08-28T15:05:29.987+0000] {dagbag.py:347} ERROR - Failed to import: /opt/airflow/dags/test_data_migration.py
Traceback (most recent call last):
  File "/home/airflow/.local/lib/python3.8/site-packages/airflow/models/dagbag.py", line 343, in parse
    loader.exec_module(new_module)
  File "<frozen importlib._bootstrap_external>", line 843, in exec_module
  File "<frozen importlib._bootstrap>", line 219, in _call_with_frames_removed
  File "/opt/airflow/dags/test_data_migration.py", line 6, in <module>
    from model import Connection
  File "/opt/airflow/dags/model.py", line 5, in <module>
    from geoalchemy2 import Geometry
ModuleNotFoundError: No module named 'geoalchemy2'
[2023-08-28T15:05:29.992+0000] {processor.py:841} WARNING - No viable dags retrieved from /opt/airflow/dags/test_data_migration.py
[2023-08-28T15:05:30.007+0000] {processor.py:179} INFO - Processing /opt/airflow/dags/test_data_migration.py took 0.064 seconds
[2023-08-28T15:06:00.439+0000] {processor.py:157} INFO - Started process (PID=325) to work on /opt/airflow/dags/test_data_migration.py
[2023-08-28T15:06:00.442+0000] {processor.py:829} INFO - Processing file /opt/airflow/dags/test_data_migration.py for tasks to queue
[2023-08-28T15:06:00.444+0000] {logging_mixin.py:151} INFO - [2023-08-28T15:06:00.444+0000] {dagbag.py:539} INFO - Filling up the DagBag from /opt/airflow/dags/test_data_migration.py
[2023-08-28T15:06:00.489+0000] {logging_mixin.py:151} INFO - [2023-08-28T15:06:00.485+0000] {dagbag.py:347} ERROR - Failed to import: /opt/airflow/dags/test_data_migration.py
Traceback (most recent call last):
  File "/home/airflow/.local/lib/python3.8/site-packages/airflow/models/dagbag.py", line 343, in parse
    loader.exec_module(new_module)
  File "<frozen importlib._bootstrap_external>", line 843, in exec_module
  File "<frozen importlib._bootstrap>", line 219, in _call_with_frames_removed
  File "/opt/airflow/dags/test_data_migration.py", line 6, in <module>
    from model import Connection
  File "/opt/airflow/dags/model.py", line 5, in <module>
    from geoalchemy2 import Geometry
ModuleNotFoundError: No module named 'geoalchemy2'
[2023-08-28T15:06:00.491+0000] {processor.py:841} WARNING - No viable dags retrieved from /opt/airflow/dags/test_data_migration.py
[2023-08-28T15:06:00.506+0000] {processor.py:179} INFO - Processing /opt/airflow/dags/test_data_migration.py took 0.070 seconds
[2023-08-28T15:06:30.942+0000] {processor.py:157} INFO - Started process (PID=341) to work on /opt/airflow/dags/test_data_migration.py
[2023-08-28T15:06:30.945+0000] {processor.py:829} INFO - Processing file /opt/airflow/dags/test_data_migration.py for tasks to queue
[2023-08-28T15:06:30.947+0000] {logging_mixin.py:151} INFO - [2023-08-28T15:06:30.947+0000] {dagbag.py:539} INFO - Filling up the DagBag from /opt/airflow/dags/test_data_migration.py
[2023-08-28T15:06:31.021+0000] {logging_mixin.py:151} INFO - [2023-08-28T15:06:31.013+0000] {dagbag.py:347} ERROR - Failed to import: /opt/airflow/dags/test_data_migration.py
Traceback (most recent call last):
  File "/home/airflow/.local/lib/python3.8/site-packages/airflow/models/dagbag.py", line 343, in parse
    loader.exec_module(new_module)
  File "<frozen importlib._bootstrap_external>", line 843, in exec_module
  File "<frozen importlib._bootstrap>", line 219, in _call_with_frames_removed
  File "/opt/airflow/dags/test_data_migration.py", line 6, in <module>
    from model import Connection
  File "/opt/airflow/dags/model.py", line 5, in <module>
    from geoalchemy2 import Geometry
ModuleNotFoundError: No module named 'geoalchemy2'
[2023-08-28T15:06:31.024+0000] {processor.py:841} WARNING - No viable dags retrieved from /opt/airflow/dags/test_data_migration.py
[2023-08-28T15:06:31.048+0000] {processor.py:179} INFO - Processing /opt/airflow/dags/test_data_migration.py took 0.111 seconds
[2023-08-28T15:07:01.528+0000] {processor.py:157} INFO - Started process (PID=357) to work on /opt/airflow/dags/test_data_migration.py
[2023-08-28T15:07:01.530+0000] {processor.py:829} INFO - Processing file /opt/airflow/dags/test_data_migration.py for tasks to queue
[2023-08-28T15:07:01.531+0000] {logging_mixin.py:151} INFO - [2023-08-28T15:07:01.531+0000] {dagbag.py:539} INFO - Filling up the DagBag from /opt/airflow/dags/test_data_migration.py
[2023-08-28T15:07:01.575+0000] {logging_mixin.py:151} INFO - [2023-08-28T15:07:01.571+0000] {dagbag.py:347} ERROR - Failed to import: /opt/airflow/dags/test_data_migration.py
Traceback (most recent call last):
  File "/home/airflow/.local/lib/python3.8/site-packages/airflow/models/dagbag.py", line 343, in parse
    loader.exec_module(new_module)
  File "<frozen importlib._bootstrap_external>", line 843, in exec_module
  File "<frozen importlib._bootstrap>", line 219, in _call_with_frames_removed
  File "/opt/airflow/dags/test_data_migration.py", line 6, in <module>
    from model import Connection
  File "/opt/airflow/dags/model.py", line 5, in <module>
    from geoalchemy2 import Geometry
ModuleNotFoundError: No module named 'geoalchemy2'
[2023-08-28T15:07:01.577+0000] {processor.py:841} WARNING - No viable dags retrieved from /opt/airflow/dags/test_data_migration.py
[2023-08-28T15:07:01.593+0000] {processor.py:179} INFO - Processing /opt/airflow/dags/test_data_migration.py took 0.068 seconds
[2023-08-28T15:07:32.031+0000] {processor.py:157} INFO - Started process (PID=373) to work on /opt/airflow/dags/test_data_migration.py
[2023-08-28T15:07:32.034+0000] {processor.py:829} INFO - Processing file /opt/airflow/dags/test_data_migration.py for tasks to queue
[2023-08-28T15:07:32.037+0000] {logging_mixin.py:151} INFO - [2023-08-28T15:07:32.037+0000] {dagbag.py:539} INFO - Filling up the DagBag from /opt/airflow/dags/test_data_migration.py
[2023-08-28T15:07:32.157+0000] {logging_mixin.py:151} INFO - [2023-08-28T15:07:32.153+0000] {dagbag.py:347} ERROR - Failed to import: /opt/airflow/dags/test_data_migration.py
Traceback (most recent call last):
  File "/home/airflow/.local/lib/python3.8/site-packages/airflow/models/dagbag.py", line 343, in parse
    loader.exec_module(new_module)
  File "<frozen importlib._bootstrap_external>", line 843, in exec_module
  File "<frozen importlib._bootstrap>", line 219, in _call_with_frames_removed
  File "/opt/airflow/dags/test_data_migration.py", line 6, in <module>
    from model import Connection
  File "/opt/airflow/dags/model.py", line 5, in <module>
    from geoalchemy2 import Geometry
ModuleNotFoundError: No module named 'geoalchemy2'
[2023-08-28T15:07:32.159+0000] {processor.py:841} WARNING - No viable dags retrieved from /opt/airflow/dags/test_data_migration.py
[2023-08-28T15:07:32.173+0000] {processor.py:179} INFO - Processing /opt/airflow/dags/test_data_migration.py took 0.145 seconds
[2023-08-28T15:08:02.515+0000] {processor.py:157} INFO - Started process (PID=389) to work on /opt/airflow/dags/test_data_migration.py
[2023-08-28T15:08:02.518+0000] {processor.py:829} INFO - Processing file /opt/airflow/dags/test_data_migration.py for tasks to queue
[2023-08-28T15:08:02.520+0000] {logging_mixin.py:151} INFO - [2023-08-28T15:08:02.520+0000] {dagbag.py:539} INFO - Filling up the DagBag from /opt/airflow/dags/test_data_migration.py
[2023-08-28T15:08:02.647+0000] {logging_mixin.py:151} INFO - [2023-08-28T15:08:02.643+0000] {dagbag.py:347} ERROR - Failed to import: /opt/airflow/dags/test_data_migration.py
Traceback (most recent call last):
  File "/home/airflow/.local/lib/python3.8/site-packages/airflow/models/dagbag.py", line 343, in parse
    loader.exec_module(new_module)
  File "<frozen importlib._bootstrap_external>", line 843, in exec_module
  File "<frozen importlib._bootstrap>", line 219, in _call_with_frames_removed
  File "/opt/airflow/dags/test_data_migration.py", line 6, in <module>
    from model import Connection
  File "/opt/airflow/dags/model.py", line 5, in <module>
    from geoalchemy2 import Geometry
ModuleNotFoundError: No module named 'geoalchemy2'
[2023-08-28T15:08:02.649+0000] {processor.py:841} WARNING - No viable dags retrieved from /opt/airflow/dags/test_data_migration.py
[2023-08-28T15:08:02.661+0000] {processor.py:179} INFO - Processing /opt/airflow/dags/test_data_migration.py took 0.150 seconds
[2023-08-28T15:08:33.203+0000] {processor.py:157} INFO - Started process (PID=405) to work on /opt/airflow/dags/test_data_migration.py
[2023-08-28T15:08:33.206+0000] {processor.py:829} INFO - Processing file /opt/airflow/dags/test_data_migration.py for tasks to queue
[2023-08-28T15:08:33.209+0000] {logging_mixin.py:151} INFO - [2023-08-28T15:08:33.209+0000] {dagbag.py:539} INFO - Filling up the DagBag from /opt/airflow/dags/test_data_migration.py
[2023-08-28T15:08:33.260+0000] {logging_mixin.py:151} INFO - [2023-08-28T15:08:33.256+0000] {dagbag.py:347} ERROR - Failed to import: /opt/airflow/dags/test_data_migration.py
Traceback (most recent call last):
  File "/home/airflow/.local/lib/python3.8/site-packages/airflow/models/dagbag.py", line 343, in parse
    loader.exec_module(new_module)
  File "<frozen importlib._bootstrap_external>", line 843, in exec_module
  File "<frozen importlib._bootstrap>", line 219, in _call_with_frames_removed
  File "/opt/airflow/dags/test_data_migration.py", line 6, in <module>
    from model import Connection
  File "/opt/airflow/dags/model.py", line 5, in <module>
    from geoalchemy2 import Geometry
ModuleNotFoundError: No module named 'geoalchemy2'
[2023-08-28T15:08:33.262+0000] {processor.py:841} WARNING - No viable dags retrieved from /opt/airflow/dags/test_data_migration.py
[2023-08-28T15:08:33.275+0000] {processor.py:179} INFO - Processing /opt/airflow/dags/test_data_migration.py took 0.075 seconds
[2023-08-28T15:09:03.636+0000] {processor.py:157} INFO - Started process (PID=421) to work on /opt/airflow/dags/test_data_migration.py
[2023-08-28T15:09:03.640+0000] {processor.py:829} INFO - Processing file /opt/airflow/dags/test_data_migration.py for tasks to queue
[2023-08-28T15:09:03.641+0000] {logging_mixin.py:151} INFO - [2023-08-28T15:09:03.641+0000] {dagbag.py:539} INFO - Filling up the DagBag from /opt/airflow/dags/test_data_migration.py
[2023-08-28T15:09:03.683+0000] {logging_mixin.py:151} INFO - [2023-08-28T15:09:03.680+0000] {dagbag.py:347} ERROR - Failed to import: /opt/airflow/dags/test_data_migration.py
Traceback (most recent call last):
  File "/home/airflow/.local/lib/python3.8/site-packages/airflow/models/dagbag.py", line 343, in parse
    loader.exec_module(new_module)
  File "<frozen importlib._bootstrap_external>", line 843, in exec_module
  File "<frozen importlib._bootstrap>", line 219, in _call_with_frames_removed
  File "/opt/airflow/dags/test_data_migration.py", line 6, in <module>
    from model import Connection
  File "/opt/airflow/dags/model.py", line 5, in <module>
    from geoalchemy2 import Geometry
ModuleNotFoundError: No module named 'geoalchemy2'
[2023-08-28T15:09:03.685+0000] {processor.py:841} WARNING - No viable dags retrieved from /opt/airflow/dags/test_data_migration.py
[2023-08-28T15:09:03.702+0000] {processor.py:179} INFO - Processing /opt/airflow/dags/test_data_migration.py took 0.068 seconds
[2023-08-28T15:09:34.085+0000] {processor.py:157} INFO - Started process (PID=437) to work on /opt/airflow/dags/test_data_migration.py
[2023-08-28T15:09:34.088+0000] {processor.py:829} INFO - Processing file /opt/airflow/dags/test_data_migration.py for tasks to queue
[2023-08-28T15:09:34.090+0000] {logging_mixin.py:151} INFO - [2023-08-28T15:09:34.090+0000] {dagbag.py:539} INFO - Filling up the DagBag from /opt/airflow/dags/test_data_migration.py
[2023-08-28T15:09:34.134+0000] {logging_mixin.py:151} INFO - [2023-08-28T15:09:34.130+0000] {dagbag.py:347} ERROR - Failed to import: /opt/airflow/dags/test_data_migration.py
Traceback (most recent call last):
  File "/home/airflow/.local/lib/python3.8/site-packages/airflow/models/dagbag.py", line 343, in parse
    loader.exec_module(new_module)
  File "<frozen importlib._bootstrap_external>", line 843, in exec_module
  File "<frozen importlib._bootstrap>", line 219, in _call_with_frames_removed
  File "/opt/airflow/dags/test_data_migration.py", line 6, in <module>
    from model import Connection
  File "/opt/airflow/dags/model.py", line 5, in <module>
    from geoalchemy2 import Geometry
ModuleNotFoundError: No module named 'geoalchemy2'
[2023-08-28T15:09:34.136+0000] {processor.py:841} WARNING - No viable dags retrieved from /opt/airflow/dags/test_data_migration.py
[2023-08-28T15:09:34.151+0000] {processor.py:179} INFO - Processing /opt/airflow/dags/test_data_migration.py took 0.069 seconds
[2023-08-28T15:10:04.595+0000] {processor.py:157} INFO - Started process (PID=453) to work on /opt/airflow/dags/test_data_migration.py
[2023-08-28T15:10:04.598+0000] {processor.py:829} INFO - Processing file /opt/airflow/dags/test_data_migration.py for tasks to queue
[2023-08-28T15:10:04.600+0000] {logging_mixin.py:151} INFO - [2023-08-28T15:10:04.599+0000] {dagbag.py:539} INFO - Filling up the DagBag from /opt/airflow/dags/test_data_migration.py
[2023-08-28T15:10:04.645+0000] {logging_mixin.py:151} INFO - [2023-08-28T15:10:04.641+0000] {dagbag.py:347} ERROR - Failed to import: /opt/airflow/dags/test_data_migration.py
Traceback (most recent call last):
  File "/home/airflow/.local/lib/python3.8/site-packages/airflow/models/dagbag.py", line 343, in parse
    loader.exec_module(new_module)
  File "<frozen importlib._bootstrap_external>", line 843, in exec_module
  File "<frozen importlib._bootstrap>", line 219, in _call_with_frames_removed
  File "/opt/airflow/dags/test_data_migration.py", line 6, in <module>
    from model import Connection
  File "/opt/airflow/dags/model.py", line 5, in <module>
    from geoalchemy2 import Geometry
ModuleNotFoundError: No module named 'geoalchemy2'
[2023-08-28T15:10:04.646+0000] {processor.py:841} WARNING - No viable dags retrieved from /opt/airflow/dags/test_data_migration.py
[2023-08-28T15:10:04.664+0000] {processor.py:179} INFO - Processing /opt/airflow/dags/test_data_migration.py took 0.071 seconds
[2023-08-28T15:10:35.064+0000] {processor.py:157} INFO - Started process (PID=469) to work on /opt/airflow/dags/test_data_migration.py
[2023-08-28T15:10:35.065+0000] {processor.py:829} INFO - Processing file /opt/airflow/dags/test_data_migration.py for tasks to queue
[2023-08-28T15:10:35.068+0000] {logging_mixin.py:151} INFO - [2023-08-28T15:10:35.067+0000] {dagbag.py:539} INFO - Filling up the DagBag from /opt/airflow/dags/test_data_migration.py
[2023-08-28T15:10:35.110+0000] {logging_mixin.py:151} INFO - [2023-08-28T15:10:35.107+0000] {dagbag.py:347} ERROR - Failed to import: /opt/airflow/dags/test_data_migration.py
Traceback (most recent call last):
  File "/home/airflow/.local/lib/python3.8/site-packages/airflow/models/dagbag.py", line 343, in parse
    loader.exec_module(new_module)
  File "<frozen importlib._bootstrap_external>", line 843, in exec_module
  File "<frozen importlib._bootstrap>", line 219, in _call_with_frames_removed
  File "/opt/airflow/dags/test_data_migration.py", line 6, in <module>
    from model import Connection
  File "/opt/airflow/dags/model.py", line 5, in <module>
    from geoalchemy2 import Geometry
ModuleNotFoundError: No module named 'geoalchemy2'
[2023-08-28T15:10:35.113+0000] {processor.py:841} WARNING - No viable dags retrieved from /opt/airflow/dags/test_data_migration.py
[2023-08-28T15:10:35.127+0000] {processor.py:179} INFO - Processing /opt/airflow/dags/test_data_migration.py took 0.066 seconds
[2023-08-28T15:11:05.643+0000] {processor.py:157} INFO - Started process (PID=485) to work on /opt/airflow/dags/test_data_migration.py
[2023-08-28T15:11:05.645+0000] {processor.py:829} INFO - Processing file /opt/airflow/dags/test_data_migration.py for tasks to queue
[2023-08-28T15:11:05.647+0000] {logging_mixin.py:151} INFO - [2023-08-28T15:11:05.647+0000] {dagbag.py:539} INFO - Filling up the DagBag from /opt/airflow/dags/test_data_migration.py
[2023-08-28T15:11:05.697+0000] {logging_mixin.py:151} INFO - [2023-08-28T15:11:05.693+0000] {dagbag.py:347} ERROR - Failed to import: /opt/airflow/dags/test_data_migration.py
Traceback (most recent call last):
  File "/home/airflow/.local/lib/python3.8/site-packages/airflow/models/dagbag.py", line 343, in parse
    loader.exec_module(new_module)
  File "<frozen importlib._bootstrap_external>", line 843, in exec_module
  File "<frozen importlib._bootstrap>", line 219, in _call_with_frames_removed
  File "/opt/airflow/dags/test_data_migration.py", line 6, in <module>
    from model import Connection
  File "/opt/airflow/dags/model.py", line 5, in <module>
    from geoalchemy2 import Geometry
ModuleNotFoundError: No module named 'geoalchemy2'
[2023-08-28T15:11:05.698+0000] {processor.py:841} WARNING - No viable dags retrieved from /opt/airflow/dags/test_data_migration.py
[2023-08-28T15:11:05.715+0000] {processor.py:179} INFO - Processing /opt/airflow/dags/test_data_migration.py took 0.076 seconds
[2023-08-28T15:11:36.129+0000] {processor.py:157} INFO - Started process (PID=501) to work on /opt/airflow/dags/test_data_migration.py
[2023-08-28T15:11:36.131+0000] {processor.py:829} INFO - Processing file /opt/airflow/dags/test_data_migration.py for tasks to queue
[2023-08-28T15:11:36.133+0000] {logging_mixin.py:151} INFO - [2023-08-28T15:11:36.133+0000] {dagbag.py:539} INFO - Filling up the DagBag from /opt/airflow/dags/test_data_migration.py
[2023-08-28T15:11:36.176+0000] {logging_mixin.py:151} INFO - [2023-08-28T15:11:36.172+0000] {dagbag.py:347} ERROR - Failed to import: /opt/airflow/dags/test_data_migration.py
Traceback (most recent call last):
  File "/home/airflow/.local/lib/python3.8/site-packages/airflow/models/dagbag.py", line 343, in parse
    loader.exec_module(new_module)
  File "<frozen importlib._bootstrap_external>", line 843, in exec_module
  File "<frozen importlib._bootstrap>", line 219, in _call_with_frames_removed
  File "/opt/airflow/dags/test_data_migration.py", line 6, in <module>
    from model import Connection
  File "/opt/airflow/dags/model.py", line 5, in <module>
    from geoalchemy2 import Geometry
ModuleNotFoundError: No module named 'geoalchemy2'
[2023-08-28T15:11:36.178+0000] {processor.py:841} WARNING - No viable dags retrieved from /opt/airflow/dags/test_data_migration.py
[2023-08-28T15:11:36.194+0000] {processor.py:179} INFO - Processing /opt/airflow/dags/test_data_migration.py took 0.068 seconds
[2023-08-28T15:12:06.591+0000] {processor.py:157} INFO - Started process (PID=522) to work on /opt/airflow/dags/test_data_migration.py
[2023-08-28T15:12:06.592+0000] {processor.py:829} INFO - Processing file /opt/airflow/dags/test_data_migration.py for tasks to queue
[2023-08-28T15:12:06.594+0000] {logging_mixin.py:151} INFO - [2023-08-28T15:12:06.594+0000] {dagbag.py:539} INFO - Filling up the DagBag from /opt/airflow/dags/test_data_migration.py
[2023-08-28T15:12:06.632+0000] {logging_mixin.py:151} INFO - [2023-08-28T15:12:06.628+0000] {dagbag.py:347} ERROR - Failed to import: /opt/airflow/dags/test_data_migration.py
Traceback (most recent call last):
  File "/home/airflow/.local/lib/python3.8/site-packages/airflow/models/dagbag.py", line 343, in parse
    loader.exec_module(new_module)
  File "<frozen importlib._bootstrap_external>", line 843, in exec_module
  File "<frozen importlib._bootstrap>", line 219, in _call_with_frames_removed
  File "/opt/airflow/dags/test_data_migration.py", line 6, in <module>
    from model import Connection
  File "/opt/airflow/dags/model.py", line 5, in <module>
    from geoalchemy2 import Geometry
ModuleNotFoundError: No module named 'geoalchemy2'
[2023-08-28T15:12:06.635+0000] {processor.py:841} WARNING - No viable dags retrieved from /opt/airflow/dags/test_data_migration.py
[2023-08-28T15:12:06.650+0000] {processor.py:179} INFO - Processing /opt/airflow/dags/test_data_migration.py took 0.062 seconds
[2023-08-28T15:12:37.106+0000] {processor.py:157} INFO - Started process (PID=538) to work on /opt/airflow/dags/test_data_migration.py
[2023-08-28T15:12:37.109+0000] {processor.py:829} INFO - Processing file /opt/airflow/dags/test_data_migration.py for tasks to queue
[2023-08-28T15:12:37.111+0000] {logging_mixin.py:151} INFO - [2023-08-28T15:12:37.110+0000] {dagbag.py:539} INFO - Filling up the DagBag from /opt/airflow/dags/test_data_migration.py
[2023-08-28T15:12:37.152+0000] {logging_mixin.py:151} INFO - [2023-08-28T15:12:37.148+0000] {dagbag.py:347} ERROR - Failed to import: /opt/airflow/dags/test_data_migration.py
Traceback (most recent call last):
  File "/home/airflow/.local/lib/python3.8/site-packages/airflow/models/dagbag.py", line 343, in parse
    loader.exec_module(new_module)
  File "<frozen importlib._bootstrap_external>", line 843, in exec_module
  File "<frozen importlib._bootstrap>", line 219, in _call_with_frames_removed
  File "/opt/airflow/dags/test_data_migration.py", line 6, in <module>
    from model import Connection
  File "/opt/airflow/dags/model.py", line 5, in <module>
    from geoalchemy2 import Geometry
ModuleNotFoundError: No module named 'geoalchemy2'
[2023-08-28T15:12:37.154+0000] {processor.py:841} WARNING - No viable dags retrieved from /opt/airflow/dags/test_data_migration.py
[2023-08-28T15:12:37.169+0000] {processor.py:179} INFO - Processing /opt/airflow/dags/test_data_migration.py took 0.065 seconds
[2023-08-28T15:13:07.548+0000] {processor.py:157} INFO - Started process (PID=554) to work on /opt/airflow/dags/test_data_migration.py
[2023-08-28T15:13:07.551+0000] {processor.py:829} INFO - Processing file /opt/airflow/dags/test_data_migration.py for tasks to queue
[2023-08-28T15:13:07.552+0000] {logging_mixin.py:151} INFO - [2023-08-28T15:13:07.552+0000] {dagbag.py:539} INFO - Filling up the DagBag from /opt/airflow/dags/test_data_migration.py
[2023-08-28T15:13:07.595+0000] {logging_mixin.py:151} INFO - [2023-08-28T15:13:07.591+0000] {dagbag.py:347} ERROR - Failed to import: /opt/airflow/dags/test_data_migration.py
Traceback (most recent call last):
  File "/home/airflow/.local/lib/python3.8/site-packages/airflow/models/dagbag.py", line 343, in parse
    loader.exec_module(new_module)
  File "<frozen importlib._bootstrap_external>", line 843, in exec_module
  File "<frozen importlib._bootstrap>", line 219, in _call_with_frames_removed
  File "/opt/airflow/dags/test_data_migration.py", line 6, in <module>
    from model import Connection
  File "/opt/airflow/dags/model.py", line 5, in <module>
    from geoalchemy2 import Geometry
ModuleNotFoundError: No module named 'geoalchemy2'
[2023-08-28T15:13:07.597+0000] {processor.py:841} WARNING - No viable dags retrieved from /opt/airflow/dags/test_data_migration.py
[2023-08-28T15:13:07.614+0000] {processor.py:179} INFO - Processing /opt/airflow/dags/test_data_migration.py took 0.069 seconds
[2023-08-28T15:13:38.044+0000] {processor.py:157} INFO - Started process (PID=570) to work on /opt/airflow/dags/test_data_migration.py
[2023-08-28T15:13:38.045+0000] {processor.py:829} INFO - Processing file /opt/airflow/dags/test_data_migration.py for tasks to queue
[2023-08-28T15:13:38.047+0000] {logging_mixin.py:151} INFO - [2023-08-28T15:13:38.046+0000] {dagbag.py:539} INFO - Filling up the DagBag from /opt/airflow/dags/test_data_migration.py
[2023-08-28T15:13:38.086+0000] {logging_mixin.py:151} INFO - [2023-08-28T15:13:38.081+0000] {dagbag.py:347} ERROR - Failed to import: /opt/airflow/dags/test_data_migration.py
Traceback (most recent call last):
  File "/home/airflow/.local/lib/python3.8/site-packages/airflow/models/dagbag.py", line 343, in parse
    loader.exec_module(new_module)
  File "<frozen importlib._bootstrap_external>", line 843, in exec_module
  File "<frozen importlib._bootstrap>", line 219, in _call_with_frames_removed
  File "/opt/airflow/dags/test_data_migration.py", line 6, in <module>
    from model import Connection
  File "/opt/airflow/dags/model.py", line 5, in <module>
    from geoalchemy2 import Geometry
ModuleNotFoundError: No module named 'geoalchemy2'
[2023-08-28T15:13:38.087+0000] {processor.py:841} WARNING - No viable dags retrieved from /opt/airflow/dags/test_data_migration.py
[2023-08-28T15:13:38.103+0000] {processor.py:179} INFO - Processing /opt/airflow/dags/test_data_migration.py took 0.061 seconds
