[2023-08-30T00:05:02.732+0000] {logging_mixin.py:151} WARNING - /home/***/.local/lib/python3.8/site-packages/***/utils/sqlalchemy.py:124 DeprecationWarning: The sql_alchemy_conn option in [core] has been moved to the sql_alchemy_conn option in [database] - the old setting has been used, but please update your config.
[2023-08-30T00:05:02.739+0000] {taskinstance.py:1159} INFO - Dependencies all met for dep_context=non-requeueable deps ti=<TaskInstance: traffic_report.import_data_to_csv scheduled__2023-08-29T00:00:00+00:00 [queued]>
[2023-08-30T00:05:02.744+0000] {taskinstance.py:1159} INFO - Dependencies all met for dep_context=requeueable deps ti=<TaskInstance: traffic_report.import_data_to_csv scheduled__2023-08-29T00:00:00+00:00 [queued]>
[2023-08-30T00:05:02.746+0000] {taskinstance.py:1361} INFO - Starting attempt 2 of 2
[2023-08-30T00:05:02.755+0000] {taskinstance.py:1382} INFO - Executing <Task(BashOperator): import_data_to_csv> on 2023-08-29 00:00:00+00:00
[2023-08-30T00:05:02.759+0000] {standard_task_runner.py:57} INFO - Started process 8499 to run task
[2023-08-30T00:05:02.761+0000] {standard_task_runner.py:84} INFO - Running: ['***', 'tasks', 'run', 'traffic_report', 'import_data_to_csv', 'scheduled__2023-08-29T00:00:00+00:00', '--job-id', '41', '--raw', '--subdir', 'DAGS_FOLDER/traffic_dag.py', '--cfg-path', '/tmp/tmpza4i42ks']
[2023-08-30T00:05:02.764+0000] {standard_task_runner.py:85} INFO - Job 41: Subtask import_data_to_csv
[2023-08-30T00:05:02.776+0000] {logging_mixin.py:151} WARNING - /home/***/.local/lib/python3.8/site-packages/***/settings.py:195 DeprecationWarning: The sql_alchemy_conn option in [core] has been moved to the sql_alchemy_conn option in [database] - the old setting has been used, but please update your config.
[2023-08-30T00:05:02.806+0000] {task_command.py:415} INFO - Running <TaskInstance: traffic_report.import_data_to_csv scheduled__2023-08-29T00:00:00+00:00 [running]> on host e69093e17de8
[2023-08-30T00:05:02.818+0000] {logging_mixin.py:151} WARNING - /home/***/.local/lib/python3.8/site-packages/***/utils/sqlalchemy.py:124 DeprecationWarning: The sql_alchemy_conn option in [core] has been moved to the sql_alchemy_conn option in [database] - the old setting has been used, but please update your config.
[2023-08-30T00:05:02.863+0000] {taskinstance.py:1660} INFO - Exporting env vars: AIRFLOW_CTX_DAG_OWNER='***' AIRFLOW_CTX_DAG_ID='traffic_report' AIRFLOW_CTX_TASK_ID='import_data_to_csv' AIRFLOW_CTX_EXECUTION_DATE='2023-08-29T00:00:00+00:00' AIRFLOW_CTX_TRY_NUMBER='2' AIRFLOW_CTX_DAG_RUN_ID='scheduled__2023-08-29T00:00:00+00:00'
[2023-08-30T00:05:02.866+0000] {subprocess.py:63} INFO - Tmp dir root location: /tmp
[2023-08-30T00:05:02.867+0000] {subprocess.py:75} INFO - Running command: ['/bin/bash', '-c', 'python /Users/jinee.hira/Dropbox/virtual_envs/austin-flow/***/dags/data_ingestion.py --date 2023-08-29']
[2023-08-30T00:05:02.878+0000] {subprocess.py:86} INFO - Output:
[2023-08-30T00:05:02.932+0000] {subprocess.py:93} INFO - python: can't open file '/Users/jinee.hira/Dropbox/virtual_envs/austin-flow/***/dags/data_ingestion.py': [Errno 2] No such file or directory
[2023-08-30T00:05:02.935+0000] {subprocess.py:97} INFO - Command exited with return code 2
[2023-08-30T00:05:02.946+0000] {taskinstance.py:1943} ERROR - Task failed with exception
Traceback (most recent call last):
  File "/home/airflow/.local/lib/python3.8/site-packages/airflow/operators/bash.py", line 210, in execute
    raise AirflowException(
airflow.exceptions.AirflowException: Bash command failed. The command returned a non-zero exit code 2.
[2023-08-30T00:05:02.950+0000] {taskinstance.py:1400} INFO - Marking task as FAILED. dag_id=traffic_report, task_id=import_data_to_csv, execution_date=20230829T000000, start_date=20230830T000502, end_date=20230830T000502
[2023-08-30T00:05:02.959+0000] {standard_task_runner.py:104} ERROR - Failed to execute job 41 for task import_data_to_csv (Bash command failed. The command returned a non-zero exit code 2.; 8499)
[2023-08-30T00:05:02.976+0000] {local_task_job_runner.py:228} INFO - Task exited with return code 1
[2023-08-30T00:05:02.993+0000] {taskinstance.py:2784} INFO - 0 downstream tasks scheduled from follow-on schedule check
[2023-08-30T19:01:48.662+0000] {logging_mixin.py:151} WARNING - /home/***/.local/lib/python3.8/site-packages/***/utils/sqlalchemy.py:124 DeprecationWarning: The sql_alchemy_conn option in [core] has been moved to the sql_alchemy_conn option in [database] - the old setting has been used, but please update your config.
[2023-08-30T19:01:48.674+0000] {taskinstance.py:1159} INFO - Dependencies all met for dep_context=non-requeueable deps ti=<TaskInstance: traffic_report.import_data_to_csv scheduled__2023-08-29T00:00:00+00:00 [queued]>
[2023-08-30T19:01:48.692+0000] {taskinstance.py:1159} INFO - Dependencies all met for dep_context=requeueable deps ti=<TaskInstance: traffic_report.import_data_to_csv scheduled__2023-08-29T00:00:00+00:00 [queued]>
[2023-08-30T19:01:48.693+0000] {taskinstance.py:1361} INFO - Starting attempt 2 of 2
[2023-08-30T19:01:48.711+0000] {taskinstance.py:1382} INFO - Executing <Task(BashOperator): import_data_to_csv> on 2023-08-29 00:00:00+00:00
[2023-08-30T19:01:48.718+0000] {standard_task_runner.py:57} INFO - Started process 714 to run task
[2023-08-30T19:01:48.727+0000] {standard_task_runner.py:84} INFO - Running: ['***', 'tasks', 'run', 'traffic_report', 'import_data_to_csv', 'scheduled__2023-08-29T00:00:00+00:00', '--job-id', '20', '--raw', '--subdir', 'DAGS_FOLDER/traffic_dag.py', '--cfg-path', '/tmp/tmpyzbv09r9']
[2023-08-30T19:01:48.731+0000] {standard_task_runner.py:85} INFO - Job 20: Subtask import_data_to_csv
[2023-08-30T19:01:48.971+0000] {logging_mixin.py:151} WARNING - /home/***/.local/lib/python3.8/site-packages/***/settings.py:195 DeprecationWarning: The sql_alchemy_conn option in [core] has been moved to the sql_alchemy_conn option in [database] - the old setting has been used, but please update your config.
[2023-08-30T19:01:54.731+0000] {task_command.py:415} INFO - Running <TaskInstance: traffic_report.import_data_to_csv scheduled__2023-08-29T00:00:00+00:00 [running]> on host 5e7fbf8b7901
[2023-08-30T19:01:54.843+0000] {logging_mixin.py:151} WARNING - /home/***/.local/lib/python3.8/site-packages/***/utils/sqlalchemy.py:124 DeprecationWarning: The sql_alchemy_conn option in [core] has been moved to the sql_alchemy_conn option in [database] - the old setting has been used, but please update your config.
[2023-08-30T19:01:55.096+0000] {taskinstance.py:1660} INFO - Exporting env vars: AIRFLOW_CTX_DAG_OWNER='***' AIRFLOW_CTX_DAG_ID='traffic_report' AIRFLOW_CTX_TASK_ID='import_data_to_csv' AIRFLOW_CTX_EXECUTION_DATE='2023-08-29T00:00:00+00:00' AIRFLOW_CTX_TRY_NUMBER='2' AIRFLOW_CTX_DAG_RUN_ID='scheduled__2023-08-29T00:00:00+00:00'
[2023-08-30T19:01:55.276+0000] {subprocess.py:63} INFO - Tmp dir root location: /tmp
[2023-08-30T19:01:55.291+0000] {subprocess.py:75} INFO - Running command: ['/bin/bash', '-c', 'python /Users/jinee.hira/Dropbox/virtual_envs/austin-flow/***/dags/data_ingestion.py --date 2023-08-29']
[2023-08-30T19:01:55.341+0000] {subprocess.py:86} INFO - Output:
[2023-08-30T19:02:06.274+0000] {subprocess.py:93} INFO - python: can't open file '/Users/jinee.hira/Dropbox/virtual_envs/austin-flow/***/dags/data_ingestion.py': [Errno 2] No such file or directory
[2023-08-30T19:02:06.282+0000] {subprocess.py:97} INFO - Command exited with return code 2
[2023-08-30T19:02:06.299+0000] {taskinstance.py:1943} ERROR - Task failed with exception
Traceback (most recent call last):
  File "/home/airflow/.local/lib/python3.8/site-packages/airflow/operators/bash.py", line 210, in execute
    raise AirflowException(
airflow.exceptions.AirflowException: Bash command failed. The command returned a non-zero exit code 2.
[2023-08-30T19:02:06.311+0000] {taskinstance.py:1400} INFO - Marking task as FAILED. dag_id=traffic_report, task_id=import_data_to_csv, execution_date=20230829T000000, start_date=20230830T190148, end_date=20230830T190206
[2023-08-30T19:02:06.331+0000] {standard_task_runner.py:104} ERROR - Failed to execute job 20 for task import_data_to_csv (Bash command failed. The command returned a non-zero exit code 2.; 714)
[2023-08-30T19:02:06.351+0000] {local_task_job_runner.py:228} INFO - Task exited with return code 1
[2023-08-30T19:02:06.386+0000] {taskinstance.py:2784} INFO - 0 downstream tasks scheduled from follow-on schedule check
[2023-08-30T19:22:01.983+0000] {logging_mixin.py:151} WARNING - /home/***/.local/lib/python3.8/site-packages/***/utils/sqlalchemy.py:124 DeprecationWarning: The sql_alchemy_conn option in [core] has been moved to the sql_alchemy_conn option in [database] - the old setting has been used, but please update your config.
[2023-08-30T19:22:01.994+0000] {taskinstance.py:1159} INFO - Dependencies all met for dep_context=non-requeueable deps ti=<TaskInstance: traffic_report.import_data_to_csv scheduled__2023-08-29T00:00:00+00:00 [queued]>
[2023-08-30T19:22:02.005+0000] {taskinstance.py:1159} INFO - Dependencies all met for dep_context=requeueable deps ti=<TaskInstance: traffic_report.import_data_to_csv scheduled__2023-08-29T00:00:00+00:00 [queued]>
[2023-08-30T19:22:02.009+0000] {taskinstance.py:1361} INFO - Starting attempt 2 of 2
[2023-08-30T19:22:02.026+0000] {taskinstance.py:1382} INFO - Executing <Task(BashOperator): import_data_to_csv> on 2023-08-29 00:00:00+00:00
[2023-08-30T19:22:02.039+0000] {standard_task_runner.py:57} INFO - Started process 347 to run task
[2023-08-30T19:22:02.048+0000] {standard_task_runner.py:84} INFO - Running: ['***', 'tasks', 'run', 'traffic_report', 'import_data_to_csv', 'scheduled__2023-08-29T00:00:00+00:00', '--job-id', '15', '--raw', '--subdir', 'DAGS_FOLDER/traffic_dag.py', '--cfg-path', '/tmp/tmpw6m3t2mc']
[2023-08-30T19:22:02.056+0000] {standard_task_runner.py:85} INFO - Job 15: Subtask import_data_to_csv
[2023-08-30T19:22:02.136+0000] {logging_mixin.py:151} WARNING - /home/***/.local/lib/python3.8/site-packages/***/settings.py:195 DeprecationWarning: The sql_alchemy_conn option in [core] has been moved to the sql_alchemy_conn option in [database] - the old setting has been used, but please update your config.
[2023-08-30T19:22:02.253+0000] {task_command.py:415} INFO - Running <TaskInstance: traffic_report.import_data_to_csv scheduled__2023-08-29T00:00:00+00:00 [running]> on host 884d86529f65
[2023-08-30T19:22:02.268+0000] {logging_mixin.py:151} WARNING - /home/***/.local/lib/python3.8/site-packages/***/utils/sqlalchemy.py:124 DeprecationWarning: The sql_alchemy_conn option in [core] has been moved to the sql_alchemy_conn option in [database] - the old setting has been used, but please update your config.
[2023-08-30T19:22:02.360+0000] {taskinstance.py:1660} INFO - Exporting env vars: AIRFLOW_CTX_DAG_OWNER='***' AIRFLOW_CTX_DAG_ID='traffic_report' AIRFLOW_CTX_TASK_ID='import_data_to_csv' AIRFLOW_CTX_EXECUTION_DATE='2023-08-29T00:00:00+00:00' AIRFLOW_CTX_TRY_NUMBER='2' AIRFLOW_CTX_DAG_RUN_ID='scheduled__2023-08-29T00:00:00+00:00'
[2023-08-30T19:22:02.369+0000] {subprocess.py:63} INFO - Tmp dir root location: /tmp
[2023-08-30T19:22:02.371+0000] {subprocess.py:75} INFO - Running command: ['/bin/bash', '-c', 'python ./dags/data_ingestion.py --date 2023-08-29']
[2023-08-30T19:22:02.398+0000] {subprocess.py:86} INFO - Output:
[2023-08-30T19:22:04.244+0000] {subprocess.py:93} INFO - python: can't open file './dags/data_ingestion.py': [Errno 2] No such file or directory
[2023-08-30T19:22:04.275+0000] {subprocess.py:97} INFO - Command exited with return code 2
[2023-08-30T19:22:04.373+0000] {taskinstance.py:1943} ERROR - Task failed with exception
Traceback (most recent call last):
  File "/home/airflow/.local/lib/python3.8/site-packages/airflow/operators/bash.py", line 210, in execute
    raise AirflowException(
airflow.exceptions.AirflowException: Bash command failed. The command returned a non-zero exit code 2.
[2023-08-30T19:22:04.398+0000] {taskinstance.py:1400} INFO - Marking task as FAILED. dag_id=traffic_report, task_id=import_data_to_csv, execution_date=20230829T000000, start_date=20230830T192201, end_date=20230830T192204
[2023-08-30T19:22:04.591+0000] {standard_task_runner.py:104} ERROR - Failed to execute job 15 for task import_data_to_csv (Bash command failed. The command returned a non-zero exit code 2.; 347)
[2023-08-30T19:22:04.642+0000] {local_task_job_runner.py:228} INFO - Task exited with return code 1
[2023-08-30T19:22:04.692+0000] {taskinstance.py:2784} INFO - 0 downstream tasks scheduled from follow-on schedule check
