[2023-08-29T19:48:58.821+0000] {logging_mixin.py:151} WARNING - /home/***/.local/lib/python3.8/site-packages/***/utils/sqlalchemy.py:124 DeprecationWarning: The sql_alchemy_conn option in [core] has been moved to the sql_alchemy_conn option in [database] - the old setting has been used, but please update your config.
[2023-08-29T19:48:58.831+0000] {taskinstance.py:1159} INFO - Dependencies all met for dep_context=non-requeueable deps ti=<TaskInstance: traffic_report.import_data_to_csv scheduled__2023-08-28T00:00:00+00:00 [queued]>
[2023-08-29T19:48:58.840+0000] {taskinstance.py:1159} INFO - Dependencies all met for dep_context=requeueable deps ti=<TaskInstance: traffic_report.import_data_to_csv scheduled__2023-08-28T00:00:00+00:00 [queued]>
[2023-08-29T19:48:58.842+0000] {taskinstance.py:1361} INFO - Starting attempt 2 of 2
[2023-08-29T19:48:58.857+0000] {taskinstance.py:1382} INFO - Executing <Task(BashOperator): import_data_to_csv> on 2023-08-28 00:00:00+00:00
[2023-08-29T19:48:58.866+0000] {standard_task_runner.py:57} INFO - Started process 609 to run task
[2023-08-29T19:48:58.875+0000] {standard_task_runner.py:84} INFO - Running: ['***', 'tasks', 'run', 'traffic_report', 'import_data_to_csv', 'scheduled__2023-08-28T00:00:00+00:00', '--job-id', '30', '--raw', '--subdir', 'DAGS_FOLDER/traffic_dag.py', '--cfg-path', '/tmp/tmp6xi9fn_e']
[2023-08-29T19:48:58.879+0000] {standard_task_runner.py:85} INFO - Job 30: Subtask import_data_to_csv
[2023-08-29T19:48:58.970+0000] {logging_mixin.py:151} WARNING - /home/***/.local/lib/python3.8/site-packages/***/settings.py:195 DeprecationWarning: The sql_alchemy_conn option in [core] has been moved to the sql_alchemy_conn option in [database] - the old setting has been used, but please update your config.
[2023-08-29T19:48:59.809+0000] {task_command.py:415} INFO - Running <TaskInstance: traffic_report.import_data_to_csv scheduled__2023-08-28T00:00:00+00:00 [running]> on host e69093e17de8
[2023-08-29T19:49:00.720+0000] {logging_mixin.py:151} WARNING - /home/***/.local/lib/python3.8/site-packages/***/utils/sqlalchemy.py:124 DeprecationWarning: The sql_alchemy_conn option in [core] has been moved to the sql_alchemy_conn option in [database] - the old setting has been used, but please update your config.
[2023-08-29T19:49:00.868+0000] {taskinstance.py:1660} INFO - Exporting env vars: AIRFLOW_CTX_DAG_OWNER='***' AIRFLOW_CTX_DAG_ID='traffic_report' AIRFLOW_CTX_TASK_ID='import_data_to_csv' AIRFLOW_CTX_EXECUTION_DATE='2023-08-28T00:00:00+00:00' AIRFLOW_CTX_TRY_NUMBER='2' AIRFLOW_CTX_DAG_RUN_ID='scheduled__2023-08-28T00:00:00+00:00'
[2023-08-29T19:49:00.897+0000] {subprocess.py:63} INFO - Tmp dir root location: /tmp
[2023-08-29T19:49:00.911+0000] {subprocess.py:75} INFO - Running command: ['/bin/bash', '-c', 'python /Users/jinee.hira/Dropbox/virtual_envs/austin-flow/***/dags/data_ingestion.py --date 2023-08-28']
[2023-08-29T19:49:00.931+0000] {subprocess.py:86} INFO - Output:
[2023-08-29T19:49:01.705+0000] {subprocess.py:93} INFO - python: can't open file '/Users/jinee.hira/Dropbox/virtual_envs/austin-flow/***/dags/data_ingestion.py': [Errno 2] No such file or directory
[2023-08-29T19:49:01.715+0000] {subprocess.py:97} INFO - Command exited with return code 2
[2023-08-29T19:49:01.733+0000] {taskinstance.py:1943} ERROR - Task failed with exception
Traceback (most recent call last):
  File "/home/airflow/.local/lib/python3.8/site-packages/airflow/operators/bash.py", line 210, in execute
    raise AirflowException(
airflow.exceptions.AirflowException: Bash command failed. The command returned a non-zero exit code 2.
[2023-08-29T19:49:01.741+0000] {taskinstance.py:1400} INFO - Marking task as FAILED. dag_id=traffic_report, task_id=import_data_to_csv, execution_date=20230828T000000, start_date=20230829T194858, end_date=20230829T194901
[2023-08-29T19:49:01.762+0000] {standard_task_runner.py:104} ERROR - Failed to execute job 30 for task import_data_to_csv (Bash command failed. The command returned a non-zero exit code 2.; 609)
[2023-08-29T19:49:01.788+0000] {local_task_job_runner.py:228} INFO - Task exited with return code 1
[2023-08-29T19:49:01.897+0000] {taskinstance.py:2784} INFO - 0 downstream tasks scheduled from follow-on schedule check
[2023-08-30T19:01:48.660+0000] {logging_mixin.py:151} WARNING - /home/***/.local/lib/python3.8/site-packages/***/utils/sqlalchemy.py:124 DeprecationWarning: The sql_alchemy_conn option in [core] has been moved to the sql_alchemy_conn option in [database] - the old setting has been used, but please update your config.
[2023-08-30T19:01:48.673+0000] {taskinstance.py:1159} INFO - Dependencies all met for dep_context=non-requeueable deps ti=<TaskInstance: traffic_report.import_data_to_csv scheduled__2023-08-28T00:00:00+00:00 [queued]>
[2023-08-30T19:01:48.689+0000] {taskinstance.py:1159} INFO - Dependencies all met for dep_context=requeueable deps ti=<TaskInstance: traffic_report.import_data_to_csv scheduled__2023-08-28T00:00:00+00:00 [queued]>
[2023-08-30T19:01:48.691+0000] {taskinstance.py:1361} INFO - Starting attempt 2 of 2
[2023-08-30T19:01:48.716+0000] {taskinstance.py:1382} INFO - Executing <Task(BashOperator): import_data_to_csv> on 2023-08-28 00:00:00+00:00
[2023-08-30T19:01:48.737+0000] {standard_task_runner.py:57} INFO - Started process 719 to run task
[2023-08-30T19:01:48.758+0000] {standard_task_runner.py:84} INFO - Running: ['***', 'tasks', 'run', 'traffic_report', 'import_data_to_csv', 'scheduled__2023-08-28T00:00:00+00:00', '--job-id', '19', '--raw', '--subdir', 'DAGS_FOLDER/traffic_dag.py', '--cfg-path', '/tmp/tmppxlyxru2']
[2023-08-30T19:01:48.782+0000] {standard_task_runner.py:85} INFO - Job 19: Subtask import_data_to_csv
[2023-08-30T19:01:51.051+0000] {logging_mixin.py:151} WARNING - /home/***/.local/lib/python3.8/site-packages/***/settings.py:195 DeprecationWarning: The sql_alchemy_conn option in [core] has been moved to the sql_alchemy_conn option in [database] - the old setting has been used, but please update your config.
[2023-08-30T19:01:54.752+0000] {task_command.py:415} INFO - Running <TaskInstance: traffic_report.import_data_to_csv scheduled__2023-08-28T00:00:00+00:00 [running]> on host 5e7fbf8b7901
[2023-08-30T19:01:54.841+0000] {logging_mixin.py:151} WARNING - /home/***/.local/lib/python3.8/site-packages/***/utils/sqlalchemy.py:124 DeprecationWarning: The sql_alchemy_conn option in [core] has been moved to the sql_alchemy_conn option in [database] - the old setting has been used, but please update your config.
[2023-08-30T19:01:55.388+0000] {taskinstance.py:1660} INFO - Exporting env vars: AIRFLOW_CTX_DAG_OWNER='***' AIRFLOW_CTX_DAG_ID='traffic_report' AIRFLOW_CTX_TASK_ID='import_data_to_csv' AIRFLOW_CTX_EXECUTION_DATE='2023-08-28T00:00:00+00:00' AIRFLOW_CTX_TRY_NUMBER='2' AIRFLOW_CTX_DAG_RUN_ID='scheduled__2023-08-28T00:00:00+00:00'
[2023-08-30T19:01:55.442+0000] {subprocess.py:63} INFO - Tmp dir root location: /tmp
[2023-08-30T19:01:55.482+0000] {subprocess.py:75} INFO - Running command: ['/bin/bash', '-c', 'python /Users/jinee.hira/Dropbox/virtual_envs/austin-flow/***/dags/data_ingestion.py --date 2023-08-28']
[2023-08-30T19:01:56.059+0000] {subprocess.py:86} INFO - Output:
[2023-08-30T19:02:06.234+0000] {subprocess.py:93} INFO - python: can't open file '/Users/jinee.hira/Dropbox/virtual_envs/austin-flow/***/dags/data_ingestion.py': [Errno 2] No such file or directory
[2023-08-30T19:02:06.237+0000] {subprocess.py:97} INFO - Command exited with return code 2
[2023-08-30T19:02:06.259+0000] {taskinstance.py:1943} ERROR - Task failed with exception
Traceback (most recent call last):
  File "/home/airflow/.local/lib/python3.8/site-packages/airflow/operators/bash.py", line 210, in execute
    raise AirflowException(
airflow.exceptions.AirflowException: Bash command failed. The command returned a non-zero exit code 2.
[2023-08-30T19:02:06.267+0000] {taskinstance.py:1400} INFO - Marking task as FAILED. dag_id=traffic_report, task_id=import_data_to_csv, execution_date=20230828T000000, start_date=20230830T190148, end_date=20230830T190206
[2023-08-30T19:02:06.299+0000] {standard_task_runner.py:104} ERROR - Failed to execute job 19 for task import_data_to_csv (Bash command failed. The command returned a non-zero exit code 2.; 719)
[2023-08-30T19:02:06.352+0000] {local_task_job_runner.py:228} INFO - Task exited with return code 1
[2023-08-30T19:02:06.390+0000] {taskinstance.py:2784} INFO - 0 downstream tasks scheduled from follow-on schedule check
[2023-08-30T19:22:05.092+0000] {logging_mixin.py:151} WARNING - /home/***/.local/lib/python3.8/site-packages/***/utils/sqlalchemy.py:124 DeprecationWarning: The sql_alchemy_conn option in [core] has been moved to the sql_alchemy_conn option in [database] - the old setting has been used, but please update your config.
[2023-08-30T19:22:05.101+0000] {taskinstance.py:1159} INFO - Dependencies all met for dep_context=non-requeueable deps ti=<TaskInstance: traffic_report.import_data_to_csv scheduled__2023-08-28T00:00:00+00:00 [queued]>
[2023-08-30T19:22:05.109+0000] {taskinstance.py:1159} INFO - Dependencies all met for dep_context=requeueable deps ti=<TaskInstance: traffic_report.import_data_to_csv scheduled__2023-08-28T00:00:00+00:00 [queued]>
[2023-08-30T19:22:05.111+0000] {taskinstance.py:1361} INFO - Starting attempt 2 of 2
[2023-08-30T19:22:05.121+0000] {taskinstance.py:1382} INFO - Executing <Task(BashOperator): import_data_to_csv> on 2023-08-28 00:00:00+00:00
[2023-08-30T19:22:05.126+0000] {standard_task_runner.py:57} INFO - Started process 354 to run task
[2023-08-30T19:22:05.129+0000] {standard_task_runner.py:84} INFO - Running: ['***', 'tasks', 'run', 'traffic_report', 'import_data_to_csv', 'scheduled__2023-08-28T00:00:00+00:00', '--job-id', '18', '--raw', '--subdir', 'DAGS_FOLDER/traffic_dag.py', '--cfg-path', '/tmp/tmp3t0ide3l']
[2023-08-30T19:22:05.135+0000] {standard_task_runner.py:85} INFO - Job 18: Subtask import_data_to_csv
[2023-08-30T19:22:05.150+0000] {logging_mixin.py:151} WARNING - /home/***/.local/lib/python3.8/site-packages/***/settings.py:195 DeprecationWarning: The sql_alchemy_conn option in [core] has been moved to the sql_alchemy_conn option in [database] - the old setting has been used, but please update your config.
[2023-08-30T19:22:05.204+0000] {task_command.py:415} INFO - Running <TaskInstance: traffic_report.import_data_to_csv scheduled__2023-08-28T00:00:00+00:00 [running]> on host 884d86529f65
[2023-08-30T19:22:05.218+0000] {logging_mixin.py:151} WARNING - /home/***/.local/lib/python3.8/site-packages/***/utils/sqlalchemy.py:124 DeprecationWarning: The sql_alchemy_conn option in [core] has been moved to the sql_alchemy_conn option in [database] - the old setting has been used, but please update your config.
[2023-08-30T19:22:05.303+0000] {taskinstance.py:1660} INFO - Exporting env vars: AIRFLOW_CTX_DAG_OWNER='***' AIRFLOW_CTX_DAG_ID='traffic_report' AIRFLOW_CTX_TASK_ID='import_data_to_csv' AIRFLOW_CTX_EXECUTION_DATE='2023-08-28T00:00:00+00:00' AIRFLOW_CTX_TRY_NUMBER='2' AIRFLOW_CTX_DAG_RUN_ID='scheduled__2023-08-28T00:00:00+00:00'
[2023-08-30T19:22:05.316+0000] {subprocess.py:63} INFO - Tmp dir root location: /tmp
[2023-08-30T19:22:05.319+0000] {subprocess.py:75} INFO - Running command: ['/bin/bash', '-c', 'python ./dags/data_ingestion.py --date 2023-08-28']
[2023-08-30T19:22:05.333+0000] {subprocess.py:86} INFO - Output:
[2023-08-30T19:22:05.439+0000] {subprocess.py:93} INFO - python: can't open file './dags/data_ingestion.py': [Errno 2] No such file or directory
[2023-08-30T19:22:05.444+0000] {subprocess.py:97} INFO - Command exited with return code 2
[2023-08-30T19:22:05.457+0000] {taskinstance.py:1943} ERROR - Task failed with exception
Traceback (most recent call last):
  File "/home/airflow/.local/lib/python3.8/site-packages/airflow/operators/bash.py", line 210, in execute
    raise AirflowException(
airflow.exceptions.AirflowException: Bash command failed. The command returned a non-zero exit code 2.
[2023-08-30T19:22:05.461+0000] {taskinstance.py:1400} INFO - Marking task as FAILED. dag_id=traffic_report, task_id=import_data_to_csv, execution_date=20230828T000000, start_date=20230830T192205, end_date=20230830T192205
[2023-08-30T19:22:05.473+0000] {standard_task_runner.py:104} ERROR - Failed to execute job 18 for task import_data_to_csv (Bash command failed. The command returned a non-zero exit code 2.; 354)
[2023-08-30T19:22:05.505+0000] {local_task_job_runner.py:228} INFO - Task exited with return code 1
[2023-08-30T19:22:05.529+0000] {taskinstance.py:2784} INFO - 0 downstream tasks scheduled from follow-on schedule check
